Workbook

Sheet QA_Summary
A1: field | B1: value | C1: note
A2: qa_run_id | B2: 20260909_154500 | C2: New independent run; awaiting_confirmation=true
A3: batch | B3: qa_batch_004 | C3: Only batch 04 positions 31-40
A4: source_workbook | B4: resutls\jeminise.com\20260906_234129\revisions\qa_batch_004_r5\SEO_Product_Optimization_qa_batch_004_r5.xlsx
A5: source_sha256_before | B5: F8E626867914229BF74FCFB13F4746B3103E08697DD69005E891661C8418B71D
A6: source_sha256_after | B6: F8E626867914229BF74FCFB13F4746B3103E08697DD69005E891661C8418B71D
A7: market | B7: US
A8: language | B8: English
A9: prompt_rubric_version | B9: prompt_qa.md + user rubric 2026-09-09
A10: product_keys | B10: =COUNTA(QA_Products!C2:C11) -> 10 | C10: Expected 10
A11: criteria_rows | B11: =COUNTA(QA_Criteria!A2:A111) -> 110 | C11: Expected 110
A12: image_rows | B12: =COUNTA(QA_Images!A2:A63) -> 62 | C12: Expected 62 baseline images
A13: keyword_rows_locked | B13: 40 | C13: Source workbook locked by product_key
A14: buyer_rows_locked | B14: 10 | C14: Source workbook locked by product_key
A15: evidence_rows_locked | B15: 10 | C15: Source workbook locked by product_key
A16: batch_average_final | B16: =AVERAGE(QA_Products!T2:T11) -> 87.25 | C16: Only valid because all 10 complete
A17: batch_result | B17: =IF(COUNTIF(QA_Products!W2:W11,"QA_INCOMPLETE")>0,"QA_INCOMPLETE",IF(COUNTIF(QA_Products!W2:W11,"QA_FAIL")>0,"NOT_PASSED",IF(COUNTIF(QA_Products!W2:W11,"QA_REVISE")>0,"NEEDS_REVISION","PASSED"))) -> NEEDS_REVISION
A18: status_counts | B18: =TEXTJOIN("; ",TRUE,"PASS="&COUNTIF(QA_Products!W2:W11,"QA_PASS"),"REVISE="&COUNTIF(QA_Products!W2:W11,"QA_REVISE"),"FAIL="&COUNTIF(QA_Products!W2:W11,"QA_FAIL"),"INCOMPLETE="&COUNTIF(QA_Products!W2:W11,"QA_INCOMPLETE")) -> PASS=3; REVISE=7; FAIL=0; INCOMPLETE=0
A19: awaiting_confirmation | B19: TRUE | C19: Stop after batch 04

Sheet QA_Products
A1: qa_run_id | B1: inventory_position | C1: product_key | D1: product_id | E1: handle | F1: product_url | G1: canonical_live | H1: title_proposed_r5 | I1: meta_title_seo_r5 | J1: description_action | K1: page_read | L1: json_read | M1: image_expected | N1: image_rows_scored | O1: visual_coverage | P1: assessed_weight | Q1: verified_points | R1: score_floor | S1: score_ceiling | T1: final_score | U1: critical_count | V1: major_count | W1: status | X1: issue_refs | Y1: evidence_refs
A2: 20260909_154500 | B2: 31 | C2: jeminise.com+christmas-cardinals-near-snowy-birdhouse-patchwork-floral-quilt-b90d55a935-b90d55a935 | D2: 8834720170183 | E2: christmas-cardinals-near-snowy-birdhouse-patchwork-floral-quilt-b90d55a935-b90d55a935 | F2: https://jeminise.com/products/christmas-cardinals-near-snowy-birdhouse-patchwork-floral-quilt-b90d55a935-b90d55a935 | G2: https://jeminise.com/products/christmas-cardinals-near-snowy-birdhouse-patchwork-floral-quilt-b90d55a935-b90d55a935 | H2: Christmas Cardinal Birdhouse Quilt Set | I2: Christmas Cardinal Birdhouse Quilt Set | J2: SET | K2: TRUE | L2: TRUE | M2: 7 | N2: 7 | O2: =COUNTIFS(QA_Images!C:C,B2,QA_Images!Y:Y,1)/N2 -> 1 | P2: =SUMIFS(QA_Criteria!J:J,QA_Criteria!C:C,B2) -> 100 | Q2: =SUMIFS(QA_Criteria!I:I,QA_Criteria!C:C,B2) -> 95 | R2: =Q2 -> 95 | S2: =Q2+(100-P2) -> 95 | T2: =IF(AND(P2=100,K2=TRUE,O2=1),Q2,"") -> 95 | U2: =COUNTIFS(QA_Issues!C:C,B2,QA_Issues!F:F,TRUE) | V2: =COUNTIFS(QA_Issues!C:C,B2,QA_Issues!E:E,"MAJOR") | W2: =IF(U2>0,"QA_FAIL",IF(OR(P2<100,K2=FALSE,O2<1),"QA_INCOMPLETE",IF(T2<70,"QA_FAIL",IF(OR(T2<85,V2>0),"QA_REVISE","QA_PASS")))) -> QA_PASS | X2: B04-E1-REVISION-TRACE | Y2: live_031; serp_004_031; source rows locked by product_key
A3: 20260909_154500 | B3: 32 | C3: jeminise.com+christmas-cardinals-on-snowy-branches-patchwork-winter-quilt-8fa1a9e2ed-8fa1a9e2ed | D3: 8834709323975 | E3: christmas-cardinals-on-snowy-branches-patchwork-winter-quilt-8fa1a9e2ed-8fa1a9e2ed | F3: https://jeminise.com/products/christmas-cardinals-on-snowy-branches-patchwork-winter-quilt-8fa1a9e2ed-8fa1a9e2ed | G3: https://jeminise.com/products/christmas-cardinals-on-snowy-branches-patchwork-winter-quilt-8fa1a9e2ed-8fa1a9e2ed | H3: Christmas Cardinals Snowy Branches Quilt Set | I3: Christmas Cardinals Snowy Branches Quilt Set | J3: SET | K3: TRUE | L3: TRUE | M3: 5 | N3: 5 | O3: =COUNTIFS(QA_Images!C:C,B3,QA_Images!Y:Y,1)/N3 -> 1 | P3: =SUMIFS(QA_Criteria!J:J,QA_Criteria!C:C,B3) -> 100 | Q3: =SUMIFS(QA_Criteria!I:I,QA_Criteria!C:C,B3) -> 95 | R3: =Q3 -> 95 | S3: =Q3+(100-P3) -> 95 | T3: =IF(AND(P3=100,K3=TRUE,O3=1),Q3,"") -> 95 | U3: =COUNTIFS(QA_Issues!C:C,B3,QA_Issues!F:F,TRUE) | V3: =COUNTIFS(QA_Issues!C:C,B3,QA_Issues!E:E,"MAJOR") | W3: =IF(U3>0,"QA_FAIL",IF(OR(P3<100,K3=FALSE,O3<1),"QA_INCOMPLETE",IF(T3<70,"QA_FAIL",IF(OR(T3<85,V3>0),"QA_REVISE","QA_PASS")))) -> QA_PASS | X3: B04-E1-REVISION-TRACE | Y3: live_032; serp_004_032; source rows locked by product_key
A4: 20260909_154500 | B4: 33 | C4: jeminise.com+cow-with-landscape-patchwork-quilt-animal-farmhouse-printed-quilt-set | D4: 8867095806151 | E4: cow-with-landscape-patchwork-quilt-animal-farmhouse-printed-quilt-set | F4: https://jeminise.com/products/cow-with-landscape-patchwork-quilt-animal-farmhouse-printed-quilt-set | G4: https://jeminise.com/products/cow-with-landscape-patchwork-quilt-animal-farmhouse-printed-quilt-set | H4: Cow Landscape Farmhouse Quilt Set | I4: Cow Landscape Farmhouse Quilt Set | J4: SET | K4: TRUE | L4: TRUE | M4: 7 | N4: 7 | O4: =COUNTIFS(QA_Images!C:C,B4,QA_Images!Y:Y,1)/N4 -> 1 | P4: =SUMIFS(QA_Criteria!J:J,QA_Criteria!C:C,B4) -> 100 | Q4: =SUMIFS(QA_Criteria!I:I,QA_Criteria!C:C,B4) -> 95 | R4: =Q4 -> 95 | S4: =Q4+(100-P4) -> 95 | T4: =IF(AND(P4=100,K4=TRUE,O4=1),Q4,"") -> 95 | U4: =COUNTIFS(QA_Issues!C:C,B4,QA_Issues!F:F,TRUE) | V4: =COUNTIFS(QA_Issues!C:C,B4,QA_Issues!E:E,"MAJOR") | W4: =IF(U4>0,"QA_FAIL",IF(OR(P4<100,K4=FALSE,O4<1),"QA_INCOMPLETE",IF(T4<70,"QA_FAIL",IF(OR(T4<85,V4>0),"QA_REVISE","QA_PASS")))) -> QA_PASS | X4: B04-E1-REVISION-TRACE | Y4: live_033; serp_004_033; source rows locked by product_key
A5: 20260909_154500 | B5: 34 | C5: jeminise.com+crocodile-patchwork-printed-quilts-animal-patchwork-bedding | D5: 8867095445703 | E5: crocodile-patchwork-printed-quilts-animal-patchwork-bedding | F5: https://jeminise.com/products/crocodile-patchwork-printed-quilts-animal-patchwork-bedding | G5: https://jeminise.com/products/crocodile-patchwork-printed-quilts-animal-patchwork-bedding | H5: Crocodile Patchwork Animal Quilt Set | I5: Crocodile Patchwork Animal Quilt Set | J5: SET | K5: TRUE | L5: TRUE | M5: 7 | N5: 7 | O5: =COUNTIFS(QA_Images!C:C,B5,QA_Images!Y:Y,1)/N5 -> 1 | P5: =SUMIFS(QA_Criteria!J:J,QA_Criteria!C:C,B5) -> 100 | Q5: =SUMIFS(QA_Criteria!I:I,QA_Criteria!C:C,B5) -> 77.5 | R5: =Q5 -> 77.5 | S5: =Q5+(100-P5) -> 77.5 | T5: =IF(AND(P5=100,K5=TRUE,O5=1),Q5,"") -> 77.5 | U5: =COUNTIFS(QA_Issues!C:C,B5,QA_Issues!F:F,TRUE) | V5: =COUNTIFS(QA_Issues!C:C,B5,QA_Issues!E:E,"MAJOR") -> 1 | W5: =IF(U5>0,"QA_FAIL",IF(OR(P5<100,K5=FALSE,O5<1),"QA_INCOMPLETE",IF(T5<70,"QA_FAIL",IF(OR(T5<85,V5>0),"QA_REVISE","QA_PASS")))) -> QA_REVISE | X5: B04-034-D2-ALLIGATOR;B04-E1-REVISION-TRACE | Y5: live_034; serp_004_034; source rows locked by product_key
A6: 20260909_154500 | B6: 35 | C6: jeminise.com+custom-retro-football-art-bedding-set-c66211cf75-c66211cf75 | D6: 8834768699591 | E6: custom-retro-football-art-bedding-set-c66211cf75-c66211cf75 | F6: https://jeminise.com/products/custom-retro-football-art-bedding-set-c66211cf75-c66211cf75 | G6: https://jeminise.com/products/custom-retro-football-art-bedding-set-c66211cf75-c66211cf75 | H6: Personalized Retro Football Flag Comforter Set | I6: Personalized Retro Football Flag Comforter Set | J6: SET | K6: TRUE | L6: TRUE | M6: 6 | N6: 6 | O6: =COUNTIFS(QA_Images!C:C,B6,QA_Images!Y:Y,1)/N6 -> 1 | P6: =SUMIFS(QA_Criteria!J:J,QA_Criteria!C:C,B6) -> 100 | Q6: =SUMIFS(QA_Criteria!I:I,QA_Criteria!C:C,B6) -> 85 | R6: =Q6 -> 85 | S6: =Q6+(100-P6) -> 85 | T6: =IF(AND(P6=100,K6=TRUE,O6=1),Q6,"") -> 85 | U6: =COUNTIFS(QA_Issues!C:C,B6,QA_Issues!F:F,TRUE) | V6: =COUNTIFS(QA_Issues!C:C,B6,QA_Issues!E:E,"MAJOR") -> 1 | W6: =IF(U6>0,"QA_FAIL",IF(OR(P6<100,K6=FALSE,O6<1),"QA_INCOMPLETE",IF(T6<70,"QA_FAIL",IF(OR(T6<85,V6>0),"QA_REVISE","QA_PASS")))) -> QA_REVISE | X6: B04-035-PERS-CONTROL;B04-E1-REVISION-TRACE | Y6: live_035; serp_004_035; source rows locked by product_key
A7: 20260909_154500 | B7: 36 | C7: jeminise.com+custom-american-football-close-up-on-grunge-vintage-comforter-26540e3264-26540e3264 | D7: 8834754445511 | E7: custom-american-football-close-up-on-grunge-vintage-comforter-26540e3264-26540e3264 | F7: https://jeminise.com/products/custom-american-football-close-up-on-grunge-vintage-comforter-26540e3264-26540e3264 | G7: https://jeminise.com/products/custom-american-football-close-up-on-grunge-vintage-comforter-26540e3264-26540e3264 | H7: Personalized Grunge Football Comforter Set | I7: Personalized Grunge Football Comforter Set | J7: SET | K7: TRUE | L7: TRUE | M7: 6 | N7: 6 | O7: =COUNTIFS(QA_Images!C:C,B7,QA_Images!Y:Y,1)/N7 -> 1 | P7: =SUMIFS(QA_Criteria!J:J,QA_Criteria!C:C,B7) -> 100 | Q7: =SUMIFS(QA_Criteria!I:I,QA_Criteria!C:C,B7) -> 85 | R7: =Q7 -> 85 | S7: =Q7+(100-P7) -> 85 | T7: =IF(AND(P7=100,K7=TRUE,O7=1),Q7,"") -> 85 | U7: =COUNTIFS(QA_Issues!C:C,B7,QA_Issues!F:F,TRUE) | V7: =COUNTIFS(QA_Issues!C:C,B7,QA_Issues!E:E,"MAJOR") -> 1 | W7: =IF(U7>0,"QA_FAIL",IF(OR(P7<100,K7=FALSE,O7<1),"QA_INCOMPLETE",IF(T7<70,"QA_FAIL",IF(OR(T7<85,V7>0),"QA_REVISE","QA_PASS")))) -> QA_REVISE | X7: B04-036-PERS-CONTROL;B04-E1-REVISION-TRACE | Y7: live_036; serp_004_036; source rows locked by product_key
A8: 20260909_154500 | B8: 37 | C8: jeminise.com+custom-american-football-on-cosmic-background-vintage-comforter-62a3849621-62a3849621 | D8: 8834752676039 | E8: custom-american-football-on-cosmic-background-vintage-comforter-62a3849621-62a3849621 | F8: https://jeminise.com/products/custom-american-football-on-cosmic-background-vintage-comforter-62a3849621-62a3849621 | G8: https://jeminise.com/products/custom-american-football-on-cosmic-background-vintage-comforter-62a3849621-62a3849621 | H8: Personalized Cosmic Football Comforter Set | I8: Personalized Cosmic Football Comforter Set | J8: SET | K8: TRUE | L8: TRUE | M8: 6 | N8: 6 | O8: =COUNTIFS(QA_Images!C:C,B8,QA_Images!Y:Y,1)/N8 -> 1 | P8: =SUMIFS(QA_Criteria!J:J,QA_Criteria!C:C,B8) -> 100 | Q8: =SUMIFS(QA_Criteria!I:I,QA_Criteria!C:C,B8) -> 85 | R8: =Q8 -> 85 | S8: =Q8+(100-P8) -> 85 | T8: =IF(AND(P8=100,K8=TRUE,O8=1),Q8,"") -> 85 | U8: =COUNTIFS(QA_Issues!C:C,B8,QA_Issues!F:F,TRUE) | V8: =COUNTIFS(QA_Issues!C:C,B8,QA_Issues!E:E,"MAJOR") -> 1 | W8: =IF(U8>0,"QA_FAIL",IF(OR(P8<100,K8=FALSE,O8<1),"QA_INCOMPLETE",IF(T8<70,"QA_FAIL",IF(OR(T8<85,V8>0),"QA_REVISE","QA_PASS")))) -> QA_REVISE | X8: B04-037-PERS-CONTROL;B04-E1-REVISION-TRACE | Y8: live_037; serp_004_037; source rows locked by product_key
A9: 20260909_154500 | B9: 38 | C9: jeminise.com+custom-american-football-on-usa-flag-background-comforter-703a7c0d82-703a7c0d82 | D9: 8834767421639 | E9: custom-american-football-on-usa-flag-background-comforter-703a7c0d82-703a7c0d82 | F9: https://jeminise.com/products/custom-american-football-on-usa-flag-background-comforter-703a7c0d82-703a7c0d82 | G9: https://jeminise.com/products/custom-american-football-on-usa-flag-background-comforter-703a7c0d82-703a7c0d82 | H9: Personalized USA Flag Football Comforter Set | I9: Personalized USA Flag Football Comforter Set | J9: SET | K9: TRUE | L9: TRUE | M9: 6 | N9: 6 | O9: =COUNTIFS(QA_Images!C:C,B9,QA_Images!Y:Y,1)/N9 -> 1 | P9: =SUMIFS(QA_Criteria!J:J,QA_Criteria!C:C,B9) -> 100 | Q9: =SUMIFS(QA_Criteria!I:I,QA_Criteria!C:C,B9) -> 85 | R9: =Q9 -> 85 | S9: =Q9+(100-P9) -> 85 | T9: =IF(AND(P9=100,K9=TRUE,O9=1),Q9,"") -> 85 | U9: =COUNTIFS(QA_Issues!C:C,B9,QA_Issues!F:F,TRUE) | V9: =COUNTIFS(QA_Issues!C:C,B9,QA_Issues!E:E,"MAJOR") -> 1 | W9: =IF(U9>0,"QA_FAIL",IF(OR(P9<100,K9=FALSE,O9<1),"QA_INCOMPLETE",IF(T9<70,"QA_FAIL",IF(OR(T9<85,V9>0),"QA_REVISE","QA_PASS")))) -> QA_REVISE | X9: B04-038-PERS-CONTROL;B04-E1-REVISION-TRACE | Y9: live_038; serp_004_038; source rows locked by product_key
A10: 20260909_154500 | B10: 39 | C10: jeminise.com+custom-american-football-with-paint-splash-background-vintage-comforter-da0e1d5bf1-da0e1d5bf1 | D10: 8834773319879 | E10: custom-american-football-with-paint-splash-background-vintage-comforter-da0e1d5bf1-da0e1d5bf1 | F10: https://jeminise.com/products/custom-american-football-with-paint-splash-background-vintage-comforter-da0e1d5bf1-da0e1d5bf1 | G10: https://jeminise.com/products/custom-american-football-with-paint-splash-background-vintage-comforter-da0e1d5bf1-da0e1d5bf1 | H10: Personalized Paint Splash Football Comforter Set | I10: Personalized Paint Splash Football Comforter Set | J10: SET | K10: TRUE | L10: TRUE | M10: 6 | N10: 6 | O10: =COUNTIFS(QA_Images!C:C,B10,QA_Images!Y:Y,1)/N10 -> 1 | P10: =SUMIFS(QA_Criteria!J:J,QA_Criteria!C:C,B10) -> 100 | Q10: =SUMIFS(QA_Criteria!I:I,QA_Criteria!C:C,B10) -> 85 | R10: =Q10 -> 85 | S10: =Q10+(100-P10) -> 85 | T10: =IF(AND(P10=100,K10=TRUE,O10=1),Q10,"") -> 85 | U10: =COUNTIFS(QA_Issues!C:C,B10,QA_Issues!F:F,TRUE) | V10: =COUNTIFS(QA_Issues!C:C,B10,QA_Issues!E:E,"MAJOR") -> 1 | W10: =IF(U10>0,"QA_FAIL",IF(OR(P10<100,K10=FALSE,O10<1),"QA_INCOMPLETE",IF(T10<70,"QA_FAIL",IF(OR(T10<85,V10>0),"QA_REVISE","QA_PASS")))) -> QA_REVISE | X10: B04-039-PERS-CONTROL;B04-E1-REVISION-TRACE | Y10: live_039; serp_004_039; source rows locked by product_key
A11: 20260909_154500 | B11: 40 | C11: jeminise.com+custom-american-football-with-patriotic-flag-comforter-4a3a1ed3c9-4a3a1ed3c9 | D11: 8834768011463 | E11: custom-american-football-with-patriotic-flag-comforter-4a3a1ed3c9-4a3a1ed3c9 | F11: https://jeminise.com/products/custom-american-football-with-patriotic-flag-comforter-4a3a1ed3c9-4a3a1ed3c9 | G11: https://jeminise.com/products/custom-american-football-with-patriotic-flag-comforter-4a3a1ed3c9-4a3a1ed3c9 | H11: Personalized Patriotic Football Comforter Set | I11: Personalized Patriotic Football Comforter Set | J11: SET | K11: TRUE | L11: TRUE | M11: 6 | N11: 6 | O11: =COUNTIFS(QA_Images!C:C,B11,QA_Images!Y:Y,1)/N11 -> 1 | P11: =SUMIFS(QA_Criteria!J:J,QA_Criteria!C:C,B11) -> 100 | Q11: =SUMIFS(QA_Criteria!I:I,QA_Criteria!C:C,B11) -> 85 | R11: =Q11 -> 85 | S11: =Q11+(100-P11) -> 85 | T11: =IF(AND(P11=100,K11=TRUE,O11=1),Q11,"") -> 85 | U11: =COUNTIFS(QA_Issues!C:C,B11,QA_Issues!F:F,TRUE) | V11: =COUNTIFS(QA_Issues!C:C,B11,QA_Issues!E:E,"MAJOR") -> 1 | W11: =IF(U11>0,"QA_FAIL",IF(OR(P11<100,K11=FALSE,O11<1),"QA_INCOMPLETE",IF(T11<70,"QA_FAIL",IF(OR(T11<85,V11>0),"QA_REVISE","QA_PASS")))) -> QA_REVISE | X11: B04-040-PERS-CONTROL;B04-E1-REVISION-TRACE | Y11: live_040; serp_004_040; source rows locked by product_key

Sheet QA_Criteria
A1: criterion_id | B1: qa_run_id | C1: inventory_position | D1: product_key | E1: criterion | F1: weight | G1: rating | H1: rating_value | I1: verified_points | J1: assessed_weight | K1: reason | L1: evidence_ref
A2: B04-031-P1 | B2: 20260909_154500 | C2: 31 | D2: jeminise.com+christmas-cardinals-near-snowy-birdhouse-patchwork-floral-quilt-b90d55a935-b90d55a935 | E2: P1 | F2: 15 | G2: FULL | H2: 1 | I2: =H2*F2 -> 15 | J2: =IF(G2<>"NOT_CHECKED",F2,0) -> 15 | K2: Live page/JSON identity matched locked product ID/handle; proposed title reviewed against product motif for position 31. | L2: SEO_Products row locked by product_key; live HTML/JSON snapshot 031
A3: B04-031-P2 | B3: 20260909_154500 | C3: 31 | D3: jeminise.com+christmas-cardinals-near-snowy-birdhouse-patchwork-floral-quilt-b90d55a935-b90d55a935 | E3: P2 | F3: 10 | G3: FULL | H3: 1 | I3: =H3*F3 -> 10 | J3: =IF(G3<>"NOT_CHECKED",F3,0) -> 10 | K3: Claims checked against live body/options/customizer evidence. Customizer evidence: name control evidence found. | L3: SEO_Products row locked by product_key; live HTML/JSON snapshot 031
A4: B04-031-K1 | B4: 20260909_154500 | C4: 31 | D4: jeminise.com+christmas-cardinals-near-snowy-birdhouse-patchwork-floral-quilt-b90d55a935-b90d55a935 | E4: K1 | F4: 10 | G4: FULL | H4: 1 | I4: =H4*F4 -> 10 | J4: =IF(G4<>"NOT_CHECKED",F4,0) -> 10 | K4: Keyword choice reviewed against product-specific motif and fresh US/English comparator queries. | L4: Keyword_Map rows for product_key; Buyer_Search_Research; serp_004_031_1/2
A5: B04-031-K2 | B5: 20260909_154500 | C5: 31 | D5: jeminise.com+christmas-cardinals-near-snowy-birdhouse-patchwork-floral-quilt-b90d55a935-b90d55a935 | E5: K2 | F5: 5 | G5: FULL | H5: 1 | I5: =H5*F5 -> 5 | J5: =IF(G5<>"NOT_CHECKED",F5,0) -> 5 | K5: SERP/product-page language supports buyer intent for finished bedding, with caution where niche query volume is weak. | L5: Keyword_Map rows for product_key; Buyer_Search_Research; serp_004_031_1/2
A6: B04-031-K3 | B6: 20260909_154500 | C6: 31 | D6: jeminise.com+christmas-cardinals-near-snowy-birdhouse-patchwork-floral-quilt-b90d55a935-b90d55a935 | E6: K3 | F6: 5 | G6: PARTIAL | H6: 0.5 | I6: =H6*F6 -> 2.5 | J6: =IF(G6<>"NOT_CHECKED",F6,0) -> 5 | K6: Cannibalization checked across batch 04; football variants share broad root but differ by retro/grunge/cosmic/USA/paint/patriotic modifier. | L6: Keyword_Map rows for product_key; Buyer_Search_Research; serp_004_031_1/2
A7: B04-031-T1 | B7: 20260909_154500 | C7: 31 | D7: jeminise.com+christmas-cardinals-near-snowy-birdhouse-patchwork-floral-quilt-b90d55a935-b90d55a935 | E7: T1 | F7: 10 | G7: FULL | H7: 1 | I7: =H7*F7 -> 10 | J7: =IF(G7<>"NOT_CHECKED",F7,0) -> 10 | K7: Mapped to meta_title_seo per requested mapping; title is customer-facing and reflects product evidence. | L7: SEO_Products row locked by product_key; live HTML/JSON snapshot 031
A8: B04-031-T2 | B8: 20260909_154500 | C8: 31 | D8: jeminise.com+christmas-cardinals-near-snowy-birdhouse-patchwork-floral-quilt-b90d55a935-b90d55a935 | E8: T2 | F8: 5 | G8: FULL | H8: 1 | I8: =H8*F8 -> 5 | J8: =IF(G8<>"NOT_CHECKED",F8,0) -> 5 | K8: Mapped to title_proposed and live theme H1 context; wording is product-facing. | L8: SEO_Products row locked by product_key; live HTML/JSON snapshot 031
A9: B04-031-D1 | B9: 20260909_154500 | C9: 31 | D9: jeminise.com+christmas-cardinals-near-snowy-birdhouse-patchwork-floral-quilt-b90d55a935-b90d55a935 | E9: D1 | F9: 5 | G9: FULL | H9: 1 | I9: =H9*F9 -> 5 | J9: =IF(G9<>"NOT_CHECKED",F9,0) -> 5 | K9: Mapped to meta_description_seo; length target treated editorially, not as a hard fail. | L9: SEO_Products row locked by product_key; live HTML/JSON snapshot 031
A10: B04-031-D2 | B10: 20260909_154500 | C10: 31 | D10: jeminise.com+christmas-cardinals-near-snowy-birdhouse-patchwork-floral-quilt-b90d55a935-b90d55a935 | E10: D2 | F10: 10 | G10: FULL | H10: 1 | I10: =H10*F10 -> 10 | J10: =IF(G10<>"NOT_CHECKED",F10,0) -> 10 | K10: Mapped to description_proposed_html; checked for customer-facing copy, claim support, material/care/components and no process wording. | L10: SEO_Products row locked by product_key; live HTML/JSON snapshot 031
A11: B04-031-I1 | B11: 20260909_154500 | C11: 31 | D11: jeminise.com+christmas-cardinals-near-snowy-birdhouse-patchwork-floral-quilt-b90d55a935-b90d55a935 | E11: I1 | F11: 20 | G11: DERIVED | H11: =AVERAGEIF(QA_Images!C:C,C11,QA_Images!W:W)/100 -> 1 | I11: =H11*F11 -> 20 | J11: =AVERAGEIF(QA_Images!C:C,C11,QA_Images!X:X)/100*F11 -> 20 | K11: I1 comes only from 7 images for this product; direct image visual coverage is 100%. | L11: QA_Images rows 2:8
A12: B04-031-E1 | B12: 20260909_154500 | C12: 31 | D12: jeminise.com+christmas-cardinals-near-snowy-birdhouse-patchwork-floral-quilt-b90d55a935-b90d55a935 | E12: E1 | F12: 5 | G12: PARTIAL | H12: 0.5 | I12: =H12*F12 -> 2.5 | J12: =IF(G12<>"NOT_CHECKED",F12,0) -> 5 | K12: Evidence chain exists but trace metadata still carries r4/revision_summary r4 fields, so traceability is partial. | L12: Product_Evidence row; revision_summary.json; SEO_Products revision column
A13: B04-032-P1 | B13: 20260909_154500 | C13: 32 | D13: jeminise.com+christmas-cardinals-on-snowy-branches-patchwork-winter-quilt-8fa1a9e2ed-8fa1a9e2ed | E13: P1 | F13: 15 | G13: FULL | H13: 1 | I13: =H13*F13 -> 15 | J13: =IF(G13<>"NOT_CHECKED",F13,0) -> 15 | K13: Live page/JSON identity matched locked product ID/handle; proposed title reviewed against product motif for position 32. | L13: SEO_Products row locked by product_key; live HTML/JSON snapshot 032
A14: B04-032-P2 | B14: 20260909_154500 | C14: 32 | D14: jeminise.com+christmas-cardinals-on-snowy-branches-patchwork-winter-quilt-8fa1a9e2ed-8fa1a9e2ed | E14: P2 | F14: 10 | G14: FULL | H14: 1 | I14: =H14*F14 -> 10 | J14: =IF(G14<>"NOT_CHECKED",F14,0) -> 10 | K14: Claims checked against live body/options/customizer evidence. Customizer evidence: not found. | L14: SEO_Products row locked by product_key; live HTML/JSON snapshot 032
A15: B04-032-K1 | B15: 20260909_154500 | C15: 32 | D15: jeminise.com+christmas-cardinals-on-snowy-branches-patchwork-winter-quilt-8fa1a9e2ed-8fa1a9e2ed | E15: K1 | F15: 10 | G15: FULL | H15: 1 | I15: =H15*F15 -> 10 | J15: =IF(G15<>"NOT_CHECKED",F15,0) -> 10 | K15: Keyword choice reviewed against product-specific motif and fresh US/English comparator queries. | L15: Keyword_Map rows for product_key; Buyer_Search_Research; serp_004_032_1/2
A16: B04-032-K2 | B16: 20260909_154500 | C16: 32 | D16: jeminise.com+christmas-cardinals-on-snowy-branches-patchwork-winter-quilt-8fa1a9e2ed-8fa1a9e2ed | E16: K2 | F16: 5 | G16: FULL | H16: 1 | I16: =H16*F16 -> 5 | J16: =IF(G16<>"NOT_CHECKED",F16,0) -> 5 | K16: SERP/product-page language supports buyer intent for finished bedding, with caution where niche query volume is weak. | L16: Keyword_Map rows for product_key; Buyer_Search_Research; serp_004_032_1/2
A17: B04-032-K3 | B17: 20260909_154500 | C17: 32 | D17: jeminise.com+christmas-cardinals-on-snowy-branches-patchwork-winter-quilt-8fa1a9e2ed-8fa1a9e2ed | E17: K3 | F17: 5 | G17: PARTIAL | H17: 0.5 | I17: =H17*F17 -> 2.5 | J17: =IF(G17<>"NOT_CHECKED",F17,0) -> 5 | K17: Cannibalization checked across batch 04; football variants share broad root but differ by retro/grunge/cosmic/USA/paint/patriotic modifier. | L17: Keyword_Map rows for product_key; Buyer_Search_Research; serp_004_032_1/2
A18: B04-032-T1 | B18: 20260909_154500 | C18: 32 | D18: jeminise.com+christmas-cardinals-on-snowy-branches-patchwork-winter-quilt-8fa1a9e2ed-8fa1a9e2ed | E18: T1 | F18: 10 | G18: FULL | H18: 1 | I18: =H18*F18 -> 10 | J18: =IF(G18<>"NOT_CHECKED",F18,0) -> 10 | K18: Mapped to meta_title_seo per requested mapping; title is customer-facing and reflects product evidence. | L18: SEO_Products row locked by product_key; live HTML/JSON snapshot 032
A19: B04-032-T2 | B19: 20260909_154500 | C19: 32 | D19: jeminise.com+christmas-cardinals-on-snowy-branches-patchwork-winter-quilt-8fa1a9e2ed-8fa1a9e2ed | E19: T2 | F19: 5 | G19: FULL | H19: 1 | I19: =H19*F19 -> 5 | J19: =IF(G19<>"NOT_CHECKED",F19,0) -> 5 | K19: Mapped to title_proposed and live theme H1 context; wording is product-facing. | L19: SEO_Products row locked by product_key; live HTML/JSON snapshot 032
A20: B04-032-D1 | B20: 20260909_154500 | C20: 32 | D20: jeminise.com+christmas-cardinals-on-snowy-branches-patchwork-winter-quilt-8fa1a9e2ed-8fa1a9e2ed | E20: D1 | F20: 5 | G20: FULL | H20: 1 | I20: =H20*F20 -> 5 | J20: =IF(G20<>"NOT_CHECKED",F20,0) -> 5 | K20: Mapped to meta_description_seo; length target treated editorially, not as a hard fail. | L20: SEO_Products row locked by product_key; live HTML/JSON snapshot 032
A21: B04-032-D2 | B21: 20260909_154500 | C21: 32 | D21: jeminise.com+christmas-cardinals-on-snowy-branches-patchwork-winter-quilt-8fa1a9e2ed-8fa1a9e2ed | E21: D2 | F21: 10 | G21: FULL | H21: 1 | I21: =H21*F21 -> 10 | J21: =IF(G21<>"NOT_CHECKED",F21,0) -> 10 | K21: Mapped to description_proposed_html; checked for customer-facing copy, claim support, material/care/components and no process wording. | L21: SEO_Products row locked by product_key; live HTML/JSON snapshot 032
A22: B04-032-I1 | B22: 20260909_154500 | C22: 32 | D22: jeminise.com+christmas-cardinals-on-snowy-branches-patchwork-winter-quilt-8fa1a9e2ed-8fa1a9e2ed | E22: I1 | F22: 20 | G22: DERIVED | H22: =AVERAGEIF(QA_Images!C:C,C22,QA_Images!W:W)/100 -> 1 | I22: =H22*F22 -> 20 | J22: =AVERAGEIF(QA_Images!C:C,C22,QA_Images!X:X)/100*F22 -> 20 | K22: I1 comes only from 5 images for this product; direct image visual coverage is 100%. | L22: QA_Images rows 9:13
A23: B04-032-E1 | B23: 20260909_154500 | C23: 32 | D23: jeminise.com+christmas-cardinals-on-snowy-branches-patchwork-winter-quilt-8fa1a9e2ed-8fa1a9e2ed | E23: E1 | F23: 5 | G23: PARTIAL | H23: 0.5 | I23: =H23*F23 -> 2.5 | J23: =IF(G23<>"NOT_CHECKED",F23,0) -> 5 | K23: Evidence chain exists but trace metadata still carries r4/revision_summary r4 fields, so traceability is partial. | L23: Product_Evidence row; revision_summary.json; SEO_Products revision column
A24: B04-033-P1 | B24: 20260909_154500 | C24: 33 | D24: jeminise.com+cow-with-landscape-patchwork-quilt-animal-farmhouse-printed-quilt-set | E24: P1 | F24: 15 | G24: FULL | H24: 1 | I24: =H24*F24 -> 15 | J24: =IF(G24<>"NOT_CHECKED",F24,0) -> 15 | K24: Live page/JSON identity matched locked product ID/handle; proposed title reviewed against product motif for position 33. | L24: SEO_Products row locked by product_key; live HTML/JSON snapshot 033
A25: B04-033-P2 | B25: 20260909_154500 | C25: 33 | D25: jeminise.com+cow-with-landscape-patchwork-quilt-animal-farmhouse-printed-quilt-set | E25: P2 | F25: 10 | G25: FULL | H25: 1 | I25: =H25*F25 -> 10 | J25: =IF(G25<>"NOT_CHECKED",F25,0) -> 10 | K25: Claims checked against live body/options/customizer evidence. Customizer evidence: name control evidence found. | L25: SEO_Products row locked by product_key; live HTML/JSON snapshot 033
A26: B04-033-K1 | B26: 20260909_154500 | C26: 33 | D26: jeminise.com+cow-with-landscape-patchwork-quilt-animal-farmhouse-printed-quilt-set | E26: K1 | F26: 10 | G26: FULL | H26: 1 | I26: =H26*F26 -> 10 | J26: =IF(G26<>"NOT_CHECKED",F26,0) -> 10 | K26: Keyword choice reviewed against product-specific motif and fresh US/English comparator queries. | L26: Keyword_Map rows for product_key; Buyer_Search_Research; serp_004_033_1/2
A27: B04-033-K2 | B27: 20260909_154500 | C27: 33 | D27: jeminise.com+cow-with-landscape-patchwork-quilt-animal-farmhouse-printed-quilt-set | E27: K2 | F27: 5 | G27: FULL | H27: 1 | I27: =H27*F27 -> 5 | J27: =IF(G27<>"NOT_CHECKED",F27,0) -> 5 | K27: SERP/product-page language supports buyer intent for finished bedding, with caution where niche query volume is weak. | L27: Keyword_Map rows for product_key; Buyer_Search_Research; serp_004_033_1/2
A28: B04-033-K3 | B28: 20260909_154500 | C28: 33 | D28: jeminise.com+cow-with-landscape-patchwork-quilt-animal-farmhouse-printed-quilt-set | E28: K3 | F28: 5 | G28: PARTIAL | H28: 0.5 | I28: =H28*F28 -> 2.5 | J28: =IF(G28<>"NOT_CHECKED",F28,0) -> 5 | K28: Cannibalization checked across batch 04; football variants share broad root but differ by retro/grunge/cosmic/USA/paint/patriotic modifier. | L28: Keyword_Map rows for product_key; Buyer_Search_Research; serp_004_033_1/2
A29: B04-033-T1 | B29: 20260909_154500 | C29: 33 | D29: jeminise.com+cow-with-landscape-patchwork-quilt-animal-farmhouse-printed-quilt-set | E29: T1 | F29: 10 | G29: FULL | H29: 1 | I29: =H29*F29 -> 10 | J29: =IF(G29<>"NOT_CHECKED",F29,0) -> 10 | K29: Mapped to meta_title_seo per requested mapping; title is customer-facing and reflects product evidence. | L29: SEO_Products row locked by product_key; live HTML/JSON snapshot 033
A30: B04-033-T2 | B30: 20260909_154500 | C30: 33 | D30: jeminise.com+cow-with-landscape-patchwork-quilt-animal-farmhouse-printed-quilt-set | E30: T2 | F30: 5 | G30: FULL | H30: 1 | I30: =H30*F30 -> 5 | J30: =IF(G30<>"NOT_CHECKED",F30,0) -> 5 | K30: Mapped to title_proposed and live theme H1 context; wording is product-facing. | L30: SEO_Products row locked by product_key; live HTML/JSON snapshot 033
A31: B04-033-D1 | B31: 20260909_154500 | C31: 33 | D31: jeminise.com+cow-with-landscape-patchwork-quilt-animal-farmhouse-printed-quilt-set | E31: D1 | F31: 5 | G31: FULL | H31: 1 | I31: =H31*F31 -> 5 | J31: =IF(G31<>"NOT_CHECKED",F31,0) -> 5 | K31: Mapped to meta_description_seo; length target treated editorially, not as a hard fail. | L31: SEO_Products row locked by product_key; live HTML/JSON snapshot 033
A32: B04-033-D2 | B32: 20260909_154500 | C32: 33 | D32: jeminise.com+cow-with-landscape-patchwork-quilt-animal-farmhouse-printed-quilt-set | E32: D2 | F32: 10 | G32: FULL | H32: 1 | I32: =H32*F32 -> 10 | J32: =IF(G32<>"NOT_CHECKED",F32,0) -> 10 | K32: Mapped to description_proposed_html; checked for customer-facing copy, claim support, material/care/components and no process wording. | L32: SEO_Products row locked by product_key; live HTML/JSON snapshot 033
A33: B04-033-I1 | B33: 20260909_154500 | C33: 33 | D33: jeminise.com+cow-with-landscape-patchwork-quilt-animal-farmhouse-printed-quilt-set | E33: I1 | F33: 20 | G33: DERIVED | H33: =AVERAGEIF(QA_Images!C:C,C33,QA_Images!W:W)/100 -> 1 | I33: =H33*F33 -> 20 | J33: =AVERAGEIF(QA_Images!C:C,C33,QA_Images!X:X)/100*F33 -> 20 | K33: I1 comes only from 7 images for this product; direct image visual coverage is 100%. | L33: QA_Images rows 14:20
A34: B04-033-E1 | B34: 20260909_154500 | C34: 33 | D34: jeminise.com+cow-with-landscape-patchwork-quilt-animal-farmhouse-printed-quilt-set | E34: E1 | F34: 5 | G34: PARTIAL | H34: 0.5 | I34: =H34*F34 -> 2.5 | J34: =IF(G34<>"NOT_CHECKED",F34,0) -> 5 | K34: Evidence chain exists but trace metadata still carries r4/revision_summary r4 fields, so traceability is partial. | L34: Product_Evidence row; revision_summary.json; SEO_Products revision column
A35: B04-034-P1 | B35: 20260909_154500 | C35: 34 | D35: jeminise.com+crocodile-patchwork-printed-quilts-animal-patchwork-bedding | E35: P1 | F35: 15 | G35: FULL | H35: 1 | I35: =H35*F35 -> 15 | J35: =IF(G35<>"NOT_CHECKED",F35,0) -> 15 | K35: Live page/JSON identity matched locked product ID/handle; proposed title reviewed against product motif for position 34. | L35: SEO_Products row locked by product_key; live HTML/JSON snapshot 034
A36: B04-034-P2 | B36: 20260909_154500 | C36: 34 | D36: jeminise.com+crocodile-patchwork-printed-quilts-animal-patchwork-bedding | E36: P2 | F36: 10 | G36: PARTIAL | H36: 0.5 | I36: =H36*F36 -> 5 | J36: =IF(G36<>"NOT_CHECKED",F36,0) -> 10 | K36: Claims checked against live body/options/customizer evidence. Customizer evidence: name control evidence found. | L36: SEO_Products row locked by product_key; live HTML/JSON snapshot 034
A37: B04-034-K1 | B37: 20260909_154500 | C37: 34 | D37: jeminise.com+crocodile-patchwork-printed-quilts-animal-patchwork-bedding | E37: K1 | F37: 10 | G37: PARTIAL | H37: 0.5 | I37: =H37*F37 -> 5 | J37: =IF(G37<>"NOT_CHECKED",F37,0) -> 10 | K37: Keyword choice reviewed against product-specific motif and fresh US/English comparator queries. | L37: Keyword_Map rows for product_key; Buyer_Search_Research; serp_004_034_1/2
A38: B04-034-K2 | B38: 20260909_154500 | C38: 34 | D38: jeminise.com+crocodile-patchwork-printed-quilts-animal-patchwork-bedding | E38: K2 | F38: 5 | G38: PARTIAL | H38: 0.5 | I38: =H38*F38 -> 2.5 | J38: =IF(G38<>"NOT_CHECKED",F38,0) -> 5 | K38: SERP/product-page language supports buyer intent for finished bedding, with caution where niche query volume is weak. | L38: Keyword_Map rows for product_key; Buyer_Search_Research; serp_004_034_1/2
A39: B04-034-K3 | B39: 20260909_154500 | C39: 34 | D39: jeminise.com+crocodile-patchwork-printed-quilts-animal-patchwork-bedding | E39: K3 | F39: 5 | G39: PARTIAL | H39: 0.5 | I39: =H39*F39 -> 2.5 | J39: =IF(G39<>"NOT_CHECKED",F39,0) -> 5 | K39: Cannibalization checked across batch 04; football variants share broad root but differ by retro/grunge/cosmic/USA/paint/patriotic modifier. | L39: Keyword_Map rows for product_key; Buyer_Search_Research; serp_004_034_1/2
A40: B04-034-T1 | B40: 20260909_154500 | C40: 34 | D40: jeminise.com+crocodile-patchwork-printed-quilts-animal-patchwork-bedding | E40: T1 | F40: 10 | G40: FULL | H40: 1 | I40: =H40*F40 -> 10 | J40: =IF(G40<>"NOT_CHECKED",F40,0) -> 10 | K40: Mapped to meta_title_seo per requested mapping; title is customer-facing and reflects product evidence. | L40: SEO_Products row locked by product_key; live HTML/JSON snapshot 034
...

Sheet QA_Images
A1: qa_image_key | B1: qa_run_id | C1: inventory_position | D1: product_key | E1: product_id | F1: media_id | G1: image_number | H1: image_location | I1: image_url | J1: download_status | K1: visual_opened | L1: visual_observation_new | M1: r5_observation_snapshot | N1: alt_proposed_r5 | O1: IM1_rating | P1: IM1_reason | Q1: IM2_rating | R1: IM2_reason | S1: IM3_rating | T1: IM3_reason | U1: IM4_rating | V1: IM4_reason | W1: image_verified_points | X1: image_assessed_weight | Y1: image_coverage | Z1: issue_refs | AA1: evidence_ref
A2: jeminise.com+christmas-cardinals-near-snowy-birdhouse-patchwork-floral-quilt-b90d55a935-b90d55a935|media:47540019036359|pos:1|url:5c4c5afdc06a | B2: 20260909_154500 | C2: 31 | D2: jeminise.com+christmas-cardinals-near-snowy-birdhouse-patchwork-floral-quilt-b90d55a935-b90d55a935 | E2: 8834720170183 | F2: 47540019036359 | G2: 1 | H2: GALLERY | I2: https://cdn.shopify.com/s/files/1/0792/5098/1063/files/cefa39b8e586dae0db27829a045f8d696721e4c0e044144b214323829fbee46b.jpg?v=1785099259 | J2: HTTP_200_DOWNLOADED | K2: TRUE | L2: Main quilt mockup with red cardinals and winter scene; visual supports cardinal Christmas bedding intent. | M2: Christmas cardinal birdhouse quilt bed mockup with red cardinals, snowy birdhouse, white flowers and red floral border. | N2: Christmas cardinal birdhouse quilt set on bed | O2: 1 | P2: Image was opened directly at readable resolution and motif/type matched product evidence. | Q2: 1 | R2: Alt/observation matches the visible asset type and motif after direct visual review. | S2: 1 | T2: Image is commercially useful for buyer verification of mockup/detail/size/material. | U2: 1 | V2: No material SEO/accessibility issue found for this image row. | W2: =SUM(O2*40,Q2*30,S2*20,U2*10) -> 100 | X2: =SUM(IF(O2<>"NOT_CHECKED",40,0),IF(Q2<>"NOT_CHECKED",30,0),IF(S2<>"NOT_CHECKED",20,0),IF(U2<>"NOT_CHECKED",10,0)) -> 100 | Y2: =IF(X2=100,1,0) -> 1 | AA2: source_snapshot/images + contact_sheet_031
A3: jeminise.com+christmas-cardinals-near-snowy-birdhouse-patchwork-floral-quilt-b90d55a935-b90d55a935|media:47540019069127|pos:2|url:a4e8dedb35ab | B3: 20260909_154500 | C3: 31 | D3: jeminise.com+christmas-cardinals-near-snowy-birdhouse-patchwork-floral-quilt-b90d55a935-b90d55a935 | E3: 8834720170183 | F3: 47540019069127 | G3: 2 | H3: GALLERY | I3: https://cdn.shopify.com/s/files/1/0792/5098/1063/files/817cf504495341989c34e5153f75779357b3dd16c9af88d5e8f16bf5cdd1d8a4.jpg?v=1785099259 | J3: HTTP_200_DOWNLOADED | K3: TRUE | L3: Product gallery mockup/close-up reviewed visually against r5 observation and proposed alt. | M3: Bedroom mockup with cardinal birdhouse quilt and premium printed craft callout. | N3: Cardinal birdhouse quilt premium craft mockup | O3: 1 | P3: Image was opened directly at readable resolution and motif/type matched product evidence. | Q3: 1 | R3: Alt/observation matches the visible asset type and motif after direct visual review. | S3: 1 | T3: Image is commercially useful for buyer verification of mockup/detail/size/material. | U3: 1 | V3: No material SEO/accessibility issue found for this image row. | W3: =SUM(O3*40,Q3*30,S3*20,U3*10) -> 100 | X3: =SUM(IF(O3<>"NOT_CHECKED",40,0),IF(Q3<>"NOT_CHECKED",30,0),IF(S3<>"NOT_CHECKED",20,0),IF(U3<>"NOT_CHECKED",10,0)) -> 100 | Y3: =IF(X3=100,1,0) -> 1 | AA3: source_snapshot/images + contact_sheet_031
A4: jeminise.com+christmas-cardinals-near-snowy-birdhouse-patchwork-floral-quilt-b90d55a935-b90d55a935|media:47540019101895|pos:3|url:b033999f6ccd | B4: 20260909_154500 | C4: 31 | D4: jeminise.com+christmas-cardinals-near-snowy-birdhouse-patchwork-floral-quilt-b90d55a935-b90d55a935 | E4: 8834720170183 | F4: 47540019101895 | G4: 3 | H4: GALLERY | I4: https://cdn.shopify.com/s/files/1/0792/5098/1063/files/192d8a6eed2602b9a36fbbd7936b0d70ef3680e4dd38270f22af78ba5c23bb4a.jpg?v=1785099259 | J4: HTTP_200_DOWNLOADED | K4: TRUE | L4: Matching pillowcase/sham view; must be distinguished from main quilt/comforter view. | M4: Optional pillow shams panel showing matching cardinal birdhouse pillow artwork and feature icons. | N4: Cardinal birdhouse quilt optional pillow shams | O4: 1 | P4: Image was opened directly at readable resolution and motif/type matched product evidence. | Q4: 1 | R4: Alt/observation matches the visible asset type and motif after direct visual review. | S4: 1 | T4: Image is commercially useful for buyer verification of mockup/detail/size/material. | U4: 1 | V4: No material SEO/accessibility issue found for this image row. | W4: =SUM(O4*40,Q4*30,S4*20,U4*10) -> 100 | X4: =SUM(IF(O4<>"NOT_CHECKED",40,0),IF(Q4<>"NOT_CHECKED",30,0),IF(S4<>"NOT_CHECKED",20,0),IF(U4<>"NOT_CHECKED",10,0)) -> 100 | Y4: =IF(X4=100,1,0) -> 1 | AA4: source_snapshot/images + contact_sheet_031
A5: jeminise.com+christmas-cardinals-near-snowy-birdhouse-patchwork-floral-quilt-b90d55a935-b90d55a935|media:47540019134663|pos:4|url:b8343c6a4dbb | B5: 20260909_154500 | C5: 31 | D5: jeminise.com+christmas-cardinals-near-snowy-birdhouse-patchwork-floral-quilt-b90d55a935-b90d55a935 | E5: 8834720170183 | F5: 47540019134663 | G5: 4 | H5: GALLERY | I5: https://cdn.shopify.com/s/files/1/0792/5098/1063/files/a5f492aee10aae43511cc5e9a46710cc38afe374b23731941e7748005cf44564.jpg?v=1785099259 | J5: HTTP_200_DOWNLOADED | K5: TRUE | L5: Product gallery mockup/close-up reviewed visually against r5 observation and proposed alt. | M5: Fabric panel showing cardinal birdhouse quilt layers and soft breathable skin-friendly fabric callout. | N5: Cardinal birdhouse quilt fabric feature panel | O5: 1 | P5: Image was opened directly at readable resolution and motif/type matched product evidence. | Q5: 1 | R5: Alt/observation matches the visible asset type and motif after direct visual review. | S5: 1 | T5: Image is commercially useful for buyer verification of mockup/detail/size/material. | U5: 1 | V5: No material SEO/accessibility issue found for this image row. | W5: =SUM(O5*40,Q5*30,S5*20,U5*10) -> 100 | X5: =SUM(IF(O5<>"NOT_CHECKED",40,0),IF(Q5<>"NOT_CHECKED",30,0),IF(S5<>"NOT_CHECKED",20,0),IF(U5<>"NOT_CHECKED",10,0)) -> 100 | Y5: =IF(X5=100,1,0) -> 1 | AA5: source_snapshot/images + contact_sheet_031
A6: jeminise.com+christmas-cardinals-near-snowy-birdhouse-patchwork-floral-quilt-b90d55a935-b90d55a935|media:47540019167431|pos:5|url:7686a7d969fe | B6: 20260909_154500 | C6: 31 | D6: jeminise.com+christmas-cardinals-near-snowy-birdhouse-patchwork-floral-quilt-b90d55a935-b90d55a935 | E6: 8834720170183 | F6: 47540019167431 | G6: 5 | H6: GALLERY | I6: https://cdn.shopify.com/s/files/1/0792/5098/1063/files/578ac27946027e8e5ec1b6c4efdccc50d46e3d6182eed1ca0e62799fb3b416fd.jpg?v=1785099259 | J6: HTTP_200_DOWNLOADED | K6: TRUE | L6: Size chart / dimension guide; not a lifestyle product mockup but valid description asset. | M6: Premium quilt set size chart with cardinal birdhouse artwork and quilt dimensions. | N6: Cardinal birdhouse quilt size chart | O6: 1 | P6: Image was opened directly at readable resolution and motif/type matched product evidence. | Q6: 1 | R6: Alt/observation matches the visible asset type and motif after direct visual review. | S6: 1 | T6: Image is commercially useful for buyer verification of mockup/detail/size/material. | U6: 1 | V6: No material SEO/accessibility issue found for this image row. | W6: =SUM(O6*40,Q6*30,S6*20,U6*10) -> 100 | X6: =SUM(IF(O6<>"NOT_CHECKED",40,0),IF(Q6<>"NOT_CHECKED",30,0),IF(S6<>"NOT_CHECKED",20,0),IF(U6<>"NOT_CHECKED",10,0)) -> 100 | Y6: =IF(X6=100,1,0) -> 1 | AA6: source_snapshot/images + contact_sheet_031
A7: jeminise.com+christmas-cardinals-near-snowy-birdhouse-patchwork-floral-quilt-b90d55a935-b90d55a935|media:47540019200199|pos:6|url:629a480d5756 | B7: 20260909_154500 | C7: 31 | D7: jeminise.com+christmas-cardinals-near-snowy-birdhouse-patchwork-floral-quilt-b90d55a935-b90d55a935 | E7: 8834720170183 | F7: 47540019200199 | G7: 6 | H7: GALLERY | I7: https://cdn.shopify.com/s/files/1/0792/5098/1063/files/17b3827a8c3b4dbbd608b08c3534148427ac4397354f3f0fe053ed23086269e8.jpg?v=1785099259 | J7: HTTP_200_DOWNLOADED | K7: TRUE | L7: Product gallery mockup/close-up reviewed visually against r5 observation and proposed alt. | M7: Bedspread features panel showing microfiber layers and anti-wrinkle, anti-static, fade resistant, shrink resistant and machine washable icons. | N7: Cardinal birdhouse quilt bedspread features | O7: 1 | P7: Image was opened directly at readable resolution and motif/type matched product evidence. | Q7: 1 | R7: Alt/observation matches the visible asset type and motif after direct visual review. | S7: 1 | T7: Image is commercially useful for buyer verification of mockup/detail/size/material. | U7: 1 | V7: No material SEO/accessibility issue found for this image row. | W7: =SUM(O7*40,Q7*30,S7*20,U7*10) -> 100 | X7: =SUM(IF(O7<>"NOT_CHECKED",40,0),IF(Q7<>"NOT_CHECKED",30,0),IF(S7<>"NOT_CHECKED",20,0),IF(U7<>"NOT_CHECKED",10,0)) -> 100 | Y7: =IF(X7=100,1,0) -> 1 | AA7: source_snapshot/images + contact_sheet_031
A8: jeminise.com+christmas-cardinals-near-snowy-birdhouse-patchwork-floral-quilt-b90d55a935-b90d55a935|media:47540019232967|pos:7|url:356ce841803f | B8: 20260909_154500 | C8: 31 | D8: jeminise.com+christmas-cardinals-near-snowy-birdhouse-patchwork-floral-quilt-b90d55a935-b90d55a935 | E8: 8834720170183 | F8: 47540019232967 | G8: 7 | H8: GALLERY | I8: https://cdn.shopify.com/s/files/1/0792/5098/1063/files/24dc7edea95f70726f65b933a6f8c4826cdc3c896050c2c5109926d64325dd21.jpg?v=1785099258 | J8: HTTP_200_DOWNLOADED | K8: TRUE | L8: Matching pillowcase/sham view; must be distinguished from main quilt/comforter view. | M8: Overhead bedroom mockup showing cardinal birdhouse quilt with matching pillows. | N8: Cardinal birdhouse quilt overhead bedroom view | O8: 1 | P8: Image was opened directly at readable resolution and motif/type matched product evidence. | Q8: 1 | R8: Alt/observation matches the visible asset type and motif after direct visual review. | S8: 1 | T8: Image is commercially useful for buyer verification of mockup/detail/size/material. | U8: 1 | V8: No material SEO/accessibility issue found for this image row. | W8: =SUM(O8*40,Q8*30,S8*20,U8*10) -> 100 | X8: =SUM(IF(O8<>"NOT_CHECKED",40,0),IF(Q8<>"NOT_CHECKED",30,0),IF(S8<>"NOT_CHECKED",20,0),IF(U8<>"NOT_CHECKED",10,0)) -> 100 | Y8: =IF(X8=100,1,0) -> 1 | AA8: source_snapshot/images + contact_sheet_031
A9: jeminise.com+christmas-cardinals-on-snowy-branches-patchwork-winter-quilt-8fa1a9e2ed-8fa1a9e2ed|media:47539987841223|pos:1|url:8dd46f7cdb17 | B9: 20260909_154500 | C9: 32 | D9: jeminise.com+christmas-cardinals-on-snowy-branches-patchwork-winter-quilt-8fa1a9e2ed-8fa1a9e2ed | E9: 8834709323975 | F9: 47539987841223 | G9: 1 | H9: GALLERY | I9: https://cdn.shopify.com/s/files/1/0792/5098/1063/files/dac06806abe736aaddf0257ef47ee3581ffb682f1ee70078a493eb9381b34f9f.jpg?v=1785098963 | J9: HTTP_200_DOWNLOADED | K9: TRUE | L9: Matching pillowcase/sham view; must be distinguished from main quilt/comforter view. | M9: Christmas cardinals snowy branches quilt bed mockup with red cardinals, berries, poinsettias and matching shams. | N9: Christmas cardinals snowy branches quilt set | O9: 1 | P9: Image was opened directly at readable resolution and motif/type matched product evidence. | Q9: 1 | R9: Alt/observation matches the visible asset type and motif after direct visual review. | S9: 1 | T9: Image is commercially useful for buyer verification of mockup/detail/size/material. | U9: 1 | V9: No material SEO/accessibility issue found for this image row. | W9: =SUM(O9*40,Q9*30,S9*20,U9*10) -> 100 | X9: =SUM(IF(O9<>"NOT_CHECKED",40,0),IF(Q9<>"NOT_CHECKED",30,0),IF(S9<>"NOT_CHECKED",20,0),IF(U9<>"NOT_CHECKED",10,0)) -> 100 | Y9: =IF(X9=100,1,0) -> 1 | AA9: source_snapshot/images + contact_sheet_032
A10: jeminise.com+christmas-cardinals-on-snowy-branches-patchwork-winter-quilt-8fa1a9e2ed-8fa1a9e2ed|media:47539987873991|pos:2|url:ef5fea9cdf29 | B10: 20260909_154500 | C10: 32 | D10: jeminise.com+christmas-cardinals-on-snowy-branches-patchwork-winter-quilt-8fa1a9e2ed-8fa1a9e2ed | E10: 8834709323975 | F10: 47539987873991 | G10: 2 | H10: GALLERY | I10: https://cdn.shopify.com/s/files/1/0792/5098/1063/files/ab7e4f9484e52e83891e552e58d6a27e151a62e654a01667625d8c86bd6a3295.jpg?v=1785098963 | J10: HTTP_200_DOWNLOADED | K10: TRUE | L10: Product gallery mockup/close-up reviewed visually against r5 observation and proposed alt. | M10: Close-up of a red cardinal head with snowy branch background and visible quilt stitching. | N10: Cardinal snowy branches quilt close-up | O10: 1 | P10: Image was opened directly at readable resolution and motif/type matched product evidence. | Q10: 1 | R10: Alt/observation matches the visible asset type and motif after direct visual review. | S10: 1 | T10: Image is commercially useful for buyer verification of mockup/detail/size/material. | U10: 1 | V10: No material SEO/accessibility issue found for this image row. | W10: =SUM(O10*40,Q10*30,S10*20,U10*10) -> 100 | X10: =SUM(IF(O10<>"NOT_CHECKED",40,0),IF(Q10<>"NOT_CHECKED",30,0),IF(S10<>"NOT_CHECKED",20,0),IF(U10<>"NOT_CHECKED",10,0)) -> 100 | Y10: =IF(X10=100,1,0) -> 1 | AA10: source_snapshot/images + contact_sheet_032
A11: jeminise.com+christmas-cardinals-on-snowy-branches-patchwork-winter-quilt-8fa1a9e2ed-8fa1a9e2ed|media:47539987906759|pos:3|url:4e43b9809484 | B11: 20260909_154500 | C11: 32 | D11: jeminise.com+christmas-cardinals-on-snowy-branches-patchwork-winter-quilt-8fa1a9e2ed-8fa1a9e2ed | E11: 8834709323975 | F11: 47539987906759 | G11: 3 | H11: GALLERY | I11: https://cdn.shopify.com/s/files/1/0792/5098/1063/files/af11f2e375dabf355f9318fb1eea3b312db7cd0ed95fb4b96e7b537d184a9d42.jpg?v=1785098963 | J11: HTTP_200_DOWNLOADED | K11: TRUE | L11: Matching pillowcase/sham view; must be distinguished from main quilt/comforter view. | M11: Matching pillow sham with two red cardinals, snowy branches, berries and poinsettias. | N11: Cardinals snowy branches pillow sham | O11: 1 | P11: Image was opened directly at readable resolution and motif/type matched product evidence. | Q11: 1 | R11: Alt/observation matches the visible asset type and motif after direct visual review. | S11: 1 | T11: Image is commercially useful for buyer verification of mockup/detail/size/material. | U11: 1 | V11: No material SEO/accessibility issue found for this image row. | W11: =SUM(O11*40,Q11*30,S11*20,U11*10) -> 100 | X11: =SUM(IF(O11<>"NOT_CHECKED",40,0),IF(Q11<>"NOT_CHECKED",30,0),IF(S11<>"NOT_CHECKED",20,0),IF(U11<>"NOT_CHECKED",10,0)) -> 100 | Y11: =IF(X11=100,1,0) -> 1 | AA11: source_snapshot/images + contact_sheet_032
A12: jeminise.com+christmas-cardinals-on-snowy-branches-patchwork-winter-quilt-8fa1a9e2ed-8fa1a9e2ed|media:47539987939527|pos:4|url:9a402e5e8190 | B12: 20260909_154500 | C12: 32 | D12: jeminise.com+christmas-cardinals-on-snowy-branches-patchwork-winter-quilt-8fa1a9e2ed-8fa1a9e2ed | E12: 8834709323975 | F12: 47539987939527 | G12: 4 | H12: GALLERY | I12: https://cdn.shopify.com/s/files/1/0792/5098/1063/files/f940efaf872da7294b0ec99795596430c32c922db66b35243684820e65417fb3.jpg?v=1785098963 | J12: HTTP_200_DOWNLOADED | K12: TRUE | L12: Matching pillowcase/sham view; must be distinguished from main quilt/comforter view. | M12: Bedroom mockup showing cardinals snowy branches quilt with coordinated pillow shams. | N12: Cardinals snowy branches quilt bedroom mockup | O12: 1 | P12: Image was opened directly at readable resolution and motif/type matched product evidence. | Q12: 1 | R12: Alt/observation matches the visible asset type and motif after direct visual review. | S12: 1 | T12: Image is commercially useful for buyer verification of mockup/detail/size/material. | U12: 1 | V12: No material SEO/accessibility issue found for this image row. | W12: =SUM(O12*40,Q12*30,S12*20,U12*10) -> 100 | X12: =SUM(IF(O12<>"NOT_CHECKED",40,0),IF(Q12<>"NOT_CHECKED",30,0),IF(S12<>"NOT_CHECKED",20,0),IF(U12<>"NOT_CHECKED",10,0)) -> 100 | Y12: =IF(X12=100,1,0) -> 1 | AA12: source_snapshot/images + contact_sheet_032
A13: jeminise.com+christmas-cardinals-on-snowy-branches-patchwork-winter-quilt-8fa1a9e2ed-8fa1a9e2ed|media:47539987972295|pos:5|url:bb263974aea1 | B13: 20260909_154500 | C13: 32 | D13: jeminise.com+christmas-cardinals-on-snowy-branches-patchwork-winter-quilt-8fa1a9e2ed-8fa1a9e2ed | E13: 8834709323975 | F13: 47539987972295 | G13: 5 | H13: GALLERY | I13: https://cdn.shopify.com/s/files/1/0792/5098/1063/files/e0cc67382e14f285ae5b93b57a9e0bfb1a6da6368549d710aed5a534af0f3e89.jpg?v=1785098963 | J13: HTTP_200_DOWNLOADED | K13: TRUE | L13: Size chart / dimension guide; not a lifestyle product mockup but valid description asset. | M13: Size and component panel showing one premium quilt and two optional standard shams. | N13: Cardinals snowy branches quilt size options | O13: 1 | P13: Image was opened directly at readable resolution and motif/type matched product evidence. | Q13: 1 | R13: Alt/observation matches the visible asset type and motif after direct visual review. | S13: 1 | T13: Image is commercially useful for buyer verification of mockup/detail/size/material. | U13: 1 | V13: No material SEO/accessibility issue found for this image row. | W13: =SUM(O13*40,Q13*30,S13*20,U13*10) -> 100 | X13: =SUM(IF(O13<>"NOT_CHECKED",40,0),IF(Q13<>"NOT_CHECKED",30,0),IF(S13<>"NOT_CHECKED",20,0),IF(U13<>"NOT_CHECKED",10,0)) -> 100 | Y13: =IF(X13=100,1,0) -> 1 | AA13: source_snapshot/images + contact_sheet_032
... A63: jeminise.com+custom-american-football-with-patriotic-flag-comforter-4a3a1ed3c9-4a3a1ed3c9|media:47540300710087|pos:6|url:d0f79ba743de | B63: 20260909_154500 | C63: 40 | D63: jeminise.com+custom-american-football-with-patriotic-flag-comforter-4a3a1ed3c9-4a3a1ed3c9 | E63: 8834768011463 | F63: 47540300710087 | G63: 6 | H63: GALLERY | I63: https://cdn.shopify.com/s/files/1/0792/5098/1063/files/e5cad84edb4d7bf77c48fd7c8e52eb3b73f04eba8bf177671fd8a059c59422e8_e9a8f6c7-84a8-4f8e-a21c-61b347436f7e.jpg?v=1785101840 | J63: HTTP_200_DOWNLOADED | K63: TRUE | L63: Size chart / dimension guide; not a lifestyle product mockup but valid description asset. | M63: Size dimension panel showing Twin, Full, Queen and King bedding dimensions. | N63: Patriotic football comforter size chart | O63: 1 | P63: Image was opened directly at readable resolution and motif/type matched product evidence. | Q63: 1 | R63: Alt/observation matches the visible asset type and motif after direct visual review. | S63: 1 | T63: Image is commercially useful for buyer verification of mockup/detail/size/material. | U63: 1 | V63: No material SEO/accessibility issue found for this image row. | W63: =SUM(O63*40,Q63*30,S63*20,U63*10) -> 100 | X63: =SUM(IF(O63<>"NOT_CHECKED",40,0),IF(Q63<>"NOT_CHECKED",30,0),IF(S63<>"NOT_CHECKED",20,0),IF(U63<>"NOT_CHECKED",10,0)) -> 100 | Y63: =IF(X63=100,1,0) -> 1 | AA63: source_snapshot/images + contact_sheet_040

Sheet QA_Issues
A1: issue_id | B1: qa_run_id | C1: inventory_position | D1: product_key | E1: severity | F1: critical | G1: history_status | H1: summary | I1: current_value | J1: source_observation | K1: reason | L1: evidence_ref | M1: suggested_fix | N1: retest_condition
A2: B04-034-D2-ALLIGATOR | B2: 20260909_154500 | C2: 34 | D2: jeminise.com+crocodile-patchwork-printed-quilts-animal-patchwork-bedding | E2: MAJOR | F2: FALSE | G2: PERSISTS | H2: Crocodile product still mixes broader alligator/crocodile language and needs tighter evidence handling. | I2: <p>Crocodile wildlife patchwork artwork gives this quilt set a bold animal-themed look. The reptile design and coordinated bedding panels create a standout wildlife bedroom style.</p><h3>Design Details</h3><ul><li>Crocodile wildlife patchwork quilt artwork.</li><li>Gallery includes the main mockup plus close-up, sham, care, comparison, size and material graphics when available.</li><li>Feature panels help confirm fabric, care, size and component details before checkout.</li></ul><h3>Options</h3><ul><li>CHOOSE QUILT SIZE and PILLOWCASES (Purchase SEPARATELY) selectors are listed.</li><li>No shopper text-entry field is described for this product.</li><li>Confirm size and pillowcase choices before checkout.</li></ul> | J2: Live/source product is crocodile patchwork; r5 text can invite alligator overlap. | K2: Intent and visual evidence support crocodile first. Alligator can be a comparator only if explicitly framed. | L2: SEO_Products description_proposed_html; live product JSON/body; SERP crocodile/alligator queries | M2: Use crocodile-led copy; if alligator remains, phrase as related search language, not product identity. | N2: Recheck D2 and image alt rows for crocodile-only identity.
A3: B04-035-PERS-CONTROL | B3: 20260909_154500 | C3: 35 | D3: jeminise.com+custom-retro-football-art-bedding-set-c66211cf75-c66211cf75 | E3: MAJOR | F3: FALSE | G3: REGRESSED | H3: Personalized football copy claims name/number controls, but the exact live/customizer limits could not be fully verified from static HTML/JSON snapshot. | I3: <p>A retro American football close-up sits over flag-inspired comforter artwork with sample name and number details. The design gives the bedding a vintage patriotic football look.</p><h3>Design Details</h3><ul><li>Retro football close-up with flag-style background.</li><li>Sample name and number placement are visible in the mockup.</li><li>Gallery includes the main mockup plus close-up, sham, care, comparison, size and material graphics when available.</li></ul><h3>Options and Personalization</h3><ul><li>Choose Product Type + Size, Choose Pillowcases and Additional Sheet Cover (Flat Sheet) selectors are listed.</li><li>Enter Name is required and accepts up to 25 characters.</li><li>Enter Number is optional and accepts up to 5 characters.</li><li>Names and numbers visible in mockups are samples unless matching input is entered.</li><li>Confirm product type, size, pillowcase and sheet-cover choices before checkout.</li></ul> | J3: not found | K3: Rubric requires exact control evidence; static HTML absence is not proof of no control, so this is scored as partial rather than critical. | L3: Live HTML + product JSON + admin export snapshot; customizer needs browser/runtime verification | M3: Keep personalization claims only with exact verified labels and character limits: Enter Name 1-25, Enter Number 1-5. | N3: Open runtime customizer and confirm required/optional labels/limits before PASS.
A4: B04-036-PERS-CONTROL | B4: 20260909_154500 | C4: 36 | D4: jeminise.com+custom-american-football-close-up-on-grunge-vintage-comforter-26540e3264-26540e3264 | E4: MAJOR | F4: FALSE | G4: REGRESSED | H4: Personalized football copy claims name/number controls, but the exact live/customizer limits could not be fully verified from static HTML/JSON snapshot. | I4: <p>An American football close-up over a grunge vintage background gives this comforter a rugged sports style. Sample name and number details show how personalization appears in the artwork.</p><h3>Design Details</h3><ul><li>Football close-up on grunge vintage comforter artwork.</li><li>Sample name and number placement are visible.</li><li>Gallery includes the main mockup plus close-up, sham, care, comparison, size and material graphics when available.</li></ul><h3>Options and Personalization</h3><ul><li>Choose Product Type + Size, Choose Pillowcases and Additional Sheet Cover (Flat Sheet) selectors are listed.</li><li>Enter Name is required and accepts up to 25 characters.</li><li>Enter Number is optional and accepts up to 5 characters.</li><li>Names and numbers visible in mockups are samples unless matching input is entered.</li><li>Confirm product type, size, pillowcase and sheet-cover choices before checkout.</li></ul> | J4: not found | K4: Rubric requires exact control evidence; static HTML absence is not proof of no control, so this is scored as partial rather than critical. | L4: Live HTML + product JSON + admin export snapshot; customizer needs browser/runtime verification | M4: Keep personalization claims only with exact verified labels and character limits: Enter Name 1-25, Enter Number 1-5. | N4: Open runtime customizer and confirm required/optional labels/limits before PASS.
A5: B04-037-PERS-CONTROL | B5: 20260909_154500 | C5: 37 | D5: jeminise.com+custom-american-football-on-cosmic-background-vintage-comforter-62a3849621-62a3849621 | E5: MAJOR | F5: FALSE | G5: REGRESSED | H5: Personalized football copy claims name/number controls, but the exact live/customizer limits could not be fully verified from static HTML/JSON snapshot. | I5: <p>An American football over a cosmic background gives this comforter a dramatic vintage sports look. Sample name and number details add a personalized player-style finish.</p><h3>Design Details</h3><ul><li>American football on cosmic background artwork.</li><li>Vintage styling with sample name and number placement is shown.</li><li>Gallery includes the main mockup plus close-up, sham, care, comparison, size and material graphics when available.</li></ul><h3>Options and Personalization</h3><ul><li>Choose Product Type + Size, Choose Pillowcases and Additional Sheet Cover (Flat Sheet) selectors are listed.</li><li>Enter Name is required and accepts up to 25 characters.</li><li>Enter Number is optional and accepts up to 5 characters.</li><li>Names and numbers visible in mockups are samples unless matching input is entered.</li><li>Confirm product type, size, pillowcase and sheet-cover choices before checkout.</li></ul> | J5: not found | K5: Rubric requires exact control evidence; static HTML absence is not proof of no control, so this is scored as partial rather than critical. | L5: Live HTML + product JSON + admin export snapshot; customizer needs browser/runtime verification | M5: Keep personalization claims only with exact verified labels and character limits: Enter Name 1-25, Enter Number 1-5. | N5: Open runtime customizer and confirm required/optional labels/limits before PASS.
A6: B04-038-PERS-CONTROL | B6: 20260909_154500 | C6: 38 | D6: jeminise.com+custom-american-football-on-usa-flag-background-comforter-703a7c0d82-703a7c0d82 | E6: MAJOR | F6: FALSE | G6: REGRESSED | H6: Personalized football copy claims name/number controls, but the exact live/customizer limits could not be fully verified from static HTML/JSON snapshot. | I6: <p>An American football sits over a USA flag background on this patriotic comforter. Sample name and number details make the design feel like custom football bedding for a player or fan.</p><h3>Design Details</h3><ul><li>Football artwork over USA flag background.</li><li>Sample name and number placement are visible in the mockup.</li><li>Gallery includes the main mockup plus close-up, sham, care, comparison, size and material graphics when available.</li></ul><h3>Options and Personalization</h3><ul><li>Choose Product Type + Size, Choose Pillowcases and Additional Sheet Cover (Flat Sheet) selectors are listed.</li><li>Enter Name is required and accepts up to 25 characters.</li><li>Enter Number is optional and accepts up to 5 characters.</li><li>Names and numbers visible in mockups are samples unless matching input is entered.</li><li>Confirm product type, size, pillowcase and sheet-cover choices before checkout.</li></ul> | J6: not found | K6: Rubric requires exact control evidence; static HTML absence is not proof of no control, so this is scored as partial rather than critical. | L6: Live HTML + product JSON + admin export snapshot; customizer needs browser/runtime verification | M6: Keep personalization claims only with exact verified labels and character limits: Enter Name 1-25, Enter Number 1-5. | N6: Open runtime customizer and confirm required/optional labels/limits before PASS.
