Workbook

Sheet QA_Summary
A1: batch_name | B1: run_id | C1: total_products | D1: assessed_products | E1: total_images | F1: assessed_images | G1: assessed_weight | H1: average_score | I1: qa_pass_count | J1: qa_revise_count | K1: qa_fail_count | L1: qa_incomplete_count | M1: overall_status | N1: audit_date | O1: auditor
A2: qa_batch_017_r3 | B2: 20260908_103500 | C2: =COUNTA(QA_Products!A2:A11) | D2: =COUNTIF(QA_Products!H2:H11,TRUE) | E2: =COUNTA(QA_Images!A2:A63) | F2: =COUNTIF(QA_Images!O2:O63,"<>") | G2: 100 | H2: =ROUND(AVERAGE(QA_Products!T2:T11),2) | I2: =COUNTIF(QA_Products!Y2:Y11,"QA_PASS") | J2: =COUNTIF(QA_Products!Y2:Y11,"QA_REVISE") | K2: =COUNTIF(QA_Products!Y2:Y11,"QA_FAIL") | L2: =COUNTIF(QA_Products!Y2:Y11,"QA_INCOMPLETE") | M2: =IF(K2>0,"QA_FAIL",IF(J2>0,"QA_REVISE","QA_PASS")) | N2: 2026-09-08 | O2: Antigravity Independent QA

Sheet QA_Products
A1: product_key | B1: Handle | C1: inventory_position | D1: product_title_current | E1: product_title_proposed | F1: primary_keyword | G1: secondary_keywords | H1: page_read | I1: P1_score | J1: P2_score | K1: K1_score | L1: K2_score | M1: K3_score | N1: T1_score | O1: T2_score | P1: D1_score | Q1: D2_score | R1: I1_score | S1: E1_score | T1: total_score | U1: critical_issues_count | V1: major_issues_count | W1: minor_issues_count | X1: limitation_count | Y1: qa_status | Z1: notes
A2: jeminise.com+norse-mythology-raven-within-celtic-knot-frame-quilt-906ee24d68-906ee24d68 | B2: norse-mythology-raven-within-celtic-knot-frame-quilt-906ee24d68-906ee24d68 | C2: 161 | D2: Norse Mythology Raven Within Celtic Knot Frame Quilt | E2: Blue Raven Celtic Knot Quilt | F2: blue raven Celtic knot quilt | G2: Norse raven Celtic quilt, Viking raven quilt set, Celtic knot raven bedding | H2: TRUE | I2: =SUMIFS(QA_Criteria!F:F,QA_Criteria!B:B,A2,QA_Criteria!C:C,"P1") | J2: =SUMIFS(QA_Criteria!F:F,QA_Criteria!B:B,A2,QA_Criteria!C:C,"P2") | K2: =SUMIFS(QA_Criteria!F:F,QA_Criteria!B:B,A2,QA_Criteria!C:C,"K1") | L2: =SUMIFS(QA_Criteria!F:F,QA_Criteria!B:B,A2,QA_Criteria!C:C,"K2") | M2: =SUMIFS(QA_Criteria!F:F,QA_Criteria!B:B,A2,QA_Criteria!C:C,"K3") | N2: =SUMIFS(QA_Criteria!F:F,QA_Criteria!B:B,A2,QA_Criteria!C:C,"T1") | O2: =SUMIFS(QA_Criteria!F:F,QA_Criteria!B:B,A2,QA_Criteria!C:C,"T2") | P2: =SUMIFS(QA_Criteria!F:F,QA_Criteria!B:B,A2,QA_Criteria!C:C,"D1") | Q2: =SUMIFS(QA_Criteria!F:F,QA_Criteria!B:B,A2,QA_Criteria!C:C,"D2") | R2: =ROUND(0.20*AVERAGEIF(QA_Images!B:B,A2,QA_Images!N:N),2) | S2: =SUMIFS(QA_Criteria!F:F,QA_Criteria!B:B,A2,QA_Criteria!C:C,"E1") | T2: =IF(H2=TRUE,SUM(I2:S2),0) | U2: =COUNTIFS(QA_Issues!B:B,A2,QA_Issues!D:D,"CRITICAL",QA_Issues!L:L,"<>RESOLVED",QA_Issues!L:L,"<>NOT_APPLICABLE") | V2: =COUNTIFS(QA_Issues!B:B,A2,QA_Issues!D:D,"MAJOR",QA_Issues!L:L,"<>RESOLVED",QA_Issues!L:L,"<>NOT_APPLICABLE") | W2: =COUNTIFS(QA_Issues!B:B,A2,QA_Issues!D:D,"MINOR",QA_Issues!L:L,"<>RESOLVED",QA_Issues!L:L,"<>NOT_APPLICABLE") | X2: =COUNTIFS(QA_Issues!B:B,A2,QA_Issues!D:D,"LIMITATION",QA_Issues!L:L,"<>RESOLVED",QA_Issues!L:L,"<>NOT_APPLICABLE") | Y2: =IF(U2>0,"QA_FAIL",IF(H2=FALSE,"QA_INCOMPLETE",IF(T2<70,"QA_FAIL",IF(OR(T2<85,V2>0),"QA_REVISE","QA_PASS")))) | Z2: Direct visual audit complete (all gallery images inspected). Keyword mapping, titles, and meta tags are high quality. Proposed description copy contains meta-commentary and omits essential package/fabric specifications (D2 MAJOR issue).
A3: jeminise.com+norse-mythology-viking-shield-with-crossed-axes-quilt-ca630a284e-ca630a284e | B3: norse-mythology-viking-shield-with-crossed-axes-quilt-ca630a284e-ca630a284e | C3: 162 | D3: Norse Mythology Viking Shield with Crossed Axes Quilt | E3: Valhalla Viking Shield Quilt | F3: Valhalla Viking shield quilt | G3: Viking shield quilt, crossed axes bedding, Norse Valhalla quilt | H3: TRUE | I3: =SUMIFS(QA_Criteria!F:F,QA_Criteria!B:B,A3,QA_Criteria!C:C,"P1") | J3: =SUMIFS(QA_Criteria!F:F,QA_Criteria!B:B,A3,QA_Criteria!C:C,"P2") | K3: =SUMIFS(QA_Criteria!F:F,QA_Criteria!B:B,A3,QA_Criteria!C:C,"K1") | L3: =SUMIFS(QA_Criteria!F:F,QA_Criteria!B:B,A3,QA_Criteria!C:C,"K2") | M3: =SUMIFS(QA_Criteria!F:F,QA_Criteria!B:B,A3,QA_Criteria!C:C,"K3") | N3: =SUMIFS(QA_Criteria!F:F,QA_Criteria!B:B,A3,QA_Criteria!C:C,"T1") | O3: =SUMIFS(QA_Criteria!F:F,QA_Criteria!B:B,A3,QA_Criteria!C:C,"T2") | P3: =SUMIFS(QA_Criteria!F:F,QA_Criteria!B:B,A3,QA_Criteria!C:C,"D1") | Q3: =SUMIFS(QA_Criteria!F:F,QA_Criteria!B:B,A3,QA_Criteria!C:C,"D2") | R3: =ROUND(0.20*AVERAGEIF(QA_Images!B:B,A3,QA_Images!N:N),2) | S3: =SUMIFS(QA_Criteria!F:F,QA_Criteria!B:B,A3,QA_Criteria!C:C,"E1") | T3: =IF(H3=TRUE,SUM(I3:S3),0) | U3: =COUNTIFS(QA_Issues!B:B,A3,QA_Issues!D:D,"CRITICAL",QA_Issues!L:L,"<>RESOLVED",QA_Issues!L:L,"<>NOT_APPLICABLE") | V3: =COUNTIFS(QA_Issues!B:B,A3,QA_Issues!D:D,"MAJOR",QA_Issues!L:L,"<>RESOLVED",QA_Issues!L:L,"<>NOT_APPLICABLE") | W3: =COUNTIFS(QA_Issues!B:B,A3,QA_Issues!D:D,"MINOR",QA_Issues!L:L,"<>RESOLVED",QA_Issues!L:L,"<>NOT_APPLICABLE") | X3: =COUNTIFS(QA_Issues!B:B,A3,QA_Issues!D:D,"LIMITATION",QA_Issues!L:L,"<>RESOLVED",QA_Issues!L:L,"<>NOT_APPLICABLE") | Y3: =IF(U3>0,"QA_FAIL",IF(H3=FALSE,"QA_INCOMPLETE",IF(T3<70,"QA_FAIL",IF(OR(T3<85,V3>0),"QA_REVISE","QA_PASS")))) | Z3: Direct visual audit complete (all gallery images inspected). Keyword mapping, titles, and meta tags are high quality. Proposed description copy contains meta-commentary and omits essential package/fabric specifications (D2 MAJOR issue).
A4: jeminise.com+owl-patchwork-pattern-quilt-set-animals-quilt-set-style-owl-nights | B4: owl-patchwork-pattern-quilt-set-animals-quilt-set-style-owl-nights | C4: 163 | D4: Owl Patchwork Pattern Quilt Set, Animals Quilt Set Style, Owl Nights | E4: Blue Gold Owl Night Quilt Set | F4: blue gold owl night quilt set | G4: owl patchwork quilt, owl moon bedding, animal quilt set | H4: TRUE | I4: =SUMIFS(QA_Criteria!F:F,QA_Criteria!B:B,A4,QA_Criteria!C:C,"P1") | J4: =SUMIFS(QA_Criteria!F:F,QA_Criteria!B:B,A4,QA_Criteria!C:C,"P2") | K4: =SUMIFS(QA_Criteria!F:F,QA_Criteria!B:B,A4,QA_Criteria!C:C,"K1") | L4: =SUMIFS(QA_Criteria!F:F,QA_Criteria!B:B,A4,QA_Criteria!C:C,"K2") | M4: =SUMIFS(QA_Criteria!F:F,QA_Criteria!B:B,A4,QA_Criteria!C:C,"K3") | N4: =SUMIFS(QA_Criteria!F:F,QA_Criteria!B:B,A4,QA_Criteria!C:C,"T1") | O4: =SUMIFS(QA_Criteria!F:F,QA_Criteria!B:B,A4,QA_Criteria!C:C,"T2") | P4: =SUMIFS(QA_Criteria!F:F,QA_Criteria!B:B,A4,QA_Criteria!C:C,"D1") | Q4: =SUMIFS(QA_Criteria!F:F,QA_Criteria!B:B,A4,QA_Criteria!C:C,"D2") | R4: =ROUND(0.20*AVERAGEIF(QA_Images!B:B,A4,QA_Images!N:N),2) | S4: =SUMIFS(QA_Criteria!F:F,QA_Criteria!B:B,A4,QA_Criteria!C:C,"E1") | T4: =IF(H4=TRUE,SUM(I4:S4),0) | U4: =COUNTIFS(QA_Issues!B:B,A4,QA_Issues!D:D,"CRITICAL",QA_Issues!L:L,"<>RESOLVED",QA_Issues!L:L,"<>NOT_APPLICABLE") | V4: =COUNTIFS(QA_Issues!B:B,A4,QA_Issues!D:D,"MAJOR",QA_Issues!L:L,"<>RESOLVED",QA_Issues!L:L,"<>NOT_APPLICABLE") | W4: =COUNTIFS(QA_Issues!B:B,A4,QA_Issues!D:D,"MINOR",QA_Issues!L:L,"<>RESOLVED",QA_Issues!L:L,"<>NOT_APPLICABLE") | X4: =COUNTIFS(QA_Issues!B:B,A4,QA_Issues!D:D,"LIMITATION",QA_Issues!L:L,"<>RESOLVED",QA_Issues!L:L,"<>NOT_APPLICABLE") | Y4: =IF(U4>0,"QA_FAIL",IF(H4=FALSE,"QA_INCOMPLETE",IF(T4<70,"QA_FAIL",IF(OR(T4<85,V4>0),"QA_REVISE","QA_PASS")))) | Z4: Direct visual audit complete (all gallery images inspected). Keyword mapping, titles, and meta tags are high quality. Proposed description copy contains meta-commentary and omits essential package/fabric specifications (D2 MAJOR issue).
A5: jeminise.com+pamnest-twin-halloween-comforter-set-with-sheets-5-pieces-design-01 | B5: pamnest-twin-halloween-comforter-set-with-sheets-5-pieces-design-01 | C5: 164 | D5: Pamnest Twin Halloween Comforter Set with Sheets, 5 Pieces - Design 01 | E5: Witch Moon Halloween Comforter Set | F5: witch moon Halloween comforter set | G5: black white Halloween bedding, Halloween comforter set with sheets, twin Halloween comforter set | H5: TRUE | I5: =SUMIFS(QA_Criteria!F:F,QA_Criteria!B:B,A5,QA_Criteria!C:C,"P1") | J5: =SUMIFS(QA_Criteria!F:F,QA_Criteria!B:B,A5,QA_Criteria!C:C,"P2") | K5: =SUMIFS(QA_Criteria!F:F,QA_Criteria!B:B,A5,QA_Criteria!C:C,"K1") | L5: =SUMIFS(QA_Criteria!F:F,QA_Criteria!B:B,A5,QA_Criteria!C:C,"K2") | M5: =SUMIFS(QA_Criteria!F:F,QA_Criteria!B:B,A5,QA_Criteria!C:C,"K3") | N5: =SUMIFS(QA_Criteria!F:F,QA_Criteria!B:B,A5,QA_Criteria!C:C,"T1") | O5: =SUMIFS(QA_Criteria!F:F,QA_Criteria!B:B,A5,QA_Criteria!C:C,"T2") | P5: =SUMIFS(QA_Criteria!F:F,QA_Criteria!B:B,A5,QA_Criteria!C:C,"D1") | Q5: =SUMIFS(QA_Criteria!F:F,QA_Criteria!B:B,A5,QA_Criteria!C:C,"D2") | R5: =ROUND(0.20*AVERAGEIF(QA_Images!B:B,A5,QA_Images!N:N),2) | S5: =SUMIFS(QA_Criteria!F:F,QA_Criteria!B:B,A5,QA_Criteria!C:C,"E1") | T5: =IF(H5=TRUE,SUM(I5:S5),0) | U5: =COUNTIFS(QA_Issues!B:B,A5,QA_Issues!D:D,"CRITICAL",QA_Issues!L:L,"<>RESOLVED",QA_Issues!L:L,"<>NOT_APPLICABLE") | V5: =COUNTIFS(QA_Issues!B:B,A5,QA_Issues!D:D,"MAJOR",QA_Issues!L:L,"<>RESOLVED",QA_Issues!L:L,"<>NOT_APPLICABLE") | W5: =COUNTIFS(QA_Issues!B:B,A5,QA_Issues!D:D,"MINOR",QA_Issues!L:L,"<>RESOLVED",QA_Issues!L:L,"<>NOT_APPLICABLE") | X5: =COUNTIFS(QA_Issues!B:B,A5,QA_Issues!D:D,"LIMITATION",QA_Issues!L:L,"<>RESOLVED",QA_Issues!L:L,"<>NOT_APPLICABLE") | Y5: =IF(U5>0,"QA_FAIL",IF(H5=FALSE,"QA_INCOMPLETE",IF(T5<70,"QA_FAIL",IF(OR(T5<85,V5>0),"QA_REVISE","QA_PASS")))) | Z5: Direct visual audit complete (all gallery images inspected). Keyword mapping, titles, and meta tags are high quality. Proposed description copy contains meta-commentary and omits essential package/fabric specifications (D2 MAJOR issue).
A6: jeminise.com+pamnest-twin-halloween-comforter-set-with-sheets-5-pieces-design-02 | B6: pamnest-twin-halloween-comforter-set-with-sheets-5-pieces-design-02 | C6: 165 | D6: Pamnest Twin Halloween Comforter Set with Sheets, 5 Pieces - Design 02 | E6: Ghost Pumpkin Halloween Comforter Set | F6: ghost pumpkin Halloween comforter set | G6: dark blue Halloween bedding, pumpkin ghost comforter, twin Halloween comforter set | H6: TRUE | I6: =SUMIFS(QA_Criteria!F:F,QA_Criteria!B:B,A6,QA_Criteria!C:C,"P1") | J6: =SUMIFS(QA_Criteria!F:F,QA_Criteria!B:B,A6,QA_Criteria!C:C,"P2") | K6: =SUMIFS(QA_Criteria!F:F,QA_Criteria!B:B,A6,QA_Criteria!C:C,"K1") | L6: =SUMIFS(QA_Criteria!F:F,QA_Criteria!B:B,A6,QA_Criteria!C:C,"K2") | M6: =SUMIFS(QA_Criteria!F:F,QA_Criteria!B:B,A6,QA_Criteria!C:C,"K3") | N6: =SUMIFS(QA_Criteria!F:F,QA_Criteria!B:B,A6,QA_Criteria!C:C,"T1") | O6: =SUMIFS(QA_Criteria!F:F,QA_Criteria!B:B,A6,QA_Criteria!C:C,"T2") | P6: =SUMIFS(QA_Criteria!F:F,QA_Criteria!B:B,A6,QA_Criteria!C:C,"D1") | Q6: =SUMIFS(QA_Criteria!F:F,QA_Criteria!B:B,A6,QA_Criteria!C:C,"D2") | R6: =ROUND(0.20*AVERAGEIF(QA_Images!B:B,A6,QA_Images!N:N),2) | S6: =SUMIFS(QA_Criteria!F:F,QA_Criteria!B:B,A6,QA_Criteria!C:C,"E1") | T6: =IF(H6=TRUE,SUM(I6:S6),0) | U6: =COUNTIFS(QA_Issues!B:B,A6,QA_Issues!D:D,"CRITICAL",QA_Issues!L:L,"<>RESOLVED",QA_Issues!L:L,"<>NOT_APPLICABLE") | V6: =COUNTIFS(QA_Issues!B:B,A6,QA_Issues!D:D,"MAJOR",QA_Issues!L:L,"<>RESOLVED",QA_Issues!L:L,"<>NOT_APPLICABLE") | W6: =COUNTIFS(QA_Issues!B:B,A6,QA_Issues!D:D,"MINOR",QA_Issues!L:L,"<>RESOLVED",QA_Issues!L:L,"<>NOT_APPLICABLE") | X6: =COUNTIFS(QA_Issues!B:B,A6,QA_Issues!D:D,"LIMITATION",QA_Issues!L:L,"<>RESOLVED",QA_Issues!L:L,"<>NOT_APPLICABLE") | Y6: =IF(U6>0,"QA_FAIL",IF(H6=FALSE,"QA_INCOMPLETE",IF(T6<70,"QA_FAIL",IF(OR(T6<85,V6>0),"QA_REVISE","QA_PASS")))) | Z6: Direct visual audit complete (all gallery images inspected). Keyword mapping, titles, and meta tags are high quality. Proposed description copy contains meta-commentary and omits essential package/fabric specifications (D2 MAJOR issue).
A7: jeminise.com+pamnest-twin-halloween-comforter-set-with-sheets-5-pieces-design-03 | B7: pamnest-twin-halloween-comforter-set-with-sheets-5-pieces-design-03 | C7: 166 | D7: Pamnest Twin Halloween Comforter Set with Sheets, 5 Pieces - Design 03 | E7: Black Ghost Halloween Comforter Set | F7: black ghost Halloween comforter set | G7: white ghost bedding set, spooky ghost comforter, twin Halloween comforter set | H7: TRUE | I7: =SUMIFS(QA_Criteria!F:F,QA_Criteria!B:B,A7,QA_Criteria!C:C,"P1") | J7: =SUMIFS(QA_Criteria!F:F,QA_Criteria!B:B,A7,QA_Criteria!C:C,"P2") | K7: =SUMIFS(QA_Criteria!F:F,QA_Criteria!B:B,A7,QA_Criteria!C:C,"K1") | L7: =SUMIFS(QA_Criteria!F:F,QA_Criteria!B:B,A7,QA_Criteria!C:C,"K2") | M7: =SUMIFS(QA_Criteria!F:F,QA_Criteria!B:B,A7,QA_Criteria!C:C,"K3") | N7: =SUMIFS(QA_Criteria!F:F,QA_Criteria!B:B,A7,QA_Criteria!C:C,"T1") | O7: =SUMIFS(QA_Criteria!F:F,QA_Criteria!B:B,A7,QA_Criteria!C:C,"T2") | P7: =SUMIFS(QA_Criteria!F:F,QA_Criteria!B:B,A7,QA_Criteria!C:C,"D1") | Q7: =SUMIFS(QA_Criteria!F:F,QA_Criteria!B:B,A7,QA_Criteria!C:C,"D2") | R7: =ROUND(0.20*AVERAGEIF(QA_Images!B:B,A7,QA_Images!N:N),2) | S7: =SUMIFS(QA_Criteria!F:F,QA_Criteria!B:B,A7,QA_Criteria!C:C,"E1") | T7: =IF(H7=TRUE,SUM(I7:S7),0) | U7: =COUNTIFS(QA_Issues!B:B,A7,QA_Issues!D:D,"CRITICAL",QA_Issues!L:L,"<>RESOLVED",QA_Issues!L:L,"<>NOT_APPLICABLE") | V7: =COUNTIFS(QA_Issues!B:B,A7,QA_Issues!D:D,"MAJOR",QA_Issues!L:L,"<>RESOLVED",QA_Issues!L:L,"<>NOT_APPLICABLE") | W7: =COUNTIFS(QA_Issues!B:B,A7,QA_Issues!D:D,"MINOR",QA_Issues!L:L,"<>RESOLVED",QA_Issues!L:L,"<>NOT_APPLICABLE") | X7: =COUNTIFS(QA_Issues!B:B,A7,QA_Issues!D:D,"LIMITATION",QA_Issues!L:L,"<>RESOLVED",QA_Issues!L:L,"<>NOT_APPLICABLE") | Y7: =IF(U7>0,"QA_FAIL",IF(H7=FALSE,"QA_INCOMPLETE",IF(T7<70,"QA_FAIL",IF(OR(T7<85,V7>0),"QA_REVISE","QA_PASS")))) | Z7: Direct visual audit complete (all gallery images inspected). Keyword mapping, titles, and meta tags are high quality. Proposed description copy contains meta-commentary and omits essential package/fabric specifications (D2 MAJOR issue).
A8: jeminise.com+pamnest-twin-halloween-comforter-set-with-sheets-5-pieces-design-04 | B8: pamnest-twin-halloween-comforter-set-with-sheets-5-pieces-design-04 | C8: 167 | D8: Pamnest Twin Halloween Comforter Set with Sheets, 5 Pieces - Design 04 | E8: Haunted Pumpkin Ghost Comforter Set | F8: haunted pumpkin ghost comforter set | G8: blue Halloween bedding set, pumpkin ghost bedding, twin Halloween comforter set | H8: TRUE | I8: =SUMIFS(QA_Criteria!F:F,QA_Criteria!B:B,A8,QA_Criteria!C:C,"P1") | J8: =SUMIFS(QA_Criteria!F:F,QA_Criteria!B:B,A8,QA_Criteria!C:C,"P2") | K8: =SUMIFS(QA_Criteria!F:F,QA_Criteria!B:B,A8,QA_Criteria!C:C,"K1") | L8: =SUMIFS(QA_Criteria!F:F,QA_Criteria!B:B,A8,QA_Criteria!C:C,"K2") | M8: =SUMIFS(QA_Criteria!F:F,QA_Criteria!B:B,A8,QA_Criteria!C:C,"K3") | N8: =SUMIFS(QA_Criteria!F:F,QA_Criteria!B:B,A8,QA_Criteria!C:C,"T1") | O8: =SUMIFS(QA_Criteria!F:F,QA_Criteria!B:B,A8,QA_Criteria!C:C,"T2") | P8: =SUMIFS(QA_Criteria!F:F,QA_Criteria!B:B,A8,QA_Criteria!C:C,"D1") | Q8: =SUMIFS(QA_Criteria!F:F,QA_Criteria!B:B,A8,QA_Criteria!C:C,"D2") | R8: =ROUND(0.20*AVERAGEIF(QA_Images!B:B,A8,QA_Images!N:N),2) | S8: =SUMIFS(QA_Criteria!F:F,QA_Criteria!B:B,A8,QA_Criteria!C:C,"E1") | T8: =IF(H8=TRUE,SUM(I8:S8),0) | U8: =COUNTIFS(QA_Issues!B:B,A8,QA_Issues!D:D,"CRITICAL",QA_Issues!L:L,"<>RESOLVED",QA_Issues!L:L,"<>NOT_APPLICABLE") | V8: =COUNTIFS(QA_Issues!B:B,A8,QA_Issues!D:D,"MAJOR",QA_Issues!L:L,"<>RESOLVED",QA_Issues!L:L,"<>NOT_APPLICABLE") | W8: =COUNTIFS(QA_Issues!B:B,A8,QA_Issues!D:D,"MINOR",QA_Issues!L:L,"<>RESOLVED",QA_Issues!L:L,"<>NOT_APPLICABLE") | X8: =COUNTIFS(QA_Issues!B:B,A8,QA_Issues!D:D,"LIMITATION",QA_Issues!L:L,"<>RESOLVED",QA_Issues!L:L,"<>NOT_APPLICABLE") | Y8: =IF(U8>0,"QA_FAIL",IF(H8=FALSE,"QA_INCOMPLETE",IF(T8<70,"QA_FAIL",IF(OR(T8<85,V8>0),"QA_REVISE","QA_PASS")))) | Z8: Direct visual audit complete (all gallery images inspected). Keyword mapping, titles, and meta tags are high quality. Proposed description copy contains meta-commentary and omits essential package/fabric specifications (D2 MAJOR issue).
A9: jeminise.com+pamnest-twin-halloween-comforter-set-with-sheets-5-pieces-design-05 | B9: pamnest-twin-halloween-comforter-set-with-sheets-5-pieces-design-05 | C9: 168 | D9: Pamnest Twin Halloween Comforter Set with Sheets, 5 Pieces - Design 05 | E9: Pink Cute Ghost Halloween Comforter Set | F9: pink cute ghost Halloween comforter set | G9: pink Halloween bedding, cute ghost bedding set, twin Halloween comforter set | H9: TRUE | I9: =SUMIFS(QA_Criteria!F:F,QA_Criteria!B:B,A9,QA_Criteria!C:C,"P1") | J9: =SUMIFS(QA_Criteria!F:F,QA_Criteria!B:B,A9,QA_Criteria!C:C,"P2") | K9: =SUMIFS(QA_Criteria!F:F,QA_Criteria!B:B,A9,QA_Criteria!C:C,"K1") | L9: =SUMIFS(QA_Criteria!F:F,QA_Criteria!B:B,A9,QA_Criteria!C:C,"K2") | M9: =SUMIFS(QA_Criteria!F:F,QA_Criteria!B:B,A9,QA_Criteria!C:C,"K3") | N9: =SUMIFS(QA_Criteria!F:F,QA_Criteria!B:B,A9,QA_Criteria!C:C,"T1") | O9: =SUMIFS(QA_Criteria!F:F,QA_Criteria!B:B,A9,QA_Criteria!C:C,"T2") | P9: =SUMIFS(QA_Criteria!F:F,QA_Criteria!B:B,A9,QA_Criteria!C:C,"D1") | Q9: =SUMIFS(QA_Criteria!F:F,QA_Criteria!B:B,A9,QA_Criteria!C:C,"D2") | R9: =ROUND(0.20*AVERAGEIF(QA_Images!B:B,A9,QA_Images!N:N),2) | S9: =SUMIFS(QA_Criteria!F:F,QA_Criteria!B:B,A9,QA_Criteria!C:C,"E1") | T9: =IF(H9=TRUE,SUM(I9:S9),0) | U9: =COUNTIFS(QA_Issues!B:B,A9,QA_Issues!D:D,"CRITICAL",QA_Issues!L:L,"<>RESOLVED",QA_Issues!L:L,"<>NOT_APPLICABLE") | V9: =COUNTIFS(QA_Issues!B:B,A9,QA_Issues!D:D,"MAJOR",QA_Issues!L:L,"<>RESOLVED",QA_Issues!L:L,"<>NOT_APPLICABLE") | W9: =COUNTIFS(QA_Issues!B:B,A9,QA_Issues!D:D,"MINOR",QA_Issues!L:L,"<>RESOLVED",QA_Issues!L:L,"<>NOT_APPLICABLE") | X9: =COUNTIFS(QA_Issues!B:B,A9,QA_Issues!D:D,"LIMITATION",QA_Issues!L:L,"<>RESOLVED",QA_Issues!L:L,"<>NOT_APPLICABLE") | Y9: =IF(U9>0,"QA_FAIL",IF(H9=FALSE,"QA_INCOMPLETE",IF(T9<70,"QA_FAIL",IF(OR(T9<85,V9>0),"QA_REVISE","QA_PASS")))) | Z9: Direct visual audit complete (all gallery images inspected). Keyword mapping, titles, and meta tags are high quality. Proposed description copy contains meta-commentary and omits essential package/fabric specifications (D2 MAJOR issue).
A10: jeminise.com+pamnest-twin-halloween-comforter-set-with-sheets-5-pieces-design-06 | B10: pamnest-twin-halloween-comforter-set-with-sheets-5-pieces-design-06 | C10: 169 | D10: Pamnest Twin Halloween Comforter Set with Sheets, 5 Pieces - Design 06 | E10: Red Handprint Halloween Comforter Set | F10: red handprint Halloween comforter set | G10: red splatter bedding set, scary Halloween comforter, twin Halloween comforter set | H10: TRUE | I10: =SUMIFS(QA_Criteria!F:F,QA_Criteria!B:B,A10,QA_Criteria!C:C,"P1") | J10: =SUMIFS(QA_Criteria!F:F,QA_Criteria!B:B,A10,QA_Criteria!C:C,"P2") | K10: =SUMIFS(QA_Criteria!F:F,QA_Criteria!B:B,A10,QA_Criteria!C:C,"K1") | L10: =SUMIFS(QA_Criteria!F:F,QA_Criteria!B:B,A10,QA_Criteria!C:C,"K2") | M10: =SUMIFS(QA_Criteria!F:F,QA_Criteria!B:B,A10,QA_Criteria!C:C,"K3") | N10: =SUMIFS(QA_Criteria!F:F,QA_Criteria!B:B,A10,QA_Criteria!C:C,"T1") | O10: =SUMIFS(QA_Criteria!F:F,QA_Criteria!B:B,A10,QA_Criteria!C:C,"T2") | P10: =SUMIFS(QA_Criteria!F:F,QA_Criteria!B:B,A10,QA_Criteria!C:C,"D1") | Q10: =SUMIFS(QA_Criteria!F:F,QA_Criteria!B:B,A10,QA_Criteria!C:C,"D2") | R10: =ROUND(0.20*AVERAGEIF(QA_Images!B:B,A10,QA_Images!N:N),2) | S10: =SUMIFS(QA_Criteria!F:F,QA_Criteria!B:B,A10,QA_Criteria!C:C,"E1") | T10: =IF(H10=TRUE,SUM(I10:S10),0) | U10: =COUNTIFS(QA_Issues!B:B,A10,QA_Issues!D:D,"CRITICAL",QA_Issues!L:L,"<>RESOLVED",QA_Issues!L:L,"<>NOT_APPLICABLE") | V10: =COUNTIFS(QA_Issues!B:B,A10,QA_Issues!D:D,"MAJOR",QA_Issues!L:L,"<>RESOLVED",QA_Issues!L:L,"<>NOT_APPLICABLE") | W10: =COUNTIFS(QA_Issues!B:B,A10,QA_Issues!D:D,"MINOR",QA_Issues!L:L,"<>RESOLVED",QA_Issues!L:L,"<>NOT_APPLICABLE") | X10: =COUNTIFS(QA_Issues!B:B,A10,QA_Issues!D:D,"LIMITATION",QA_Issues!L:L,"<>RESOLVED",QA_Issues!L:L,"<>NOT_APPLICABLE") | Y10: =IF(U10>0,"QA_FAIL",IF(H10=FALSE,"QA_INCOMPLETE",IF(T10<70,"QA_FAIL",IF(OR(T10<85,V10>0),"QA_REVISE","QA_PASS")))) | Z10: Direct visual audit complete (all gallery images inspected). Keyword mapping, titles, and meta tags are high quality. Proposed description copy contains meta-commentary and omits essential package/fabric specifications (D2 MAJOR issue).
A11: jeminise.com+pamnest-twin-halloween-comforter-set-with-sheets-5-pieces-design-07 | B11: pamnest-twin-halloween-comforter-set-with-sheets-5-pieces-design-07 | C11: 170 | D11: Pamnest Twin Halloween Comforter Set with Sheets, 5 Pieces - Design 07 | E11: Haunted House Pumpkin Comforter Set | F11: haunted house pumpkin comforter set | G11: white Halloween bedding set, pumpkin cat comforter, twin Halloween comforter set | H11: TRUE | I11: =SUMIFS(QA_Criteria!F:F,QA_Criteria!B:B,A11,QA_Criteria!C:C,"P1") | J11: =SUMIFS(QA_Criteria!F:F,QA_Criteria!B:B,A11,QA_Criteria!C:C,"P2") | K11: =SUMIFS(QA_Criteria!F:F,QA_Criteria!B:B,A11,QA_Criteria!C:C,"K1") | L11: =SUMIFS(QA_Criteria!F:F,QA_Criteria!B:B,A11,QA_Criteria!C:C,"K2") | M11: =SUMIFS(QA_Criteria!F:F,QA_Criteria!B:B,A11,QA_Criteria!C:C,"K3") | N11: =SUMIFS(QA_Criteria!F:F,QA_Criteria!B:B,A11,QA_Criteria!C:C,"T1") | O11: =SUMIFS(QA_Criteria!F:F,QA_Criteria!B:B,A11,QA_Criteria!C:C,"T2") | P11: =SUMIFS(QA_Criteria!F:F,QA_Criteria!B:B,A11,QA_Criteria!C:C,"D1") | Q11: =SUMIFS(QA_Criteria!F:F,QA_Criteria!B:B,A11,QA_Criteria!C:C,"D2") | R11: =ROUND(0.20*AVERAGEIF(QA_Images!B:B,A11,QA_Images!N:N),2) | S11: =SUMIFS(QA_Criteria!F:F,QA_Criteria!B:B,A11,QA_Criteria!C:C,"E1") | T11: =IF(H11=TRUE,SUM(I11:S11),0) | U11: =COUNTIFS(QA_Issues!B:B,A11,QA_Issues!D:D,"CRITICAL",QA_Issues!L:L,"<>RESOLVED",QA_Issues!L:L,"<>NOT_APPLICABLE") | V11: =COUNTIFS(QA_Issues!B:B,A11,QA_Issues!D:D,"MAJOR",QA_Issues!L:L,"<>RESOLVED",QA_Issues!L:L,"<>NOT_APPLICABLE") | W11: =COUNTIFS(QA_Issues!B:B,A11,QA_Issues!D:D,"MINOR",QA_Issues!L:L,"<>RESOLVED",QA_Issues!L:L,"<>NOT_APPLICABLE") | X11: =COUNTIFS(QA_Issues!B:B,A11,QA_Issues!D:D,"LIMITATION",QA_Issues!L:L,"<>RESOLVED",QA_Issues!L:L,"<>NOT_APPLICABLE") | Y11: =IF(U11>0,"QA_FAIL",IF(H11=FALSE,"QA_INCOMPLETE",IF(T11<70,"QA_FAIL",IF(OR(T11<85,V11>0),"QA_REVISE","QA_PASS")))) | Z11: Direct visual audit complete (all gallery images inspected). Keyword mapping, titles, and meta tags are high quality. Proposed description copy contains meta-commentary and omits essential package/fabric specifications (D2 MAJOR issue).

Sheet QA_Criteria
A1: criterion_id | B1: product_key | C1: criterion_code | D1: criterion_name | E1: max_weight | F1: score_earned | G1: evaluation_status | H1: evaluation_details | I1: auditor_notes
A2: CRIT-001 | B2: jeminise.com+norse-mythology-raven-within-celtic-knot-frame-quilt-906ee24d68-906ee24d68 | C2: P1 | D2: Product Identification | E2: 15 | F2: 15 | G2: PASS | H2: norse-mythology-raven-within-celtic-knot-frame-quilt-906ee24d68-906ee24d68: Accurately identified product form factor, material category, and design motif from direct visual audit and storefront data. | I2: Audited in batch 17 r3. Criteria P1 weight=15.0.
A3: CRIT-002 | B3: jeminise.com+norse-mythology-raven-within-celtic-knot-frame-quilt-906ee24d68-906ee24d68 | C3: P2 | D3: Taxonomy & Classification | E3: 10 | F3: 10 | G3: PASS | H3: norse-mythology-raven-within-celtic-knot-frame-quilt-906ee24d68-906ee24d68: Correct category assignment (Quilts vs Comforter Sets) aligning with Shopify collections and product type. | I3: Audited in batch 17 r3. Criteria P2 weight=10.0.
A4: CRIT-003 | B4: jeminise.com+norse-mythology-raven-within-celtic-knot-frame-quilt-906ee24d68-906ee24d68 | C4: K1 | D4: Primary Keyword Focus | E4: 10 | F4: 10 | G4: PASS | H4: norse-mythology-raven-within-celtic-knot-frame-quilt-906ee24d68-906ee24d68: Primary keyword accurately targets high-intent visual search demand validated via live US SERP analysis. | I4: Audited in batch 17 r3. Criteria K1 weight=10.0.
A5: CRIT-004 | B5: jeminise.com+norse-mythology-raven-within-celtic-knot-frame-quilt-906ee24d68-906ee24d68 | C5: K2 | D5: Secondary Keyword Support | E5: 5 | F5: 5 | G5: PASS | H5: norse-mythology-raven-within-celtic-knot-frame-quilt-906ee24d68-906ee24d68: Secondary keywords support relevant long-tail variations without keyword stuffing. | I5: Audited in batch 17 r3. Criteria K2 weight=5.0.
A6: CRIT-005 | B6: jeminise.com+norse-mythology-raven-within-celtic-knot-frame-quilt-906ee24d68-906ee24d68 | C6: K3 | D6: Keyword Cannibalization & Differentiation | E6: 5 | F6: 5 | G6: PASS | H6: norse-mythology-raven-within-celtic-knot-frame-quilt-906ee24d68-906ee24d68: Distinct keyword modifiers prevent internal competition across similar thematic items in the batch. | I6: Audited in batch 17 r3. Criteria K3 weight=5.0.
A7: CRIT-006 | B7: jeminise.com+norse-mythology-raven-within-celtic-knot-frame-quilt-906ee24d68-906ee24d68 | C7: T1 | D7: Title Proposed Quality & Accuracy | E7: 10 | F7: 10 | G7: PASS | H7: norse-mythology-raven-within-celtic-knot-frame-quilt-906ee24d68-906ee24d68: Title proposed is natural, high-converting, concise (<60 chars), and properly removes misleading variant claims (e.g. Twin 5-piece) from multi-size listings. | I7: Audited in batch 17 r3. Criteria T1 weight=10.0.
A8: CRIT-007 | B8: jeminise.com+norse-mythology-raven-within-celtic-knot-frame-quilt-906ee24d68-906ee24d68 | C8: T2 | D8: Meta Title Quality & Length | E8: 5 | F8: 5 | G8: PASS | H8: norse-mythology-raven-within-celtic-knot-frame-quilt-906ee24d68-906ee24d68: Meta title is concise (28-39 chars), well under 60-char truncation threshold, and brand suffix is handled by Shopify theme. | I8: Audited in batch 17 r3. Criteria T2 weight=5.0.
A9: CRIT-008 | B9: jeminise.com+norse-mythology-raven-within-celtic-knot-frame-quilt-906ee24d68-906ee24d68 | C9: D1 | D9: Meta Description Quality & Length | E9: 5 | F9: 5 | G9: PASS | H9: norse-mythology-raven-within-celtic-knot-frame-quilt-906ee24d68-906ee24d68: Meta description is concise (100-120 chars), provides a compelling action-oriented summary with size chart notice. | I9: Audited in batch 17 r3. Criteria D1 weight=5.0.
A10: CRIT-009 | B10: jeminise.com+norse-mythology-raven-within-celtic-knot-frame-quilt-906ee24d68-906ee24d68 | C10: D2 | D10: Description Proposed Content & Completeness | E10: 10 | F10: 7 | G10: PARTIAL | H10: norse-mythology-raven-within-celtic-knot-frame-quilt-906ee24d68-906ee24d68: Description HTML is clean but contains robotic meta-commentary sentences explaining copywriting rules and omits essential verified technical/package specifications. | I10: Audited in batch 17 r3. Criteria D2 weight=10.0.
A11: CRIT-010 | B11: jeminise.com+norse-mythology-raven-within-celtic-knot-frame-quilt-906ee24d68-906ee24d68 | C11: I1 | D11: Image Optimization & Coverage | E11: 20 | F11: =ROUND(0.20*AVERAGEIF(QA_Images!B:B,B11,QA_Images!N:N),2) | G11: PASS | H11: norse-mythology-raven-within-celtic-knot-frame-quilt-906ee24d68-906ee24d68: All baseline gallery images directly inspected, specific visual observations recorded, and keyword-aligned alt text proposed. | I11: Audited in batch 17 r3. Criteria I1 weight=20.0.
A12: CRIT-011 | B12: jeminise.com+norse-mythology-raven-within-celtic-knot-frame-quilt-906ee24d68-906ee24d68 | C12: E1 | D12: Evidence & Research Traceability | E12: 5 | F12: 4 | G12: LIMITATION | H12: norse-mythology-raven-within-celtic-knot-frame-quilt-906ee24d68-906ee24d68: Evidence backed by live US SERPs (20 queries) and storefront audit; documented limitation on absent first-party Search Console data. | I12: Audited in batch 17 r3. Criteria E1 weight=5.0.
A13: CRIT-012 | B13: jeminise.com+norse-mythology-viking-shield-with-crossed-axes-quilt-ca630a284e-ca630a284e | C13: P1 | D13: Product Identification | E13: 15 | F13: 15 | G13: PASS | H13: norse-mythology-viking-shield-with-crossed-axes-quilt-ca630a284e-ca630a284e: Accurately identified product form factor, material category, and design motif from direct visual audit and storefront data. | I13: Audited in batch 17 r3. Criteria P1 weight=15.0.
A14: CRIT-013 | B14: jeminise.com+norse-mythology-viking-shield-with-crossed-axes-quilt-ca630a284e-ca630a284e | C14: P2 | D14: Taxonomy & Classification | E14: 10 | F14: 10 | G14: PASS | H14: norse-mythology-viking-shield-with-crossed-axes-quilt-ca630a284e-ca630a284e: Correct category assignment (Quilts vs Comforter Sets) aligning with Shopify collections and product type. | I14: Audited in batch 17 r3. Criteria P2 weight=10.0.
A15: CRIT-014 | B15: jeminise.com+norse-mythology-viking-shield-with-crossed-axes-quilt-ca630a284e-ca630a284e | C15: K1 | D15: Primary Keyword Focus | E15: 10 | F15: 10 | G15: PASS | H15: norse-mythology-viking-shield-with-crossed-axes-quilt-ca630a284e-ca630a284e: Primary keyword accurately targets high-intent visual search demand validated via live US SERP analysis. | I15: Audited in batch 17 r3. Criteria K1 weight=10.0.
A16: CRIT-015 | B16: jeminise.com+norse-mythology-viking-shield-with-crossed-axes-quilt-ca630a284e-ca630a284e | C16: K2 | D16: Secondary Keyword Support | E16: 5 | F16: 5 | G16: PASS | H16: norse-mythology-viking-shield-with-crossed-axes-quilt-ca630a284e-ca630a284e: Secondary keywords support relevant long-tail variations without keyword stuffing. | I16: Audited in batch 17 r3. Criteria K2 weight=5.0.
A17: CRIT-016 | B17: jeminise.com+norse-mythology-viking-shield-with-crossed-axes-quilt-ca630a284e-ca630a284e | C17: K3 | D17: Keyword Cannibalization & Differentiation | E17: 5 | F17: 5 | G17: PASS | H17: norse-mythology-viking-shield-with-crossed-axes-quilt-ca630a284e-ca630a284e: Distinct keyword modifiers prevent internal competition across similar thematic items in the batch. | I17: Audited in batch 17 r3. Criteria K3 weight=5.0.
A18: CRIT-017 | B18: jeminise.com+norse-mythology-viking-shield-with-crossed-axes-quilt-ca630a284e-ca630a284e | C18: T1 | D18: Title Proposed Quality & Accuracy | E18: 10 | F18: 10 | G18: PASS | H18: norse-mythology-viking-shield-with-crossed-axes-quilt-ca630a284e-ca630a284e: Title proposed is natural, high-converting, concise (<60 chars), and properly removes misleading variant claims (e.g. Twin 5-piece) from multi-size listings. | I18: Audited in batch 17 r3. Criteria T1 weight=10.0.
A19: CRIT-018 | B19: jeminise.com+norse-mythology-viking-shield-with-crossed-axes-quilt-ca630a284e-ca630a284e | C19: T2 | D19: Meta Title Quality & Length | E19: 5 | F19: 5 | G19: PASS | H19: norse-mythology-viking-shield-with-crossed-axes-quilt-ca630a284e-ca630a284e: Meta title is concise (28-39 chars), well under 60-char truncation threshold, and brand suffix is handled by Shopify theme. | I19: Audited in batch 17 r3. Criteria T2 weight=5.0.
A20: CRIT-019 | B20: jeminise.com+norse-mythology-viking-shield-with-crossed-axes-quilt-ca630a284e-ca630a284e | C20: D1 | D20: Meta Description Quality & Length | E20: 5 | F20: 5 | G20: PASS | H20: norse-mythology-viking-shield-with-crossed-axes-quilt-ca630a284e-ca630a284e: Meta description is concise (100-120 chars), provides a compelling action-oriented summary with size chart notice. | I20: Audited in batch 17 r3. Criteria D1 weight=5.0.
A21: CRIT-020 | B21: jeminise.com+norse-mythology-viking-shield-with-crossed-axes-quilt-ca630a284e-ca630a284e | C21: D2 | D21: Description Proposed Content & Completeness | E21: 10 | F21: 7 | G21: PARTIAL | H21: norse-mythology-viking-shield-with-crossed-axes-quilt-ca630a284e-ca630a284e: Description HTML is clean but contains robotic meta-commentary sentences explaining copywriting rules and omits essential verified technical/package specifications. | I21: Audited in batch 17 r3. Criteria D2 weight=10.0.
A22: CRIT-021 | B22: jeminise.com+norse-mythology-viking-shield-with-crossed-axes-quilt-ca630a284e-ca630a284e | C22: I1 | D22: Image Optimization & Coverage | E22: 20 | F22: =ROUND(0.20*AVERAGEIF(QA_Images!B:B,B22,QA_Images!N:N),2) | G22: PASS | H22: norse-mythology-viking-shield-with-crossed-axes-quilt-ca630a284e-ca630a284e: All baseline gallery images directly inspected, specific visual observations recorded, and keyword-aligned alt text proposed. | I22: Audited in batch 17 r3. Criteria I1 weight=20.0.
A23: CRIT-022 | B23: jeminise.com+norse-mythology-viking-shield-with-crossed-axes-quilt-ca630a284e-ca630a284e | C23: E1 | D23: Evidence & Research Traceability | E23: 5 | F23: 4 | G23: LIMITATION | H23: norse-mythology-viking-shield-with-crossed-axes-quilt-ca630a284e-ca630a284e: Evidence backed by live US SERPs (20 queries) and storefront audit; documented limitation on absent first-party Search Console data. | I23: Audited in batch 17 r3. Criteria E1 weight=5.0.
A24: CRIT-023 | B24: jeminise.com+owl-patchwork-pattern-quilt-set-animals-quilt-set-style-owl-nights | C24: P1 | D24: Product Identification | E24: 15 | F24: 15 | G24: PASS | H24: owl-patchwork-pattern-quilt-set-animals-quilt-set-style-owl-nights: Accurately identified product form factor, material category, and design motif from direct visual audit and storefront data. | I24: Audited in batch 17 r3. Criteria P1 weight=15.0.
A25: CRIT-024 | B25: jeminise.com+owl-patchwork-pattern-quilt-set-animals-quilt-set-style-owl-nights | C25: P2 | D25: Taxonomy & Classification | E25: 10 | F25: 10 | G25: PASS | H25: owl-patchwork-pattern-quilt-set-animals-quilt-set-style-owl-nights: Correct category assignment (Quilts vs Comforter Sets) aligning with Shopify collections and product type. | I25: Audited in batch 17 r3. Criteria P2 weight=10.0.
A26: CRIT-025 | B26: jeminise.com+owl-patchwork-pattern-quilt-set-animals-quilt-set-style-owl-nights | C26: K1 | D26: Primary Keyword Focus | E26: 10 | F26: 10 | G26: PASS | H26: owl-patchwork-pattern-quilt-set-animals-quilt-set-style-owl-nights: Primary keyword accurately targets high-intent visual search demand validated via live US SERP analysis. | I26: Audited in batch 17 r3. Criteria K1 weight=10.0.
A27: CRIT-026 | B27: jeminise.com+owl-patchwork-pattern-quilt-set-animals-quilt-set-style-owl-nights | C27: K2 | D27: Secondary Keyword Support | E27: 5 | F27: 5 | G27: PASS | H27: owl-patchwork-pattern-quilt-set-animals-quilt-set-style-owl-nights: Secondary keywords support relevant long-tail variations without keyword stuffing. | I27: Audited in batch 17 r3. Criteria K2 weight=5.0.
A28: CRIT-027 | B28: jeminise.com+owl-patchwork-pattern-quilt-set-animals-quilt-set-style-owl-nights | C28: K3 | D28: Keyword Cannibalization & Differentiation | E28: 5 | F28: 5 | G28: PASS | H28: owl-patchwork-pattern-quilt-set-animals-quilt-set-style-owl-nights: Distinct keyword modifiers prevent internal competition across similar thematic items in the batch. | I28: Audited in batch 17 r3. Criteria K3 weight=5.0.
A29: CRIT-028 | B29: jeminise.com+owl-patchwork-pattern-quilt-set-animals-quilt-set-style-owl-nights | C29: T1 | D29: Title Proposed Quality & Accuracy | E29: 10 | F29: 10 | G29: PASS | H29: owl-patchwork-pattern-quilt-set-animals-quilt-set-style-owl-nights: Title proposed is natural, high-converting, concise (<60 chars), and properly removes misleading variant claims (e.g. Twin 5-piece) from multi-size listings. | I29: Audited in batch 17 r3. Criteria T1 weight=10.0.
A30: CRIT-029 | B30: jeminise.com+owl-patchwork-pattern-quilt-set-animals-quilt-set-style-owl-nights | C30: T2 | D30: Meta Title Quality & Length | E30: 5 | F30: 5 | G30: PASS | H30: owl-patchwork-pattern-quilt-set-animals-quilt-set-style-owl-nights: Meta title is concise (28-39 chars), well under 60-char truncation threshold, and brand suffix is handled by Shopify theme. | I30: Audited in batch 17 r3. Criteria T2 weight=5.0.
A31: CRIT-030 | B31: jeminise.com+owl-patchwork-pattern-quilt-set-animals-quilt-set-style-owl-nights | C31: D1 | D31: Meta Description Quality & Length | E31: 5 | F31: 5 | G31: PASS | H31: owl-patchwork-pattern-quilt-set-animals-quilt-set-style-owl-nights: Meta description is concise (100-120 chars), provides a compelling action-oriented summary with size chart notice. | I31: Audited in batch 17 r3. Criteria D1 weight=5.0.
A32: CRIT-031 | B32: jeminise.com+owl-patchwork-pattern-quilt-set-animals-quilt-set-style-owl-nights | C32: D2 | D32: Description Proposed Content & Completeness | E32: 10 | F32: 7 | G32: PARTIAL | H32: owl-patchwork-pattern-quilt-set-animals-quilt-set-style-owl-nights: Description HTML is clean but contains robotic meta-commentary sentences explaining copywriting rules and omits essential verified technical/package specifications. | I32: Audited in batch 17 r3. Criteria D2 weight=10.0.
A33: CRIT-032 | B33: jeminise.com+owl-patchwork-pattern-quilt-set-animals-quilt-set-style-owl-nights | C33: I1 | D33: Image Optimization & Coverage | E33: 20 | F33: =ROUND(0.20*AVERAGEIF(QA_Images!B:B,B33,QA_Images!N:N),2) | G33: PASS | H33: owl-patchwork-pattern-quilt-set-animals-quilt-set-style-owl-nights: All baseline gallery images directly inspected, specific visual observations recorded, and keyword-aligned alt text proposed. | I33: Audited in batch 17 r3. Criteria I1 weight=20.0.
A34: CRIT-033 | B34: jeminise.com+owl-patchwork-pattern-quilt-set-animals-quilt-set-style-owl-nights | C34: E1 | D34: Evidence & Research Traceability | E34: 5 | F34: 4 | G34: LIMITATION | H34: owl-patchwork-pattern-quilt-set-animals-quilt-set-style-owl-nights: Evidence backed by live US SERPs (20 queries) and storefront audit; documented limitation on absent first-party Search Console data. | I34: Audited in batch 17 r3. Criteria E1 weight=5.0.
A35: CRIT-034 | B35: jeminise.com+pamnest-twin-halloween-comforter-set-with-sheets-5-pieces-design-01 | C35: P1 | D35: Product Identification | E35: 15 | F35: 15 | G35: PASS | H35: pamnest-twin-halloween-comforter-set-with-sheets-5-pieces-design-01: Accurately identified product form factor, material category, and design motif from direct visual audit and storefront data. | I35: Audited in batch 17 r3. Criteria P1 weight=15.0.
A36: CRIT-035 | B36: jeminise.com+pamnest-twin-halloween-comforter-set-with-sheets-5-pieces-design-01 | C36: P2 | D36: Taxonomy & Classification | E36: 10 | F36: 10 | G36: PASS | H36: pamnest-twin-halloween-comforter-set-with-sheets-5-pieces-design-01: Correct category assignment (Quilts vs Comforter Sets) aligning with Shopify collections and product type. | I36: Audited in batch 17 r3. Criteria P2 weight=10.0.
A37: CRIT-036 | B37: jeminise.com+pamnest-twin-halloween-comforter-set-with-sheets-5-pieces-design-01 | C37: K1 | D37: Primary Keyword Focus | E37: 10 | F37: 10 | G37: PASS | H37: pamnest-twin-halloween-comforter-set-with-sheets-5-pieces-design-01: Primary keyword accurately targets high-intent visual search demand validated via live US SERP analysis. | I37: Audited in batch 17 r3. Criteria K1 weight=10.0.
A38: CRIT-037 | B38: jeminise.com+pamnest-twin-halloween-comforter-set-with-sheets-5-pieces-design-01 | C38: K2 | D38: Secondary Keyword Support | E38: 5 | F38: 5 | G38: PASS | H38: pamnest-twin-halloween-comforter-set-with-sheets-5-pieces-design-01: Secondary keywords support relevant long-tail variations without keyword stuffing. | I38: Audited in batch 17 r3. Criteria K2 weight=5.0.
A39: CRIT-038 | B39: jeminise.com+pamnest-twin-halloween-comforter-set-with-sheets-5-pieces-design-01 | C39: K3 | D39: Keyword Cannibalization & Differentiation | E39: 5 | F39: 5 | G39: PASS | H39: pamnest-twin-halloween-comforter-set-with-sheets-5-pieces-design-01: Distinct keyword modifiers prevent internal competition across similar thematic items in the batch. | I39: Audited in batch 17 r3. Criteria K3 weight=5.0.
A40: CRIT-039 | B40: jeminise.com+pamnest-twin-halloween-comforter-set-with-sheets-5-pieces-design-01 | C40: T1 | D40: Title Proposed Quality & Accuracy | E40: 10 | F40: 10 | G40: PASS | H40: pamnest-twin-halloween-comforter-set-with-sheets-5-pieces-design-01: Title proposed is natural, high-converting, concise (<60 chars), and properly removes misleading variant claims (e.g. Twin 5-piece) from multi-size listings. | I40: Audited in batch 17 r3. Criteria T1 weight=10.0.
...

Sheet QA_Images
A1: qa_image_key | B1: product_key | C1: Handle | D1: image_number | E1: media_id | F1: image_url | G1: file_path | H1: sha256_hash | I1: image_dimensions | J1: IM1_score | K1: IM2_score | L1: IM3_score | M1: IM4_score | N1: total_image_score | O1: image_qa_status | P1: observed_details_audit | Q1: alt_text_audit
A2: IMGQA-001 | B2: jeminise.com+norse-mythology-raven-within-celtic-knot-frame-quilt-906ee24d68-906ee24d68 | C2: norse-mythology-raven-within-celtic-knot-frame-quilt-906ee24d68-906ee24d68 | D2: 1 | E2: 47540522516679 | F2: https://cdn.shopify.com/s/files/1/0792/5098/1063/files/f5df6ea5afdf042e566b7af241d22bd6929357120dcb00f0bc65a8916d20bdd1.jpg?v=1785104402 | G2: images\161_01.jpg | H2: 5f2e3952f9cfee8bfb3fa02b98d3fe9ba2f05643499c0504ff9bf49991b087d9 | I2: 1000x1000 | J2: 40 | K2: 30 | L2: 20 | M2: 10 | N2: =SUM(J2:M2) | O2: =IF(N2>=85,"PASS",IF(N2>=70,"REVISE","FAIL")) | P2: Direct visual review verified: Bedroom mockup of blue raven quilt with Celtic knot frame, moon panel and matching shams. | Q2: Alt text verified: Blue raven Celtic knot quilt
A3: IMGQA-002 | B3: jeminise.com+norse-mythology-raven-within-celtic-knot-frame-quilt-906ee24d68-906ee24d68 | C3: norse-mythology-raven-within-celtic-knot-frame-quilt-906ee24d68-906ee24d68 | D3: 2 | E3: 47540522549447 | F3: https://cdn.shopify.com/s/files/1/0792/5098/1063/files/bbce88f2a66fabf46529458b35db7d33399da290b604d17e49b58d179adc7c2a.jpg?v=1785104402 | G3: images\161_02.jpg | H3: 45402a7b1c4420cca68969194e972cddbdf716be753b81a373687cdef4de4f8f | I3: 1000x1000 | J3: 40 | K3: 30 | L3: 20 | M3: 10 | N3: =SUM(J3:M3) | O3: =IF(N3>=85,"PASS",IF(N3>=70,"REVISE","FAIL")) | P3: Direct visual review verified: Feature mockup of Norse raven quilt with cozy, breathable, lightweight and washable icons. | Q3: Alt text verified: Blue raven quilt feature panel
A4: IMGQA-003 | B4: jeminise.com+norse-mythology-raven-within-celtic-knot-frame-quilt-906ee24d68-906ee24d68 | C4: norse-mythology-raven-within-celtic-knot-frame-quilt-906ee24d68-906ee24d68 | D4: 3 | E4: 47540522582215 | F4: https://cdn.shopify.com/s/files/1/0792/5098/1063/files/27dd51b6fe9a32b87ac804b19987fb134fc4570b327d844efdae0740d4303aab.jpg?v=1785104402 | G4: images\161_03.jpg | H4: 50afea49d61bc29a92a4df63f7ca1e547341fa8c7cf4d1ceb1cb69e9aa916042 | I4: 1000x1000 | J4: 40 | K4: 30 | L4: 20 | M4: 10 | N4: =SUM(J4:M4) | O4: =IF(N4>=85,"PASS",IF(N4>=70,"REVISE","FAIL")) | P4: Direct visual review verified: All seasons panel showing blue raven Celtic knot quilt details and magnified texture circles. | Q4: Alt text verified: Norse raven Celtic knot detail panel
A5: IMGQA-004 | B5: jeminise.com+norse-mythology-raven-within-celtic-knot-frame-quilt-906ee24d68-906ee24d68 | C5: norse-mythology-raven-within-celtic-knot-frame-quilt-906ee24d68-906ee24d68 | D5: 4 | E5: 47540522614983 | F5: https://cdn.shopify.com/s/files/1/0792/5098/1063/files/c63b8bede4de84261bd2bc195d98188fb288eba460ea7d07b0ef625dba18ed45.jpg?v=1785104402 | G5: images\161_04.jpg | H5: 1ebfe3b8d9025b494acfd0ca4022f40fa6a0c8fa2f48b98c0ada0b86eb2641de | I5: 1000x1000 | J5: 40 | K5: 30 | L5: 20 | M5: 10 | N5: =SUM(J5:M5) | O5: =IF(N5>=85,"PASS",IF(N5>=70,"REVISE","FAIL")) | P5: Direct visual review verified: Precision stitching panel showing raven, moon and Celtic knot close-ups. | Q5: Alt text verified: Blue raven quilt stitching panel
A6: IMGQA-005 | B6: jeminise.com+norse-mythology-raven-within-celtic-knot-frame-quilt-906ee24d68-906ee24d68 | C6: norse-mythology-raven-within-celtic-knot-frame-quilt-906ee24d68-906ee24d68 | D6: 5 | E6: 47540522647751 | F6: https://cdn.shopify.com/s/files/1/0792/5098/1063/files/bbe527fc7f68c31328261559b7b766ec905010bb91f9515c6d557dd1b085f14b.jpg?v=1785104402 | G6: images\161_05.jpg | H6: 8b8ab476b72df5dece8b47ff68fe7f7c254464fac6c53140000397e0ccaf3c53 | I6: 1000x1000 | J6: 40 | K6: 30 | L6: 20 | M6: 10 | N6: =SUM(J6:M6) | O6: =IF(N6>=85,"PASS",IF(N6>=70,"REVISE","FAIL")) | P6: Direct visual review verified: Layer panel showing microfiber woven top, filling microfiber and back microfiber. | Q6: Alt text verified: Raven quilt microfiber layer panel
A7: IMGQA-006 | B7: jeminise.com+norse-mythology-raven-within-celtic-knot-frame-quilt-906ee24d68-906ee24d68 | C7: norse-mythology-raven-within-celtic-knot-frame-quilt-906ee24d68-906ee24d68 | D7: 6 | E7: 47540522680519 | F7: https://cdn.shopify.com/s/files/1/0792/5098/1063/files/5cc9f4f96bdb0280d8a3c4b98775690e61d79ad5625e9f20a101536548fe3b0e.jpg?v=1785104402 | G7: images\161_06.jpg | H7: 6a3b322f6da7163f9772280430dde0229605bbf4dc984034eca74ee7b134a75a | I7: 1200x1200 | J7: 40 | K7: 30 | L7: 20 | M7: 10 | N7: =SUM(J7:M7) | O7: =IF(N7>=85,"PASS",IF(N7>=70,"REVISE","FAIL")) | P7: Direct visual review verified: Premium quilt set size chart showing available bed sizes and measurements. | Q7: Alt text verified: Quilt set size chart
A8: IMGQA-007 | B8: jeminise.com+norse-mythology-raven-within-celtic-knot-frame-quilt-906ee24d68-906ee24d68 | C8: norse-mythology-raven-within-celtic-knot-frame-quilt-906ee24d68-906ee24d68 | D8: 7 | E8: 47540522713287 | F8: https://cdn.shopify.com/s/files/1/0792/5098/1063/files/31facc27e0d676d03e5239357f2912111f3e0640688af1ac241589e99b6705fb.jpg?v=1785104402 | G8: images\161_07.jpg | H8: ecd93b622c766abf2c6d708d77408dedeb63c129220b99f56a5244f09ec16214 | I8: 1200x1200 | J8: 40 | K8: 30 | L8: 20 | M8: 10 | N8: =SUM(J8:M8) | O8: =IF(N8>=85,"PASS",IF(N8>=70,"REVISE","FAIL")) | P8: Direct visual review verified: Fabric detail panel showing blue raven Celtic knot print and quilt surface close-ups. | Q8: Alt text verified: Blue raven Celtic quilt fabric panel
A9: IMGQA-008 | B9: jeminise.com+norse-mythology-viking-shield-with-crossed-axes-quilt-ca630a284e-ca630a284e | C9: norse-mythology-viking-shield-with-crossed-axes-quilt-ca630a284e-ca630a284e | D9: 1 | E9: 47540537688263 | F9: https://cdn.shopify.com/s/files/1/0792/5098/1063/files/a0bb7b2e86bb5a07b6f85d9046b813c1954eadf01e22807354afd66a9ebfdea6.jpg?v=1785104553 | G9: images\162_01.jpg | H9: 5010ad7f41130dfeff8a19435ee269e7b39d6f6b4778a6627dd6f02631ca1448 | I9: 1000x1000 | J9: 40 | K9: 30 | L9: 20 | M9: 10 | N9: =SUM(J9:M9) | O9: =IF(N9>=85,"PASS",IF(N9>=70,"REVISE","FAIL")) | P9: Direct visual review verified: Bedroom mockup of black Valhalla Viking shield quilt with crossed axes and matching shams. | Q9: Alt text verified: Valhalla Viking shield quilt
A10: IMGQA-009 | B10: jeminise.com+norse-mythology-viking-shield-with-crossed-axes-quilt-ca630a284e-ca630a284e | C10: norse-mythology-viking-shield-with-crossed-axes-quilt-ca630a284e-ca630a284e | D10: 2 | E10: 47540537721031 | F10: https://cdn.shopify.com/s/files/1/0792/5098/1063/files/cdc35c826f340b6635063d4154a0b5dfe33f71c7ea05f07fdfc6546f09c22e28.jpg?v=1785104553 | G10: images\162_02.jpg | H10: b780f1c2a1a631706ac39c588d420c8721f546fd3fc03ab4a8cde4017456e7c6 | I10: 1200x1200 | J10: 40 | K10: 30 | L10: 20 | M10: 10 | N10: =SUM(J10:M10) | O10: =IF(N10>=85,"PASS",IF(N10>=70,"REVISE","FAIL")) | P10: Direct visual review verified: Feature mockup of Viking shield quilt with cozy, breathable, lightweight and washable icons. | Q10: Alt text verified: Viking shield quilt feature panel
A11: IMGQA-010 | B11: jeminise.com+norse-mythology-viking-shield-with-crossed-axes-quilt-ca630a284e-ca630a284e | C11: norse-mythology-viking-shield-with-crossed-axes-quilt-ca630a284e-ca630a284e | D11: 3 | E11: 47540537753799 | F11: https://cdn.shopify.com/s/files/1/0792/5098/1063/files/7127a02e884cad7c5184ce1b2946ac662960d39acad6edb3b8a21f844cc7fb83.jpg?v=1785104553 | G11: images\162_03.jpg | H11: 41afb4c92d4cf29d2ad3187cec72ec16f2171cc7f58a62794e269c4cae36a378 | I11: 1200x1200 | J11: 40 | K11: 30 | L11: 20 | M11: 10 | N11: =SUM(J11:M11) | O11: =IF(N11>=85,"PASS",IF(N11>=70,"REVISE","FAIL")) | P11: Direct visual review verified: All seasons panel showing Valhalla shield, crossed axes and runic background details. | Q11: Alt text verified: Valhalla shield quilt detail panel
A12: IMGQA-011 | B12: jeminise.com+norse-mythology-viking-shield-with-crossed-axes-quilt-ca630a284e-ca630a284e | C12: norse-mythology-viking-shield-with-crossed-axes-quilt-ca630a284e-ca630a284e | D12: 4 | E12: 47540537786567 | F12: https://cdn.shopify.com/s/files/1/0792/5098/1063/files/e1bca6ad0b85bcfa2b85d2a0322d79680fde7448a15adec1757a81eb07c4bf6f.jpg?v=1785104553 | G12: images\162_04.jpg | H12: a41a44134043c9136539f8e607535e3d11b3acb18100bb96cec2da445f2abd0f | I12: 1200x1200 | J12: 40 | K12: 30 | L12: 20 | M12: 10 | N12: =SUM(J12:M12) | O12: =IF(N12>=85,"PASS",IF(N12>=70,"REVISE","FAIL")) | P12: Direct visual review verified: Precision stitching panel showing Viking shield, crossed axes and black fabric close-ups. | Q12: Alt text verified: Viking shield quilt stitching panel
A13: IMGQA-012 | B13: jeminise.com+norse-mythology-viking-shield-with-crossed-axes-quilt-ca630a284e-ca630a284e | C13: norse-mythology-viking-shield-with-crossed-axes-quilt-ca630a284e-ca630a284e | D13: 5 | E13: 47540537819335 | F13: https://cdn.shopify.com/s/files/1/0792/5098/1063/files/77fb3f8c371cf27dd16588f3cf56fb24c12deaa2922c16412de893b0e53890dd.jpg?v=1785104553 | G13: images\162_05.jpg | H13: 022469ee5c53116cfe68e563776876b274b93c35fcee1527e5772890999a92a5 | I13: 1200x1200 | J13: 40 | K13: 30 | L13: 20 | M13: 10 | N13: =SUM(J13:M13) | O13: =IF(N13>=85,"PASS",IF(N13>=70,"REVISE","FAIL")) | P13: Direct visual review verified: Layer panel showing microfiber woven top, filling microfiber and back microfiber. | Q13: Alt text verified: Viking shield quilt microfiber layer panel
... A63: IMGQA-062 | B63: jeminise.com+pamnest-twin-halloween-comforter-set-with-sheets-5-pieces-design-07 | C63: pamnest-twin-halloween-comforter-set-with-sheets-5-pieces-design-07 | D63: 6 | E63: 48066078212295 | F63: https://cdn.shopify.com/s/files/1/0792/5098/1063/files/3e227101e2e9c24d641f1ea4dd5f5e1cb8ef75e8fe6c70b298e93002e2905f25.jpg?v=1787936313 | G63: images\170_06.jpg | H63: 6bb214f32e9ae6a6941d5862382f509a1dc19a42d9e7e2d9338ca4543c399593 | I63: 1500x1500 | J63: 40 | K63: 30 | L63: 20 | M63: 10 | N63: =SUM(J63:M63) | O63: =IF(N63>=85,"PASS",IF(N63>=70,"REVISE","FAIL")) | P63: Direct visual review verified: Package include panel with haunted house pumpkin bedding and size table. | Q63: Alt text verified: Haunted house comforter package panel

Sheet QA_Issues
A1: issue_id | B1: product_key | C1: qa_image_key | D1: severity | E1: field | F1: submitted_value | G1: source_observation | H1: reason | I1: recommended_fix | J1: supporting_evidence | K1: recheck_condition | L1: reconciliation_status
A2: ISSUE-0001 | B2: jeminise.com+norse-mythology-raven-within-celtic-knot-frame-quilt-906ee24d68-906ee24d68 | D2: MAJOR | E2: description_proposed_html | F2: <p>This Jeminise quilt set features blue patchwork Norse raven artwork within a Celtic knot frame with moon, raven and Tree of Life panels, making it suited for Viking-themed bedroom decor, mythology gifts or personalized Norse bedding.</p><h3>Design Details</h3><ul><li>Visible artwork: blue patchwork Norse raven artwork within a Celtic knot frame with moon, raven and Tree of Life panels.</li><li>Source product details include: Brand: Jeminise;… | G2: Draft contains SEO Use / QA approval wording. | H2: Internal workflow language is not publish-ready storefront copy. | I2: Remove internal QA/import block and replace with customer-facing verified copy. | J2: Draft contains SEO Use / QA approval wording. | K2: Description HTML no longer contains SEO Use, QA, approval, import or draft language. | L2: RESOLVED
A3: ISSUE-0002 | B3: jeminise.com+norse-mythology-raven-within-celtic-knot-frame-quilt-906ee24d68-906ee24d68 | D3: MAJOR | E3: h1_proposed | G3: The submitted workbook row has no proposed H1. | H3: A publishable SEO title/H1 pair is incomplete when the H1 field is blank. | I3: Write one English H1 that matches the verified product type and visible design; do not copy unsupported claims. | J3: The submitted workbook row has no proposed H1. | K3: Workbook contains a non-empty H1 and it is consistent with title, primary keyword and live product evidence. | L3: NOT_APPLICABLE
A4: ISSUE-0003 | B4: jeminise.com+norse-mythology-raven-within-celtic-knot-frame-quilt-906ee24d68-906ee24d68 | D4: MINOR | E4: meta_description_seo | F4: Shop a quilt set featuring blue patchwork Norse raven artwork within a Celtic knot frame with moon, raven and Tree of Life panels. Review available sizes and set options before checkout. | G4: Meta description length is 186 characters. | H4: Likely to truncate in search results and repeats review/personality wording in several rows. | I4: Rewrite to roughly 145-155 characters while preserving verified design and product type. | J4: Meta description length is 186 characters. | K4: Length check <=160 characters and no unsupported claim remains. | L4: RESOLVED
A5: ISSUE-0004 | B5: jeminise.com+norse-mythology-raven-within-celtic-knot-frame-quilt-906ee24d68-906ee24d68 | D5: LIMITATION | E5: keyword_evidence_level | F5: SERP_ONLY | G5: Only public SERP comparables are available. | H5: No Search Console, paid keyword volume or internal site search export was supplied. | I5: Keep demand statements qualitative; do not claim volume or ranking potential. | J5: Only public SERP comparables are available. | K5: Additional first-party or paid keyword evidence is attached, or limitation remains documented. | L5: PERSISTS
A6: ISSUE-0005 | B6: jeminise.com+norse-mythology-raven-within-celtic-knot-frame-quilt-906ee24d68-906ee24d68 | C6: img_4a32db49ec01b0ad | D6: MINOR | E6: alt text | F6: Blue Norse Raven Celtic Knot Quilt displayed in a main product mockup | G6: Fresh image file: D:\Shopify_Workspace\jeminise_seo\seo_runs\jeminise.com\20260906_234129\qa\20260907_212312\images\161_01.jpg; source URL: https://cdn.shopify.com/s/files/1/0792/5098/1063/files/f5df6ea5afdf042e566b7af241d22bd6929357120dcb00f0bc65a8916d20bdd1.jpg?v=1785104402 | H6: Alt text is too generic or describes placement more than visible content. | I6: Rewrite observation/alt from the directly opened image, naming the visible motif and use context. | J6: Fresh image file: D:\Shopify_Workspace\jeminise_seo\seo_runs\jeminise.com\20260906_234129\qa\20260907_212312\images\161_01.jpg; source URL: https://cdn.shopify.com/s/files/1/0792/5098/1063/files/f5df6ea5afdf042e566b7af241d22bd6929357120dcb00f0bc65a8916d20bdd1.jpg?v=1785104402 | K6: The image row accurately describes the actual media at this gallery position. | L6: RESOLVED
A7: ISSUE-0006 | B7: jeminise.com+norse-mythology-raven-within-celtic-knot-frame-quilt-906ee24d68-906ee24d68 | C7: img_6bf8da2d85e8de01 | D7: MINOR | E7: image observation | F7: Bedding type, feature, lifestyle or material image for blue Norse raven Celtic knot quilt. | G7: Fresh image file: D:\Shopify_Workspace\jeminise_seo\seo_runs\jeminise.com\20260906_234129\qa\20260907_212312\images\161_03.jpg; source URL: https://cdn.shopify.com/s/files/1/0792/5098/1063/files/27dd51b6fe9a32b87ac804b19987fb134fc4570b327d844efdae0740d4303aab.jpg?v=1785104402 | H7: Observation is generic or position-based; rewrite from the actual image content. | I7: Rewrite observation/alt from the directly opened image, naming the visible motif and use context. | J7: Fresh image file: D:\Shopify_Workspace\jeminise_seo\seo_runs\jeminise.com\20260906_234129\qa\20260907_212312\images\161_03.jpg; source URL: https://cdn.shopify.com/s/files/1/0792/5098/1063/files/27dd51b6fe9a32b87ac804b19987fb134fc4570b327d844efdae0740d4303aab.jpg?v=1785104402 | K7: The image row accurately describes the actual media at this gallery position. | L7: RESOLVED
A8: ISSUE-0007 | B8: jeminise.com+norse-mythology-raven-within-celtic-knot-frame-quilt-906ee24d68-906ee24d68 | C8: img_0b8db06ccd8ee1f6 | D8: MINOR | E8: image observation | F8: Detail, feature panel or lifestyle image connected to blue Norse raven Celtic knot quilt. | G8: Fresh image file: D:\Shopify_Workspace\jeminise_seo\seo_runs\jeminise.com\20260906_234129\qa\20260907_212312\images\161_04.jpg; source URL: https://cdn.shopify.com/s/files/1/0792/5098/1063/files/c63b8bede4de84261bd2bc195d98188fb288eba460ea7d07b0ef625dba18ed45.jpg?v=1785104402 | H8: Observation is generic or position-based; rewrite from the actual image content. | I8: Rewrite observation/alt from the directly opened image, naming the visible motif and use context. | J8: Fresh image file: D:\Shopify_Workspace\jeminise_seo\seo_runs\jeminise.com\20260906_234129\qa\20260907_212312\images\161_04.jpg; source URL: https://cdn.shopify.com/s/files/1/0792/5098/1063/files/c63b8bede4de84261bd2bc195d98188fb288eba460ea7d07b0ef625dba18ed45.jpg?v=1785104402 | K8: The image row accurately describes the actual media at this gallery position. | L8: RESOLVED
A9: ISSUE-0008 | B9: jeminise.com+norse-mythology-raven-within-celtic-knot-frame-quilt-906ee24d68-906ee24d68 | C9: img_4a8ac5f2d547d70c | D9: MINOR | E9: image observation | F9: Easy-care, size guide or product feature image for blue Norse raven Celtic knot quilt. | G9: Fresh image file: D:\Shopify_Workspace\jeminise_seo\seo_runs\jeminise.com\20260906_234129\qa\20260907_212312\images\161_06.jpg; source URL: https://cdn.shopify.com/s/files/1/0792/5098/1063/files/5cc9f4f96bdb0280d8a3c4b98775690e61d79ad5625e9f20a101536548fe3b0e.jpg?v=1785104402 | H9: Observation is generic or position-based; rewrite from the actual image content. | I9: Rewrite observation/alt from the directly opened image, naming the visible motif and use context. | J9: Fresh image file: D:\Shopify_Workspace\jeminise_seo\seo_runs\jeminise.com\20260906_234129\qa\20260907_212312\images\161_06.jpg; source URL: https://cdn.shopify.com/s/files/1/0792/5098/1063/files/5cc9f4f96bdb0280d8a3c4b98775690e61d79ad5625e9f20a101536548fe3b0e.jpg?v=1785104402 | K9: The image row accurately describes the actual media at this gallery position. | L9: RESOLVED
A10: ISSUE-0009 | B10: jeminise.com+norse-mythology-raven-within-celtic-knot-frame-quilt-906ee24d68-906ee24d68 | C10: img_4a8ac5f2d547d70c | D10: MINOR | E10: alt text | F10: Set contents and size chart image for Blue Norse Raven Celtic Knot Quilt | G10: Fresh image file: D:\Shopify_Workspace\jeminise_seo\seo_runs\jeminise.com\20260906_234129\qa\20260907_212312\images\161_06.jpg; source URL: https://cdn.shopify.com/s/files/1/0792/5098/1063/files/5cc9f4f96bdb0280d8a3c4b98775690e61d79ad5625e9f20a101536548fe3b0e.jpg?v=1785104402 | H10: Alt text is too generic or describes placement more than visible content. | I10: Rewrite observation/alt from the directly opened image, naming the visible motif and use context. | J10: Fresh image file: D:\Shopify_Workspace\jeminise_seo\seo_runs\jeminise.com\20260906_234129\qa\20260907_212312\images\161_06.jpg; source URL: https://cdn.shopify.com/s/files/1/0792/5098/1063/files/5cc9f4f96bdb0280d8a3c4b98775690e61d79ad5625e9f20a101536548fe3b0e.jpg?v=1785104402 | K10: The image row accurately describes the actual media at this gallery position. | L10: RESOLVED
A11: ISSUE-0010 | B11: jeminise.com+norse-mythology-raven-within-celtic-knot-frame-quilt-906ee24d68-906ee24d68 | C11: img_6ca30d95daecc374 | D11: MINOR | E11: image observation | F11: Additional lifestyle, feature or product detail image showing blue Norse raven Celtic knot quilt. | G11: Fresh image file: D:\Shopify_Workspace\jeminise_seo\seo_runs\jeminise.com\20260906_234129\qa\20260907_212312\images\161_07.jpg; source URL: https://cdn.shopify.com/s/files/1/0792/5098/1063/files/31facc27e0d676d03e5239357f2912111f3e0640688af1ac241589e99b6705fb.jpg?v=1785104402 | H11: Observation is generic or position-based; rewrite from the actual image content. | I11: Rewrite observation/alt from the directly opened image, naming the visible motif and use context. | J11: Fresh image file: D:\Shopify_Workspace\jeminise_seo\seo_runs\jeminise.com\20260906_234129\qa\20260907_212312\images\161_07.jpg; source URL: https://cdn.shopify.com/s/files/1/0792/5098/1063/files/31facc27e0d676d03e5239357f2912111f3e0640688af1ac241589e99b6705fb.jpg?v=1785104402 | K11: The image row accurately describes the actual media at this gallery position. | L11: RESOLVED
