Workbook

Sheet QA_Summary
A1: metric | B1: value | C1: definition
A2: rubric_version | B2: prompt_qa.md@sha256:C2C1DEFDB72362291F7DA656FA7FEA9283A02782FC8CA66D2E4637F2511500DD | C2: Rubric QA áp dụng.
A3: source_workbook | B3: D:\Shopify_Workspace\jeminise_seo\resutls\jeminise.com\20260906_234129\batches\SEO_Product_Optimization_through_batch_034.xlsx | C3: Workbook giai đoạn 1 được đóng băng; không chỉnh sửa.
A4: source_sha256_at_handoff | B4: 609EF38D46896F234EA7AAEEC74F393267003D20D6DE8C5BA9BD21BFB19675EE | C4: Hash tính lại khi hoàn tất báo cáo.
A5: qa_run_id | B5: 20260907_083534 | C5: Run QA độc lập.
A6: batch_id | B6: qa_batch_001 | C6: Inventory positions 1–10.
A7: products_checked | B7: 10 | C7: Đúng 10 product key.
A8: images_checked | B8: 65 | C8: 65/65 ảnh mở trực tiếp ở ảnh gốc.
A9: batch_final_score | B9: =AVERAGE(QA_Products!$K$2:$K$11) -> 74.325 | C9: Trung bình đều 10 final_score; không bù lỗi chặn.
A10: batch_result | B10: =IF(COUNTIF(QA_Products!$L$2:$L$11,"QA_PASS")=ROWS(QA_Products!$L$2:$L$11),"PASSED","NOT_PASSED") -> NOT_PASSED | C10: Lô chỉ đạt khi mọi sản phẩm QA_PASS.
A11: status_counts | B11: ="PASS="&COUNTIF(QA_Products!$L$2:$L$11,"QA_PASS")&"; REVISE="&COUNTIF(QA_Products!$L$2:$L$11,"QA_REVISE")&"; FAIL="&COUNTIF(QA_Products!$L$2:$L$11,"QA_FAIL")&"; INCOMPLETE="&COUNTIF(QA_Products!$L$2:$L$11,"QA_INCOMPLETE") -> PASS=0; REVISE=7; FAIL=3; INCOMPLETE=0 | C11: Số sản phẩm theo kết luận.
A12: issue_counts | B12: {"MINOR": 17, "MAJOR": 29, "LIMITATION": 3, "CRITICAL": 2} | C12: Số phát hiện theo severity.
A13: admin_limitation | B13: No Shopify admin export | C13: Không suy ra admin SEO fields/alt từ storefront.
A14: xlsx_status | B14: COMPLETE | C14: Workbook QA đã được tạo bằng openpyxl theo yêu cầu rõ của người dùng, tính lại và render kiểm tra.

Sheet QA_Products
A1: inventory_position | B1: product_key | C1: url | D1: handle | E1: product_id | F1: revision | G1: verified_points | H1: assessed_weight | I1: score_lower_bound | J1: score_upper_bound | K1: final_score | L1: qa_status | M1: keyword_evidence_level | N1: images_expected | O1: images_checked | P1: image_inventory_complete | Q1: image_coverage | R1: critical_count | S1: major_count | T1: minor_count | U1: limitation_count | V1: issue_refs | W1: evidence_refs
A2: 1 | B2: jeminise.com+autumn-cardinals-perched-above-large-sunflowers-quilt-with-cardinal-birds-9a3b408b20-9a3b408b20 | C2: https://jeminise.com/products/autumn-cardinals-perched-above-large-sunflowers-quilt-with-cardinal-birds-9a3b408b20-9a3b408b20 | D2: autumn-cardinals-perched-above-large-sunflowers-quilt-with-cardinal-birds-9a3b408b20-9a3b408b20 | E2: 8834718105799 | F2: r1 | G2: =SUMIF(QA_Criteria!$A$2:$A$111,B2,QA_Criteria!$F$2:$F$111) -> 76.5 | H2: =SUMIF(QA_Criteria!$A$2:$A$111,B2,QA_Criteria!$G$2:$G$111) -> 100 | I2: =G2 -> 76.5 | J2: =G2+(100-H2) -> 76.5 | K2: =IF(AND(H2=100,Q2=1,P2=TRUE),G2,"") -> 76.5 | L2: =IF(R2>0,"QA_FAIL",IF(K2="","QA_INCOMPLETE",IF(K2<70,"QA_FAIL",IF(OR(K2<85,S2>0),"QA_REVISE","QA_PASS")))) -> QA_REVISE | M2: HYPOTHESIS_ONLY | N2: 5 | O2: 5 | P2: TRUE | Q2: 1 | R2: =COUNTIFS(QA_Issues!$B$2:$B$52,B2,QA_Issues!$D$2:$D$52,"CRITICAL") -> 0 | S2: =COUNTIFS(QA_Issues!$B$2:$B$52,B2,QA_Issues!$D$2:$D$52,"MAJOR") -> 1 | T2: =COUNTIFS(QA_Issues!$B$2:$B$52,B2,QA_Issues!$D$2:$D$52,"MINOR") -> 1 | U2: =COUNTIFS(QA_Issues!$B$2:$B$52,B2,QA_Issues!$D$2:$D$52,"LIMITATION") -> 1 | V2: ["ISS-001-IMG-05", "ISS-001-DESC", "ISS-001-KW"] | W2: ["evidence_batch_001_001", "https://jeminise.com/products/autumn-cardinals-perched-above-large-sunflowers-quilt-with-cardinal-birds-9a3b408b20-9a3b408b20", "serp_qa_001"]
A3: 2 | B3: jeminise.com+bright-teal-yellow-softball-comforter-set-premium-sports-theme | C3: https://jeminise.com/products/bright-teal-yellow-softball-comforter-set-premium-sports-theme | D3: bright-teal-yellow-softball-comforter-set-premium-sports-theme | E3: 8867219865799 | F3: r1 | G3: =SUMIF(QA_Criteria!$A$2:$A$111,B3,QA_Criteria!$F$2:$F$111) -> 77.642857 | H3: =SUMIF(QA_Criteria!$A$2:$A$111,B3,QA_Criteria!$G$2:$G$111) -> 100 | I3: =G3 -> 77.642857 | J3: =G3+(100-H3) -> 77.642857 | K3: =IF(AND(H3=100,Q3=1,P3=TRUE),G3,"") -> 77.642857 | L3: =IF(R3>0,"QA_FAIL",IF(K3="","QA_INCOMPLETE",IF(K3<70,"QA_FAIL",IF(OR(K3<85,S3>0),"QA_REVISE","QA_PASS")))) -> QA_REVISE | M3: SERP_ONLY | N3: 7 | O3: 7 | P3: TRUE | Q3: 1 | R3: =COUNTIFS(QA_Issues!$B$2:$B$52,B3,QA_Issues!$D$2:$D$52,"CRITICAL") -> 0 | S3: =COUNTIFS(QA_Issues!$B$2:$B$52,B3,QA_Issues!$D$2:$D$52,"MAJOR") -> 5 | T3: =COUNTIFS(QA_Issues!$B$2:$B$52,B3,QA_Issues!$D$2:$D$52,"MINOR") -> 1 | U3: =COUNTIFS(QA_Issues!$B$2:$B$52,B3,QA_Issues!$D$2:$D$52,"LIMITATION") -> 0 | V3: ["ISS-002-IMG-02", "ISS-002-IMG-04", "ISS-002-IMG-05", "ISS-002-IMG-07", "ISS-002-DESC", "ISS-002-ENC"] | W3: ["evidence_batch_001_002", "https://jeminise.com/products/bright-teal-yellow-softball-comforter-set-premium-sports-theme", "serp_qa_002"]
A4: 3 | B4: jeminise.com+cardinals-perched-beside-decorated-christmas-tree-patchwork-winter-quilt-7cd7bc46a0-7cd7bc46a0 | C4: https://jeminise.com/products/cardinals-perched-beside-decorated-christmas-tree-patchwork-winter-quilt-7cd7bc46a0-7cd7bc46a0 | D4: cardinals-perched-beside-decorated-christmas-tree-patchwork-winter-quilt-7cd7bc46a0-7cd7bc46a0 | E4: 8834714534087 | F4: r1 | G4: =SUMIF(QA_Criteria!$A$2:$A$111,B4,QA_Criteria!$F$2:$F$111) -> 79 | H4: =SUMIF(QA_Criteria!$A$2:$A$111,B4,QA_Criteria!$G$2:$G$111) -> 100 | I4: =G4 -> 79 | J4: =G4+(100-H4) -> 79 | K4: =IF(AND(H4=100,Q4=1,P4=TRUE),G4,"") -> 79 | L4: =IF(R4>0,"QA_FAIL",IF(K4="","QA_INCOMPLETE",IF(K4<70,"QA_FAIL",IF(OR(K4<85,S4>0),"QA_REVISE","QA_PASS")))) -> QA_REVISE | M4: SERP_ONLY | N4: 5 | O4: 5 | P4: TRUE | Q4: 1 | R4: =COUNTIFS(QA_Issues!$B$2:$B$52,B4,QA_Issues!$D$2:$D$52,"CRITICAL") -> 0 | S4: =COUNTIFS(QA_Issues!$B$2:$B$52,B4,QA_Issues!$D$2:$D$52,"MAJOR") -> 2 | T4: =COUNTIFS(QA_Issues!$B$2:$B$52,B4,QA_Issues!$D$2:$D$52,"MINOR") -> 1 | U4: =COUNTIFS(QA_Issues!$B$2:$B$52,B4,QA_Issues!$D$2:$D$52,"LIMITATION") -> 0 | V4: ["ISS-003-IMG-05", "ISS-003-DESC", "ISS-003-SERP"] | W4: ["evidence_batch_001_003", "https://jeminise.com/products/cardinals-perched-beside-decorated-christmas-tree-patchwork-winter-quilt-7cd7bc46a0-7cd7bc46a0", "serp_qa_003"]
A5: 4 | B5: jeminise.com+cardinals-perched-on-branch-with-roses-patchwork-winter-quilt-21ac904cd7-21ac904cd7 | C5: https://jeminise.com/products/cardinals-perched-on-branch-with-roses-patchwork-winter-quilt-21ac904cd7-21ac904cd7 | D5: cardinals-perched-on-branch-with-roses-patchwork-winter-quilt-21ac904cd7-21ac904cd7 | E5: 8834733015239 | F5: r1 | G5: =SUMIF(QA_Criteria!$A$2:$A$111,B5,QA_Criteria!$F$2:$F$111) -> 76.5 | H5: =SUMIF(QA_Criteria!$A$2:$A$111,B5,QA_Criteria!$G$2:$G$111) -> 100 | I5: =G5 -> 76.5 | J5: =G5+(100-H5) -> 76.5 | K5: =IF(AND(H5=100,Q5=1,P5=TRUE),G5,"") -> 76.5 | L5: =IF(R5>0,"QA_FAIL",IF(K5="","QA_INCOMPLETE",IF(K5<70,"QA_FAIL",IF(OR(K5<85,S5>0),"QA_REVISE","QA_PASS")))) -> QA_REVISE | M5: SERP_ONLY | N5: 5 | O5: 5 | P5: TRUE | Q5: 1 | R5: =COUNTIFS(QA_Issues!$B$2:$B$52,B5,QA_Issues!$D$2:$D$52,"CRITICAL") -> 0 | S5: =COUNTIFS(QA_Issues!$B$2:$B$52,B5,QA_Issues!$D$2:$D$52,"MAJOR") -> 2 | T5: =COUNTIFS(QA_Issues!$B$2:$B$52,B5,QA_Issues!$D$2:$D$52,"MINOR") -> 1 | U5: =COUNTIFS(QA_Issues!$B$2:$B$52,B5,QA_Issues!$D$2:$D$52,"LIMITATION") -> 0 | V5: ["ISS-004-IMG-05", "ISS-004-DESC", "ISS-004-SERP"] | W5: ["evidence_batch_001_004", "https://jeminise.com/products/cardinals-perched-on-branch-with-roses-patchwork-winter-quilt-21ac904cd7-21ac904cd7", "serp_qa_004"]
A6: 5 | B6: jeminise.com+cat-patchwork-quilt-set-animal-pattern-bedding-cat-pattern-quilt-set | C6: https://jeminise.com/products/cat-patchwork-quilt-set-animal-pattern-bedding-cat-pattern-quilt-set | D6: cat-patchwork-quilt-set-animal-pattern-bedding-cat-pattern-quilt-set | E6: 8867094823111 | F6: r1 | G6: =SUMIF(QA_Criteria!$A$2:$A$111,B6,QA_Criteria!$F$2:$F$111) -> 70.071429 | H6: =SUMIF(QA_Criteria!$A$2:$A$111,B6,QA_Criteria!$G$2:$G$111) -> 100 | I6: =G6 -> 70.071429 | J6: =G6+(100-H6) -> 70.071429 | K6: =IF(AND(H6=100,Q6=1,P6=TRUE),G6,"") -> 70.071429 | L6: =IF(R6>0,"QA_FAIL",IF(K6="","QA_INCOMPLETE",IF(K6<70,"QA_FAIL",IF(OR(K6<85,S6>0),"QA_REVISE","QA_PASS")))) -> QA_FAIL | M6: SERP_ONLY | N6: 7 | O6: 7 | P6: TRUE | Q6: 1 | R6: =COUNTIFS(QA_Issues!$B$2:$B$52,B6,QA_Issues!$D$2:$D$52,"CRITICAL") -> 1 | S6: =COUNTIFS(QA_Issues!$B$2:$B$52,B6,QA_Issues!$D$2:$D$52,"MAJOR") -> 3 | T6: =COUNTIFS(QA_Issues!$B$2:$B$52,B6,QA_Issues!$D$2:$D$52,"MINOR") -> 2 | U6: =COUNTIFS(QA_Issues!$B$2:$B$52,B6,QA_Issues!$D$2:$D$52,"LIMITATION") -> 0 | V6: ["ISS-005-IMG-02", "ISS-005-IMG-03", "ISS-005-IMG-04", "ISS-005-DESC", "ISS-005-FACT", "ISS-005-SERP"] | W6: ["evidence_batch_001_005", "https://jeminise.com/products/cat-patchwork-quilt-set-animal-pattern-bedding-cat-pattern-quilt-set", "serp_qa_005"]
A7: 6 | B7: jeminise.com+cat-quilt-set-cat-patchwork-style-printed-bedding-animal-patchwork | C7: https://jeminise.com/products/cat-quilt-set-cat-patchwork-style-printed-bedding-animal-patchwork | D7: cat-quilt-set-cat-patchwork-style-printed-bedding-animal-patchwork | E7: 8867094986951 | F7: r1 | G7: =SUMIF(QA_Criteria!$A$2:$A$111,B7,QA_Criteria!$F$2:$F$111) -> 65.071429 | H7: =SUMIF(QA_Criteria!$A$2:$A$111,B7,QA_Criteria!$G$2:$G$111) -> 100 | I7: =G7 -> 65.071429 | J7: =G7+(100-H7) -> 65.071429 | K7: =IF(AND(H7=100,Q7=1,P7=TRUE),G7,"") -> 65.071429 | L7: =IF(R7>0,"QA_FAIL",IF(K7="","QA_INCOMPLETE",IF(K7<70,"QA_FAIL",IF(OR(K7<85,S7>0),"QA_REVISE","QA_PASS")))) -> QA_FAIL | M7: HYPOTHESIS_ONLY | N7: 7 | O7: 7 | P7: TRUE | Q7: 1 | R7: =COUNTIFS(QA_Issues!$B$2:$B$52,B7,QA_Issues!$D$2:$D$52,"CRITICAL") -> 0 | S7: =COUNTIFS(QA_Issues!$B$2:$B$52,B7,QA_Issues!$D$2:$D$52,"MAJOR") -> 3 | T7: =COUNTIFS(QA_Issues!$B$2:$B$52,B7,QA_Issues!$D$2:$D$52,"MINOR") -> 2 | U7: =COUNTIFS(QA_Issues!$B$2:$B$52,B7,QA_Issues!$D$2:$D$52,"LIMITATION") -> 1 | V7: ["ISS-006-IMG-02", "ISS-006-IMG-03", "ISS-006-IMG-04", "ISS-006-DESC", "ISS-006-KW", "ISS-006-FACT"] | W7: ["evidence_batch_001_006", "https://jeminise.com/products/cat-quilt-set-cat-patchwork-style-printed-bedding-animal-patchwork", "serp_qa_006"]
A8: 7 | B8: jeminise.com+celtic-and-fantasy-quilt-set-with-twisting-tree-trunk-and-exposed-roots-c7b1460bad-c7b1460bad | C8: https://jeminise.com/products/celtic-and-fantasy-quilt-set-with-twisting-tree-trunk-and-exposed-roots-c7b1460bad-c7b1460bad | D8: celtic-and-fantasy-quilt-set-with-twisting-tree-trunk-and-exposed-roots-c7b1460bad-c7b1460bad | E8: 8833350467783 | F8: r1 | G8: =SUMIF(QA_Criteria!$A$2:$A$111,B8,QA_Criteria!$F$2:$F$111) -> 80.071429 | H8: =SUMIF(QA_Criteria!$A$2:$A$111,B8,QA_Criteria!$G$2:$G$111) -> 100 | I8: =G8 -> 80.071429 | J8: =G8+(100-H8) -> 80.071429 | K8: =IF(AND(H8=100,Q8=1,P8=TRUE),G8,"") -> 80.071429 | L8: =IF(R8>0,"QA_FAIL",IF(K8="","QA_INCOMPLETE",IF(K8<70,"QA_FAIL",IF(OR(K8<85,S8>0),"QA_REVISE","QA_PASS")))) -> QA_REVISE | M8: SERP_ONLY | N8: 7 | O8: 7 | P8: TRUE | Q8: 1 | R8: =COUNTIFS(QA_Issues!$B$2:$B$52,B8,QA_Issues!$D$2:$D$52,"CRITICAL") -> 0 | S8: =COUNTIFS(QA_Issues!$B$2:$B$52,B8,QA_Issues!$D$2:$D$52,"MAJOR") -> 2 | T8: =COUNTIFS(QA_Issues!$B$2:$B$52,B8,QA_Issues!$D$2:$D$52,"MINOR") -> 2 | U8: =COUNTIFS(QA_Issues!$B$2:$B$52,B8,QA_Issues!$D$2:$D$52,"LIMITATION") -> 0 | V8: ["ISS-007-IMG-02", "ISS-007-IMG-03", "ISS-007-IMG-04", "ISS-007-DESC"] | W8: ["evidence_batch_001_007", "https://jeminise.com/products/celtic-and-fantasy-quilt-set-with-twisting-tree-trunk-and-exposed-roots-c7b1460bad-c7b1460bad", "serp_qa_007"]
A9: 8 | B9: jeminise.com+celtic-mythology-tree-of-life-quilt-set-with-celtic-knotwork-border-12786aba7e-12786aba7e | C9: https://jeminise.com/products/celtic-mythology-tree-of-life-quilt-set-with-celtic-knotwork-border-12786aba7e-12786aba7e | D9: celtic-mythology-tree-of-life-quilt-set-with-celtic-knotwork-border-12786aba7e-12786aba7e | E9: 8833347518663 | F9: r1 | G9: =SUMIF(QA_Criteria!$A$2:$A$111,B9,QA_Criteria!$F$2:$F$111) -> 85.071429 | H9: =SUMIF(QA_Criteria!$A$2:$A$111,B9,QA_Criteria!$G$2:$G$111) -> 100 | I9: =G9 -> 85.071429 | J9: =G9+(100-H9) -> 85.071429 | K9: =IF(AND(H9=100,Q9=1,P9=TRUE),G9,"") -> 85.071429 | L9: =IF(R9>0,"QA_FAIL",IF(K9="","QA_INCOMPLETE",IF(K9<70,"QA_FAIL",IF(OR(K9<85,S9>0),"QA_REVISE","QA_PASS")))) -> QA_REVISE | M9: SERP_ONLY | N9: 7 | O9: 7 | P9: TRUE | Q9: 1 | R9: =COUNTIFS(QA_Issues!$B$2:$B$52,B9,QA_Issues!$D$2:$D$52,"CRITICAL") -> 0 | S9: =COUNTIFS(QA_Issues!$B$2:$B$52,B9,QA_Issues!$D$2:$D$52,"MAJOR") -> 2 | T9: =COUNTIFS(QA_Issues!$B$2:$B$52,B9,QA_Issues!$D$2:$D$52,"MINOR") -> 2 | U9: =COUNTIFS(QA_Issues!$B$2:$B$52,B9,QA_Issues!$D$2:$D$52,"LIMITATION") -> 0 | V9: ["ISS-008-IMG-02", "ISS-008-IMG-03", "ISS-008-IMG-04", "ISS-008-DESC"] | W9: ["evidence_batch_001_008", "https://jeminise.com/products/celtic-mythology-tree-of-life-quilt-set-with-celtic-knotwork-border-12786aba7e-12786aba7e", "serp_qa_008"]
A10: 9 | B10: jeminise.com+chicken-pattern-quilt-set-animal-patchwork-farmhouse-quilt-set | C10: https://jeminise.com/products/chicken-pattern-quilt-set-animal-patchwork-farmhouse-quilt-set | D10: chicken-pattern-quilt-set-animal-patchwork-farmhouse-quilt-set | E10: 8867095019719 | F10: r1 | G10: =SUMIF(QA_Criteria!$A$2:$A$111,B10,QA_Criteria!$F$2:$F$111) -> 72.571429 | H10: =SUMIF(QA_Criteria!$A$2:$A$111,B10,QA_Criteria!$G$2:$G$111) -> 100 | I10: =G10 -> 72.571429 | J10: =G10+(100-H10) -> 72.571429 | K10: =IF(AND(H10=100,Q10=1,P10=TRUE),G10,"") -> 72.571429 | L10: =IF(R10>0,"QA_FAIL",IF(K10="","QA_INCOMPLETE",IF(K10<70,"QA_FAIL",IF(OR(K10<85,S10>0),"QA_REVISE","QA_PASS")))) -> QA_REVISE | M10: SERP_ONLY | N10: 7 | O10: 7 | P10: TRUE | Q10: 1 | R10: =COUNTIFS(QA_Issues!$B$2:$B$52,B10,QA_Issues!$D$2:$D$52,"CRITICAL") -> 0 | S10: =COUNTIFS(QA_Issues!$B$2:$B$52,B10,QA_Issues!$D$2:$D$52,"MAJOR") -> 3 | T10: =COUNTIFS(QA_Issues!$B$2:$B$52,B10,QA_Issues!$D$2:$D$52,"MINOR") -> 2 | U10: =COUNTIFS(QA_Issues!$B$2:$B$52,B10,QA_Issues!$D$2:$D$52,"LIMITATION") -> 0 | V10: ["ISS-009-IMG-02", "ISS-009-IMG-03", "ISS-009-IMG-04", "ISS-009-DESC", "ISS-009-FACT"] | W10: ["evidence_batch_001_009", "https://jeminise.com/products/chicken-pattern-quilt-set-animal-patchwork-farmhouse-quilt-set", "serp_qa_009"]
A11: 10 | B11: jeminise.com+christian-bedding-set-inspirational-bible-verse-comforte-design-01 | C11: https://jeminise.com/products/christian-bedding-set-inspirational-bible-verse-comforte-design-01 | D11: christian-bedding-set-inspirational-bible-verse-comforte-design-01 | E11: 8867138240711 | F11: r1 | G11: =SUMIF(QA_Criteria!$A$2:$A$111,B11,QA_Criteria!$F$2:$F$111) -> 60.75 | H11: =SUMIF(QA_Criteria!$A$2:$A$111,B11,QA_Criteria!$G$2:$G$111) -> 100 | I11: =G11 -> 60.75 | J11: =G11+(100-H11) -> 60.75 | K11: =IF(AND(H11=100,Q11=1,P11=TRUE),G11,"") -> 60.75 | L11: =IF(R11>0,"QA_FAIL",IF(K11="","QA_INCOMPLETE",IF(K11<70,"QA_FAIL",IF(OR(K11<85,S11>0),"QA_REVISE","QA_PASS")))) -> QA_FAIL | M11: SERP_ONLY | N11: 8 | O11: 8 | P11: TRUE | Q11: 1 | R11: =COUNTIFS(QA_Issues!$B$2:$B$52,B11,QA_Issues!$D$2:$D$52,"CRITICAL") -> 1 | S11: =COUNTIFS(QA_Issues!$B$2:$B$52,B11,QA_Issues!$D$2:$D$52,"MAJOR") -> 6 | T11: =COUNTIFS(QA_Issues!$B$2:$B$52,B11,QA_Issues!$D$2:$D$52,"MINOR") -> 3 | U11: =COUNTIFS(QA_Issues!$B$2:$B$52,B11,QA_Issues!$D$2:$D$52,"LIMITATION") -> 0 | V11: ["ISS-010-IMG-02", "ISS-010-IMG-03", "ISS-010-IMG-04", "ISS-010-IMG-05", "ISS-010-IMG-06", "ISS-010-IMG-07", "ISS-010-IMG-08", "ISS-010-DESC", "ISS-010-ENC", "ISS-010-PERS"] | W11: ["evidence_batch_001_010", "https://jeminise.com/products/christian-bedding-set-inspirational-bible-verse-comforte-design-01", "serp_qa_010"]

Sheet QA_Criteria
A1: product_key | B1: criterion_id | C1: weight | D1: assessment | E1: rating | F1: earned_points | G1: assessed_weight | H1: reason | I1: evidence_refs | J1: issue_refs
A2: jeminise.com+autumn-cardinals-perched-above-large-sunflowers-quilt-with-cardinal-birds-9a3b408b20-9a3b408b20 | B2: P1 | C2: 15 | D2: FULL | E2: =IF(B2="I1",AVERAGEIF(QA_Images!$A$2:$A$66,A2,QA_Images!$T$2:$T$66)/100,IF(D2="FULL",1,IF(D2="PARTIAL",0.5,IF(D2="FAIL",0,"")))) -> 1 | F2: =IF(E2="",0,C2*E2) -> 15 | G2: =IF(B2="I1",20*AVERAGEIF(QA_Images!$A$2:$A$66,A2,QA_Images!$U$2:$U$66)/100,IF(D2="NOT_CHECKED",0,C2)) -> 15 | H2: Đối chiếu loại sản phẩm, thiết kế và màu với product JSON, H1 live và toàn bộ gallery. | I2: ["evidence_batch_001_001", "https://jeminise.com/products/autumn-cardinals-perched-above-large-sunflowers-quilt-with-cardinal-birds-9a3b408b20-9a3b408b20", "serp_qa_001"] | J2: ["ISS-001-IMG-05", "ISS-001-DESC", "ISS-001-KW"]
A3: jeminise.com+autumn-cardinals-perched-above-large-sunflowers-quilt-with-cardinal-birds-9a3b408b20-9a3b408b20 | B3: P2 | C3: 10 | D3: PARTIAL | E3: =IF(B3="I1",AVERAGEIF(QA_Images!$A$2:$A$66,A3,QA_Images!$T$2:$T$66)/100,IF(D3="FULL",1,IF(D3="PARTIAL",0.5,IF(D3="FAIL",0,"")))) -> 0.5 | F3: =IF(E3="",0,C3*E3) -> 5 | G3: =IF(B3="I1",20*AVERAGEIF(QA_Images!$A$2:$A$66,A3,QA_Images!$U$2:$U$66)/100,IF(D3="NOT_CHECKED",0,C3)) -> 10 | H3: Đối chiếu chất liệu, kích thước, thành phần đi kèm, biến thể và personalization với nguồn live/snapshot. | I3: ["evidence_batch_001_001", "https://jeminise.com/products/autumn-cardinals-perched-above-large-sunflowers-quilt-with-cardinal-birds-9a3b408b20-9a3b408b20", "serp_qa_001"] | J3: ["ISS-001-IMG-05", "ISS-001-DESC", "ISS-001-KW"]
A4: jeminise.com+autumn-cardinals-perched-above-large-sunflowers-quilt-with-cardinal-birds-9a3b408b20-9a3b408b20 | B4: K1 | C4: 10 | D4: FULL | E4: =IF(B4="I1",AVERAGEIF(QA_Images!$A$2:$A$66,A4,QA_Images!$T$2:$T$66)/100,IF(D4="FULL",1,IF(D4="PARTIAL",0.5,IF(D4="FAIL",0,"")))) -> 1 | F4: =IF(E4="",0,C4*E4) -> 10 | G4: =IF(B4="I1",20*AVERAGEIF(QA_Images!$A$2:$A$66,A4,QA_Images!$U$2:$U$66)/100,IF(D4="NOT_CHECKED",0,C4)) -> 10 | H4: Đối chiếu long-tail với thiết kế riêng và nguy cơ trùng intent trong cụm sản phẩm. | I4: ["evidence_batch_001_001", "https://jeminise.com/products/autumn-cardinals-perched-above-large-sunflowers-quilt-with-cardinal-birds-9a3b408b20-9a3b408b20", "serp_qa_001"] | J4: ["ISS-001-IMG-05", "ISS-001-DESC", "ISS-001-KW"]
A5: jeminise.com+autumn-cardinals-perched-above-large-sunflowers-quilt-with-cardinal-birds-9a3b408b20-9a3b408b20 | B5: K2 | C5: 5 | D5: PARTIAL | E5: =IF(B5="I1",AVERAGEIF(QA_Images!$A$2:$A$66,A5,QA_Images!$T$2:$T$66)/100,IF(D5="FULL",1,IF(D5="PARTIAL",0.5,IF(D5="FAIL",0,"")))) -> 0.5 | F5: =IF(E5="",0,C5*E5) -> 2.5 | G5: =IF(B5="I1",20*AVERAGEIF(QA_Images!$A$2:$A$66,A5,QA_Images!$U$2:$U$66)/100,IF(D5="NOT_CHECKED",0,C5)) -> 5 | H5: Đã đọc SERP cho primary keyword và phương án gần nhất; đánh giá loại trang/intent. | I5: ["evidence_batch_001_001", "https://jeminise.com/products/autumn-cardinals-perched-above-large-sunflowers-quilt-with-cardinal-birds-9a3b408b20-9a3b408b20", "serp_qa_001"] | J5: ["ISS-001-IMG-05", "ISS-001-DESC", "ISS-001-KW"]
A6: jeminise.com+autumn-cardinals-perched-above-large-sunflowers-quilt-with-cardinal-birds-9a3b408b20-9a3b408b20 | B6: K3 | C6: 5 | D6: PARTIAL | E6: =IF(B6="I1",AVERAGEIF(QA_Images!$A$2:$A$66,A6,QA_Images!$T$2:$T$66)/100,IF(D6="FULL",1,IF(D6="PARTIAL",0.5,IF(D6="FAIL",0,"")))) -> 0.5 | F6: =IF(E6="",0,C6*E6) -> 2.5 | G6: =IF(B6="I1",20*AVERAGEIF(QA_Images!$A$2:$A$66,A6,QA_Images!$U$2:$U$66)/100,IF(D6="NOT_CHECKED",0,C6)) -> 5 | H6: Không suy diễn volume; phân biệt SERP_ONLY và HYPOTHESIS_ONLY. | I6: ["evidence_batch_001_001", "https://jeminise.com/products/autumn-cardinals-perched-above-large-sunflowers-quilt-with-cardinal-birds-9a3b408b20-9a3b408b20", "serp_qa_001"] | J6: ["ISS-001-IMG-05", "ISS-001-DESC", "ISS-001-KW"]
A7: jeminise.com+autumn-cardinals-perched-above-large-sunflowers-quilt-with-cardinal-birds-9a3b408b20-9a3b408b20 | B7: T1 | C7: 10 | D7: FULL | E7: =IF(B7="I1",AVERAGEIF(QA_Images!$A$2:$A$66,A7,QA_Images!$T$2:$T$66)/100,IF(D7="FULL",1,IF(D7="PARTIAL",0.5,IF(D7="FAIL",0,"")))) -> 1 | F7: =IF(E7="",0,C7*E7) -> 10 | G7: =IF(B7="I1",20*AVERAGEIF(QA_Images!$A$2:$A$66,A7,QA_Images!$U$2:$U$66)/100,IF(D7="NOT_CHECKED",0,C7)) -> 10 | H7: Đánh giá SEO title English về độ đúng, tự nhiên, keyword và điểm phân biệt. | I7: ["evidence_batch_001_001", "https://jeminise.com/products/autumn-cardinals-perched-above-large-sunflowers-quilt-with-cardinal-birds-9a3b408b20-9a3b408b20", "serp_qa_001"] | J7: ["ISS-001-IMG-05", "ISS-001-DESC", "ISS-001-KW"]
A8: jeminise.com+autumn-cardinals-perched-above-large-sunflowers-quilt-with-cardinal-birds-9a3b408b20-9a3b408b20 | B8: T2 | C8: 5 | D8: FULL | E8: =IF(B8="I1",AVERAGEIF(QA_Images!$A$2:$A$66,A8,QA_Images!$T$2:$T$66)/100,IF(D8="FULL",1,IF(D8="PARTIAL",0.5,IF(D8="FAIL",0,"")))) -> 1 | F8: =IF(E8="",0,C8*E8) -> 5 | G8: =IF(B8="I1",20*AVERAGEIF(QA_Images!$A$2:$A$66,A8,QA_Images!$U$2:$U$66)/100,IF(D8="NOT_CHECKED",0,C8)) -> 5 | H8: Đánh giá H1 đề xuất độc lập với SEO title và đối chiếu lỗi ký tự nguồn. | I8: ["evidence_batch_001_001", "https://jeminise.com/products/autumn-cardinals-perched-above-large-sunflowers-quilt-with-cardinal-birds-9a3b408b20-9a3b408b20", "serp_qa_001"] | J8: ["ISS-001-IMG-05", "ISS-001-DESC", "ISS-001-KW"]
A9: jeminise.com+autumn-cardinals-perched-above-large-sunflowers-quilt-with-cardinal-birds-9a3b408b20-9a3b408b20 | B9: D1 | C9: 5 | D9: FULL | E9: =IF(B9="I1",AVERAGEIF(QA_Images!$A$2:$A$66,A9,QA_Images!$T$2:$T$66)/100,IF(D9="FULL",1,IF(D9="PARTIAL",0.5,IF(D9="FAIL",0,"")))) -> 1 | F9: =IF(E9="",0,C9*E9) -> 5 | G9: =IF(B9="I1",20*AVERAGEIF(QA_Images!$A$2:$A$66,A9,QA_Images!$U$2:$U$66)/100,IF(D9="NOT_CHECKED",0,C9)) -> 5 | H9: Đánh giá meta description về tính cụ thể và căn cứ claim. | I9: ["evidence_batch_001_001", "https://jeminise.com/products/autumn-cardinals-perched-above-large-sunflowers-quilt-with-cardinal-birds-9a3b408b20-9a3b408b20", "serp_qa_001"] | J9: ["ISS-001-IMG-05", "ISS-001-DESC", "ISS-001-KW"]
A10: jeminise.com+autumn-cardinals-perched-above-large-sunflowers-quilt-with-cardinal-birds-9a3b408b20-9a3b408b20 | B10: D2 | C10: 10 | D10: FAIL | E10: =IF(B10="I1",AVERAGEIF(QA_Images!$A$2:$A$66,A10,QA_Images!$T$2:$T$66)/100,IF(D10="FULL",1,IF(D10="PARTIAL",0.5,IF(D10="FAIL",0,"")))) -> 0 | F10: =IF(E10="",0,C10*E10) -> 0 | G10: =IF(B10="I1",20*AVERAGEIF(QA_Images!$A$2:$A$66,A10,QA_Images!$U$2:$U$66)/100,IF(D10="NOT_CHECKED",0,C10)) -> 10 | H10: Description SET có HTML đầy đủ nhưng chứa câu nội bộ 'This draft should be reviewed...' và dữ liệu nguồn thô/mâu thuẫn; chưa phải nội dung publish-ready. | I10: ["evidence_batch_001_001", "https://jeminise.com/products/autumn-cardinals-perched-above-large-sunflowers-quilt-with-cardinal-birds-9a3b408b20-9a3b408b20", "serp_qa_001"] | J10: ["ISS-001-IMG-05", "ISS-001-DESC", "ISS-001-KW"]
A11: jeminise.com+autumn-cardinals-perched-above-large-sunflowers-quilt-with-cardinal-birds-9a3b408b20-9a3b408b20 | B11: I1 | C11: 20 | D11: DERIVED | E11: =IF(B11="I1",AVERAGEIF(QA_Images!$A$2:$A$66,A11,QA_Images!$T$2:$T$66)/100,IF(D11="FULL",1,IF(D11="PARTIAL",0.5,IF(D11="FAIL",0,"")))) -> 0.95 | F11: =IF(E11="",0,C11*E11) -> 19 | G11: =IF(B11="I1",20*AVERAGEIF(QA_Images!$A$2:$A$66,A11,QA_Images!$U$2:$U$66)/100,IF(D11="NOT_CHECKED",0,C11)) -> 20 | H11: Tính từ trung bình 5 ảnh: 95.0000/100. | I11: ["evidence_batch_001_001", "https://jeminise.com/products/autumn-cardinals-perched-above-large-sunflowers-quilt-with-cardinal-birds-9a3b408b20-9a3b408b20", "serp_qa_001"] | J11: ["ISS-001-IMG-05", "ISS-001-DESC", "ISS-001-KW"]
A12: jeminise.com+autumn-cardinals-perched-above-large-sunflowers-quilt-with-cardinal-birds-9a3b408b20-9a3b408b20 | B12: E1 | C12: 5 | D12: PARTIAL | E12: =IF(B12="I1",AVERAGEIF(QA_Images!$A$2:$A$66,A12,QA_Images!$T$2:$T$66)/100,IF(D12="FULL",1,IF(D12="PARTIAL",0.5,IF(D12="FAIL",0,"")))) -> 0.5 | F12: =IF(E12="",0,C12*E12) -> 2.5 | G12: =IF(B12="I1",20*AVERAGEIF(QA_Images!$A$2:$A$66,A12,QA_Images!$U$2:$U$66)/100,IF(D12="NOT_CHECKED",0,C12)) -> 5 | H12: Kiểm tra liên kết product key/handle/evidence/revision giữa workbook, snapshot và nguồn live. | I12: ["evidence_batch_001_001", "https://jeminise.com/products/autumn-cardinals-perched-above-large-sunflowers-quilt-with-cardinal-birds-9a3b408b20-9a3b408b20", "serp_qa_001"] | J12: ["ISS-001-IMG-05", "ISS-001-DESC", "ISS-001-KW"]
A13: jeminise.com+bright-teal-yellow-softball-comforter-set-premium-sports-theme | B13: P1 | C13: 15 | D13: FULL | E13: =IF(B13="I1",AVERAGEIF(QA_Images!$A$2:$A$66,A13,QA_Images!$T$2:$T$66)/100,IF(D13="FULL",1,IF(D13="PARTIAL",0.5,IF(D13="FAIL",0,"")))) -> 1 | F13: =IF(E13="",0,C13*E13) -> 15 | G13: =IF(B13="I1",20*AVERAGEIF(QA_Images!$A$2:$A$66,A13,QA_Images!$U$2:$U$66)/100,IF(D13="NOT_CHECKED",0,C13)) -> 15 | H13: Đối chiếu loại sản phẩm, thiết kế và màu với product JSON, H1 live và toàn bộ gallery. | I13: ["evidence_batch_001_002", "https://jeminise.com/products/bright-teal-yellow-softball-comforter-set-premium-sports-theme", "serp_qa_002"] | J13: ["ISS-002-IMG-02", "ISS-002-IMG-04", "ISS-002-IMG-05", "ISS-002-IMG-07", "ISS-002-DESC", "ISS-002-ENC"]
... A111: jeminise.com+christian-bedding-set-inspirational-bible-verse-comforte-design-01 | B111: E1 | C111: 5 | D111: PARTIAL | E111: =IF(B111="I1",AVERAGEIF(QA_Images!$A$2:$A$66,A111,QA_Images!$T$2:$T$66)/100,IF(D111="FULL",1,IF(D111="PARTIAL",0.5,IF(D111="FAIL",0,"")))) -> 0.5 | F111: =IF(E111="",0,C111*E111) -> 2.5 | G111: =IF(B111="I1",20*AVERAGEIF(QA_Images!$A$2:$A$66,A111,QA_Images!$U$2:$U$66)/100,IF(D111="NOT_CHECKED",0,C111)) -> 5 | H111: Kiểm tra liên kết product key/handle/evidence/revision giữa workbook, snapshot và nguồn live. | I111: ["evidence_batch_001_010", "https://jeminise.com/products/christian-bedding-set-inspirational-bible-verse-comforte-design-01", "serp_qa_010"] | J111: ["ISS-010-IMG-02", "ISS-010-IMG-03", "ISS-010-IMG-04", "ISS-010-IMG-05", "ISS-010-IMG-06", "ISS-010-IMG-07", "ISS-010-IMG-08", "ISS-010-DESC", "ISS-010-ENC", "ISS-010-PERS"]

Sheet QA_Images
A1: product_key | B1: qa_image_key | C1: image_url_source | D1: image_url_workbook | E1: media_id | F1: workbook_image_id | G1: variant | H1: image_location | I1: check_method | J1: checked_at | K1: qa_observation | L1: submitted_observation | M1: storefront_alt_observed | N1: alt_action | O1: alt_effective | P1: IM1 | Q1: IM2 | R1: IM3 | S1: IM4 | T1: image_verified_points | U1: image_assessed_weight | V1: image_final_score | W1: image_score_lower_bound | X1: image_score_upper_bound | Y1: issue_refs | Z1: evidence_refs
A2: jeminise.com+autumn-cardinals-perched-above-large-sunflowers-quilt-with-cardinal-birds-9a3b408b20-9a3b408b20 | B2: qaimg_9808a3488a22128b | C2: https://cdn.shopify.com/s/files/1/0792/5098/1063/files/0754b2731a7ffd916d0ef8b214706e796d780fbd4ba38c8f47f27b6dcfbf352e.jpg?v=1785099190 | D2: https://cdn.shopify.com/s/files/1/0792/5098/1063/files/0754b2731a7ffd916d0ef8b214706e796d780fbd4ba38c8f47f27b6dcfbf352e.jpg?v=1785099190 | E2: 38506577854663 | F2: 47540016382151 | H2: GALLERY | I2: DIRECT_ORIGINAL_IMAGE | J2: 2026-09-07T09:05:41.201318+07:00 | K2: Bed mockup with two red cardinals, large yellow sunflowers and autumn leaves. | L2: Main bed mockup showing red cardinals, large yellow sunflowers, autumn leaves. | M2: Autumn Cardinals Perched Above Large Sunflowers Quilt with Cardinal Birds | N2: SET | O2: Cardinal Sunflower Patchwork Quilt Set displayed on a bed | P2: FULL | Q2: FULL | R2: FULL | S2: FULL | T2: =IF(P2="FULL",40,IF(P2="PARTIAL",40/2,0))+IF(Q2="FULL",30,IF(Q2="PARTIAL",30/2,0))+IF(R2="FULL",20,IF(R2="PARTIAL",20/2,0))+IF(S2="FULL",10,IF(S2="PARTIAL",10/2,0)) -> 100 | U2: =IF(P2="NOT_CHECKED",0,40)+IF(Q2="NOT_CHECKED",0,30)+IF(R2="NOT_CHECKED",0,20)+IF(S2="NOT_CHECKED",0,10) -> 100 | V2: =IF(U2=100,T2,"") -> 100 | W2: =T2 -> 100 | X2: =T2+(100-U2) -> 100 | Y2: [] | Z2: ["seo_runs\\jeminise.com\\20260906_234129\\evidence\\images\\1_autumn-cardinals-perched-above-large-sunflowers-quilt-with-cardinal-birds-9a3b408b20-9a3b408b20\\image_01_47540016382151.jpg; seo_runs\\jeminise.com\\20260906_234129\\evidence\\contact_sheets\\1_autumn-cardinals-perched-above-large-sunflowers-quilt-with-cardinal-birds-9a3b408b20-9a3b408b20.jpg", "https://jeminise.com/products/autumn-cardinals-perched-above-large-sunflowers-quilt-with-cardinal-birds-9a3b408b20-9a3b408b20", "https://cdn.shopify.com/s/files/1/0792/5098/1063/files/0754b2731a7ffd916d0ef8b214706e796d780fbd4ba38c8f47f27b6dcfbf352e.jpg?v=1785099190"]
A3: jeminise.com+autumn-cardinals-perched-above-large-sunflowers-quilt-with-cardinal-birds-9a3b408b20-9a3b408b20 | B3: qaimg_c8e0c4111df9742a | C3: https://cdn.shopify.com/s/files/1/0792/5098/1063/files/a10aa0018e665e644a60b7c4aea8b5e152ec768ebb35af1090452cddbc9e9828.jpg?v=1785099190 | D3: https://cdn.shopify.com/s/files/1/0792/5098/1063/files/a10aa0018e665e644a60b7c4aea8b5e152ec768ebb35af1090452cddbc9e9828.jpg?v=1785099190 | E3: 38506577887431 | F3: 47540016414919 | H3: GALLERY | I3: DIRECT_ORIGINAL_IMAGE | J3: 2026-09-07T09:05:41.201318+07:00 | K3: Close-up of the cardinal-and-sunflower print and quilted stitching. | L3: Secondary detail or room mockup showing red cardinals, large yellow sunflowers, autumn leaves and visible quilted/printed texture. | M3: Autumn Cardinals Perched Above Large Sunflowers Quilt with Cardinal Birds | N3: SET | O3: Close view of red cardinals, large yellow sunflowers, autumn leaves on the quilt set | P3: FULL | Q3: FULL | R3: FULL | S3: FULL | T3: =IF(P3="FULL",40,IF(P3="PARTIAL",40/2,0))+IF(Q3="FULL",30,IF(Q3="PARTIAL",30/2,0))+IF(R3="FULL",20,IF(R3="PARTIAL",20/2,0))+IF(S3="FULL",10,IF(S3="PARTIAL",10/2,0)) -> 100 | U3: =IF(P3="NOT_CHECKED",0,40)+IF(Q3="NOT_CHECKED",0,30)+IF(R3="NOT_CHECKED",0,20)+IF(S3="NOT_CHECKED",0,10) -> 100 | V3: =IF(U3=100,T3,"") -> 100 | W3: =T3 -> 100 | X3: =T3+(100-U3) -> 100 | Y3: [] | Z3: ["seo_runs\\jeminise.com\\20260906_234129\\evidence\\images\\1_autumn-cardinals-perched-above-large-sunflowers-quilt-with-cardinal-birds-9a3b408b20-9a3b408b20\\image_02_47540016414919.jpg; seo_runs\\jeminise.com\\20260906_234129\\evidence\\contact_sheets\\1_autumn-cardinals-perched-above-large-sunflowers-quilt-with-cardinal-birds-9a3b408b20-9a3b408b20.jpg", "https://jeminise.com/products/autumn-cardinals-perched-above-large-sunflowers-quilt-with-cardinal-birds-9a3b408b20-9a3b408b20", "https://cdn.shopify.com/s/files/1/0792/5098/1063/files/a10aa0018e665e644a60b7c4aea8b5e152ec768ebb35af1090452cddbc9e9828.jpg?v=1785099190"]
A4: jeminise.com+autumn-cardinals-perched-above-large-sunflowers-quilt-with-cardinal-birds-9a3b408b20-9a3b408b20 | B4: qaimg_151738926e676561 | C4: https://cdn.shopify.com/s/files/1/0792/5098/1063/files/c50488380d22611c83d218b77be9cfcf5799df4d9903913c09a1798712931b22.jpg?v=1785099190 | D4: https://cdn.shopify.com/s/files/1/0792/5098/1063/files/c50488380d22611c83d218b77be9cfcf5799df4d9903913c09a1798712931b22.jpg?v=1785099190 | E4: 38506577920199 | F4: 47540016447687 | H4: GALLERY | I4: DIRECT_ORIGINAL_IMAGE | J4: 2026-09-07T09:05:41.201318+07:00 | K4: Pillow sham using the cardinal-and-sunflower artwork. | L4: Matching pillow sham or bedding detail using the same red cardinals, large yellow sunflowers, autumn leaves artwork. | M4: Autumn Cardinals Perched Above Large Sunflowers Quilt with Cardinal Birds | N4: SET | O4: Matching pillow sham for Cardinal Sunflower Patchwork Quilt Set | P4: FULL | Q4: FULL | R4: FULL | S4: FULL | T4: =IF(P4="FULL",40,IF(P4="PARTIAL",40/2,0))+IF(Q4="FULL",30,IF(Q4="PARTIAL",30/2,0))+IF(R4="FULL",20,IF(R4="PARTIAL",20/2,0))+IF(S4="FULL",10,IF(S4="PARTIAL",10/2,0)) -> 100 | U4: =IF(P4="NOT_CHECKED",0,40)+IF(Q4="NOT_CHECKED",0,30)+IF(R4="NOT_CHECKED",0,20)+IF(S4="NOT_CHECKED",0,10) -> 100 | V4: =IF(U4=100,T4,"") -> 100 | W4: =T4 -> 100 | X4: =T4+(100-U4) -> 100 | Y4: [] | Z4: ["seo_runs\\jeminise.com\\20260906_234129\\evidence\\images\\1_autumn-cardinals-perched-above-large-sunflowers-quilt-with-cardinal-birds-9a3b408b20-9a3b408b20\\image_03_47540016447687.jpg; seo_runs\\jeminise.com\\20260906_234129\\evidence\\contact_sheets\\1_autumn-cardinals-perched-above-large-sunflowers-quilt-with-cardinal-birds-9a3b408b20-9a3b408b20.jpg", "https://jeminise.com/products/autumn-cardinals-perched-above-large-sunflowers-quilt-with-cardinal-birds-9a3b408b20-9a3b408b20", "https://cdn.shopify.com/s/files/1/0792/5098/1063/files/c50488380d22611c83d218b77be9cfcf5799df4d9903913c09a1798712931b22.jpg?v=1785099190"]
A5: jeminise.com+autumn-cardinals-perched-above-large-sunflowers-quilt-with-cardinal-birds-9a3b408b20-9a3b408b20 | B5: qaimg_e40aceb16ae7429c | C5: https://cdn.shopify.com/s/files/1/0792/5098/1063/files/455c5869333cc7654f6c30f3d09716ec1513311734a21a6aa82bf5fe0767ac69.jpg?v=1785099191 | D5: https://cdn.shopify.com/s/files/1/0792/5098/1063/files/455c5869333cc7654f6c30f3d09716ec1513311734a21a6aa82bf5fe0767ac69.jpg?v=1785099191 | E5: 38506577952967 | F5: 47540016480455 | H5: GALLERY | I5: DIRECT_ORIGINAL_IMAGE | J5: 2026-09-07T09:05:41.201318+07:00 | K5: Alternate bedroom angle showing the cardinal-and-sunflower quilt. | L5: Room/folded product or fabric information image tied to the red cardinals, large yellow sunflowers, autumn leaves design. | M5: Autumn Cardinals Perched Above Large Sunflowers Quilt with Cardinal Birds | N5: SET | O5: Cardinal Sunflower Patchwork Quilt Set shown in a bedroom setting | P5: FULL | Q5: FULL | R5: FULL | S5: FULL | T5: =IF(P5="FULL",40,IF(P5="PARTIAL",40/2,0))+IF(Q5="FULL",30,IF(Q5="PARTIAL",30/2,0))+IF(R5="FULL",20,IF(R5="PARTIAL",20/2,0))+IF(S5="FULL",10,IF(S5="PARTIAL",10/2,0)) -> 100 | U5: =IF(P5="NOT_CHECKED",0,40)+IF(Q5="NOT_CHECKED",0,30)+IF(R5="NOT_CHECKED",0,20)+IF(S5="NOT_CHECKED",0,10) -> 100 | V5: =IF(U5=100,T5,"") -> 100 | W5: =T5 -> 100 | X5: =T5+(100-U5) -> 100 | Y5: [] | Z5: ["seo_runs\\jeminise.com\\20260906_234129\\evidence\\images\\1_autumn-cardinals-perched-above-large-sunflowers-quilt-with-cardinal-birds-9a3b408b20-9a3b408b20\\image_04_47540016480455.jpg; seo_runs\\jeminise.com\\20260906_234129\\evidence\\contact_sheets\\1_autumn-cardinals-perched-above-large-sunflowers-quilt-with-cardinal-birds-9a3b408b20-9a3b408b20.jpg", "https://jeminise.com/products/autumn-cardinals-perched-above-large-sunflowers-quilt-with-cardinal-birds-9a3b408b20-9a3b408b20", "https://cdn.shopify.com/s/files/1/0792/5098/1063/files/455c5869333cc7654f6c30f3d09716ec1513311734a21a6aa82bf5fe0767ac69.jpg?v=1785099191"]
A6: jeminise.com+autumn-cardinals-perched-above-large-sunflowers-quilt-with-cardinal-birds-9a3b408b20-9a3b408b20 | B6: qaimg_8a56044406ccfa03 | C6: https://cdn.shopify.com/s/files/1/0792/5098/1063/files/f17ccb354040b3320b99a1960533bd6ef949db1145d3897d55a33673489caad9.jpg?v=1785099190 | D6: https://cdn.shopify.com/s/files/1/0792/5098/1063/files/f17ccb354040b3320b99a1960533bd6ef949db1145d3897d55a33673489caad9.jpg?v=1785099190 | E6: 38506577985735 | F6: 47540016513223 | H6: GALLERY | I6: DIRECT_ORIGINAL_IMAGE | J6: 2026-09-07T09:05:41.201318+07:00 | K6: Included-components and dimensions graphic: one quilt; two standard shams are optional; Throw/Twin/Queen/King sizes shown. | L6: Sizing or included-components information image for the bedding set. | M6: Autumn Cardinals Perched Above Large Sunflowers Quilt with Cardinal Birds | N6: SET | O6: Size guide for Cardinal Sunflower Patchwork Quilt Set | P6: FULL | Q6: PARTIAL | R6: PARTIAL | S6: FULL | T6: =IF(P6="FULL",40,IF(P6="PARTIAL",40/2,0))+IF(Q6="FULL",30,IF(Q6="PARTIAL",30/2,0))+IF(R6="FULL",20,IF(R6="PARTIAL",20/2,0))+IF(S6="FULL",10,IF(S6="PARTIAL",10/2,0)) -> 75 | U6: =IF(P6="NOT_CHECKED",0,40)+IF(Q6="NOT_CHECKED",0,30)+IF(R6="NOT_CHECKED",0,20)+IF(S6="NOT_CHECKED",0,10) -> 100 | V6: =IF(U6=100,T6,"") -> 75 | W6: =T6 -> 75 | X6: =T6+(100-U6) -> 75 | Y6: ["ISS-001-IMG-05"] | Z6: ["seo_runs\\jeminise.com\\20260906_234129\\evidence\\images\\1_autumn-cardinals-perched-above-large-sunflowers-quilt-with-cardinal-birds-9a3b408b20-9a3b408b20\\image_05_47540016513223.jpg; seo_runs\\jeminise.com\\20260906_234129\\evidence\\contact_sheets\\1_autumn-cardinals-perched-above-large-sunflowers-quilt-with-cardinal-birds-9a3b408b20-9a3b408b20.jpg", "https://jeminise.com/products/autumn-cardinals-perched-above-large-sunflowers-quilt-with-cardinal-birds-9a3b408b20-9a3b408b20", "https://cdn.shopify.com/s/files/1/0792/5098/1063/files/f17ccb354040b3320b99a1960533bd6ef949db1145d3897d55a33673489caad9.jpg?v=1785099190"]
A7: jeminise.com+bright-teal-yellow-softball-comforter-set-premium-sports-theme | B7: qaimg_1fd378044829575a | C7: https://cdn.shopify.com/s/files/1/0792/5098/1063/files/aaac3be2edd458da15620b4b48ea0557ee8e33aa5a6ff9ed0d0db11848fd4cbe.jpg?v=1787245111 | D7: https://cdn.shopify.com/s/files/1/0792/5098/1063/files/aaac3be2edd458da15620b4b48ea0557ee8e33aa5a6ff9ed0d0db11848fd4cbe.jpg?v=1787245111 | E7: 38895967404231 | F7: 47934735909063 | H7: GALLERY | I7: DIRECT_ORIGINAL_IMAGE | J7: 2026-09-07T09:05:41.201318+07:00 | K7: Front bed mockup: teal, black and white softball patchwork, player silhouettes, number 88, RILEY and EAT SLEEP SOFTBALL text. | L7: Main bed mockup showing softball patchwork in teal, black and white with player silhouettes and text. | M7: Bright Teal Yellow Softball Comforter Set – Premium Sports Theme Bedding for Girls, Teens & Women Who Love Softball, Offered in Twin, Queen, King Bed Sizes | N7: SET | O7: Bright Teal Softball Comforter Set displayed on a bed | P7: FULL | Q7: FULL | R7: FULL | S7: FULL | T7: =IF(P7="FULL",40,IF(P7="PARTIAL",40/2,0))+IF(Q7="FULL",30,IF(Q7="PARTIAL",30/2,0))+IF(R7="FULL",20,IF(R7="PARTIAL",20/2,0))+IF(S7="FULL",10,IF(S7="PARTIAL",10/2,0)) -> 100 | U7: =IF(P7="NOT_CHECKED",0,40)+IF(Q7="NOT_CHECKED",0,30)+IF(R7="NOT_CHECKED",0,20)+IF(S7="NOT_CHECKED",0,10) -> 100 | V7: =IF(U7=100,T7,"") -> 100 | W7: =T7 -> 100 | X7: =T7+(100-U7) -> 100 | Y7: [] | Z7: ["seo_runs\\jeminise.com\\20260906_234129\\evidence\\images\\2_bright-teal-yellow-softball-comforter-set-premium-sports-theme\\image_01_47934735909063.jpg; seo_runs\\jeminise.com\\20260906_234129\\evidence\\contact_sheets\\2_bright-teal-yellow-softball-comforter-set-premium-sports-theme.jpg", "https://jeminise.com/products/bright-teal-yellow-softball-comforter-set-premium-sports-theme", "https://cdn.shopify.com/s/files/1/0792/5098/1063/files/aaac3be2edd458da15620b4b48ea0557ee8e33aa5a6ff9ed0d0db11848fd4cbe.jpg?v=1787245111"]
A8: jeminise.com+bright-teal-yellow-softball-comforter-set-premium-sports-theme | B8: qaimg_e4eff0625849f778 | C8: https://cdn.shopify.com/s/files/1/0792/5098/1063/files/b4d8d185bcbb550263dadfadb3419fffc97f4c44e070091e393e7296e5d6fb3c.jpg?v=1787245111 | D8: https://cdn.shopify.com/s/files/1/0792/5098/1063/files/b4d8d185bcbb550263dadfadb3419fffc97f4c44e070091e393e7296e5d6fb3c.jpg?v=1787245111 | E8: 38895967436999 | F8: 47934735941831 | H8: GALLERY | I8: DIRECT_ORIGINAL_IMAGE | J8: 2026-09-07T09:05:41.201318+07:00 | K8: Angled bedroom mockup of the same softball comforter design. | L8: Secondary detail or room mockup showing softball patchwork in teal, black and white with player silhouettes and text and visible quilted/printed texture. | M8: Bright Teal Yellow Softball Comforter Set – Premium Sports Theme Bedding for Girls, Teens & Women Who Love Softball, Offered in Twin, Queen, King Bed Sizes | N8: SET | O8: Close view of softball patchwork in teal, black and white with player silhouettes and text on the comforter set | P8: FULL | Q8: PARTIAL | R8: FAIL | S8: FULL | T8: =IF(P8="FULL",40,IF(P8="PARTIAL",40/2,0))+IF(Q8="FULL",30,IF(Q8="PARTIAL",30/2,0))+IF(R8="FULL",20,IF(R8="PARTIAL",20/2,0))+IF(S8="FULL",10,IF(S8="PARTIAL",10/2,0)) -> 65 | U8: =IF(P8="NOT_CHECKED",0,40)+IF(Q8="NOT_CHECKED",0,30)+IF(R8="NOT_CHECKED",0,20)+IF(S8="NOT_CHECKED",0,10) -> 100 | V8: =IF(U8=100,T8,"") -> 65 | W8: =T8 -> 65 | X8: =T8+(100-U8) -> 65 | Y8: ["ISS-002-IMG-02"] | Z8: ["seo_runs\\jeminise.com\\20260906_234129\\evidence\\images\\2_bright-teal-yellow-softball-comforter-set-premium-sports-theme\\image_02_47934735941831.jpg; seo_runs\\jeminise.com\\20260906_234129\\evidence\\contact_sheets\\2_bright-teal-yellow-softball-comforter-set-premium-sports-theme.jpg", "https://jeminise.com/products/bright-teal-yellow-softball-comforter-set-premium-sports-theme", "https://cdn.shopify.com/s/files/1/0792/5098/1063/files/b4d8d185bcbb550263dadfadb3419fffc97f4c44e070091e393e7296e5d6fb3c.jpg?v=1787245111"]
A9: jeminise.com+bright-teal-yellow-softball-comforter-set-premium-sports-theme | B9: qaimg_818a7f1a1cf31342 | C9: https://cdn.shopify.com/s/files/1/0792/5098/1063/files/4905418785c478f3ccf76145151452929eacdfc883190607ac14b204c401e760.jpg?v=1787245111 | D9: https://cdn.shopify.com/s/files/1/0792/5098/1063/files/4905418785c478f3ccf76145151452929eacdfc883190607ac14b204c401e760.jpg?v=1787245111 | E9: 38895967469767 | F9: 47934735974599 | H9: GALLERY | I9: DIRECT_ORIGINAL_IMAGE | J9: 2026-09-07T09:05:41.201318+07:00 | K9: Close view of two pillowcases with number 88 and a batter silhouette. | L9: Matching pillow sham or bedding detail using the same softball patchwork in teal, black and white with player silhouettes and text artwork. | M9: Bright Teal Yellow Softball Comforter Set – Premium Sports Theme Bedding for Girls, Teens & Women Who Love Softball, Offered in Twin, Queen, King Bed Sizes | N9: SET | O9: Matching pillow sham for Bright Teal Softball Comforter Set | P9: FULL | Q9: FULL | R9: FULL | S9: FULL | T9: =IF(P9="FULL",40,IF(P9="PARTIAL",40/2,0))+IF(Q9="FULL",30,IF(Q9="PARTIAL",30/2,0))+IF(R9="FULL",20,IF(R9="PARTIAL",20/2,0))+IF(S9="FULL",10,IF(S9="PARTIAL",10/2,0)) -> 100 | U9: =IF(P9="NOT_CHECKED",0,40)+IF(Q9="NOT_CHECKED",0,30)+IF(R9="NOT_CHECKED",0,20)+IF(S9="NOT_CHECKED",0,10) -> 100 | V9: =IF(U9=100,T9,"") -> 100 | W9: =T9 -> 100 | X9: =T9+(100-U9) -> 100 | Y9: [] | Z9: ["seo_runs\\jeminise.com\\20260906_234129\\evidence\\images\\2_bright-teal-yellow-softball-comforter-set-premium-sports-theme\\image_03_47934735974599.jpg; seo_runs\\jeminise.com\\20260906_234129\\evidence\\contact_sheets\\2_bright-teal-yellow-softball-comforter-set-premium-sports-theme.jpg", "https://jeminise.com/products/bright-teal-yellow-softball-comforter-set-premium-sports-theme", "https://cdn.shopify.com/s/files/1/0792/5098/1063/files/4905418785c478f3ccf76145151452929eacdfc883190607ac14b204c401e760.jpg?v=1787245111"]
A10: jeminise.com+bright-teal-yellow-softball-comforter-set-premium-sports-theme | B10: qaimg_e39a0722bea43dc5 | C10: https://cdn.shopify.com/s/files/1/0792/5098/1063/files/66e753b90ce33322bda9902192b0d181e5f65b4823b1464fb51d32bee82398ed.jpg?v=1787245111 | D10: https://cdn.shopify.com/s/files/1/0792/5098/1063/files/66e753b90ce33322bda9902192b0d181e5f65b4823b1464fb51d32bee82398ed.jpg?v=1787245111 | E10: 38895967502535 | F10: 47934736007367 | H10: GALLERY | I10: DIRECT_ORIGINAL_IMAGE | J10: 2026-09-07T09:05:41.201318+07:00 | K10: Folded comforter showing the printed face and plain white reverse. | L10: Room/folded product or fabric information image tied to the softball patchwork in teal, black and white with player silhouettes and text design. | M10: Bright Teal Yellow Softball Comforter Set – Premium Sports Theme Bedding for Girls, Teens & Women Who Love Softball, Offered in Twin, Queen, King Bed Sizes | N10: SET | O10: Bright Teal Softball Comforter Set shown in a bedroom setting | P10: FULL | Q10: PARTIAL | R10: FAIL | S10: FULL | T10: =IF(P10="FULL",40,IF(P10="PARTIAL",40/2,0))+IF(Q10="FULL",30,IF(Q10="PARTIAL",30/2,0))+IF(R10="FULL",20,IF(R10="PARTIAL",20/2,0))+IF(S10="FULL",10,IF(S10="PARTIAL",10/2,0)) -> 65 | U10: =IF(P10="NOT_CHECKED",0,40)+IF(Q10="NOT_CHECKED",0,30)+IF(R10="NOT_CHECKED",0,20)+IF(S10="NOT_CHECKED",0,10) -> 100 | V10: =IF(U10=100,T10,"") -> 65 | W10: =T10 -> 65 | X10: =T10+(100-U10) -> 65 | Y10: ["ISS-002-IMG-04"] | Z10: ["seo_runs\\jeminise.com\\20260906_234129\\evidence\\images\\2_bright-teal-yellow-softball-comforter-set-premium-sports-theme\\image_04_47934736007367.jpg; seo_runs\\jeminise.com\\20260906_234129\\evidence\\contact_sheets\\2_bright-teal-yellow-softball-comforter-set-premium-sports-theme.jpg", "https://jeminise.com/products/bright-teal-yellow-softball-comforter-set-premium-sports-theme", "https://cdn.shopify.com/s/files/1/0792/5098/1063/files/66e753b90ce33322bda9902192b0d181e5f65b4823b1464fb51d32bee82398ed.jpg?v=1787245111"]
A11: jeminise.com+bright-teal-yellow-softball-comforter-set-premium-sports-theme | B11: qaimg_d6033fe2a892182c | C11: https://cdn.shopify.com/s/files/1/0792/5098/1063/files/a8d8145d1b6e7b4bbc3eb1dc71a100a3f3243648810f40f7f678de166dbfd428.jpg?v=1787245111 | D11: https://cdn.shopify.com/s/files/1/0792/5098/1063/files/a8d8145d1b6e7b4bbc3eb1dc71a100a3f3243648810f40f7f678de166dbfd428.jpg?v=1787245111 | E11: 38895967535303 | F11: 47934736040135 | H11: GALLERY | I11: DIRECT_ORIGINAL_IMAGE | J11: 2026-09-07T09:05:41.201318+07:00 | K11: Close-up comparing the plain reverse with the printed face; no size chart is present. | L11: Sizing or included-components information image for the bedding set. | M11: Bright Teal Yellow Softball Comforter Set – Premium Sports Theme Bedding for Girls, Teens & Women Who Love Softball, Offered in Twin, Queen, King Bed Sizes | N11: SET | O11: Size guide for Bright Teal Softball Comforter Set | P11: FULL | Q11: FAIL | R11: FAIL | S11: FULL | T11: =IF(P11="FULL",40,IF(P11="PARTIAL",40/2,0))+IF(Q11="FULL",30,IF(Q11="PARTIAL",30/2,0))+IF(R11="FULL",20,IF(R11="PARTIAL",20/2,0))+IF(S11="FULL",10,IF(S11="PARTIAL",10/2,0)) -> 50 | U11: =IF(P11="NOT_CHECKED",0,40)+IF(Q11="NOT_CHECKED",0,30)+IF(R11="NOT_CHECKED",0,20)+IF(S11="NOT_CHECKED",0,10) -> 100 | V11: =IF(U11=100,T11,"") -> 50 | W11: =T11 -> 50 | X11: =T11+(100-U11) -> 50 | Y11: ["ISS-002-IMG-05"] | Z11: ["seo_runs\\jeminise.com\\20260906_234129\\evidence\\images\\2_bright-teal-yellow-softball-comforter-set-premium-sports-theme\\image_05_47934736040135.jpg; seo_runs\\jeminise.com\\20260906_234129\\evidence\\contact_sheets\\2_bright-teal-yellow-softball-comforter-set-premium-sports-theme.jpg", "https://jeminise.com/products/bright-teal-yellow-softball-comforter-set-premium-sports-theme", "https://cdn.shopify.com/s/files/1/0792/5098/1063/files/a8d8145d1b6e7b4bbc3eb1dc71a100a3f3243648810f40f7f678de166dbfd428.jpg?v=1787245111"]
A12: jeminise.com+bright-teal-yellow-softball-comforter-set-premium-sports-theme | B12: qaimg_fef8ad032f828b5c | C12: https://cdn.shopify.com/s/files/1/0792/5098/1063/files/b5c74b68d1b4eff2209b7123e3fbe61d1e31afd73aa5ba647e17c194e2e66c44_6ab5c586-a618-40f4-b48e-38e09e6a461b.jpg?v=1787245111 | D12: https://cdn.shopify.com/s/files/1/0792/5098/1063/files/b5c74b68d1b4eff2209b7123e3fbe61d1e31afd73aa5ba647e17c194e2e66c44_6ab5c586-a618-40f4-b48e-38e09e6a461b.jpg?v=1787245111 | E12: 38895967568071 | F12: 47934736072903 | H12: GALLERY | I12: DIRECT_ORIGINAL_IMAGE | J12: 2026-09-07T09:05:41.201318+07:00 | K12: Feature graphic stating machine washable, soft microfiber filling, lightweight and breathable. | L12: Feature image describing fabric layers, softness, breathability or care details. | M12: Bright Teal Yellow Softball Comforter Set – Premium Sports Theme Bedding for Girls, Teens & Women Who Love Softball, Offered in Twin, Queen, King Bed Sizes | N12: SET | O12: Fabric feature graphic for Bright Teal Softball Comforter Set | P12: FULL | Q12: FULL | R12: FULL | S12: FULL | T12: =IF(P12="FULL",40,IF(P12="PARTIAL",40/2,0))+IF(Q12="FULL",30,IF(Q12="PARTIAL",30/2,0))+IF(R12="FULL",20,IF(R12="PARTIAL",20/2,0))+IF(S12="FULL",10,IF(S12="PARTIAL",10/2,0)) -> 100 | U12: =IF(P12="NOT_CHECKED",0,40)+IF(Q12="NOT_CHECKED",0,30)+IF(R12="NOT_CHECKED",0,20)+IF(S12="NOT_CHECKED",0,10) -> 100 | V12: =IF(U12=100,T12,"") -> 100 | W12: =T12 -> 100 | X12: =T12+(100-U12) -> 100 | Y12: [] | Z12: ["seo_runs\\jeminise.com\\20260906_234129\\evidence\\images\\2_bright-teal-yellow-softball-comforter-set-premium-sports-theme\\image_06_47934736072903.jpg; seo_runs\\jeminise.com\\20260906_234129\\evidence\\contact_sheets\\2_bright-teal-yellow-softball-comforter-set-premium-sports-theme.jpg", "https://jeminise.com/products/bright-teal-yellow-softball-comforter-set-premium-sports-theme", "https://cdn.shopify.com/s/files/1/0792/5098/1063/files/b5c74b68d1b4eff2209b7123e3fbe61d1e31afd73aa5ba647e17c194e2e66c44_6ab5c586-a618-40f4-b48e-38e09e6a461b.jpg?v=1787245111"]
A13: jeminise.com+bright-teal-yellow-softball-comforter-set-premium-sports-theme | B13: qaimg_f68e96fb788aa5d7 | C13: https://cdn.shopify.com/s/files/1/0792/5098/1063/files/a0ebf0c8e5cb1f2c8f924529805ea1d20494460dd41a740514b8862f5d5a2f4f_b03a920f-a52a-4b39-842e-77c13ca56137.jpg?v=1787245111 | D13: https://cdn.shopify.com/s/files/1/0792/5098/1063/files/a0ebf0c8e5cb1f2c8f924529805ea1d20494460dd41a740514b8862f5d5a2f4f_b03a920f-a52a-4b39-842e-77c13ca56137.jpg?v=1787245111 | E13: 38895967600839 | F13: 47934736105671 | H13: GALLERY | I13: DIRECT_ORIGINAL_IMAGE | J13: 2026-09-07T09:05:41.201318+07:00 | K13: Included-components graphic stating one comforter and two pillowcases included. | L13: Additional bedroom mockup showing the softball patchwork in teal, black and white with player silhouettes and text design on a bed. | M13: Bright Teal Yellow Softball Comforter Set – Premium Sports Theme Bedding for Girls, Teens & Women Who Love Softball, Offered in Twin, Queen, King Bed Sizes | N13: SET | O13: Bedroom mockup of Bright Teal Softball Comforter Set | P13: FULL | Q13: FAIL | R13: FAIL | S13: FULL | T13: =IF(P13="FULL",40,IF(P13="PARTIAL",40/2,0))+IF(Q13="FULL",30,IF(Q13="PARTIAL",30/2,0))+IF(R13="FULL",20,IF(R13="PARTIAL",20/2,0))+IF(S13="FULL",10,IF(S13="PARTIAL",10/2,0)) -> 50 | U13: =IF(P13="NOT_CHECKED",0,40)+IF(Q13="NOT_CHECKED",0,30)+IF(R13="NOT_CHECKED",0,20)+IF(S13="NOT_CHECKED",0,10) -> 100 | V13: =IF(U13=100,T13,"") -> 50 | W13: =T13 -> 50 | X13: =T13+(100-U13) -> 50 | Y13: ["ISS-002-IMG-07"] | Z13: ["seo_runs\\jeminise.com\\20260906_234129\\evidence\\images\\2_bright-teal-yellow-softball-comforter-set-premium-sports-theme\\image_07_47934736105671.jpg; seo_runs\\jeminise.com\\20260906_234129\\evidence\\contact_sheets\\2_bright-teal-yellow-softball-comforter-set-premium-sports-theme.jpg", "https://jeminise.com/products/bright-teal-yellow-softball-comforter-set-premium-sports-theme", "https://cdn.shopify.com/s/files/1/0792/5098/1063/files/a0ebf0c8e5cb1f2c8f924529805ea1d20494460dd41a740514b8862f5d5a2f4f_b03a920f-a52a-4b39-842e-77c13ca56137.jpg?v=1787245111"]
... A66: jeminise.com+christian-bedding-set-inspirational-bible-verse-comforte-design-01 | B66: qaimg_734f2f8be24b67c2 | C66: https://cdn.shopify.com/s/files/1/0792/5098/1063/files/d6b8438a259ef28ba839a68ba108f40464bc9629b0bc2168779fc7776c9cbffa.jpg?v=1787237695 | D66: https://cdn.shopify.com/s/files/1/0792/5098/1063/files/d6b8438a259ef28ba839a68ba108f40464bc9629b0bc2168779fc7776c9cbffa.jpg?v=1787237695 | E66: 38895075721415 | F66: 47933838196935 | H66: GALLERY | I66: DIRECT_ORIGINAL_IMAGE | J66: 2026-09-07T09:05:41.201318+07:00 | K66: Twin, Full, Queen and King dimension chart. | L66: Additional product information image for size, care, personalization or bedding type. | M66: Christian Bedding Set – Inspirational Bible Verse Comforter – Religious Bedding for Women, Faith Gift for Mom, Daughter, Sister, Birthday & Religious Gifts (God Says I am #1) | N66: SET | O66: Size or personalization guide for Personalized God Says I Am Christian Bedding Set | P66: FULL | Q66: PARTIAL | R66: PARTIAL | S66: FULL | T66: =IF(P66="FULL",40,IF(P66="PARTIAL",40/2,0))+IF(Q66="FULL",30,IF(Q66="PARTIAL",30/2,0))+IF(R66="FULL",20,IF(R66="PARTIAL",20/2,0))+IF(S66="FULL",10,IF(S66="PARTIAL",10/2,0)) -> 75 | U66: =IF(P66="NOT_CHECKED",0,40)+IF(Q66="NOT_CHECKED",0,30)+IF(R66="NOT_CHECKED",0,20)+IF(S66="NOT_CHECKED",0,10) -> 100 | V66: =IF(U66=100,T66,"") -> 75 | W66: =T66 -> 75 | X66: =T66+(100-U66) -> 75 | Y66: ["ISS-010-IMG-08"] | Z66: ["seo_runs\\jeminise.com\\20260906_234129\\evidence\\images\\10_christian-bedding-set-inspirational-bible-verse-comforte-design-01\\image_08_47933838196935.jpg; seo_runs\\jeminise.com\\20260906_234129\\evidence\\contact_sheets\\10_christian-bedding-set-inspirational-bible-verse-comforte-design-01.jpg", "https://jeminise.com/products/christian-bedding-set-inspirational-bible-verse-comforte-design-01", "https://cdn.shopify.com/s/files/1/0792/5098/1063/files/d6b8438a259ef28ba839a68ba108f40464bc9629b0bc2168779fc7776c9cbffa.jpg?v=1787237695"]

Sheet QA_Issues
A1: issue_id | B1: product_key | C1: qa_image_key | D1: severity | E1: field | F1: submitted_value | G1: source_observation | H1: reason | I1: recommended_fix | J1: supporting_evidence | K1: recheck_condition
A2: ISS-001-IMG-05 | B2: jeminise.com+autumn-cardinals-perched-above-large-sunflowers-quilt-with-cardinal-birds-9a3b408b20-9a3b408b20 | C2: qaimg_8a56044406ccfa03 | D2: MINOR | E2: image_observation/alt_effective | F2: Sizing or included-components information image for the bedding set. | Size guide for Cardinal Sunflower Patchwork Quilt Set | G2: Included-components and dimensions graphic: one quilt; two standard shams are optional; Throw/Twin/Queen/King sizes shown. | H2: Nhận xét hoặc alt theo mẫu vị trí không phản ánh đầy đủ/đúng nội dung ảnh thực tế. | I2: Cardinal sunflower quilt size and optional sham guide | J2: seo_runs\jeminise.com\20260906_234129\evidence\images\1_autumn-cardinals-perched-above-large-sunflowers-quilt-with-cardinal-birds-9a3b408b20-9a3b408b20\image_05_47540016513223.jpg; seo_runs\jeminise.com\20260906_234129\evidence\contact_sheets\1_autumn-cardinals-perched-above-large-sunflowers-quilt-with-cardinal-birds-9a3b408b20-9a3b408b20.jpg; https://jeminise.com/products/autumn-cardinals-perched-above-large-sunflowers-quilt-with-cardinal-birds-9a3b408b20-9a3b408b20; https://cdn.shopify.com/s/files/1/0792/5098/1063/files/f17ccb354040b3320b99a1960533bd6ef949db1145d3897d55a33673489caad9.jpg?v=1785099190 | K2: Mở lại ảnh gốc và xác nhận observation/alt mới mô tả đúng ảnh.
A3: ISS-002-IMG-02 | B3: jeminise.com+bright-teal-yellow-softball-comforter-set-premium-sports-theme | C3: qaimg_e4eff0625849f778 | D3: MAJOR | E3: image_observation/alt_effective | F3: Secondary detail or room mockup showing softball patchwork in teal, black and white with player silhouettes and text and visible quilted/printed texture. | Close view of softball patchwork in teal, black and white with player silhouettes and text on the comforter set | G3: Angled bedroom mockup of the same softball comforter design. | H3: Nhận xét hoặc alt theo mẫu vị trí không phản ánh đầy đủ/đúng nội dung ảnh thực tế. | I3: Teal softball comforter set in an angled bedroom view | J3: seo_runs\jeminise.com\20260906_234129\evidence\images\2_bright-teal-yellow-softball-comforter-set-premium-sports-theme\image_02_47934735941831.jpg; seo_runs\jeminise.com\20260906_234129\evidence\contact_sheets\2_bright-teal-yellow-softball-comforter-set-premium-sports-theme.jpg; https://jeminise.com/products/bright-teal-yellow-softball-comforter-set-premium-sports-theme; https://cdn.shopify.com/s/files/1/0792/5098/1063/files/b4d8d185bcbb550263dadfadb3419fffc97f4c44e070091e393e7296e5d6fb3c.jpg?v=1787245111 | K3: Mở lại ảnh gốc và xác nhận observation/alt mới mô tả đúng ảnh.
A4: ISS-002-IMG-04 | B4: jeminise.com+bright-teal-yellow-softball-comforter-set-premium-sports-theme | C4: qaimg_e39a0722bea43dc5 | D4: MAJOR | E4: image_observation/alt_effective | F4: Room/folded product or fabric information image tied to the softball patchwork in teal, black and white with player silhouettes and text design. | Bright Teal Softball Comforter Set shown in a bedroom setting | G4: Folded comforter showing the printed face and plain white reverse. | H4: Nhận xét hoặc alt theo mẫu vị trí không phản ánh đầy đủ/đúng nội dung ảnh thực tế. | I4: Folded teal softball comforter showing the white reverse | J4: seo_runs\jeminise.com\20260906_234129\evidence\images\2_bright-teal-yellow-softball-comforter-set-premium-sports-theme\image_04_47934736007367.jpg; seo_runs\jeminise.com\20260906_234129\evidence\contact_sheets\2_bright-teal-yellow-softball-comforter-set-premium-sports-theme.jpg; https://jeminise.com/products/bright-teal-yellow-softball-comforter-set-premium-sports-theme; https://cdn.shopify.com/s/files/1/0792/5098/1063/files/66e753b90ce33322bda9902192b0d181e5f65b4823b1464fb51d32bee82398ed.jpg?v=1787245111 | K4: Mở lại ảnh gốc và xác nhận observation/alt mới mô tả đúng ảnh.
A5: ISS-002-IMG-05 | B5: jeminise.com+bright-teal-yellow-softball-comforter-set-premium-sports-theme | C5: qaimg_d6033fe2a892182c | D5: MAJOR | E5: image_observation/alt_effective | F5: Sizing or included-components information image for the bedding set. | Size guide for Bright Teal Softball Comforter Set | G5: Close-up comparing the plain reverse with the printed face; no size chart is present. | H5: Nhận xét hoặc alt theo mẫu vị trí không phản ánh đầy đủ/đúng nội dung ảnh thực tế. | I5: Close-up of teal softball comforter print and white reverse | J5: seo_runs\jeminise.com\20260906_234129\evidence\images\2_bright-teal-yellow-softball-comforter-set-premium-sports-theme\image_05_47934736040135.jpg; seo_runs\jeminise.com\20260906_234129\evidence\contact_sheets\2_bright-teal-yellow-softball-comforter-set-premium-sports-theme.jpg; https://jeminise.com/products/bright-teal-yellow-softball-comforter-set-premium-sports-theme; https://cdn.shopify.com/s/files/1/0792/5098/1063/files/a8d8145d1b6e7b4bbc3eb1dc71a100a3f3243648810f40f7f678de166dbfd428.jpg?v=1787245111 | K5: Mở lại ảnh gốc và xác nhận observation/alt mới mô tả đúng ảnh.
A6: ISS-002-IMG-07 | B6: jeminise.com+bright-teal-yellow-softball-comforter-set-premium-sports-theme | C6: qaimg_f68e96fb788aa5d7 | D6: MAJOR | E6: image_observation/alt_effective | F6: Additional bedroom mockup showing the softball patchwork in teal, black and white with player silhouettes and text design on a bed. | Bedroom mockup of Bright Teal Softball Comforter Set | G6: Included-components graphic stating one comforter and two pillowcases included. | H6: Nhận xét hoặc alt theo mẫu vị trí không phản ánh đầy đủ/đúng nội dung ảnh thực tế. | I6: Teal softball comforter set with two included pillowcases | J6: seo_runs\jeminise.com\20260906_234129\evidence\images\2_bright-teal-yellow-softball-comforter-set-premium-sports-theme\image_07_47934736105671.jpg; seo_runs\jeminise.com\20260906_234129\evidence\contact_sheets\2_bright-teal-yellow-softball-comforter-set-premium-sports-theme.jpg; https://jeminise.com/products/bright-teal-yellow-softball-comforter-set-premium-sports-theme; https://cdn.shopify.com/s/files/1/0792/5098/1063/files/a0ebf0c8e5cb1f2c8f924529805ea1d20494460dd41a740514b8862f5d5a2f4f_b03a920f-a52a-4b39-842e-77c13ca56137.jpg?v=1787245111 | K6: Mở lại ảnh gốc và xác nhận observation/alt mới mô tả đúng ảnh.
A7: ISS-003-IMG-05 | B7: jeminise.com+cardinals-perched-beside-decorated-christmas-tree-patchwork-winter-quilt-7cd7bc46a0-7cd7bc46a0 | C7: qaimg_5ee8cd8c5a75c19e | D7: MINOR | E7: image_observation/alt_effective | F7: Sizing or included-components information image for the bedding set. | Size guide for Cardinal Christmas Memorial Patchwork Quilt | G7: Included-components and dimensions graphic for the quilt and optional shams. | H7: Nhận xét hoặc alt theo mẫu vị trí không phản ánh đầy đủ/đúng nội dung ảnh thực tế. | I7: Christmas cardinal quilt size and optional sham guide | J7: seo_runs\jeminise.com\20260906_234129\evidence\images\3_cardinals-perched-beside-decorated-christmas-tree-patchwork-winter-quilt-7cd7bc46a0-7cd7bc46a0\image_05_47540004225223.jpg; seo_runs\jeminise.com\20260906_234129\evidence\contact_sheets\3_cardinals-perched-beside-decorated-christmas-tree-patchwork-winter-quilt-7cd7bc46a0-7cd7bc46a0.jpg; https://jeminise.com/products/cardinals-perched-beside-decorated-christmas-tree-patchwork-winter-quilt-7cd7bc46a0-7cd7bc46a0; https://cdn.shopify.com/s/files/1/0792/5098/1063/files/61192968c1230d5ae97babcfd885b0b0e273f4d893aaaf63a91706f8a569a358.jpg?v=1785099109 | K7: Mở lại ảnh gốc và xác nhận observation/alt mới mô tả đúng ảnh.
