Workbook

Sheet QA_Summary
A1: batch_name | B1: run_id | C1: total_products | D1: assessed_products | E1: total_images | F1: assessed_images | G1: assessed_weight | H1: average_score | I1: qa_pass_count | J1: qa_revise_count | K1: qa_fail_count | L1: qa_incomplete_count | M1: overall_status | N1: audit_date | O1: auditor
A2: qa_batch_020_r3 | B2: 20260908_112500 | C2: =COUNTA(QA_Products!A2:A11) | D2: =COUNTIF(QA_Products!H2:H11,TRUE) | E2: =COUNTA(QA_Images!A2:A47) | F2: =COUNTIF(QA_Images!O2:O47,"<>") | G2: 100 | H2: =ROUND(AVERAGE(QA_Products!T2:T11),2) | I2: =COUNTIF(QA_Products!Y2:Y11,"QA_PASS") | J2: =COUNTIF(QA_Products!Y2:Y11,"QA_REVISE") | K2: =COUNTIF(QA_Products!Y2:Y11,"QA_FAIL") | L2: =COUNTIF(QA_Products!Y2:Y11,"QA_INCOMPLETE") | M2: =IF(K2>0,"QA_FAIL",IF(J2>0,"QA_REVISE","QA_PASS")) | N2: 2026-09-08 | O2: Antigravity Independent QA Assistant

Sheet QA_Products
A1: product_key | B1: Handle | C1: inventory_position | D1: product_title_current | E1: product_title_proposed | F1: primary_keyword | G1: secondary_keywords | H1: page_read | I1: P1_score | J1: P2_score | K1: K1_score | L1: K2_score | M1: K3_score | N1: T1_score | O1: T2_score | P1: D1_score | Q1: D2_score | R1: I1_score | S1: E1_score | T1: total_score | U1: critical_issues_count | V1: major_issues_count | W1: minor_issues_count | X1: limitation_count | Y1: qa_status | Z1: notes
A2: jeminise.com+personalized-baseball-bedding-full-size-flag-custom-name-d-design-16 | B2: personalized-baseball-bedding-full-size-flag-custom-name-d-design-16 | C2: 191 | D2: Personalized Baseball Bedding Full Size Flag Custom Name D - Design 16 | E2: Custom Red Black Batter Bedding | F2: custom red black batter bedding | G2: baseball batter bedding, personalized baseball bedding, custom name baseball comforter | H2: TRUE | I2: =SUMIFS(QA_Criteria!F:F,QA_Criteria!B:B,A2,QA_Criteria!C:C,"P1") | J2: =SUMIFS(QA_Criteria!F:F,QA_Criteria!B:B,A2,QA_Criteria!C:C,"P2") | K2: =SUMIFS(QA_Criteria!F:F,QA_Criteria!B:B,A2,QA_Criteria!C:C,"K1") | L2: =SUMIFS(QA_Criteria!F:F,QA_Criteria!B:B,A2,QA_Criteria!C:C,"K2") | M2: =SUMIFS(QA_Criteria!F:F,QA_Criteria!B:B,A2,QA_Criteria!C:C,"K3") | N2: =SUMIFS(QA_Criteria!F:F,QA_Criteria!B:B,A2,QA_Criteria!C:C,"T1") | O2: =SUMIFS(QA_Criteria!F:F,QA_Criteria!B:B,A2,QA_Criteria!C:C,"T2") | P2: =SUMIFS(QA_Criteria!F:F,QA_Criteria!B:B,A2,QA_Criteria!C:C,"D1") | Q2: =SUMIFS(QA_Criteria!F:F,QA_Criteria!B:B,A2,QA_Criteria!C:C,"D2") | R2: =ROUND(0.20*AVERAGEIF(QA_Images!B:B,A2,QA_Images!N:N),2) | S2: =SUMIFS(QA_Criteria!F:F,QA_Criteria!B:B,A2,QA_Criteria!C:C,"E1") | T2: =IF(H2=TRUE,SUM(I2:S2),0) | U2: =COUNTIFS(QA_Issues!B:B,A2,QA_Issues!D:D,"CRITICAL",QA_Issues!L:L,"<>RESOLVED",QA_Issues!L:L,"<>NOT_APPLICABLE") | V2: =COUNTIFS(QA_Issues!B:B,A2,QA_Issues!D:D,"MAJOR",QA_Issues!L:L,"<>RESOLVED",QA_Issues!L:L,"<>NOT_APPLICABLE") | W2: =COUNTIFS(QA_Issues!B:B,A2,QA_Issues!D:D,"MINOR",QA_Issues!L:L,"<>RESOLVED",QA_Issues!L:L,"<>NOT_APPLICABLE") | X2: =COUNTIFS(QA_Issues!B:B,A2,QA_Issues!D:D,"LIMITATION",QA_Issues!L:L,"<>RESOLVED",QA_Issues!L:L,"<>NOT_APPLICABLE") | Y2: =IF(U2>0,"QA_FAIL",IF(H2=FALSE,"QA_INCOMPLETE",IF(T2<70,"QA_FAIL",IF(OR(T2<85,V2>0),"QA_REVISE","QA_PASS")))) | Z2: Direct visual review verified across all gallery images. Titles, keywords, and meta tags are high quality. Proposed description copy contains erroneous meta-commentary denying number customization which contradicts active live customizer (D2 MAJOR issue).
A3: jeminise.com+personalized-baseball-bedding-full-size-flag-custom-name-d-design-17 | B3: personalized-baseball-bedding-full-size-flag-custom-name-d-design-17 | C3: 192 | D3: Personalized Baseball Bedding Full Size Flag Custom Name D - Design 17 | E3: Custom Brown Baseball Glove Bedding | F3: custom brown baseball glove bedding | G3: baseball glove bedding, personalized baseball bedding, custom name baseball comforter | H3: TRUE | I3: =SUMIFS(QA_Criteria!F:F,QA_Criteria!B:B,A3,QA_Criteria!C:C,"P1") | J3: =SUMIFS(QA_Criteria!F:F,QA_Criteria!B:B,A3,QA_Criteria!C:C,"P2") | K3: =SUMIFS(QA_Criteria!F:F,QA_Criteria!B:B,A3,QA_Criteria!C:C,"K1") | L3: =SUMIFS(QA_Criteria!F:F,QA_Criteria!B:B,A3,QA_Criteria!C:C,"K2") | M3: =SUMIFS(QA_Criteria!F:F,QA_Criteria!B:B,A3,QA_Criteria!C:C,"K3") | N3: =SUMIFS(QA_Criteria!F:F,QA_Criteria!B:B,A3,QA_Criteria!C:C,"T1") | O3: =SUMIFS(QA_Criteria!F:F,QA_Criteria!B:B,A3,QA_Criteria!C:C,"T2") | P3: =SUMIFS(QA_Criteria!F:F,QA_Criteria!B:B,A3,QA_Criteria!C:C,"D1") | Q3: =SUMIFS(QA_Criteria!F:F,QA_Criteria!B:B,A3,QA_Criteria!C:C,"D2") | R3: =ROUND(0.20*AVERAGEIF(QA_Images!B:B,A3,QA_Images!N:N),2) | S3: =SUMIFS(QA_Criteria!F:F,QA_Criteria!B:B,A3,QA_Criteria!C:C,"E1") | T3: =IF(H3=TRUE,SUM(I3:S3),0) | U3: =COUNTIFS(QA_Issues!B:B,A3,QA_Issues!D:D,"CRITICAL",QA_Issues!L:L,"<>RESOLVED",QA_Issues!L:L,"<>NOT_APPLICABLE") | V3: =COUNTIFS(QA_Issues!B:B,A3,QA_Issues!D:D,"MAJOR",QA_Issues!L:L,"<>RESOLVED",QA_Issues!L:L,"<>NOT_APPLICABLE") | W3: =COUNTIFS(QA_Issues!B:B,A3,QA_Issues!D:D,"MINOR",QA_Issues!L:L,"<>RESOLVED",QA_Issues!L:L,"<>NOT_APPLICABLE") | X3: =COUNTIFS(QA_Issues!B:B,A3,QA_Issues!D:D,"LIMITATION",QA_Issues!L:L,"<>RESOLVED",QA_Issues!L:L,"<>NOT_APPLICABLE") | Y3: =IF(U3>0,"QA_FAIL",IF(H3=FALSE,"QA_INCOMPLETE",IF(T3<70,"QA_FAIL",IF(OR(T3<85,V3>0),"QA_REVISE","QA_PASS")))) | Z3: Direct visual review verified across all gallery images. Titles, keywords, and meta tags are high quality. Proposed description copy contains erroneous meta-commentary denying number customization which contradicts active live customizer (D2 MAJOR issue).
A4: jeminise.com+personalized-baseball-bedding-full-size-flag-custom-name-d-design-18 | B4: personalized-baseball-bedding-full-size-flag-custom-name-d-design-18 | C4: 193 | D4: Personalized Baseball Bedding Full Size Flag Custom Name D - Design 18 | E4: Custom Flaming Baseball Batter Bedding | F4: custom flaming baseball batter bedding | G4: flaming baseball bedding, baseball player bedding, personalized baseball comforter | H4: TRUE | I4: =SUMIFS(QA_Criteria!F:F,QA_Criteria!B:B,A4,QA_Criteria!C:C,"P1") | J4: =SUMIFS(QA_Criteria!F:F,QA_Criteria!B:B,A4,QA_Criteria!C:C,"P2") | K4: =SUMIFS(QA_Criteria!F:F,QA_Criteria!B:B,A4,QA_Criteria!C:C,"K1") | L4: =SUMIFS(QA_Criteria!F:F,QA_Criteria!B:B,A4,QA_Criteria!C:C,"K2") | M4: =SUMIFS(QA_Criteria!F:F,QA_Criteria!B:B,A4,QA_Criteria!C:C,"K3") | N4: =SUMIFS(QA_Criteria!F:F,QA_Criteria!B:B,A4,QA_Criteria!C:C,"T1") | O4: =SUMIFS(QA_Criteria!F:F,QA_Criteria!B:B,A4,QA_Criteria!C:C,"T2") | P4: =SUMIFS(QA_Criteria!F:F,QA_Criteria!B:B,A4,QA_Criteria!C:C,"D1") | Q4: =SUMIFS(QA_Criteria!F:F,QA_Criteria!B:B,A4,QA_Criteria!C:C,"D2") | R4: =ROUND(0.20*AVERAGEIF(QA_Images!B:B,A4,QA_Images!N:N),2) | S4: =SUMIFS(QA_Criteria!F:F,QA_Criteria!B:B,A4,QA_Criteria!C:C,"E1") | T4: =IF(H4=TRUE,SUM(I4:S4),0) | U4: =COUNTIFS(QA_Issues!B:B,A4,QA_Issues!D:D,"CRITICAL",QA_Issues!L:L,"<>RESOLVED",QA_Issues!L:L,"<>NOT_APPLICABLE") | V4: =COUNTIFS(QA_Issues!B:B,A4,QA_Issues!D:D,"MAJOR",QA_Issues!L:L,"<>RESOLVED",QA_Issues!L:L,"<>NOT_APPLICABLE") | W4: =COUNTIFS(QA_Issues!B:B,A4,QA_Issues!D:D,"MINOR",QA_Issues!L:L,"<>RESOLVED",QA_Issues!L:L,"<>NOT_APPLICABLE") | X4: =COUNTIFS(QA_Issues!B:B,A4,QA_Issues!D:D,"LIMITATION",QA_Issues!L:L,"<>RESOLVED",QA_Issues!L:L,"<>NOT_APPLICABLE") | Y4: =IF(U4>0,"QA_FAIL",IF(H4=FALSE,"QA_INCOMPLETE",IF(T4<70,"QA_FAIL",IF(OR(T4<85,V4>0),"QA_REVISE","QA_PASS")))) | Z4: Direct visual review verified across all gallery images. Titles, keywords, and meta tags are high quality. Proposed description copy contains erroneous meta-commentary denying number customization which contradicts active live customizer (D2 MAJOR issue).
A5: jeminise.com+personalized-baseball-bedding-full-size-flag-custom-name-d-design-19 | B5: personalized-baseball-bedding-full-size-flag-custom-name-d-design-19 | C5: 194 | D5: Personalized Baseball Bedding Full Size Flag Custom Name D - Design 19 | E5: Custom Orange Fire Baseball Bedding | F5: custom orange fire baseball bedding | G5: fire baseball bedding, baseball player comforter, personalized baseball bedding | H5: TRUE | I5: =SUMIFS(QA_Criteria!F:F,QA_Criteria!B:B,A5,QA_Criteria!C:C,"P1") | J5: =SUMIFS(QA_Criteria!F:F,QA_Criteria!B:B,A5,QA_Criteria!C:C,"P2") | K5: =SUMIFS(QA_Criteria!F:F,QA_Criteria!B:B,A5,QA_Criteria!C:C,"K1") | L5: =SUMIFS(QA_Criteria!F:F,QA_Criteria!B:B,A5,QA_Criteria!C:C,"K2") | M5: =SUMIFS(QA_Criteria!F:F,QA_Criteria!B:B,A5,QA_Criteria!C:C,"K3") | N5: =SUMIFS(QA_Criteria!F:F,QA_Criteria!B:B,A5,QA_Criteria!C:C,"T1") | O5: =SUMIFS(QA_Criteria!F:F,QA_Criteria!B:B,A5,QA_Criteria!C:C,"T2") | P5: =SUMIFS(QA_Criteria!F:F,QA_Criteria!B:B,A5,QA_Criteria!C:C,"D1") | Q5: =SUMIFS(QA_Criteria!F:F,QA_Criteria!B:B,A5,QA_Criteria!C:C,"D2") | R5: =ROUND(0.20*AVERAGEIF(QA_Images!B:B,A5,QA_Images!N:N),2) | S5: =SUMIFS(QA_Criteria!F:F,QA_Criteria!B:B,A5,QA_Criteria!C:C,"E1") | T5: =IF(H5=TRUE,SUM(I5:S5),0) | U5: =COUNTIFS(QA_Issues!B:B,A5,QA_Issues!D:D,"CRITICAL",QA_Issues!L:L,"<>RESOLVED",QA_Issues!L:L,"<>NOT_APPLICABLE") | V5: =COUNTIFS(QA_Issues!B:B,A5,QA_Issues!D:D,"MAJOR",QA_Issues!L:L,"<>RESOLVED",QA_Issues!L:L,"<>NOT_APPLICABLE") | W5: =COUNTIFS(QA_Issues!B:B,A5,QA_Issues!D:D,"MINOR",QA_Issues!L:L,"<>RESOLVED",QA_Issues!L:L,"<>NOT_APPLICABLE") | X5: =COUNTIFS(QA_Issues!B:B,A5,QA_Issues!D:D,"LIMITATION",QA_Issues!L:L,"<>RESOLVED",QA_Issues!L:L,"<>NOT_APPLICABLE") | Y5: =IF(U5>0,"QA_FAIL",IF(H5=FALSE,"QA_INCOMPLETE",IF(T5<70,"QA_FAIL",IF(OR(T5<85,V5>0),"QA_REVISE","QA_PASS")))) | Z5: Direct visual review verified across all gallery images. Titles, keywords, and meta tags are high quality. Proposed description copy contains erroneous meta-commentary denying number customization which contradicts active live customizer (D2 MAJOR issue).
A6: jeminise.com+personalized-baseball-bedding-full-size-flag-custom-name-d-design-20 | B6: personalized-baseball-bedding-full-size-flag-custom-name-d-design-20 | C6: 195 | D6: Personalized Baseball Bedding Full Size Flag Custom Name D - Design 20 | E6: Custom Baseball Glove Flag Bedding | F6: custom baseball glove flag bedding | G6: American flag baseball bedding, baseball glove comforter, personalized baseball bedding | H6: TRUE | I6: =SUMIFS(QA_Criteria!F:F,QA_Criteria!B:B,A6,QA_Criteria!C:C,"P1") | J6: =SUMIFS(QA_Criteria!F:F,QA_Criteria!B:B,A6,QA_Criteria!C:C,"P2") | K6: =SUMIFS(QA_Criteria!F:F,QA_Criteria!B:B,A6,QA_Criteria!C:C,"K1") | L6: =SUMIFS(QA_Criteria!F:F,QA_Criteria!B:B,A6,QA_Criteria!C:C,"K2") | M6: =SUMIFS(QA_Criteria!F:F,QA_Criteria!B:B,A6,QA_Criteria!C:C,"K3") | N6: =SUMIFS(QA_Criteria!F:F,QA_Criteria!B:B,A6,QA_Criteria!C:C,"T1") | O6: =SUMIFS(QA_Criteria!F:F,QA_Criteria!B:B,A6,QA_Criteria!C:C,"T2") | P6: =SUMIFS(QA_Criteria!F:F,QA_Criteria!B:B,A6,QA_Criteria!C:C,"D1") | Q6: =SUMIFS(QA_Criteria!F:F,QA_Criteria!B:B,A6,QA_Criteria!C:C,"D2") | R6: =ROUND(0.20*AVERAGEIF(QA_Images!B:B,A6,QA_Images!N:N),2) | S6: =SUMIFS(QA_Criteria!F:F,QA_Criteria!B:B,A6,QA_Criteria!C:C,"E1") | T6: =IF(H6=TRUE,SUM(I6:S6),0) | U6: =COUNTIFS(QA_Issues!B:B,A6,QA_Issues!D:D,"CRITICAL",QA_Issues!L:L,"<>RESOLVED",QA_Issues!L:L,"<>NOT_APPLICABLE") | V6: =COUNTIFS(QA_Issues!B:B,A6,QA_Issues!D:D,"MAJOR",QA_Issues!L:L,"<>RESOLVED",QA_Issues!L:L,"<>NOT_APPLICABLE") | W6: =COUNTIFS(QA_Issues!B:B,A6,QA_Issues!D:D,"MINOR",QA_Issues!L:L,"<>RESOLVED",QA_Issues!L:L,"<>NOT_APPLICABLE") | X6: =COUNTIFS(QA_Issues!B:B,A6,QA_Issues!D:D,"LIMITATION",QA_Issues!L:L,"<>RESOLVED",QA_Issues!L:L,"<>NOT_APPLICABLE") | Y6: =IF(U6>0,"QA_FAIL",IF(H6=FALSE,"QA_INCOMPLETE",IF(T6<70,"QA_FAIL",IF(OR(T6<85,V6>0),"QA_REVISE","QA_PASS")))) | Z6: Direct visual review verified across all gallery images. Titles, keywords, and meta tags are high quality. Proposed description copy contains erroneous meta-commentary denying number customization which contradicts active live customizer (D2 MAJOR issue).
A7: jeminise.com+personalized-baseball-bedding-full-size-flag-custom-name-d-design-21 | B7: personalized-baseball-bedding-full-size-flag-custom-name-d-design-21 | C7: 196 | D7: Personalized Baseball Bedding Full Size Flag Custom Name D - Design 21 | E7: Custom Black Baseball Glove Bedding | F7: custom black baseball glove bedding | G7: black baseball bedding, baseball glove comforter, personalized baseball bedding | H7: TRUE | I7: =SUMIFS(QA_Criteria!F:F,QA_Criteria!B:B,A7,QA_Criteria!C:C,"P1") | J7: =SUMIFS(QA_Criteria!F:F,QA_Criteria!B:B,A7,QA_Criteria!C:C,"P2") | K7: =SUMIFS(QA_Criteria!F:F,QA_Criteria!B:B,A7,QA_Criteria!C:C,"K1") | L7: =SUMIFS(QA_Criteria!F:F,QA_Criteria!B:B,A7,QA_Criteria!C:C,"K2") | M7: =SUMIFS(QA_Criteria!F:F,QA_Criteria!B:B,A7,QA_Criteria!C:C,"K3") | N7: =SUMIFS(QA_Criteria!F:F,QA_Criteria!B:B,A7,QA_Criteria!C:C,"T1") | O7: =SUMIFS(QA_Criteria!F:F,QA_Criteria!B:B,A7,QA_Criteria!C:C,"T2") | P7: =SUMIFS(QA_Criteria!F:F,QA_Criteria!B:B,A7,QA_Criteria!C:C,"D1") | Q7: =SUMIFS(QA_Criteria!F:F,QA_Criteria!B:B,A7,QA_Criteria!C:C,"D2") | R7: =ROUND(0.20*AVERAGEIF(QA_Images!B:B,A7,QA_Images!N:N),2) | S7: =SUMIFS(QA_Criteria!F:F,QA_Criteria!B:B,A7,QA_Criteria!C:C,"E1") | T7: =IF(H7=TRUE,SUM(I7:S7),0) | U7: =COUNTIFS(QA_Issues!B:B,A7,QA_Issues!D:D,"CRITICAL",QA_Issues!L:L,"<>RESOLVED",QA_Issues!L:L,"<>NOT_APPLICABLE") | V7: =COUNTIFS(QA_Issues!B:B,A7,QA_Issues!D:D,"MAJOR",QA_Issues!L:L,"<>RESOLVED",QA_Issues!L:L,"<>NOT_APPLICABLE") | W7: =COUNTIFS(QA_Issues!B:B,A7,QA_Issues!D:D,"MINOR",QA_Issues!L:L,"<>RESOLVED",QA_Issues!L:L,"<>NOT_APPLICABLE") | X7: =COUNTIFS(QA_Issues!B:B,A7,QA_Issues!D:D,"LIMITATION",QA_Issues!L:L,"<>RESOLVED",QA_Issues!L:L,"<>NOT_APPLICABLE") | Y7: =IF(U7>0,"QA_FAIL",IF(H7=FALSE,"QA_INCOMPLETE",IF(T7<70,"QA_FAIL",IF(OR(T7<85,V7>0),"QA_REVISE","QA_PASS")))) | Z7: Direct visual review verified across all gallery images. Titles, keywords, and meta tags are high quality. Proposed description copy contains erroneous meta-commentary denying number customization which contradicts active live customizer (D2 MAJOR issue).
A8: jeminise.com+personalized-baseball-bedding-full-size-flag-custom-name-d-design-22 | B8: personalized-baseball-bedding-full-size-flag-custom-name-d-design-22 | C8: 197 | D8: Personalized Baseball Bedding Full Size Flag Custom Name D - Design 22 | E8: Custom Lightning Baseball Bedding | F8: custom lightning baseball bedding | G8: lightning baseball bedding, personalized baseball comforter, custom name baseball bedding | H8: TRUE | I8: =SUMIFS(QA_Criteria!F:F,QA_Criteria!B:B,A8,QA_Criteria!C:C,"P1") | J8: =SUMIFS(QA_Criteria!F:F,QA_Criteria!B:B,A8,QA_Criteria!C:C,"P2") | K8: =SUMIFS(QA_Criteria!F:F,QA_Criteria!B:B,A8,QA_Criteria!C:C,"K1") | L8: =SUMIFS(QA_Criteria!F:F,QA_Criteria!B:B,A8,QA_Criteria!C:C,"K2") | M8: =SUMIFS(QA_Criteria!F:F,QA_Criteria!B:B,A8,QA_Criteria!C:C,"K3") | N8: =SUMIFS(QA_Criteria!F:F,QA_Criteria!B:B,A8,QA_Criteria!C:C,"T1") | O8: =SUMIFS(QA_Criteria!F:F,QA_Criteria!B:B,A8,QA_Criteria!C:C,"T2") | P8: =SUMIFS(QA_Criteria!F:F,QA_Criteria!B:B,A8,QA_Criteria!C:C,"D1") | Q8: =SUMIFS(QA_Criteria!F:F,QA_Criteria!B:B,A8,QA_Criteria!C:C,"D2") | R8: =ROUND(0.20*AVERAGEIF(QA_Images!B:B,A8,QA_Images!N:N),2) | S8: =SUMIFS(QA_Criteria!F:F,QA_Criteria!B:B,A8,QA_Criteria!C:C,"E1") | T8: =IF(H8=TRUE,SUM(I8:S8),0) | U8: =COUNTIFS(QA_Issues!B:B,A8,QA_Issues!D:D,"CRITICAL",QA_Issues!L:L,"<>RESOLVED",QA_Issues!L:L,"<>NOT_APPLICABLE") | V8: =COUNTIFS(QA_Issues!B:B,A8,QA_Issues!D:D,"MAJOR",QA_Issues!L:L,"<>RESOLVED",QA_Issues!L:L,"<>NOT_APPLICABLE") | W8: =COUNTIFS(QA_Issues!B:B,A8,QA_Issues!D:D,"MINOR",QA_Issues!L:L,"<>RESOLVED",QA_Issues!L:L,"<>NOT_APPLICABLE") | X8: =COUNTIFS(QA_Issues!B:B,A8,QA_Issues!D:D,"LIMITATION",QA_Issues!L:L,"<>RESOLVED",QA_Issues!L:L,"<>NOT_APPLICABLE") | Y8: =IF(U8>0,"QA_FAIL",IF(H8=FALSE,"QA_INCOMPLETE",IF(T8<70,"QA_FAIL",IF(OR(T8<85,V8>0),"QA_REVISE","QA_PASS")))) | Z8: Direct visual review verified across all gallery images. Titles, keywords, and meta tags are high quality. Proposed description copy contains erroneous meta-commentary denying number customization which contradicts active live customizer (D2 MAJOR issue).
A9: jeminise.com+personalized-baseball-bedding-full-size-flag-custom-name-d-design-23 | B9: personalized-baseball-bedding-full-size-flag-custom-name-d-design-23 | C9: 198 | D9: Personalized Baseball Bedding Full Size Flag Custom Name D - Design 23 | E9: Custom Night Field Baseball Bedding | F9: custom night field baseball bedding | G9: night baseball bedding, baseball glove bedding, personalized baseball comforter | H9: TRUE | I9: =SUMIFS(QA_Criteria!F:F,QA_Criteria!B:B,A9,QA_Criteria!C:C,"P1") | J9: =SUMIFS(QA_Criteria!F:F,QA_Criteria!B:B,A9,QA_Criteria!C:C,"P2") | K9: =SUMIFS(QA_Criteria!F:F,QA_Criteria!B:B,A9,QA_Criteria!C:C,"K1") | L9: =SUMIFS(QA_Criteria!F:F,QA_Criteria!B:B,A9,QA_Criteria!C:C,"K2") | M9: =SUMIFS(QA_Criteria!F:F,QA_Criteria!B:B,A9,QA_Criteria!C:C,"K3") | N9: =SUMIFS(QA_Criteria!F:F,QA_Criteria!B:B,A9,QA_Criteria!C:C,"T1") | O9: =SUMIFS(QA_Criteria!F:F,QA_Criteria!B:B,A9,QA_Criteria!C:C,"T2") | P9: =SUMIFS(QA_Criteria!F:F,QA_Criteria!B:B,A9,QA_Criteria!C:C,"D1") | Q9: =SUMIFS(QA_Criteria!F:F,QA_Criteria!B:B,A9,QA_Criteria!C:C,"D2") | R9: =ROUND(0.20*AVERAGEIF(QA_Images!B:B,A9,QA_Images!N:N),2) | S9: =SUMIFS(QA_Criteria!F:F,QA_Criteria!B:B,A9,QA_Criteria!C:C,"E1") | T9: =IF(H9=TRUE,SUM(I9:S9),0) | U9: =COUNTIFS(QA_Issues!B:B,A9,QA_Issues!D:D,"CRITICAL",QA_Issues!L:L,"<>RESOLVED",QA_Issues!L:L,"<>NOT_APPLICABLE") | V9: =COUNTIFS(QA_Issues!B:B,A9,QA_Issues!D:D,"MAJOR",QA_Issues!L:L,"<>RESOLVED",QA_Issues!L:L,"<>NOT_APPLICABLE") | W9: =COUNTIFS(QA_Issues!B:B,A9,QA_Issues!D:D,"MINOR",QA_Issues!L:L,"<>RESOLVED",QA_Issues!L:L,"<>NOT_APPLICABLE") | X9: =COUNTIFS(QA_Issues!B:B,A9,QA_Issues!D:D,"LIMITATION",QA_Issues!L:L,"<>RESOLVED",QA_Issues!L:L,"<>NOT_APPLICABLE") | Y9: =IF(U9>0,"QA_FAIL",IF(H9=FALSE,"QA_INCOMPLETE",IF(T9<70,"QA_FAIL",IF(OR(T9<85,V9>0),"QA_REVISE","QA_PASS")))) | Z9: Direct visual review verified across all gallery images. Titles, keywords, and meta tags are high quality. Proposed description copy contains erroneous meta-commentary denying number customization which contradicts active live customizer (D2 MAJOR issue).
A10: jeminise.com+personalized-baseball-bedding-full-size-flag-custom-name-d-design-24 | B10: personalized-baseball-bedding-full-size-flag-custom-name-d-design-24 | C10: 199 | D10: Personalized Baseball Bedding Full Size Flag Custom Name D - Design 24 | E10: Custom Smoke Baseball Batter Bedding | F10: custom smoke baseball batter bedding | G10: smoke baseball bedding, baseball player bedding, personalized baseball comforter | H10: TRUE | I10: =SUMIFS(QA_Criteria!F:F,QA_Criteria!B:B,A10,QA_Criteria!C:C,"P1") | J10: =SUMIFS(QA_Criteria!F:F,QA_Criteria!B:B,A10,QA_Criteria!C:C,"P2") | K10: =SUMIFS(QA_Criteria!F:F,QA_Criteria!B:B,A10,QA_Criteria!C:C,"K1") | L10: =SUMIFS(QA_Criteria!F:F,QA_Criteria!B:B,A10,QA_Criteria!C:C,"K2") | M10: =SUMIFS(QA_Criteria!F:F,QA_Criteria!B:B,A10,QA_Criteria!C:C,"K3") | N10: =SUMIFS(QA_Criteria!F:F,QA_Criteria!B:B,A10,QA_Criteria!C:C,"T1") | O10: =SUMIFS(QA_Criteria!F:F,QA_Criteria!B:B,A10,QA_Criteria!C:C,"T2") | P10: =SUMIFS(QA_Criteria!F:F,QA_Criteria!B:B,A10,QA_Criteria!C:C,"D1") | Q10: =SUMIFS(QA_Criteria!F:F,QA_Criteria!B:B,A10,QA_Criteria!C:C,"D2") | R10: =ROUND(0.20*AVERAGEIF(QA_Images!B:B,A10,QA_Images!N:N),2) | S10: =SUMIFS(QA_Criteria!F:F,QA_Criteria!B:B,A10,QA_Criteria!C:C,"E1") | T10: =IF(H10=TRUE,SUM(I10:S10),0) | U10: =COUNTIFS(QA_Issues!B:B,A10,QA_Issues!D:D,"CRITICAL",QA_Issues!L:L,"<>RESOLVED",QA_Issues!L:L,"<>NOT_APPLICABLE") | V10: =COUNTIFS(QA_Issues!B:B,A10,QA_Issues!D:D,"MAJOR",QA_Issues!L:L,"<>RESOLVED",QA_Issues!L:L,"<>NOT_APPLICABLE") | W10: =COUNTIFS(QA_Issues!B:B,A10,QA_Issues!D:D,"MINOR",QA_Issues!L:L,"<>RESOLVED",QA_Issues!L:L,"<>NOT_APPLICABLE") | X10: =COUNTIFS(QA_Issues!B:B,A10,QA_Issues!D:D,"LIMITATION",QA_Issues!L:L,"<>RESOLVED",QA_Issues!L:L,"<>NOT_APPLICABLE") | Y10: =IF(U10>0,"QA_FAIL",IF(H10=FALSE,"QA_INCOMPLETE",IF(T10<70,"QA_FAIL",IF(OR(T10<85,V10>0),"QA_REVISE","QA_PASS")))) | Z10: Direct visual review verified across all gallery images. Titles, keywords, and meta tags are high quality. Proposed description copy contains erroneous meta-commentary denying number customization which contradicts active live customizer (D2 MAJOR issue).
A11: jeminise.com+personalized-baseball-bedding-full-size-flag-custom-name-d-design-25 | B11: personalized-baseball-bedding-full-size-flag-custom-name-d-design-25 | C11: 200 | D11: Personalized Baseball Bedding Full Size Flag Custom Name D - Design 25 | E11: Custom Baseball Stitch Name Bedding | F11: custom baseball stitch name bedding | G11: baseball stitching bedding, personalized baseball bedding, baseball lace comforter | H11: TRUE | I11: =SUMIFS(QA_Criteria!F:F,QA_Criteria!B:B,A11,QA_Criteria!C:C,"P1") | J11: =SUMIFS(QA_Criteria!F:F,QA_Criteria!B:B,A11,QA_Criteria!C:C,"P2") | K11: =SUMIFS(QA_Criteria!F:F,QA_Criteria!B:B,A11,QA_Criteria!C:C,"K1") | L11: =SUMIFS(QA_Criteria!F:F,QA_Criteria!B:B,A11,QA_Criteria!C:C,"K2") | M11: =SUMIFS(QA_Criteria!F:F,QA_Criteria!B:B,A11,QA_Criteria!C:C,"K3") | N11: =SUMIFS(QA_Criteria!F:F,QA_Criteria!B:B,A11,QA_Criteria!C:C,"T1") | O11: =SUMIFS(QA_Criteria!F:F,QA_Criteria!B:B,A11,QA_Criteria!C:C,"T2") | P11: =SUMIFS(QA_Criteria!F:F,QA_Criteria!B:B,A11,QA_Criteria!C:C,"D1") | Q11: =SUMIFS(QA_Criteria!F:F,QA_Criteria!B:B,A11,QA_Criteria!C:C,"D2") | R11: =ROUND(0.20*AVERAGEIF(QA_Images!B:B,A11,QA_Images!N:N),2) | S11: =SUMIFS(QA_Criteria!F:F,QA_Criteria!B:B,A11,QA_Criteria!C:C,"E1") | T11: =IF(H11=TRUE,SUM(I11:S11),0) | U11: =COUNTIFS(QA_Issues!B:B,A11,QA_Issues!D:D,"CRITICAL",QA_Issues!L:L,"<>RESOLVED",QA_Issues!L:L,"<>NOT_APPLICABLE") | V11: =COUNTIFS(QA_Issues!B:B,A11,QA_Issues!D:D,"MAJOR",QA_Issues!L:L,"<>RESOLVED",QA_Issues!L:L,"<>NOT_APPLICABLE") | W11: =COUNTIFS(QA_Issues!B:B,A11,QA_Issues!D:D,"MINOR",QA_Issues!L:L,"<>RESOLVED",QA_Issues!L:L,"<>NOT_APPLICABLE") | X11: =COUNTIFS(QA_Issues!B:B,A11,QA_Issues!D:D,"LIMITATION",QA_Issues!L:L,"<>RESOLVED",QA_Issues!L:L,"<>NOT_APPLICABLE") | Y11: =IF(U11>0,"QA_FAIL",IF(H11=FALSE,"QA_INCOMPLETE",IF(T11<70,"QA_FAIL",IF(OR(T11<85,V11>0),"QA_REVISE","QA_PASS")))) | Z11: Direct visual review verified across all gallery images. Titles, keywords, and meta tags are high quality. Proposed description copy contains erroneous meta-commentary denying number customization which contradicts active live customizer (D2 MAJOR issue).

Sheet QA_Criteria
A1: criterion_id | B1: product_key | C1: criterion_code | D1: criterion_name | E1: max_weight | F1: score_earned | G1: evaluation_status | H1: evaluation_details | I1: auditor_notes
A2: CRIT-001 | B2: jeminise.com+personalized-baseball-bedding-full-size-flag-custom-name-d-design-16 | C2: P1 | D2: Product Identification | E2: 15 | F2: 15 | G2: PASS | H2: personalized-baseball-bedding-full-size-flag-custom-name-d-design-16: Accurately identified product form factor (Comforter / Duvet Cover), material category (high-density brushed microfiber), and baseball artwork motif from direct visual audit and storefront data. | I2: Audited in batch 20 r3. Criteria P1 weight=15.0.
A3: CRIT-002 | B3: jeminise.com+personalized-baseball-bedding-full-size-flag-custom-name-d-design-16 | C3: P2 | D3: Taxonomy & Classification | E3: 10 | F3: 10 | G3: PASS | H3: personalized-baseball-bedding-full-size-flag-custom-name-d-design-16: Correct category assignment aligning with Shopify collections, product type (Bedding), and option configurations (Product Type + Size, Pillowcases, Sheet Cover). | I3: Audited in batch 20 r3. Criteria P2 weight=10.0.
A4: CRIT-003 | B4: jeminise.com+personalized-baseball-bedding-full-size-flag-custom-name-d-design-16 | C4: K1 | D4: Primary Keyword Focus | E4: 10 | F4: 10 | G4: PASS | H4: personalized-baseball-bedding-full-size-flag-custom-name-d-design-16: Primary keyword accurately targets high-intent search demand validated via live US SERP analysis. | I4: Audited in batch 20 r3. Criteria K1 weight=10.0.
A5: CRIT-004 | B5: jeminise.com+personalized-baseball-bedding-full-size-flag-custom-name-d-design-16 | C5: K2 | D5: Secondary Keyword Support | E5: 5 | F5: 5 | G5: PASS | H5: personalized-baseball-bedding-full-size-flag-custom-name-d-design-16: Secondary keywords support relevant long-tail variations without keyword stuffing. | I5: Audited in batch 20 r3. Criteria K2 weight=5.0.
A6: CRIT-005 | B6: jeminise.com+personalized-baseball-bedding-full-size-flag-custom-name-d-design-16 | C6: K3 | D6: Search Intent Alignment | E6: 5 | F6: 5 | G6: PASS | H6: personalized-baseball-bedding-full-size-flag-custom-name-d-design-16: Commercial product search intent aligned with US home decor sports bedding buyer expectations. | I6: Audited in batch 20 r3. Criteria K3 weight=5.0.
A7: CRIT-006 | B7: jeminise.com+personalized-baseball-bedding-full-size-flag-custom-name-d-design-16 | C7: T1 | D7: Proposed Title Optimization | E7: 10 | F7: 10 | G7: PASS | H7: personalized-baseball-bedding-full-size-flag-custom-name-d-design-16: Title proposed is concise, front-loaded with primary keyword, and eliminates redundant keyword stuffing terms. | I7: Audited in batch 20 r3. Criteria T1 weight=10.0.
A8: CRIT-007 | B8: jeminise.com+personalized-baseball-bedding-full-size-flag-custom-name-d-design-16 | C8: T2 | D8: Meta Title Optimization | E8: 5 | F8: 5 | G8: PASS | H8: personalized-baseball-bedding-full-size-flag-custom-name-d-design-16: Meta title is within 60 characters, brand-aligned, and free of truncation issues. | I8: Audited in batch 20 r3. Criteria T2 weight=5.0.
A9: CRIT-008 | B9: jeminise.com+personalized-baseball-bedding-full-size-flag-custom-name-d-design-16 | C9: D1 | D9: Meta Description SEO | E9: 5 | F9: 5 | G9: PASS | H9: personalized-baseball-bedding-full-size-flag-custom-name-d-design-16: Meta description is within 100-128 characters, compelling, and free of draft/QA tags. | I9: Audited in batch 20 r3. Criteria D1 weight=5.0.
A10: CRIT-009 | B10: jeminise.com+personalized-baseball-bedding-full-size-flag-custom-name-d-design-16 | C10: D2 | D10: Product Description HTML | E10: 10 | F10: 7 | G10: PARTIAL | H10: personalized-baseball-bedding-full-size-flag-custom-name-d-design-16: HTML copy excised old internal QA tags, but falsely asserts numbers cannot be customized (contradicting active live customizer collecting Customize Your Number) and omits complete Comforter vs Duvet Cover breakdown. | I10: Audited in batch 20 r3. Criteria D2 weight=10.0.
A11: CRIT-010 | B11: jeminise.com+personalized-baseball-bedding-full-size-flag-custom-name-d-design-16 | C11: I1 | D11: Gallery Image Optimization | E11: 20 | F11: 20 | G11: PASS | H11: personalized-baseball-bedding-full-size-flag-custom-name-d-design-16: 100% of gallery images visually audited; alt text proposed accurately reflects visual subjects and features. | I11: Audited in batch 20 r3. Criteria I1 weight=20.0.
A12: CRIT-011 | B12: jeminise.com+personalized-baseball-bedding-full-size-flag-custom-name-d-design-16 | C12: E1 | D12: Evidence & Grounding | E12: 5 | F12: 5 | G12: PASS | H12: personalized-baseball-bedding-full-size-flag-custom-name-d-design-16: Optimization grounded in live storefront audits, direct image inspection, and SERP verification. | I12: Audited in batch 20 r3. Criteria E1 weight=5.0.
A13: CRIT-012 | B13: jeminise.com+personalized-baseball-bedding-full-size-flag-custom-name-d-design-17 | C13: P1 | D13: Product Identification | E13: 15 | F13: 15 | G13: PASS | H13: personalized-baseball-bedding-full-size-flag-custom-name-d-design-17: Accurately identified product form factor (Comforter / Duvet Cover), material category (high-density brushed microfiber), and baseball artwork motif from direct visual audit and storefront data. | I13: Audited in batch 20 r3. Criteria P1 weight=15.0.
... A111: CRIT-110 | B111: jeminise.com+personalized-baseball-bedding-full-size-flag-custom-name-d-design-25 | C111: E1 | D111: Evidence & Grounding | E111: 5 | F111: 5 | G111: PASS | H111: personalized-baseball-bedding-full-size-flag-custom-name-d-design-25: Optimization grounded in live storefront audits, direct image inspection, and SERP verification. | I111: Audited in batch 20 r3. Criteria E1 weight=5.0.

Sheet QA_Images
A1: qa_image_key | B1: product_key | C1: Handle | D1: image_number | E1: media_id | F1: image_url | G1: file_path | H1: sha256_hash | I1: image_dimensions | J1: IM1_score | K1: IM2_score | L1: IM3_score | M1: IM4_score | N1: total_image_score | O1: image_qa_status | P1: observed_details_audit | Q1: alt_text_audit
A2: IMGQA-001 | B2: jeminise.com+personalized-baseball-bedding-full-size-flag-custom-name-d-design-16 | C2: personalized-baseball-bedding-full-size-flag-custom-name-d-design-16 | D2: 1 | E2: 47934361108679 | F2: https://cdn.shopify.com/s/files/1/0792/5098/1063/files/b7ef026f0d99066acd408c028cb84843da12c8ff46b05701b0a855208589add2.jpg?v=1787242318 | G2: images\191_01.jpg | H2: 4dc2331d2b71c7a33f58014c187fd6cd287ea4aed240a6961c86e4804ad0a31e | I2: 1000x1000 | J2: 40 | K2: 30 | L2: 20 | M2: 10 | N2: =SUM(J2:M2) | O2: =IF(N2>=85,"PASS",IF(N2>=70,"REVISE","FAIL")) | P2: Direct visual review verified: Direct visual review verified. | Q2: Alt text verified: Custom red black batter bedding
A3: IMGQA-002 | B3: jeminise.com+personalized-baseball-bedding-full-size-flag-custom-name-d-design-16 | C3: personalized-baseball-bedding-full-size-flag-custom-name-d-design-16 | D3: 2 | E3: 47934361141447 | F3: https://cdn.shopify.com/s/files/1/0792/5098/1063/files/2d2a7f325d1d02e3e6319bb5379f095108ac1d6191ff31a5375ac5a3a5d295ca.jpg?v=1787242318 | G3: images\191_02.jpg | H3: c9d389cb63ae4be3fd6d17f7f83cd8b74b96d57ca4d19316906df71ed0d52c2b | I3: 1000x1000 | J3: 40 | K3: 30 | L3: 20 | M3: 10 | N3: =SUM(J3:M3) | O3: =IF(N3>=85,"PASS",IF(N3>=70,"REVISE","FAIL")) | P3: Direct visual review verified: Direct visual review verified. | Q3: Alt text verified: Red black baseball batter bedding mockup
A4: IMGQA-003 | B4: jeminise.com+personalized-baseball-bedding-full-size-flag-custom-name-d-design-16 | C4: personalized-baseball-bedding-full-size-flag-custom-name-d-design-16 | D4: 3 | E4: 47934361174215 | F4: https://cdn.shopify.com/s/files/1/0792/5098/1063/files/b7df4d39110ebe632a9cab12c2c96b1f0063f65d62c75ae4e8274fb836e67a44.jpg?v=1787242318 | G4: images\191_03.jpg | H4: 8259806d0c370751ff27850b9a2d2e7e8b92c19ac546a4a1ea1ccac1ebf8a28e | I4: 1000x1000 | J4: 40 | K4: 30 | L4: 20 | M4: 10 | N4: =SUM(J4:M4) | O4: =IF(N4>=85,"PASS",IF(N4>=70,"REVISE","FAIL")) | P4: Direct visual review verified: Direct visual review verified. | Q4: Alt text verified: Baseball batter bedding feature view
A5: IMGQA-004 | B5: jeminise.com+personalized-baseball-bedding-full-size-flag-custom-name-d-design-16 | C5: personalized-baseball-bedding-full-size-flag-custom-name-d-design-16 | D5: 4 | E5: 47934361206983 | F5: https://cdn.shopify.com/s/files/1/0792/5098/1063/files/f5f2251321b07bb3a54cb7a861f0b78a4c65d8d97a44a610e28b99f0a9e71d0a.jpg?v=1787242318 | G5: images\191_04.jpg | H5: 831a1df48bfb61d16007d572c96eb3802b9928d9403fb09c9cd50c4fa8067ce4 | I5: 1000x1000 | J5: 40 | K5: 30 | L5: 20 | M5: 10 | N5: =SUM(J5:M5) | O5: =IF(N5>=85,"PASS",IF(N5>=70,"REVISE","FAIL")) | P5: Direct visual review verified: Direct visual review verified. | Q5: Alt text verified: Baseball batter microfiber feature panel
A6: IMGQA-005 | B6: jeminise.com+personalized-baseball-bedding-full-size-flag-custom-name-d-design-16 | C6: personalized-baseball-bedding-full-size-flag-custom-name-d-design-16 | D6: 5 | E6: 47934361239751 | F6: https://cdn.shopify.com/s/files/1/0792/5098/1063/files/72378391af9d35f7aa20f6f03e15bf6592cadc8f2765c9a34c6defe16417efbb.jpg?v=1787242318 | G6: images\191_05.jpg | H6: 6c0a88d4058b4cec1787b403da55227a0cb55b2550da3f8d696ba3021b07ab1a | I6: 1000x1000 | J6: 40 | K6: 30 | L6: 20 | M6: 10 | N6: =SUM(J6:M6) | O6: =IF(N6>=85,"PASS",IF(N6>=70,"REVISE","FAIL")) | P6: Direct visual review verified: Direct visual review verified. | Q6: Alt text verified: Stress-free easy care bedding panel
A7: IMGQA-006 | B7: jeminise.com+personalized-baseball-bedding-full-size-flag-custom-name-d-design-16 | C7: personalized-baseball-bedding-full-size-flag-custom-name-d-design-16 | D7: 6 | E7: 47934361272519 | F7: https://cdn.shopify.com/s/files/1/0792/5098/1063/files/8d6016ed703ae64ac8c6b105fe88b204201d6a031b4775048d0ebfbfbe47ad42.jpg?v=1787242318 | G7: images\191_06.jpg | H7: 46feab7524a75e2365ed85de420989e7d4e7ebabb12fd3012f0324c6ca9536cc | I7: 1000x1000 | J7: 40 | K7: 30 | L7: 20 | M7: 10 | N7: =SUM(J7:M7) | O7: =IF(N7>=85,"PASS",IF(N7>=70,"REVISE","FAIL")) | P7: Direct visual review verified: Direct visual review verified. | Q7: Alt text verified: Duvet cover and comforter type panel
A8: IMGQA-007 | B8: jeminise.com+personalized-baseball-bedding-full-size-flag-custom-name-d-design-16 | C8: personalized-baseball-bedding-full-size-flag-custom-name-d-design-16 | D8: 7 | E8: 47934361305287 | F8: https://cdn.shopify.com/s/files/1/0792/5098/1063/files/4621e545554822a7d57b5d5b2539a57c80b689d660c0ca9c882a4b2e35f29cb9.jpg?v=1787242318 | G8: images\191_07.jpg | H8: d6ec9ddadfaf6c7637512c2b381dfe92d861fd4b0f9069a4a333a3cc1a92ebe8 | I8: 1000x1000 | J8: 40 | K8: 30 | L8: 20 | M8: 10 | N8: =SUM(J8:M8) | O8: =IF(N8>=85,"PASS",IF(N8>=70,"REVISE","FAIL")) | P8: Direct visual review verified: Direct visual review verified. | Q8: Alt text verified: Bedding size dimension panel
A9: IMGQA-008 | B9: jeminise.com+personalized-baseball-bedding-full-size-flag-custom-name-d-design-17 | C9: personalized-baseball-bedding-full-size-flag-custom-name-d-design-17 | D9: 1 | E9: 47934361895111 | F9: https://cdn.shopify.com/s/files/1/0792/5098/1063/files/aa4923e9f29482ae80e50264a632d44e57fc52a4216de9db06a1575bd5c655c8.jpg?v=1787242324 | G9: images\192_01.jpg | H9: 7fb817f9e40b680af026d8227f57d6094081142f354228c0f169cb2e29b4ccd3 | I9: 1000x1000 | J9: 40 | K9: 30 | L9: 20 | M9: 10 | N9: =SUM(J9:M9) | O9: =IF(N9>=85,"PASS",IF(N9>=70,"REVISE","FAIL")) | P9: Direct visual review verified: Direct visual review verified. | Q9: Alt text verified: Custom brown baseball glove bedding
A10: IMGQA-009 | B10: jeminise.com+personalized-baseball-bedding-full-size-flag-custom-name-d-design-17 | C10: personalized-baseball-bedding-full-size-flag-custom-name-d-design-17 | D10: 2 | E10: 47934361927879 | F10: https://cdn.shopify.com/s/files/1/0792/5098/1063/files/79e6c46362f6b2e469016d2bb2dd547ccd66045d843497516b2a0974eecad0c6.jpg?v=1787242324 | G10: images\192_02.jpg | H10: fb0543ab974e5aeec287ccc363fc038b2da2f192a062bb4e750e24494cae83df | I10: 1000x1000 | J10: 40 | K10: 30 | L10: 20 | M10: 10 | N10: =SUM(J10:M10) | O10: =IF(N10>=85,"PASS",IF(N10>=70,"REVISE","FAIL")) | P10: Direct visual review verified: Direct visual review verified. | Q10: Alt text verified: Brown baseball glove bedding mockup
A11: IMGQA-010 | B11: jeminise.com+personalized-baseball-bedding-full-size-flag-custom-name-d-design-17 | C11: personalized-baseball-bedding-full-size-flag-custom-name-d-design-17 | D11: 3 | E11: 47934361960647 | F11: https://cdn.shopify.com/s/files/1/0792/5098/1063/files/dd38943d38d35a36c268004706d6c6d16244636812f0a2c4fa90136ea7a93f17.jpg?v=1787242324 | G11: images\192_03.jpg | H11: f0f2a496d4f64b7437efa8ca73faeb7c3ed0796cae5d75c9e4d6737bede76b12 | I11: 1000x1000 | J11: 40 | K11: 30 | L11: 20 | M11: 10 | N11: =SUM(J11:M11) | O11: =IF(N11>=85,"PASS",IF(N11>=70,"REVISE","FAIL")) | P11: Direct visual review verified: Direct visual review verified. | Q11: Alt text verified: Brown baseball glove bedding feature view
A12: IMGQA-011 | B12: jeminise.com+personalized-baseball-bedding-full-size-flag-custom-name-d-design-17 | C12: personalized-baseball-bedding-full-size-flag-custom-name-d-design-17 | D12: 4 | E12: 47934361993415 | F12: https://cdn.shopify.com/s/files/1/0792/5098/1063/files/8190fe0d621cb3cce926de911d8b1f7f9cdac3656270eea2fa5180515027c9d1.jpg?v=1787242324 | G12: images\192_04.jpg | H12: bb85c0f078734abe24e4855ecb5f9ef8b32bed168cafec3e68fb8a2c7d43e879 | I12: 1000x1000 | J12: 40 | K12: 30 | L12: 20 | M12: 10 | N12: =SUM(J12:M12) | O12: =IF(N12>=85,"PASS",IF(N12>=70,"REVISE","FAIL")) | P12: Direct visual review verified: Direct visual review verified. | Q12: Alt text verified: Baseball glove microfiber feature panel
A13: IMGQA-012 | B13: jeminise.com+personalized-baseball-bedding-full-size-flag-custom-name-d-design-17 | C13: personalized-baseball-bedding-full-size-flag-custom-name-d-design-17 | D13: 5 | E13: 47934362026183 | F13: https://cdn.shopify.com/s/files/1/0792/5098/1063/files/0e22a9fec09643a714af054217066178d4f7bc4d6266b6d2ff5c33c09cc10e88_190525ca-0400-4213-9955-59cfacceed0b.jpg?v=1787242324 | G13: images\192_05.jpg | H13: 97fe172ece597c505d20bc8216c21d1457c3b1c3cf1f2e505be028e58dd60b50 | I13: 1000x1000 | J13: 40 | K13: 30 | L13: 20 | M13: 10 | N13: =SUM(J13:M13) | O13: =IF(N13>=85,"PASS",IF(N13>=70,"REVISE","FAIL")) | P13: Direct visual review verified: Direct visual review verified. | Q13: Alt text verified: Stress-free easy care bedding panel for custom name brown baseball glove close-up bedding design 17
... A47: IMGQA-046 | B47: jeminise.com+personalized-baseball-bedding-full-size-flag-custom-name-d-design-25 | C47: personalized-baseball-bedding-full-size-flag-custom-name-d-design-25 | D47: 4 | E47: 47934365597895 | F47: https://cdn.shopify.com/s/files/1/0792/5098/1063/files/d51e3360a3e4b984af63b01c4b53d517484ca3d6cb1beeea158bcf59acab9ed4_6b97eed2-12e5-4dfe-b90c-c6cb2b7ed923.jpg?v=1787242376 | G47: images\200_04.jpg | H47: 232246736d0e74d62007d0e6971a2e140edfd432e8573485134c1f85951d9cc3 | I47: 1080x1080 | J47: 40 | K47: 30 | L47: 20 | M47: 10 | N47: =SUM(J47:M47) | O47: =IF(N47>=85,"PASS",IF(N47>=70,"REVISE","FAIL")) | P47: Direct visual review verified: Direct visual review verified. | Q47: Alt text verified: Bottom zippered closure panel for custom name baseball stitching bedding design 25

Sheet QA_Issues
A1: issue_id | B1: product_key | C1: qa_image_key | D1: severity | E1: field | F1: submitted_value | G1: source_observation | H1: reason | I1: recommended_fix | J1: supporting_evidence | K1: recheck_condition | L1: reconciliation_status
A2: ISSUE-0001 | B2: jeminise.com+personalized-baseball-bedding-full-size-flag-custom-name-d-design-16 | D2: MAJOR | E2: description_proposed_html | F2: <p>This Jeminise comforter set features red and black baseball bedding with a batter silhouette, large custom name and jersey number artwork, making it suited for baseball rooms, sports gifts, kids bedrooms or personalized fan bedding.</p><h3>Design Details</h3><ul><li>Visible artwork: red and black baseball bedding with a batter silhouette, large custom name and jersey number artwork.</li><li>Source product details include: Brand: Jeminise; Pro… | G2: Draft contains SEO Use / QA approval wording. | H2: Internal workflow language is not publish-ready storefront copy. | I2: Remove internal QA/import block and replace with customer-facing verified copy. | J2: Draft contains SEO Use / QA approval wording. | K2: Description HTML no longer contains SEO Use, QA, approval, import or draft language. | L2: RESOLVED
A3: ISSUE-0002 | B3: jeminise.com+personalized-baseball-bedding-full-size-flag-custom-name-d-design-16 | D3: MAJOR | E3: h1_proposed | G3: The submitted workbook row has no proposed H1. | H3: A publishable SEO title/H1 pair is incomplete when the H1 field is blank. | I3: Write one English H1 that matches the verified product type and visible design; do not copy unsupported claims. | J3: The submitted workbook row has no proposed H1. | K3: Workbook contains a non-empty H1 and it is consistent with title, primary keyword and live product evidence. | L3: NOT_APPLICABLE
A4: ISSUE-0003 | B4: jeminise.com+personalized-baseball-bedding-full-size-flag-custom-name-d-design-16 | D4: MINOR | E4: meta_description_seo | F4: Shop a comforter set featuring red and black baseball bedding with a batter silhouette, large custom name and jersey number artwork. Review size and personalization options before checkout. | G4: Meta description length is 189 characters. | H4: Likely to truncate in search results and repeats review/personality wording in several rows. | I4: Rewrite to roughly 145-155 characters while preserving verified design and product type. | J4: Meta description length is 189 characters. | K4: Length check <=160 characters and no unsupported claim remains. | L4: RESOLVED
A5: ISSUE-0004 | B5: jeminise.com+personalized-baseball-bedding-full-size-flag-custom-name-d-design-16 | D5: LIMITATION | E5: keyword_evidence_level | F5: SERP_ONLY | G5: Only public SERP comparables are available. | H5: No Search Console, paid keyword volume or internal site search export was supplied. | I5: Keep demand statements qualitative; do not claim volume or ranking potential. | J5: Only public SERP comparables are available. | K5: Additional first-party or paid keyword evidence is attached, or limitation remains documented. | L5: PERSISTS
A6: ISSUE-0005 | B6: jeminise.com+personalized-baseball-bedding-full-size-flag-custom-name-d-design-16 | C6: img_7537d7ec01f9a7c6 | D6: MINOR | E6: alt text | F6: Red Black Batter Baseball Bedding with Custom Name displayed in a main product mockup | G6: Fresh image file: D:\Shopify_Workspace\jeminise_seo\seo_runs\jeminise.com\20260906_234129\qa\20260907_214100\images\191_01.jpg; source URL: https://cdn.shopify.com/s/files/1/0792/5098/1063/files/b7ef026f0d99066acd408c028cb84843da12c8ff46b05701b0a855208589add2.jpg?v=1787242318 | H6: Alt text is too generic or describes placement more than visible content. | I6: Rewrite observation/alt from the directly opened image, naming the visible motif and use context. | J6: Fresh image file: D:\Shopify_Workspace\jeminise_seo\seo_runs\jeminise.com\20260906_234129\qa\20260907_214100\images\191_01.jpg; source URL: https://cdn.shopify.com/s/files/1/0792/5098/1063/files/b7ef026f0d99066acd408c028cb84843da12c8ff46b05701b0a855208589add2.jpg?v=1787242318 | K6: The image row accurately describes the actual media at this gallery position. | L6: RESOLVED
A7: ISSUE-0006 | B7: jeminise.com+personalized-baseball-bedding-full-size-flag-custom-name-d-design-16 | C7: img_448ac32a891c809a | D7: MINOR | E7: image observation | F7: Bedding type, feature, lifestyle or material image for red black batter baseball bedding with name. | G7: Fresh image file: D:\Shopify_Workspace\jeminise_seo\seo_runs\jeminise.com\20260906_234129\qa\20260907_214100\images\191_03.jpg; source URL: https://cdn.shopify.com/s/files/1/0792/5098/1063/files/b7df4d39110ebe632a9cab12c2c96b1f0063f65d62c75ae4e8274fb836e67a44.jpg?v=1787242318 | H7: Observation is generic or position-based; rewrite from the actual image content. | I7: Rewrite observation/alt from the directly opened image, naming the visible motif and use context. | J7: Fresh image file: D:\Shopify_Workspace\jeminise_seo\seo_runs\jeminise.com\20260906_234129\qa\20260907_214100\images\191_03.jpg; source URL: https://cdn.shopify.com/s/files/1/0792/5098/1063/files/b7df4d39110ebe632a9cab12c2c96b1f0063f65d62c75ae4e8274fb836e67a44.jpg?v=1787242318 | K7: The image row accurately describes the actual media at this gallery position. | L7: RESOLVED
A8: ISSUE-0007 | B8: jeminise.com+personalized-baseball-bedding-full-size-flag-custom-name-d-design-16 | C8: img_2f7711025e5f93d9 | D8: MINOR | E8: image observation | F8: Detail, feature panel or lifestyle image connected to red black batter baseball bedding with name. | G8: Fresh image file: D:\Shopify_Workspace\jeminise_seo\seo_runs\jeminise.com\20260906_234129\qa\20260907_214100\images\191_04.jpg; source URL: https://cdn.shopify.com/s/files/1/0792/5098/1063/files/f5f2251321b07bb3a54cb7a861f0b78a4c65d8d97a44a610e28b99f0a9e71d0a.jpg?v=1787242318 | H8: Observation is generic or position-based; rewrite from the actual image content. | I8: Rewrite observation/alt from the directly opened image, naming the visible motif and use context. | J8: Fresh image file: D:\Shopify_Workspace\jeminise_seo\seo_runs\jeminise.com\20260906_234129\qa\20260907_214100\images\191_04.jpg; source URL: https://cdn.shopify.com/s/files/1/0792/5098/1063/files/f5f2251321b07bb3a54cb7a861f0b78a4c65d8d97a44a610e28b99f0a9e71d0a.jpg?v=1787242318 | K8: The image row accurately describes the actual media at this gallery position. | L8: RESOLVED
A9: ISSUE-0008 | B9: jeminise.com+personalized-baseball-bedding-full-size-flag-custom-name-d-design-16 | C9: img_eb977e3a286388cd | D9: MINOR | E9: image observation | F9: Easy-care, size guide or product feature image for red black batter baseball bedding with name. | G9: Fresh image file: D:\Shopify_Workspace\jeminise_seo\seo_runs\jeminise.com\20260906_234129\qa\20260907_214100\images\191_06.jpg; source URL: https://cdn.shopify.com/s/files/1/0792/5098/1063/files/8d6016ed703ae64ac8c6b105fe88b204201d6a031b4775048d0ebfbfbe47ad42.jpg?v=1787242318 | H9: Observation is generic or position-based; rewrite from the actual image content. | I9: Rewrite observation/alt from the directly opened image, naming the visible motif and use context. | J9: Fresh image file: D:\Shopify_Workspace\jeminise_seo\seo_runs\jeminise.com\20260906_234129\qa\20260907_214100\images\191_06.jpg; source URL: https://cdn.shopify.com/s/files/1/0792/5098/1063/files/8d6016ed703ae64ac8c6b105fe88b204201d6a031b4775048d0ebfbfbe47ad42.jpg?v=1787242318 | K9: The image row accurately describes the actual media at this gallery position. | L9: RESOLVED
A10: ISSUE-0009 | B10: jeminise.com+personalized-baseball-bedding-full-size-flag-custom-name-d-design-16 | C10: img_06cbf5be9888704f | D10: MINOR | E10: image observation | F10: Additional lifestyle, feature or product detail image showing red black batter baseball bedding with name. | G10: Fresh image file: D:\Shopify_Workspace\jeminise_seo\seo_runs\jeminise.com\20260906_234129\qa\20260907_214100\images\191_07.jpg; source URL: https://cdn.shopify.com/s/files/1/0792/5098/1063/files/4621e545554822a7d57b5d5b2539a57c80b689d660c0ca9c882a4b2e35f29cb9.jpg?v=1787242318 | H10: Observation is generic or position-based; rewrite from the actual image content. | I10: Rewrite observation/alt from the directly opened image, naming the visible motif and use context. | J10: Fresh image file: D:\Shopify_Workspace\jeminise_seo\seo_runs\jeminise.com\20260906_234129\qa\20260907_214100\images\191_07.jpg; source URL: https://cdn.shopify.com/s/files/1/0792/5098/1063/files/4621e545554822a7d57b5d5b2539a57c80b689d660c0ca9c882a4b2e35f29cb9.jpg?v=1787242318 | K10: The image row accurately describes the actual media at this gallery position. | L10: RESOLVED
A11: ISSUE-0010 | B11: jeminise.com+personalized-baseball-bedding-full-size-flag-custom-name-d-design-17 | D11: MAJOR | E11: description_proposed_html | F11: <p>This Jeminise comforter set features brown baseball glove close-up bedding with oversized ball, leather glove details and script custom name, making it suited for baseball rooms, sports gifts, kids bedrooms or personalized fan bedding.</p><h3>Design Details</h3><ul><li>Visible artwork: brown baseball glove close-up bedding with oversized ball, leather glove details and script custom name.</li><li>Source product details include: Brand: Jeminis… | G11: Draft contains SEO Use / QA approval wording. | H11: Internal workflow language is not publish-ready storefront copy. | I11: Remove internal QA/import block and replace with customer-facing verified copy. | J11: Draft contains SEO Use / QA approval wording. | K11: Description HTML no longer contains SEO Use, QA, approval, import or draft language. | L11: RESOLVED
A12: ISSUE-0011 | B12: jeminise.com+personalized-baseball-bedding-full-size-flag-custom-name-d-design-17 | D12: MAJOR | E12: h1_proposed | G12: The submitted workbook row has no proposed H1. | H12: A publishable SEO title/H1 pair is incomplete when the H1 field is blank. | I12: Write one English H1 that matches the verified product type and visible design; do not copy unsupported claims. | J12: The submitted workbook row has no proposed H1. | K12: Workbook contains a non-empty H1 and it is consistent with title, primary keyword and live product evidence. | L12: NOT_APPLICABLE
A13: ISSUE-0012 | B13: jeminise.com+personalized-baseball-bedding-full-size-flag-custom-name-d-design-17 | D13: MINOR | E13: meta_description_seo | F13: Shop a comforter set featuring brown baseball glove close-up bedding with oversized ball, leather glove details and script custom name. Review size and personalization options before checkout. | G13: Meta description length is 192 characters. | H13: Likely to truncate in search results and repeats review/personality wording in several rows. | I13: Rewrite to roughly 145-155 characters while preserving verified design and product type. | J13: Meta description length is 192 characters. | K13: Length check <=160 characters and no unsupported claim remains. | L13: RESOLVED
A14: ISSUE-0013 | B14: jeminise.com+personalized-baseball-bedding-full-size-flag-custom-name-d-design-17 | D14: LIMITATION | E14: keyword_evidence_level | F14: SERP_ONLY | G14: Only public SERP comparables are available. | H14: No Search Console, paid keyword volume or internal site search export was supplied. | I14: Keep demand statements qualitative; do not claim volume or ranking potential. | J14: Only public SERP comparables are available. | K14: Additional first-party or paid keyword evidence is attached, or limitation remains documented. | L14: PERSISTS
A15: ISSUE-0014 | B15: jeminise.com+personalized-baseball-bedding-full-size-flag-custom-name-d-design-17 | C15: img_97d31b0c9d6a1a1c | D15: MINOR | E15: alt text | F15: Brown Baseball Glove Bedding with Script Name displayed in a main product mockup | G15: Fresh image file: D:\Shopify_Workspace\jeminise_seo\seo_runs\jeminise.com\20260906_234129\qa\20260907_214100\images\192_01.jpg; source URL: https://cdn.shopify.com/s/files/1/0792/5098/1063/files/aa4923e9f29482ae80e50264a632d44e57fc52a4216de9db06a1575bd5c655c8.jpg?v=1787242324 | H15: Alt text is too generic or describes placement more than visible content. | I15: Rewrite observation/alt from the directly opened image, naming the visible motif and use context. | J15: Fresh image file: D:\Shopify_Workspace\jeminise_seo\seo_runs\jeminise.com\20260906_234129\qa\20260907_214100\images\192_01.jpg; source URL: https://cdn.shopify.com/s/files/1/0792/5098/1063/files/aa4923e9f29482ae80e50264a632d44e57fc52a4216de9db06a1575bd5c655c8.jpg?v=1787242324 | K15: The image row accurately describes the actual media at this gallery position. | L15: RESOLVED
A16: ISSUE-0015 | B16: jeminise.com+personalized-baseball-bedding-full-size-flag-custom-name-d-design-17 | C16: img_abe61f3283666ae8 | D16: MINOR | E16: image observation | F16: Bedding type, feature, lifestyle or material image for brown baseball glove close-up bedding with script name. | G16: Fresh image file: D:\Shopify_Workspace\jeminise_seo\seo_runs\jeminise.com\20260906_234129\qa\20260907_214100\images\192_03.jpg; source URL: https://cdn.shopify.com/s/files/1/0792/5098/1063/files/dd38943d38d35a36c268004706d6c6d16244636812f0a2c4fa90136ea7a93f17.jpg?v=1787242324 | H16: Observation is generic or position-based; rewrite from the actual image content. | I16: Rewrite observation/alt from the directly opened image, naming the visible motif and use context. | J16: Fresh image file: D:\Shopify_Workspace\jeminise_seo\seo_runs\jeminise.com\20260906_234129\qa\20260907_214100\images\192_03.jpg; source URL: https://cdn.shopify.com/s/files/1/0792/5098/1063/files/dd38943d38d35a36c268004706d6c6d16244636812f0a2c4fa90136ea7a93f17.jpg?v=1787242324 | K16: The image row accurately describes the actual media at this gallery position. | L16: RESOLVED
A17: ISSUE-0016 | B17: jeminise.com+personalized-baseball-bedding-full-size-flag-custom-name-d-design-17 | C17: img_3fb5a3a61c6a42d2 | D17: MINOR | E17: image observation | F17: Detail, feature panel or lifestyle image connected to brown baseball glove close-up bedding with script name. | G17: Fresh image file: D:\Shopify_Workspace\jeminise_seo\seo_runs\jeminise.com\20260906_234129\qa\20260907_214100\images\192_04.jpg; source URL: https://cdn.shopify.com/s/files/1/0792/5098/1063/files/8190fe0d621cb3cce926de911d8b1f7f9cdac3656270eea2fa5180515027c9d1.jpg?v=1787242324 | H17: Observation is generic or position-based; rewrite from the actual image content. | I17: Rewrite observation/alt from the directly opened image, naming the visible motif and use context. | J17: Fresh image file: D:\Shopify_Workspace\jeminise_seo\seo_runs\jeminise.com\20260906_234129\qa\20260907_214100\images\192_04.jpg; source URL: https://cdn.shopify.com/s/files/1/0792/5098/1063/files/8190fe0d621cb3cce926de911d8b1f7f9cdac3656270eea2fa5180515027c9d1.jpg?v=1787242324 | K17: The image row accurately describes the actual media at this gallery position. | L17: RESOLVED
A18: ISSUE-0017 | B18: jeminise.com+personalized-baseball-bedding-full-size-flag-custom-name-d-design-17 | C18: img_79c21b4a603fbdba | D18: MINOR | E18: image observation | F18: Easy-care, size guide or product feature image for brown baseball glove close-up bedding with script name. | G18: Fresh image file: D:\Shopify_Workspace\jeminise_seo\seo_runs\jeminise.com\20260906_234129\qa\20260907_214100\images\192_06.jpg; source URL: https://cdn.shopify.com/s/files/1/0792/5098/1063/files/50f96559dd878ae5bbee14ba7a34337ccd740d21a8ffe86a8a1be819656d26c0_138364e3-3d1c-426f-92a3-317dccefdfb3.jpg?v=1787242324 | H18: Observation is generic or position-based; rewrite from the actual image content. | I18: Rewrite observation/alt from the directly opened image, naming the visible motif and use context. | J18: Fresh image file: D:\Shopify_Workspace\jeminise_seo\seo_runs\jeminise.com\20260906_234129\qa\20260907_214100\images\192_06.jpg; source URL: https://cdn.shopify.com/s/files/1/0792/5098/1063/files/50f96559dd878ae5bbee14ba7a34337ccd740d21a8ffe86a8a1be819656d26c0_138364e3-3d1c-426f-92a3-317dccefdfb3.jpg?v=1787242324 | K18: The image row accurately describes the actual media at this gallery position. | L18: RESOLVED
A19: ISSUE-0018 | B19: jeminise.com+personalized-baseball-bedding-full-size-flag-custom-name-d-design-17 | C19: img_4dc687fec74e588b | D19: MINOR | E19: image observation | F19: Additional lifestyle, feature or product detail image showing brown baseball glove close-up bedding with script name. | G19: Fresh image file: D:\Shopify_Workspace\jeminise_seo\seo_runs\jeminise.com\20260906_234129\qa\20260907_214100\images\192_07.jpg; source URL: https://cdn.shopify.com/s/files/1/0792/5098/1063/files/d6b8438a259ef28ba839a68ba108f40464bc9629b0bc2168779fc7776c9cbffa_bc33aecb-4db9-4354-b1fd-308ab7d32cd9.jpg?v=1787242324 | H19: Observation is generic or position-based; rewrite from the actual image content. | I19: Rewrite observation/alt from the directly opened image, naming the visible motif and use context. | J19: Fresh image file: D:\Shopify_Workspace\jeminise_seo\seo_runs\jeminise.com\20260906_234129\qa\20260907_214100\images\192_07.jpg; source URL: https://cdn.shopify.com/s/files/1/0792/5098/1063/files/d6b8438a259ef28ba839a68ba108f40464bc9629b0bc2168779fc7776c9cbffa_bc33aecb-4db9-4354-b1fd-308ab7d32cd9.jpg?v=1787242324 | K19: The image row accurately describes the actual media at this gallery position. | L19: RESOLVED
A20: ISSUE-0019 | B20: jeminise.com+personalized-baseball-bedding-full-size-flag-custom-name-d-design-18 | D20: MAJOR | E20: description_proposed_html | F20: <p>This Jeminise comforter set features black baseball bedding with flame effects, batter artwork, vertical custom name and jersey number, making it suited for baseball rooms, sports gifts, kids bedrooms or personalized fan bedding.</p><h3>Design Details</h3><ul><li>Visible artwork: black baseball bedding with flame effects, batter artwork, vertical custom name and jersey number.</li><li>Source product details include: Brand: Jeminise; Product T… | G20: Draft contains SEO Use / QA approval wording. | H20: Internal workflow language is not publish-ready storefront copy. | I20: Remove internal QA/import block and replace with customer-facing verified copy. | J20: Draft contains SEO Use / QA approval wording. | K20: Description HTML no longer contains SEO Use, QA, approval, import or draft language. | L20: RESOLVED
A21: ISSUE-0020 | B21: jeminise.com+personalized-baseball-bedding-full-size-flag-custom-name-d-design-18 | D21: MAJOR | E21: h1_proposed | G21: The submitted workbook row has no proposed H1. | H21: A publishable SEO title/H1 pair is incomplete when the H1 field is blank. | I21: Write one English H1 that matches the verified product type and visible design; do not copy unsupported claims. | J21: The submitted workbook row has no proposed H1. | K21: Workbook contains a non-empty H1 and it is consistent with title, primary keyword and live product evidence. | L21: NOT_APPLICABLE
A22: ISSUE-0021 | B22: jeminise.com+personalized-baseball-bedding-full-size-flag-custom-name-d-design-18 | D22: MINOR | E22: meta_description_seo | F22: Shop a comforter set featuring black baseball bedding with flame effects, batter artwork, vertical custom name and jersey number. Review size and personalization options before checkout. | G22: Meta description length is 186 characters. | H22: Likely to truncate in search results and repeats review/personality wording in several rows. | I22: Rewrite to roughly 145-155 characters while preserving verified design and product type. | J22: Meta description length is 186 characters. | K22: Length check <=160 characters and no unsupported claim remains. | L22: RESOLVED
A23: ISSUE-0022 | B23: jeminise.com+personalized-baseball-bedding-full-size-flag-custom-name-d-design-18 | D23: LIMITATION | E23: keyword_evidence_level | F23: SERP_ONLY | G23: Only public SERP comparables are available. | H23: No Search Console, paid keyword volume or internal site search export was supplied. | I23: Keep demand statements qualitative; do not claim volume or ranking potential. | J23: Only public SERP comparables are available. | K23: Additional first-party or paid keyword evidence is attached, or limitation remains documented. | L23: PERSISTS
A24: ISSUE-0023 | B24: jeminise.com+personalized-baseball-bedding-full-size-flag-custom-name-d-design-18 | C24: img_74f1b22a91715453 | D24: MINOR | E24: alt text | F24: Flaming Baseball Batter Bedding with Custom Name displayed in a main product mockup | G24: Fresh image file: D:\Shopify_Workspace\jeminise_seo\seo_runs\jeminise.com\20260906_234129\qa\20260907_214100\images\193_01.jpg; source URL: https://cdn.shopify.com/s/files/1/0792/5098/1063/files/0fd40d9335554d99de52ba6149196d8c8282f53db344007b27c3052e0709ff05.jpg?v=1787242319 | H24: Alt text is too generic or describes placement more than visible content. | I24: Rewrite observation/alt from the directly opened image, naming the visible motif and use context. | J24: Fresh image file: D:\Shopify_Workspace\jeminise_seo\seo_runs\jeminise.com\20260906_234129\qa\20260907_214100\images\193_01.jpg; source URL: https://cdn.shopify.com/s/files/1/0792/5098/1063/files/0fd40d9335554d99de52ba6149196d8c8282f53db344007b27c3052e0709ff05.jpg?v=1787242319 | K24: The image row accurately describes the actual media at this gallery position. | L24: RESOLVED
