Workbook

Sheet QA_Summary
A1: metric | B1: value | C1: definition
A2: rubric_version | B2: prompt_qa.md v1.0 / prompt.md v2.4 | C2: Independent r7 QA.
A3: source_workbook | B3: D:\Shopify_Workspace\jeminise_seo\resutls\jeminise.com\20260906_234129\revisions\qa_batch_001_r7\SEO_Product_Optimization_qa_batch_001_r7.xlsx | C3: Frozen r7 workbook; not edited.
A4: source_sha256_at_freeze_and_handoff | B4: A965CFD64371561152CF92B4B3B1CDF449E3F06BC3E0EB4060CAD54DC5AD713B | C4: Must match snapshot.
A5: qa_run_id | B5: 20260908_230550 | C5: Fresh independent QA run.
A6: batch_id | B6: qa_batch_001_r7 | C6: Inventory positions 1–10 only.
A7: products_checked | B7: 10 | C7: Official product-key scope.
A8: images_checked | B8: 65/65 | C8: Direct visual coverage 100%.
A9: batch_final_score | B9: =AVERAGE('QA_Products'!$M$2:$M$11) | C9: Average of all ten complete product scores.
A10: batch_result | B10: =IF(COUNTIF('QA_Products'!$N$2:$N$11,"QA_PASS")=ROWS('QA_Products'!$N$2:$N$11),"PASSED","NOT_PASSED") | C10: Batch passes only when all products pass.
A11: status_counts | B11: ="PASS="&COUNTIF('QA_Products'!$N$2:$N$11,"QA_PASS")&"; REVISE="&COUNTIF('QA_Products'!$N$2:$N$11,"QA_REVISE")&"; FAIL="&COUNTIF('QA_Products'!$N$2:$N$11,"QA_FAIL")&"; INCOMPLETE="&COUNTIF('QA_Products'!$N$2:$N$11,"QA_INCOMPLETE") | C11: Product QA statuses.
A12: issue_counts | B12: {"MAJOR": 4, "LIMITATION": 12, "MINOR": 2} | C12: Open r7 findings.
A13: historical_r4_review | B13: {"RESOLVED": 18, "PERSISTS": 5} | C13: 23 r4 issues rechecked, not scored.
A14: xlsx_status | B14: COMPLETE | C14: Exactly five sheets.

Sheet QA_Products
A1: inventory_position | B1: product_key | C1: title_proposed | D1: url | E1: handle | F1: product_id | G1: revision | H1: page_read | I1: verified_points | J1: assessed_weight | K1: score_lower_bound | L1: score_upper_bound | M1: final_score | N1: qa_status | O1: keyword_evidence_level | P1: images_expected | Q1: images_checked | R1: image_inventory_complete | S1: image_coverage | T1: critical_count | U1: major_count | V1: minor_count | W1: limitation_count | X1: issue_refs | Y1: evidence_refs
A2: 1 | B2: jeminise.com+autumn-cardinals-perched-above-large-sunflowers-quilt-with-cardinal-birds-9a3b408b20-9a3b408b20 | C2: Cardinal Sunflower Autumn Quilt Set | D2: https://jeminise.com/products/autumn-cardinals-perched-above-large-sunflowers-quilt-with-cardinal-birds-9a3b408b20-9a3b408b20 | E2: autumn-cardinals-perched-above-large-sunflowers-quilt-with-cardinal-birds-9a3b408b20-9a3b408b20 | F2: 8834718105799 | G2: r7 | H2: TRUE | I2: =SUMIF('QA_Criteria'!$A$2:$A$111,B2,'QA_Criteria'!$G$2:$G$111) | J2: =SUMIF('QA_Criteria'!$A$2:$A$111,B2,'QA_Criteria'!$H$2:$H$111) | K2: =I2 | L2: =I2+(100-J2) | M2: =IF(AND(J2=100,S2=1,R2=TRUE),I2,"") | N2: =IF(T2>0,"QA_FAIL",IF(M2="","QA_INCOMPLETE",IF(M2<70,"QA_FAIL",IF(OR(M2<85,U2>0),"QA_REVISE","QA_PASS")))) | O2: HYPOTHESIS_ONLY | P2: 5 | Q2: 5 | R2: TRUE | S2: 1 | T2: =COUNTIFS('QA_Issues'!$B$2:$B$19,B2,'QA_Issues'!$E$2:$E$19,"CRITICAL") | U2: =COUNTIFS('QA_Issues'!$B$2:$B$19,B2,'QA_Issues'!$E$2:$E$19,"MAJOR") | V2: =COUNTIFS('QA_Issues'!$B$2:$B$19,B2,'QA_Issues'!$E$2:$E$19,"MINOR") | W2: =COUNTIFS('QA_Issues'!$B$2:$B$19,B2,'QA_Issues'!$E$2:$E$19,"LIMITATION") | X2: ["R7-ISS-001-SIZE", "R7-ISS-001-HYP", "R7-ISS-001-TRACE"] | Y2: ["evidence_batch_001_001", "https://jeminise.com/products/autumn-cardinals-perched-above-large-sunflowers-quilt-with-cardinal-birds-9a3b408b20-9a3b408b20", "serp_r7_001", "customizer_audit.json"]
A3: 2 | B3: jeminise.com+bright-teal-yellow-softball-comforter-set-premium-sports-theme | C3: Personalized Teal Softball Comforter Set | D3: https://jeminise.com/products/bright-teal-yellow-softball-comforter-set-premium-sports-theme | E3: bright-teal-yellow-softball-comforter-set-premium-sports-theme | F3: 8867219865799 | G3: r7 | H3: TRUE | I3: =SUMIF('QA_Criteria'!$A$2:$A$111,B3,'QA_Criteria'!$G$2:$G$111) | J3: =SUMIF('QA_Criteria'!$A$2:$A$111,B3,'QA_Criteria'!$H$2:$H$111) | K3: =I3 | L3: =I3+(100-J3) | M3: =IF(AND(J3=100,S3=1,R3=TRUE),I3,"") | N3: =IF(T3>0,"QA_FAIL",IF(M3="","QA_INCOMPLETE",IF(M3<70,"QA_FAIL",IF(OR(M3<85,U3>0),"QA_REVISE","QA_PASS")))) | O3: SERP_ONLY | P3: 7 | Q3: 7 | R3: TRUE | S3: 1 | T3: =COUNTIFS('QA_Issues'!$B$2:$B$19,B3,'QA_Issues'!$E$2:$E$19,"CRITICAL") | U3: =COUNTIFS('QA_Issues'!$B$2:$B$19,B3,'QA_Issues'!$E$2:$E$19,"MAJOR") | V3: =COUNTIFS('QA_Issues'!$B$2:$B$19,B3,'QA_Issues'!$E$2:$E$19,"MINOR") | W3: =COUNTIFS('QA_Issues'!$B$2:$B$19,B3,'QA_Issues'!$E$2:$E$19,"LIMITATION") | X3: ["R7-ISS-002-ENC", "R7-ISS-002-TRACE"] | Y3: ["evidence_batch_001_002", "https://jeminise.com/products/bright-teal-yellow-softball-comforter-set-premium-sports-theme", "serp_r7_002", "customizer_audit.json"]
A4: 3 | B4: jeminise.com+cardinals-perched-beside-decorated-christmas-tree-patchwork-winter-quilt-7cd7bc46a0-7cd7bc46a0 | C4: Christmas Cardinal Memorial Quilt Set | D4: https://jeminise.com/products/cardinals-perched-beside-decorated-christmas-tree-patchwork-winter-quilt-7cd7bc46a0-7cd7bc46a0 | E4: cardinals-perched-beside-decorated-christmas-tree-patchwork-winter-quilt-7cd7bc46a0-7cd7bc46a0 | F4: 8834714534087 | G4: r7 | H4: TRUE | I4: =SUMIF('QA_Criteria'!$A$2:$A$111,B4,'QA_Criteria'!$G$2:$G$111) | J4: =SUMIF('QA_Criteria'!$A$2:$A$111,B4,'QA_Criteria'!$H$2:$H$111) | K4: =I4 | L4: =I4+(100-J4) | M4: =IF(AND(J4=100,S4=1,R4=TRUE),I4,"") | N4: =IF(T4>0,"QA_FAIL",IF(M4="","QA_INCOMPLETE",IF(M4<70,"QA_FAIL",IF(OR(M4<85,U4>0),"QA_REVISE","QA_PASS")))) | O4: SERP_ONLY | P4: 5 | Q4: 5 | R4: TRUE | S4: 1 | T4: =COUNTIFS('QA_Issues'!$B$2:$B$19,B4,'QA_Issues'!$E$2:$E$19,"CRITICAL") | U4: =COUNTIFS('QA_Issues'!$B$2:$B$19,B4,'QA_Issues'!$E$2:$E$19,"MAJOR") | V4: =COUNTIFS('QA_Issues'!$B$2:$B$19,B4,'QA_Issues'!$E$2:$E$19,"MINOR") | W4: =COUNTIFS('QA_Issues'!$B$2:$B$19,B4,'QA_Issues'!$E$2:$E$19,"LIMITATION") | X4: ["R7-ISS-003-SIZE", "R7-ISS-003-TRACE"] | Y4: ["evidence_batch_001_003", "https://jeminise.com/products/cardinals-perched-beside-decorated-christmas-tree-patchwork-winter-quilt-7cd7bc46a0-7cd7bc46a0", "serp_r7_003", "customizer_audit.json"]
A5: 4 | B5: jeminise.com+cardinals-perched-on-branch-with-roses-patchwork-winter-quilt-21ac904cd7-21ac904cd7 | C5: Cardinal Roses Memorial Quilt Set | D5: https://jeminise.com/products/cardinals-perched-on-branch-with-roses-patchwork-winter-quilt-21ac904cd7-21ac904cd7 | E5: cardinals-perched-on-branch-with-roses-patchwork-winter-quilt-21ac904cd7-21ac904cd7 | F5: 8834733015239 | G5: r7 | H5: TRUE | I5: =SUMIF('QA_Criteria'!$A$2:$A$111,B5,'QA_Criteria'!$G$2:$G$111) | J5: =SUMIF('QA_Criteria'!$A$2:$A$111,B5,'QA_Criteria'!$H$2:$H$111) | K5: =I5 | L5: =I5+(100-J5) | M5: =IF(AND(J5=100,S5=1,R5=TRUE),I5,"") | N5: =IF(T5>0,"QA_FAIL",IF(M5="","QA_INCOMPLETE",IF(M5<70,"QA_FAIL",IF(OR(M5<85,U5>0),"QA_REVISE","QA_PASS")))) | O5: SERP_ONLY | P5: 5 | Q5: 5 | R5: TRUE | S5: 1 | T5: =COUNTIFS('QA_Issues'!$B$2:$B$19,B5,'QA_Issues'!$E$2:$E$19,"CRITICAL") | U5: =COUNTIFS('QA_Issues'!$B$2:$B$19,B5,'QA_Issues'!$E$2:$E$19,"MAJOR") | V5: =COUNTIFS('QA_Issues'!$B$2:$B$19,B5,'QA_Issues'!$E$2:$E$19,"MINOR") | W5: =COUNTIFS('QA_Issues'!$B$2:$B$19,B5,'QA_Issues'!$E$2:$E$19,"LIMITATION") | X5: ["R7-ISS-004-SIZE", "R7-ISS-004-EDITORIAL", "R7-ISS-004-TRACE"] | Y5: ["evidence_batch_001_004", "https://jeminise.com/products/cardinals-perched-on-branch-with-roses-patchwork-winter-quilt-21ac904cd7-21ac904cd7", "serp_r7_004", "customizer_audit.json"]
A6: 5 | B6: jeminise.com+cat-patchwork-quilt-set-animal-pattern-bedding-cat-pattern-quilt-set | C6: Colorful Cat Patchwork Quilt Set | D6: https://jeminise.com/products/cat-patchwork-quilt-set-animal-pattern-bedding-cat-pattern-quilt-set | E6: cat-patchwork-quilt-set-animal-pattern-bedding-cat-pattern-quilt-set | F6: 8867094823111 | G6: r7 | H6: TRUE | I6: =SUMIF('QA_Criteria'!$A$2:$A$111,B6,'QA_Criteria'!$G$2:$G$111) | J6: =SUMIF('QA_Criteria'!$A$2:$A$111,B6,'QA_Criteria'!$H$2:$H$111) | K6: =I6 | L6: =I6+(100-J6) | M6: =IF(AND(J6=100,S6=1,R6=TRUE),I6,"") | N6: =IF(T6>0,"QA_FAIL",IF(M6="","QA_INCOMPLETE",IF(M6<70,"QA_FAIL",IF(OR(M6<85,U6>0),"QA_REVISE","QA_PASS")))) | O6: SERP_ONLY | P6: 7 | Q6: 7 | R6: TRUE | S6: 1 | T6: =COUNTIFS('QA_Issues'!$B$2:$B$19,B6,'QA_Issues'!$E$2:$E$19,"CRITICAL") | U6: =COUNTIFS('QA_Issues'!$B$2:$B$19,B6,'QA_Issues'!$E$2:$E$19,"MAJOR") | V6: =COUNTIFS('QA_Issues'!$B$2:$B$19,B6,'QA_Issues'!$E$2:$E$19,"MINOR") | W6: =COUNTIFS('QA_Issues'!$B$2:$B$19,B6,'QA_Issues'!$E$2:$E$19,"LIMITATION") | X6: ["R7-ISS-005-TRACE"] | Y6: ["evidence_batch_001_005", "https://jeminise.com/products/cat-patchwork-quilt-set-animal-pattern-bedding-cat-pattern-quilt-set", "serp_r7_005", "customizer_audit.json"]
A7: 6 | B7: jeminise.com+cat-quilt-set-cat-patchwork-style-printed-bedding-animal-patchwork | C7: Geometric Cat Patchwork Quilt Set | D7: https://jeminise.com/products/cat-quilt-set-cat-patchwork-style-printed-bedding-animal-patchwork | E7: cat-quilt-set-cat-patchwork-style-printed-bedding-animal-patchwork | F7: 8867094986951 | G7: r7 | H7: TRUE | I7: =SUMIF('QA_Criteria'!$A$2:$A$111,B7,'QA_Criteria'!$G$2:$G$111) | J7: =SUMIF('QA_Criteria'!$A$2:$A$111,B7,'QA_Criteria'!$H$2:$H$111) | K7: =I7 | L7: =I7+(100-J7) | M7: =IF(AND(J7=100,S7=1,R7=TRUE),I7,"") | N7: =IF(T7>0,"QA_FAIL",IF(M7="","QA_INCOMPLETE",IF(M7<70,"QA_FAIL",IF(OR(M7<85,U7>0),"QA_REVISE","QA_PASS")))) | O7: HYPOTHESIS_ONLY | P7: 7 | Q7: 7 | R7: TRUE | S7: 1 | T7: =COUNTIFS('QA_Issues'!$B$2:$B$19,B7,'QA_Issues'!$E$2:$E$19,"CRITICAL") | U7: =COUNTIFS('QA_Issues'!$B$2:$B$19,B7,'QA_Issues'!$E$2:$E$19,"MAJOR") | V7: =COUNTIFS('QA_Issues'!$B$2:$B$19,B7,'QA_Issues'!$E$2:$E$19,"MINOR") | W7: =COUNTIFS('QA_Issues'!$B$2:$B$19,B7,'QA_Issues'!$E$2:$E$19,"LIMITATION") | X7: ["R7-ISS-006-HYP", "R7-ISS-006-TRACE"] | Y7: ["evidence_batch_001_006", "https://jeminise.com/products/cat-quilt-set-cat-patchwork-style-printed-bedding-animal-patchwork", "serp_r7_006", "customizer_audit.json"]
A8: 7 | B8: jeminise.com+celtic-and-fantasy-quilt-set-with-twisting-tree-trunk-and-exposed-roots-c7b1460bad-c7b1460bad | C8: Celtic Fantasy Tree Quilt Set | D8: https://jeminise.com/products/celtic-and-fantasy-quilt-set-with-twisting-tree-trunk-and-exposed-roots-c7b1460bad-c7b1460bad | E8: celtic-and-fantasy-quilt-set-with-twisting-tree-trunk-and-exposed-roots-c7b1460bad-c7b1460bad | F8: 8833350467783 | G8: r7 | H8: TRUE | I8: =SUMIF('QA_Criteria'!$A$2:$A$111,B8,'QA_Criteria'!$G$2:$G$111) | J8: =SUMIF('QA_Criteria'!$A$2:$A$111,B8,'QA_Criteria'!$H$2:$H$111) | K8: =I8 | L8: =I8+(100-J8) | M8: =IF(AND(J8=100,S8=1,R8=TRUE),I8,"") | N8: =IF(T8>0,"QA_FAIL",IF(M8="","QA_INCOMPLETE",IF(M8<70,"QA_FAIL",IF(OR(M8<85,U8>0),"QA_REVISE","QA_PASS")))) | O8: SERP_ONLY | P8: 7 | Q8: 7 | R8: TRUE | S8: 1 | T8: =COUNTIFS('QA_Issues'!$B$2:$B$19,B8,'QA_Issues'!$E$2:$E$19,"CRITICAL") | U8: =COUNTIFS('QA_Issues'!$B$2:$B$19,B8,'QA_Issues'!$E$2:$E$19,"MAJOR") | V8: =COUNTIFS('QA_Issues'!$B$2:$B$19,B8,'QA_Issues'!$E$2:$E$19,"MINOR") | W8: =COUNTIFS('QA_Issues'!$B$2:$B$19,B8,'QA_Issues'!$E$2:$E$19,"LIMITATION") | X8: ["R7-ISS-007-TRACE"] | Y8: ["evidence_batch_001_007", "https://jeminise.com/products/celtic-and-fantasy-quilt-set-with-twisting-tree-trunk-and-exposed-roots-c7b1460bad-c7b1460bad", "serp_r7_007", "customizer_audit.json"]
A9: 8 | B9: jeminise.com+celtic-mythology-tree-of-life-quilt-set-with-celtic-knotwork-border-12786aba7e-12786aba7e | C9: Celtic Tree of Life Quilt Set | D9: https://jeminise.com/products/celtic-mythology-tree-of-life-quilt-set-with-celtic-knotwork-border-12786aba7e-12786aba7e | E9: celtic-mythology-tree-of-life-quilt-set-with-celtic-knotwork-border-12786aba7e-12786aba7e | F9: 8833347518663 | G9: r7 | H9: TRUE | I9: =SUMIF('QA_Criteria'!$A$2:$A$111,B9,'QA_Criteria'!$G$2:$G$111) | J9: =SUMIF('QA_Criteria'!$A$2:$A$111,B9,'QA_Criteria'!$H$2:$H$111) | K9: =I9 | L9: =I9+(100-J9) | M9: =IF(AND(J9=100,S9=1,R9=TRUE),I9,"") | N9: =IF(T9>0,"QA_FAIL",IF(M9="","QA_INCOMPLETE",IF(M9<70,"QA_FAIL",IF(OR(M9<85,U9>0),"QA_REVISE","QA_PASS")))) | O9: SERP_ONLY | P9: 7 | Q9: 7 | R9: TRUE | S9: 1 | T9: =COUNTIFS('QA_Issues'!$B$2:$B$19,B9,'QA_Issues'!$E$2:$E$19,"CRITICAL") | U9: =COUNTIFS('QA_Issues'!$B$2:$B$19,B9,'QA_Issues'!$E$2:$E$19,"MAJOR") | V9: =COUNTIFS('QA_Issues'!$B$2:$B$19,B9,'QA_Issues'!$E$2:$E$19,"MINOR") | W9: =COUNTIFS('QA_Issues'!$B$2:$B$19,B9,'QA_Issues'!$E$2:$E$19,"LIMITATION") | X9: ["R7-ISS-008-TRACE"] | Y9: ["evidence_batch_001_008", "https://jeminise.com/products/celtic-mythology-tree-of-life-quilt-set-with-celtic-knotwork-border-12786aba7e-12786aba7e", "serp_r7_008", "customizer_audit.json"]
A10: 9 | B10: jeminise.com+chicken-pattern-quilt-set-animal-patchwork-farmhouse-quilt-set | C10: Farmhouse Chicken Patchwork Quilt Set | D10: https://jeminise.com/products/chicken-pattern-quilt-set-animal-patchwork-farmhouse-quilt-set | E10: chicken-pattern-quilt-set-animal-patchwork-farmhouse-quilt-set | F10: 8867095019719 | G10: r7 | H10: TRUE | I10: =SUMIF('QA_Criteria'!$A$2:$A$111,B10,'QA_Criteria'!$G$2:$G$111) | J10: =SUMIF('QA_Criteria'!$A$2:$A$111,B10,'QA_Criteria'!$H$2:$H$111) | K10: =I10 | L10: =I10+(100-J10) | M10: =IF(AND(J10=100,S10=1,R10=TRUE),I10,"") | N10: =IF(T10>0,"QA_FAIL",IF(M10="","QA_INCOMPLETE",IF(M10<70,"QA_FAIL",IF(OR(M10<85,U10>0),"QA_REVISE","QA_PASS")))) | O10: SERP_ONLY | P10: 7 | Q10: 7 | R10: TRUE | S10: 1 | T10: =COUNTIFS('QA_Issues'!$B$2:$B$19,B10,'QA_Issues'!$E$2:$E$19,"CRITICAL") | U10: =COUNTIFS('QA_Issues'!$B$2:$B$19,B10,'QA_Issues'!$E$2:$E$19,"MAJOR") | V10: =COUNTIFS('QA_Issues'!$B$2:$B$19,B10,'QA_Issues'!$E$2:$E$19,"MINOR") | W10: =COUNTIFS('QA_Issues'!$B$2:$B$19,B10,'QA_Issues'!$E$2:$E$19,"LIMITATION") | X10: ["R7-ISS-009-TRACE"] | Y10: ["evidence_batch_001_009", "https://jeminise.com/products/chicken-pattern-quilt-set-animal-patchwork-farmhouse-quilt-set", "serp_r7_009", "customizer_audit.json"]
A11: 10 | B11: jeminise.com+christian-bedding-set-inspirational-bible-verse-comforte-design-01 | C11: Personalized God Says I Am Christian Bedding Set | D11: https://jeminise.com/products/christian-bedding-set-inspirational-bible-verse-comforte-design-01 | E11: christian-bedding-set-inspirational-bible-verse-comforte-design-01 | F11: 8867138240711 | G11: r7 | H11: TRUE | I11: =SUMIF('QA_Criteria'!$A$2:$A$111,B11,'QA_Criteria'!$G$2:$G$111) | J11: =SUMIF('QA_Criteria'!$A$2:$A$111,B11,'QA_Criteria'!$H$2:$H$111) | K11: =I11 | L11: =I11+(100-J11) | M11: =IF(AND(J11=100,S11=1,R11=TRUE),I11,"") | N11: =IF(T11>0,"QA_FAIL",IF(M11="","QA_INCOMPLETE",IF(M11<70,"QA_FAIL",IF(OR(M11<85,U11>0),"QA_REVISE","QA_PASS")))) | O11: SERP_ONLY | P11: 8 | Q11: 8 | R11: TRUE | S11: 1 | T11: =COUNTIFS('QA_Issues'!$B$2:$B$19,B11,'QA_Issues'!$E$2:$E$19,"CRITICAL") | U11: =COUNTIFS('QA_Issues'!$B$2:$B$19,B11,'QA_Issues'!$E$2:$E$19,"MAJOR") | V11: =COUNTIFS('QA_Issues'!$B$2:$B$19,B11,'QA_Issues'!$E$2:$E$19,"MINOR") | W11: =COUNTIFS('QA_Issues'!$B$2:$B$19,B11,'QA_Issues'!$E$2:$E$19,"LIMITATION") | X11: ["R7-ISS-010-ENC", "R7-ISS-010-TRACE"] | Y11: ["evidence_batch_001_010", "https://jeminise.com/products/christian-bedding-set-inspirational-bible-verse-comforte-design-01", "serp_r7_010", "customizer_audit.json"]

Sheet QA_Criteria
A1: product_key | B1: criterion_id | C1: criterion_name | D1: weight | E1: assessment | F1: rating | G1: earned_points | H1: assessed_weight | I1: reason | J1: evidence_refs | K1: issue_refs | L1: revision
A2: jeminise.com+autumn-cardinals-perched-above-large-sunflowers-quilt-with-cardinal-birds-9a3b408b20-9a3b408b20 | B2: P1 | C2: Identity and source integrity | D2: 15 | E2: FULL | F2: =IF(B2="I1",AVERAGEIF('QA_Images'!$A$2:$A$66,A2,'QA_Images'!$T$2:$T$66)/100,IF(E2="FULL",1,IF(E2="PARTIAL",0.5,IF(E2="FAIL",0,"")))) | G2: =IF(F2="",0,D2*F2) | H2: =IF(B2="I1",20*AVERAGEIF('QA_Images'!$A$2:$A$66,A2,'QA_Images'!$U$2:$U$66)/100,IF(E2="NOT_CHECKED",0,D2)) | I2: Product key, handle, ID, canonical, H1 and gallery identity match the live page/product JSON. | J2: ["evidence_batch_001_001", "https://jeminise.com/products/autumn-cardinals-perched-above-large-sunflowers-quilt-with-cardinal-birds-9a3b408b20-9a3b408b20", "serp_r7_001", "live_source_comparison.json", "visual_observations.json"] | K2: [] | L2: r7
A3: jeminise.com+autumn-cardinals-perched-above-large-sunflowers-quilt-with-cardinal-birds-9a3b408b20-9a3b408b20 | B3: P2 | C3: Product facts and purchase options | D3: 10 | E3: FULL | F3: =IF(B3="I1",AVERAGEIF('QA_Images'!$A$2:$A$66,A3,'QA_Images'!$T$2:$T$66)/100,IF(E3="FULL",1,IF(E3="PARTIAL",0.5,IF(E3="FAIL",0,"")))) | G3: =IF(F3="",0,D3*F3) | H3: =IF(B3="I1",20*AVERAGEIF('QA_Images'!$A$2:$A$66,A3,'QA_Images'!$U$2:$U$66)/100,IF(E3="NOT_CHECKED",0,D3)) | I3: Live variants, selectable sizes/pillowcase rules, gallery facts and product type were independently re-read. | J3: ["evidence_batch_001_001", "https://jeminise.com/products/autumn-cardinals-perched-above-large-sunflowers-quilt-with-cardinal-birds-9a3b408b20-9a3b408b20", "serp_r7_001", "live_source_comparison.json", "visual_observations.json"] | K3: [] | L3: r7
A4: jeminise.com+autumn-cardinals-perched-above-large-sunflowers-quilt-with-cardinal-birds-9a3b408b20-9a3b408b20 | B4: K1 | C4: Primary keyword evidence | D4: 10 | E4: PARTIAL | F4: =IF(B4="I1",AVERAGEIF('QA_Images'!$A$2:$A$66,A4,'QA_Images'!$T$2:$T$66)/100,IF(E4="FULL",1,IF(E4="PARTIAL",0.5,IF(E4="FAIL",0,"")))) | G4: =IF(F4="",0,D4*F4) | H4: =IF(B4="I1",20*AVERAGEIF('QA_Images'!$A$2:$A$66,A4,'QA_Images'!$U$2:$U$66)/100,IF(E4="NOT_CHECKED",0,D4)) | I4: Fresh US SERP supports related finished bedding intent, but the exact long-tail query remains niche/hypothesis-led. | J4: ["evidence_batch_001_001", "https://jeminise.com/products/autumn-cardinals-perched-above-large-sunflowers-quilt-with-cardinal-birds-9a3b408b20-9a3b408b20", "serp_r7_001", "live_source_comparison.json", "visual_observations.json"] | K4: ["R7-ISS-001-HYP"] | L4: r7
A5: jeminise.com+autumn-cardinals-perched-above-large-sunflowers-quilt-with-cardinal-birds-9a3b408b20-9a3b408b20 | B5: K2 | C5: SERP intent and comparator | D5: 5 | E5: FULL | F5: =IF(B5="I1",AVERAGEIF('QA_Images'!$A$2:$A$66,A5,'QA_Images'!$T$2:$T$66)/100,IF(E5="FULL",1,IF(E5="PARTIAL",0.5,IF(E5="FAIL",0,"")))) | G5: =IF(F5="",0,D5*F5) | H5: =IF(B5="I1",20*AVERAGEIF('QA_Images'!$A$2:$A$66,A5,'QA_Images'!$U$2:$U$66)/100,IF(E5="NOT_CHECKED",0,D5)) | I5: Primary and nearest comparator show commercial finished-product intent. | J5: ["evidence_batch_001_001", "https://jeminise.com/products/autumn-cardinals-perched-above-large-sunflowers-quilt-with-cardinal-birds-9a3b408b20-9a3b408b20", "serp_r7_001", "live_source_comparison.json", "visual_observations.json"] | K5: ["R7-ISS-001-HYP"] | L5: r7
A6: jeminise.com+autumn-cardinals-perched-above-large-sunflowers-quilt-with-cardinal-birds-9a3b408b20-9a3b408b20 | B6: K3 | C6: Cannibalization differentiation | D6: 5 | E6: FULL | F6: =IF(B6="I1",AVERAGEIF('QA_Images'!$A$2:$A$66,A6,'QA_Images'!$T$2:$T$66)/100,IF(E6="FULL",1,IF(E6="PARTIAL",0.5,IF(E6="FAIL",0,"")))) | G6: =IF(F6="",0,D6*F6) | H6: =IF(B6="I1",20*AVERAGEIF('QA_Images'!$A$2:$A$66,A6,'QA_Images'!$U$2:$U$66)/100,IF(E6="NOT_CHECKED",0,D6)) | I6: R7 keyword rows document a unique motif, collection/internal-link role and explicit sibling exclusions. | J6: ["evidence_batch_001_001", "https://jeminise.com/products/autumn-cardinals-perched-above-large-sunflowers-quilt-with-cardinal-birds-9a3b408b20-9a3b408b20", "serp_r7_001", "live_source_comparison.json", "visual_observations.json"] | K6: [] | L6: r7
A7: jeminise.com+autumn-cardinals-perched-above-large-sunflowers-quilt-with-cardinal-birds-9a3b408b20-9a3b408b20 | B7: T1 | C7: SEO title | D7: 10 | E7: FULL | F7: =IF(B7="I1",AVERAGEIF('QA_Images'!$A$2:$A$66,A7,'QA_Images'!$T$2:$T$66)/100,IF(E7="FULL",1,IF(E7="PARTIAL",0.5,IF(E7="FAIL",0,"")))) | G7: =IF(F7="",0,D7*F7) | H7: =IF(B7="I1",20*AVERAGEIF('QA_Images'!$A$2:$A$66,A7,'QA_Images'!$U$2:$U$66)/100,IF(E7="NOT_CHECKED",0,D7)) | I7: SEO title is concise, clean, product-specific and aligned with verified motif/product type. | J7: ["evidence_batch_001_001", "https://jeminise.com/products/autumn-cardinals-perched-above-large-sunflowers-quilt-with-cardinal-birds-9a3b408b20-9a3b408b20", "serp_r7_001", "live_source_comparison.json", "visual_observations.json"] | K7: [] | L7: r7
A8: jeminise.com+autumn-cardinals-perched-above-large-sunflowers-quilt-with-cardinal-birds-9a3b408b20-9a3b408b20 | B8: T2 | C8: Proposed product title/H1 | D8: 5 | E8: FULL | F8: =IF(B8="I1",AVERAGEIF('QA_Images'!$A$2:$A$66,A8,'QA_Images'!$T$2:$T$66)/100,IF(E8="FULL",1,IF(E8="PARTIAL",0.5,IF(E8="FAIL",0,"")))) | G8: =IF(F8="",0,D8*F8) | H8: =IF(B8="I1",20*AVERAGEIF('QA_Images'!$A$2:$A$66,A8,'QA_Images'!$U$2:$U$66)/100,IF(E8="NOT_CHECKED",0,D8)) | I8: Proposed product title/H1 is concise, clean, product-specific and aligned with verified motif/product type. | J8: ["evidence_batch_001_001", "https://jeminise.com/products/autumn-cardinals-perched-above-large-sunflowers-quilt-with-cardinal-birds-9a3b408b20-9a3b408b20", "serp_r7_001", "live_source_comparison.json", "visual_observations.json"] | K8: [] | L8: r7
A9: jeminise.com+autumn-cardinals-perched-above-large-sunflowers-quilt-with-cardinal-birds-9a3b408b20-9a3b408b20 | B9: D1 | C9: Meta description | D9: 5 | E9: FULL | F9: =IF(B9="I1",AVERAGEIF('QA_Images'!$A$2:$A$66,A9,'QA_Images'!$T$2:$T$66)/100,IF(E9="FULL",1,IF(E9="PARTIAL",0.5,IF(E9="FAIL",0,"")))) | G9: =IF(F9="",0,D9*F9) | H9: =IF(B9="I1",20*AVERAGEIF('QA_Images'!$A$2:$A$66,A9,'QA_Images'!$U$2:$U$66)/100,IF(E9="NOT_CHECKED",0,D9)) | I9: Meta description is complete, readable and evidence-led; 145–165 characters is treated only as editorial guidance. | J9: ["evidence_batch_001_001", "https://jeminise.com/products/autumn-cardinals-perched-above-large-sunflowers-quilt-with-cardinal-birds-9a3b408b20-9a3b408b20", "serp_r7_001", "live_source_comparison.json", "visual_observations.json"] | K9: [] | L9: r7
A10: jeminise.com+autumn-cardinals-perched-above-large-sunflowers-quilt-with-cardinal-birds-9a3b408b20-9a3b408b20 | B10: D2 | C10: Description HTML | D10: 10 | E10: PARTIAL | F10: =IF(B10="I1",AVERAGEIF('QA_Images'!$A$2:$A$66,A10,'QA_Images'!$T$2:$T$66)/100,IF(E10="FULL",1,IF(E10="PARTIAL",0.5,IF(E10="FAIL",0,"")))) | G10: =IF(F10="",0,D10*F10) | H10: =IF(B10="I1",20*AVERAGEIF('QA_Images'!$A$2:$A$66,A10,'QA_Images'!$U$2:$U$66)/100,IF(E10="NOT_CHECKED",0,D10)) | I10: Most copy is useful, but live size values conflict with r7 and/or an internal SEO-intent sentence remains. | J10: ["evidence_batch_001_001", "https://jeminise.com/products/autumn-cardinals-perched-above-large-sunflowers-quilt-with-cardinal-birds-9a3b408b20-9a3b408b20", "serp_r7_001", "live_source_comparison.json", "visual_observations.json"] | K10: ["R7-ISS-001-SIZE"] | L10: r7
A11: jeminise.com+autumn-cardinals-perched-above-large-sunflowers-quilt-with-cardinal-birds-9a3b408b20-9a3b408b20 | B11: I1 | C11: Image/alt quality | D11: 20 | E11: DERIVED_FROM_IMAGES | F11: =IF(B11="I1",AVERAGEIF('QA_Images'!$A$2:$A$66,A11,'QA_Images'!$T$2:$T$66)/100,IF(E11="FULL",1,IF(E11="PARTIAL",0.5,IF(E11="FAIL",0,"")))) | G11: =IF(F11="",0,D11*F11) | H11: =IF(B11="I1",20*AVERAGEIF('QA_Images'!$A$2:$A$66,A11,'QA_Images'!$U$2:$U$66)/100,IF(E11="NOT_CHECKED",0,D11)) | I11: Derived from 5 freshly opened images; every observation and SET alt matches the exact scene/panel. | J11: ["evidence_batch_001_001", "https://jeminise.com/products/autumn-cardinals-perched-above-large-sunflowers-quilt-with-cardinal-birds-9a3b408b20-9a3b408b20", "serp_r7_001", "live_source_comparison.json", "visual_observations.json"] | K11: [] | L11: r7
A12: jeminise.com+autumn-cardinals-perched-above-large-sunflowers-quilt-with-cardinal-birds-9a3b408b20-9a3b408b20 | B12: E1 | C12: Evidence traceability | D12: 5 | E12: PARTIAL | F12: =IF(B12="I1",AVERAGEIF('QA_Images'!$A$2:$A$66,A12,'QA_Images'!$T$2:$T$66)/100,IF(E12="FULL",1,IF(E12="PARTIAL",0.5,IF(E12="FAIL",0,"")))) | G12: =IF(F12="",0,D12*F12) | H12: =IF(B12="I1",20*AVERAGEIF('QA_Images'!$A$2:$A$66,A12,'QA_Images'!$U$2:$U$66)/100,IF(E12="NOT_CHECKED",0,D12)) | I12: File/hash and evidence refs are clear, but row-level revision metadata and revision_summary still identify r5 inside the r7 package. | J12: ["evidence_batch_001_001", "https://jeminise.com/products/autumn-cardinals-perched-above-large-sunflowers-quilt-with-cardinal-birds-9a3b408b20-9a3b408b20", "serp_r7_001", "live_source_comparison.json", "visual_observations.json"] | K12: ["R7-ISS-001-TRACE"] | L12: r7
A13: jeminise.com+bright-teal-yellow-softball-comforter-set-premium-sports-theme | B13: P1 | C13: Identity and source integrity | D13: 15 | E13: FULL | F13: =IF(B13="I1",AVERAGEIF('QA_Images'!$A$2:$A$66,A13,'QA_Images'!$T$2:$T$66)/100,IF(E13="FULL",1,IF(E13="PARTIAL",0.5,IF(E13="FAIL",0,"")))) | G13: =IF(F13="",0,D13*F13) | H13: =IF(B13="I1",20*AVERAGEIF('QA_Images'!$A$2:$A$66,A13,'QA_Images'!$U$2:$U$66)/100,IF(E13="NOT_CHECKED",0,D13)) | I13: Product key, handle, ID, canonical, H1 and gallery identity match the live page/product JSON. | J13: ["evidence_batch_001_002", "https://jeminise.com/products/bright-teal-yellow-softball-comforter-set-premium-sports-theme", "serp_r7_002", "live_source_comparison.json", "visual_observations.json"] | K13: [] | L13: r7
... A111: jeminise.com+christian-bedding-set-inspirational-bible-verse-comforte-design-01 | B111: E1 | C111: Evidence traceability | D111: 5 | E111: PARTIAL | F111: =IF(B111="I1",AVERAGEIF('QA_Images'!$A$2:$A$66,A111,'QA_Images'!$T$2:$T$66)/100,IF(E111="FULL",1,IF(E111="PARTIAL",0.5,IF(E111="FAIL",0,"")))) | G111: =IF(F111="",0,D111*F111) | H111: =IF(B111="I1",20*AVERAGEIF('QA_Images'!$A$2:$A$66,A111,'QA_Images'!$U$2:$U$66)/100,IF(E111="NOT_CHECKED",0,D111)) | I111: File/hash and evidence refs are clear, but row-level revision metadata and revision_summary still identify r5 inside the r7 package. | J111: ["evidence_batch_001_010", "https://jeminise.com/products/christian-bedding-set-inspirational-bible-verse-comforte-design-01", "serp_r7_010", "live_source_comparison.json", "visual_observations.json"] | K111: ["R7-ISS-010-TRACE"] | L111: r7

Sheet QA_Images
A1: product_key | B1: qa_image_key | C1: image_url_source | D1: image_url_workbook | E1: media_id | F1: workbook_image_id | G1: variant | H1: image_location | I1: check_method | J1: checked_at | K1: qa_observation | L1: submitted_observation | M1: storefront_alt_observed | N1: alt_action | O1: alt_effective | P1: IM1 | Q1: IM2 | R1: IM3 | S1: IM4 | T1: image_verified_points | U1: image_assessed_weight | V1: image_final_score | W1: image_score_lower_bound | X1: image_score_upper_bound | Y1: issue_refs | Z1: evidence_refs
A2: jeminise.com+autumn-cardinals-perched-above-large-sunflowers-quilt-with-cardinal-birds-9a3b408b20-9a3b408b20 | B2: jeminise.com+autumn-cardinals-perched-above-large-sunflowers-quilt-with-cardinal-birds-9a3b408b20-9a3b408b20|47540016382151|GALLERY|1 | C2: https://cdn.shopify.com/s/files/1/0792/5098/1063/files/0754b2731a7ffd916d0ef8b214706e796d780fbd4ba38c8f47f27b6dcfbf352e.jpg?v=1785099190 | D2: https://cdn.shopify.com/s/files/1/0792/5098/1063/files/0754b2731a7ffd916d0ef8b214706e796d780fbd4ba38c8f47f27b6dcfbf352e.jpg?v=1785099190 | E2: 47540016382151 | F2: 47540016382151 | H2: GALLERY | I2: DIRECT_ORIGINAL_IMAGE_REQA_R7 | J2: 2026-09-08T23:27:07.723474+07:00 | K2: Red cardinals perched above large yellow sunflowers on an autumn quilt bed mockup with matching shams. | L2: Red cardinals perched above large yellow sunflowers on an autumn quilt bed mockup with matching shams. | M2: Autumn Cardinals Perched Above Large Sunflowers Quilt with Cardinal Birds | N2: SET | O2: Cardinal sunflower autumn quilt set on bed | P2: FULL | Q2: FULL | R2: FULL | S2: FULL | T2: =IF(P2="FULL",40,IF(P2="PARTIAL",40/2,0))+IF(Q2="FULL",30,IF(Q2="PARTIAL",30/2,0))+IF(R2="FULL",20,IF(R2="PARTIAL",20/2,0))+IF(S2="FULL",10,IF(S2="PARTIAL",10/2,0)) | U2: =IF(P2="NOT_CHECKED",0,40)+IF(Q2="NOT_CHECKED",0,30)+IF(R2="NOT_CHECKED",0,20)+IF(S2="NOT_CHECKED",0,10) | V2: =IF(U2=100,T2,"") | W2: =T2 | X2: =T2+(100-U2) | Y2: [] | Z2: ["D:\\Shopify_Workspace\\jeminise_seo\\seo_runs\\jeminise.com\\20260906_234129\\qa\\20260908_230550\\images\\001_01_47540016382151.jpg", "https://cdn.shopify.com/s/files/1/0792/5098/1063/files/0754b2731a7ffd916d0ef8b214706e796d780fbd4ba38c8f47f27b6dcfbf352e.jpg?v=1785099190", "seo_runs\\jeminise.com\\20260906_234129\\evidence\\images\\1_autumn-cardinals-perched-above-large-sunflowers-quilt-with-cardinal-birds-9a3b408b20-9a3b408b20\\image_01_47540016382151.jpg; seo_runs\\jeminise.com\\20260906_234129\\evidence\\contact_sheets\\1_autumn-cardinals-perched-above-large-sunflowers-quilt-with-cardinal-birds-9a3b408b20-9a3b408b20.jpg"]
A3: jeminise.com+autumn-cardinals-perched-above-large-sunflowers-quilt-with-cardinal-birds-9a3b408b20-9a3b408b20 | B3: jeminise.com+autumn-cardinals-perched-above-large-sunflowers-quilt-with-cardinal-birds-9a3b408b20-9a3b408b20|47540016414919|GALLERY|2 | C3: https://cdn.shopify.com/s/files/1/0792/5098/1063/files/a10aa0018e665e644a60b7c4aea8b5e152ec768ebb35af1090452cddbc9e9828.jpg?v=1785099190 | D3: https://cdn.shopify.com/s/files/1/0792/5098/1063/files/a10aa0018e665e644a60b7c4aea8b5e152ec768ebb35af1090452cddbc9e9828.jpg?v=1785099190 | E3: 47540016414919 | F3: 47540016414919 | H3: GALLERY | I3: DIRECT_ORIGINAL_IMAGE_REQA_R7 | J3: 2026-09-08T23:27:07.723474+07:00 | K3: Close-up of a red cardinal, sunflower petals, orange leaves and visible quilt stitching. | L3: Close-up of a red cardinal, sunflower petals, orange leaves and visible quilt stitching. | M3: Autumn Cardinals Perched Above Large Sunflowers Quilt with Cardinal Birds | N3: SET | O3: Close-up of cardinal sunflower quilt stitching | P3: FULL | Q3: FULL | R3: FULL | S3: FULL | T3: =IF(P3="FULL",40,IF(P3="PARTIAL",40/2,0))+IF(Q3="FULL",30,IF(Q3="PARTIAL",30/2,0))+IF(R3="FULL",20,IF(R3="PARTIAL",20/2,0))+IF(S3="FULL",10,IF(S3="PARTIAL",10/2,0)) | U3: =IF(P3="NOT_CHECKED",0,40)+IF(Q3="NOT_CHECKED",0,30)+IF(R3="NOT_CHECKED",0,20)+IF(S3="NOT_CHECKED",0,10) | V3: =IF(U3=100,T3,"") | W3: =T3 | X3: =T3+(100-U3) | Y3: [] | Z3: ["D:\\Shopify_Workspace\\jeminise_seo\\seo_runs\\jeminise.com\\20260906_234129\\qa\\20260908_230550\\images\\001_02_47540016414919.jpg", "https://cdn.shopify.com/s/files/1/0792/5098/1063/files/a10aa0018e665e644a60b7c4aea8b5e152ec768ebb35af1090452cddbc9e9828.jpg?v=1785099190", "seo_runs\\jeminise.com\\20260906_234129\\evidence\\images\\1_autumn-cardinals-perched-above-large-sunflowers-quilt-with-cardinal-birds-9a3b408b20-9a3b408b20\\image_02_47540016414919.jpg; seo_runs\\jeminise.com\\20260906_234129\\evidence\\contact_sheets\\1_autumn-cardinals-perched-above-large-sunflowers-quilt-with-cardinal-birds-9a3b408b20-9a3b408b20.jpg"]
A4: jeminise.com+autumn-cardinals-perched-above-large-sunflowers-quilt-with-cardinal-birds-9a3b408b20-9a3b408b20 | B4: jeminise.com+autumn-cardinals-perched-above-large-sunflowers-quilt-with-cardinal-birds-9a3b408b20-9a3b408b20|47540016447687|GALLERY|3 | C4: https://cdn.shopify.com/s/files/1/0792/5098/1063/files/c50488380d22611c83d218b77be9cfcf5799df4d9903913c09a1798712931b22.jpg?v=1785099190 | D4: https://cdn.shopify.com/s/files/1/0792/5098/1063/files/c50488380d22611c83d218b77be9cfcf5799df4d9903913c09a1798712931b22.jpg?v=1785099190 | E4: 47540016447687 | F4: 47540016447687 | H4: GALLERY | I4: DIRECT_ORIGINAL_IMAGE_REQA_R7 | J4: 2026-09-08T23:27:07.723474+07:00 | K4: Matching pillow sham with two cardinals, sunflower artwork and autumn leaf accents. | L4: Matching pillow sham with two cardinals, sunflower artwork and autumn leaf accents. | M4: Autumn Cardinals Perched Above Large Sunflowers Quilt with Cardinal Birds | N4: SET | O4: Cardinal sunflower pillow sham with autumn leaves | P4: FULL | Q4: FULL | R4: FULL | S4: FULL | T4: =IF(P4="FULL",40,IF(P4="PARTIAL",40/2,0))+IF(Q4="FULL",30,IF(Q4="PARTIAL",30/2,0))+IF(R4="FULL",20,IF(R4="PARTIAL",20/2,0))+IF(S4="FULL",10,IF(S4="PARTIAL",10/2,0)) | U4: =IF(P4="NOT_CHECKED",0,40)+IF(Q4="NOT_CHECKED",0,30)+IF(R4="NOT_CHECKED",0,20)+IF(S4="NOT_CHECKED",0,10) | V4: =IF(U4=100,T4,"") | W4: =T4 | X4: =T4+(100-U4) | Y4: [] | Z4: ["D:\\Shopify_Workspace\\jeminise_seo\\seo_runs\\jeminise.com\\20260906_234129\\qa\\20260908_230550\\images\\001_03_47540016447687.jpg", "https://cdn.shopify.com/s/files/1/0792/5098/1063/files/c50488380d22611c83d218b77be9cfcf5799df4d9903913c09a1798712931b22.jpg?v=1785099190", "seo_runs\\jeminise.com\\20260906_234129\\evidence\\images\\1_autumn-cardinals-perched-above-large-sunflowers-quilt-with-cardinal-birds-9a3b408b20-9a3b408b20\\image_03_47540016447687.jpg; seo_runs\\jeminise.com\\20260906_234129\\evidence\\contact_sheets\\1_autumn-cardinals-perched-above-large-sunflowers-quilt-with-cardinal-birds-9a3b408b20-9a3b408b20.jpg"]
A5: jeminise.com+autumn-cardinals-perched-above-large-sunflowers-quilt-with-cardinal-birds-9a3b408b20-9a3b408b20 | B5: jeminise.com+autumn-cardinals-perched-above-large-sunflowers-quilt-with-cardinal-birds-9a3b408b20-9a3b408b20|47540016480455|GALLERY|4 | C5: https://cdn.shopify.com/s/files/1/0792/5098/1063/files/455c5869333cc7654f6c30f3d09716ec1513311734a21a6aa82bf5fe0767ac69.jpg?v=1785099191 | D5: https://cdn.shopify.com/s/files/1/0792/5098/1063/files/455c5869333cc7654f6c30f3d09716ec1513311734a21a6aa82bf5fe0767ac69.jpg?v=1785099191 | E5: 47540016480455 | F5: 47540016480455 | H5: GALLERY | I5: DIRECT_ORIGINAL_IMAGE_REQA_R7 | J5: 2026-09-08T23:27:07.723474+07:00 | K5: Bedroom scene showing the cardinal sunflower quilt styled across a bed with coordinated pillows. | L5: Bedroom scene showing the cardinal sunflower quilt styled across a bed with coordinated pillows. | M5: Autumn Cardinals Perched Above Large Sunflowers Quilt with Cardinal Birds | N5: SET | O5: Cardinal sunflower autumn quilt bedroom mockup | P5: FULL | Q5: FULL | R5: FULL | S5: FULL | T5: =IF(P5="FULL",40,IF(P5="PARTIAL",40/2,0))+IF(Q5="FULL",30,IF(Q5="PARTIAL",30/2,0))+IF(R5="FULL",20,IF(R5="PARTIAL",20/2,0))+IF(S5="FULL",10,IF(S5="PARTIAL",10/2,0)) | U5: =IF(P5="NOT_CHECKED",0,40)+IF(Q5="NOT_CHECKED",0,30)+IF(R5="NOT_CHECKED",0,20)+IF(S5="NOT_CHECKED",0,10) | V5: =IF(U5=100,T5,"") | W5: =T5 | X5: =T5+(100-U5) | Y5: [] | Z5: ["D:\\Shopify_Workspace\\jeminise_seo\\seo_runs\\jeminise.com\\20260906_234129\\qa\\20260908_230550\\images\\001_04_47540016480455.jpg", "https://cdn.shopify.com/s/files/1/0792/5098/1063/files/455c5869333cc7654f6c30f3d09716ec1513311734a21a6aa82bf5fe0767ac69.jpg?v=1785099191", "seo_runs\\jeminise.com\\20260906_234129\\evidence\\images\\1_autumn-cardinals-perched-above-large-sunflowers-quilt-with-cardinal-birds-9a3b408b20-9a3b408b20\\image_04_47540016480455.jpg; seo_runs\\jeminise.com\\20260906_234129\\evidence\\contact_sheets\\1_autumn-cardinals-perched-above-large-sunflowers-quilt-with-cardinal-birds-9a3b408b20-9a3b408b20.jpg"]
A6: jeminise.com+autumn-cardinals-perched-above-large-sunflowers-quilt-with-cardinal-birds-9a3b408b20-9a3b408b20 | B6: jeminise.com+autumn-cardinals-perched-above-large-sunflowers-quilt-with-cardinal-birds-9a3b408b20-9a3b408b20|47540016513223|GALLERY|5 | C6: https://cdn.shopify.com/s/files/1/0792/5098/1063/files/f17ccb354040b3320b99a1960533bd6ef949db1145d3897d55a33673489caad9.jpg?v=1785099190 | D6: https://cdn.shopify.com/s/files/1/0792/5098/1063/files/f17ccb354040b3320b99a1960533bd6ef949db1145d3897d55a33673489caad9.jpg?v=1785099190 | E6: 47540016513223 | F6: 47540016513223 | H6: GALLERY | I6: DIRECT_ORIGINAL_IMAGE_REQA_R7 | J6: 2026-09-08T23:27:07.723474+07:00 | K6: Size and component panel showing quilt size choices and two optional standard shams. | L6: Size and component panel showing quilt size choices and two optional standard shams. | M6: Autumn Cardinals Perched Above Large Sunflowers Quilt with Cardinal Birds | N6: SET | O6: Cardinal sunflower quilt size and sham options | P6: FULL | Q6: FULL | R6: FULL | S6: FULL | T6: =IF(P6="FULL",40,IF(P6="PARTIAL",40/2,0))+IF(Q6="FULL",30,IF(Q6="PARTIAL",30/2,0))+IF(R6="FULL",20,IF(R6="PARTIAL",20/2,0))+IF(S6="FULL",10,IF(S6="PARTIAL",10/2,0)) | U6: =IF(P6="NOT_CHECKED",0,40)+IF(Q6="NOT_CHECKED",0,30)+IF(R6="NOT_CHECKED",0,20)+IF(S6="NOT_CHECKED",0,10) | V6: =IF(U6=100,T6,"") | W6: =T6 | X6: =T6+(100-U6) | Y6: [] | Z6: ["D:\\Shopify_Workspace\\jeminise_seo\\seo_runs\\jeminise.com\\20260906_234129\\qa\\20260908_230550\\images\\001_05_47540016513223.jpg", "https://cdn.shopify.com/s/files/1/0792/5098/1063/files/f17ccb354040b3320b99a1960533bd6ef949db1145d3897d55a33673489caad9.jpg?v=1785099190", "seo_runs\\jeminise.com\\20260906_234129\\evidence\\images\\1_autumn-cardinals-perched-above-large-sunflowers-quilt-with-cardinal-birds-9a3b408b20-9a3b408b20\\image_05_47540016513223.jpg; seo_runs\\jeminise.com\\20260906_234129\\evidence\\contact_sheets\\1_autumn-cardinals-perched-above-large-sunflowers-quilt-with-cardinal-birds-9a3b408b20-9a3b408b20.jpg"]
A7: jeminise.com+bright-teal-yellow-softball-comforter-set-premium-sports-theme | B7: jeminise.com+bright-teal-yellow-softball-comforter-set-premium-sports-theme|47934735909063|GALLERY|1 | C7: https://cdn.shopify.com/s/files/1/0792/5098/1063/files/aaac3be2edd458da15620b4b48ea0557ee8e33aa5a6ff9ed0d0db11848fd4cbe.jpg?v=1787245111 | D7: https://cdn.shopify.com/s/files/1/0792/5098/1063/files/aaac3be2edd458da15620b4b48ea0557ee8e33aa5a6ff9ed0d0db11848fd4cbe.jpg?v=1787245111 | E7: 47934735909063 | F7: 47934735909063 | H7: GALLERY | I7: DIRECT_ORIGINAL_IMAGE_REQA_R7 | J7: 2026-09-08T23:27:07.723474+07:00 | K7: Teal, black and white softball comforter bed mockup with player silhouettes, Riley name, number 88 and Eat Sleep Softball artwork. | L7: Teal, black and white softball comforter bed mockup with player silhouettes, Riley name, number 88 and Eat Sleep Softball artwork. | M7: Bright Teal Yellow Softball Comforter Set – Premium Sports Theme Bedding for Girls, Teens & Women Who Love Softball, Offered in Twin, Queen, King Bed Sizes | N7: SET | O7: Personalized teal softball comforter set | P7: FULL | Q7: FULL | R7: FULL | S7: FULL | T7: =IF(P7="FULL",40,IF(P7="PARTIAL",40/2,0))+IF(Q7="FULL",30,IF(Q7="PARTIAL",30/2,0))+IF(R7="FULL",20,IF(R7="PARTIAL",20/2,0))+IF(S7="FULL",10,IF(S7="PARTIAL",10/2,0)) | U7: =IF(P7="NOT_CHECKED",0,40)+IF(Q7="NOT_CHECKED",0,30)+IF(R7="NOT_CHECKED",0,20)+IF(S7="NOT_CHECKED",0,10) | V7: =IF(U7=100,T7,"") | W7: =T7 | X7: =T7+(100-U7) | Y7: [] | Z7: ["D:\\Shopify_Workspace\\jeminise_seo\\seo_runs\\jeminise.com\\20260906_234129\\qa\\20260908_230550\\images\\002_01_47934735909063.jpg", "https://cdn.shopify.com/s/files/1/0792/5098/1063/files/aaac3be2edd458da15620b4b48ea0557ee8e33aa5a6ff9ed0d0db11848fd4cbe.jpg?v=1787245111", "seo_runs\\jeminise.com\\20260906_234129\\evidence\\images\\2_bright-teal-yellow-softball-comforter-set-premium-sports-theme\\image_01_47934735909063.jpg; seo_runs\\jeminise.com\\20260906_234129\\evidence\\contact_sheets\\2_bright-teal-yellow-softball-comforter-set-premium-sports-theme.jpg"]
A8: jeminise.com+bright-teal-yellow-softball-comforter-set-premium-sports-theme | B8: jeminise.com+bright-teal-yellow-softball-comforter-set-premium-sports-theme|47934735941831|GALLERY|2 | C8: https://cdn.shopify.com/s/files/1/0792/5098/1063/files/b4d8d185bcbb550263dadfadb3419fffc97f4c44e070091e393e7296e5d6fb3c.jpg?v=1787245111 | D8: https://cdn.shopify.com/s/files/1/0792/5098/1063/files/b4d8d185bcbb550263dadfadb3419fffc97f4c44e070091e393e7296e5d6fb3c.jpg?v=1787245111 | E8: 47934735941831 | F8: 47934735941831 | H8: GALLERY | I8: DIRECT_ORIGINAL_IMAGE_REQA_R7 | J8: 2026-09-08T23:27:07.723474+07:00 | K8: Angled bedroom mockup of the teal softball comforter with coordinated pillowcases, Riley name and number 88. | L8: Angled bedroom mockup of the teal softball comforter with coordinated pillowcases, Riley name and number 88. | M8: Bright Teal Yellow Softball Comforter Set – Premium Sports Theme Bedding for Girls, Teens & Women Who Love Softball, Offered in Twin, Queen, King Bed Sizes | N8: SET | O8: Teal softball comforter bedroom mockup | P8: FULL | Q8: FULL | R8: FULL | S8: FULL | T8: =IF(P8="FULL",40,IF(P8="PARTIAL",40/2,0))+IF(Q8="FULL",30,IF(Q8="PARTIAL",30/2,0))+IF(R8="FULL",20,IF(R8="PARTIAL",20/2,0))+IF(S8="FULL",10,IF(S8="PARTIAL",10/2,0)) | U8: =IF(P8="NOT_CHECKED",0,40)+IF(Q8="NOT_CHECKED",0,30)+IF(R8="NOT_CHECKED",0,20)+IF(S8="NOT_CHECKED",0,10) | V8: =IF(U8=100,T8,"") | W8: =T8 | X8: =T8+(100-U8) | Y8: [] | Z8: ["D:\\Shopify_Workspace\\jeminise_seo\\seo_runs\\jeminise.com\\20260906_234129\\qa\\20260908_230550\\images\\002_02_47934735941831.jpg", "https://cdn.shopify.com/s/files/1/0792/5098/1063/files/b4d8d185bcbb550263dadfadb3419fffc97f4c44e070091e393e7296e5d6fb3c.jpg?v=1787245111", "seo_runs\\jeminise.com\\20260906_234129\\evidence\\images\\2_bright-teal-yellow-softball-comforter-set-premium-sports-theme\\image_02_47934735941831.jpg; seo_runs\\jeminise.com\\20260906_234129\\evidence\\contact_sheets\\2_bright-teal-yellow-softball-comforter-set-premium-sports-theme.jpg"]
A9: jeminise.com+bright-teal-yellow-softball-comforter-set-premium-sports-theme | B9: jeminise.com+bright-teal-yellow-softball-comforter-set-premium-sports-theme|47934735974599|GALLERY|3 | C9: https://cdn.shopify.com/s/files/1/0792/5098/1063/files/4905418785c478f3ccf76145151452929eacdfc883190607ac14b204c401e760.jpg?v=1787245111 | D9: https://cdn.shopify.com/s/files/1/0792/5098/1063/files/4905418785c478f3ccf76145151452929eacdfc883190607ac14b204c401e760.jpg?v=1787245111 | E9: 47934735974599 | F9: 47934735974599 | H9: GALLERY | I9: DIRECT_ORIGINAL_IMAGE_REQA_R7 | J9: 2026-09-08T23:27:07.723474+07:00 | K9: Coordinated pillowcases showing softball player silhouettes and number 88 on teal patchwork artwork. | L9: Coordinated pillowcases showing softball player silhouettes and number 88 on teal patchwork artwork. | M9: Bright Teal Yellow Softball Comforter Set – Premium Sports Theme Bedding for Girls, Teens & Women Who Love Softball, Offered in Twin, Queen, King Bed Sizes | N9: SET | O9: Teal softball pillowcases with number 88 | P9: FULL | Q9: FULL | R9: FULL | S9: FULL | T9: =IF(P9="FULL",40,IF(P9="PARTIAL",40/2,0))+IF(Q9="FULL",30,IF(Q9="PARTIAL",30/2,0))+IF(R9="FULL",20,IF(R9="PARTIAL",20/2,0))+IF(S9="FULL",10,IF(S9="PARTIAL",10/2,0)) | U9: =IF(P9="NOT_CHECKED",0,40)+IF(Q9="NOT_CHECKED",0,30)+IF(R9="NOT_CHECKED",0,20)+IF(S9="NOT_CHECKED",0,10) | V9: =IF(U9=100,T9,"") | W9: =T9 | X9: =T9+(100-U9) | Y9: [] | Z9: ["D:\\Shopify_Workspace\\jeminise_seo\\seo_runs\\jeminise.com\\20260906_234129\\qa\\20260908_230550\\images\\002_03_47934735974599.jpg", "https://cdn.shopify.com/s/files/1/0792/5098/1063/files/4905418785c478f3ccf76145151452929eacdfc883190607ac14b204c401e760.jpg?v=1787245111", "seo_runs\\jeminise.com\\20260906_234129\\evidence\\images\\2_bright-teal-yellow-softball-comforter-set-premium-sports-theme\\image_03_47934735974599.jpg; seo_runs\\jeminise.com\\20260906_234129\\evidence\\contact_sheets\\2_bright-teal-yellow-softball-comforter-set-premium-sports-theme.jpg"]
A10: jeminise.com+bright-teal-yellow-softball-comforter-set-premium-sports-theme | B10: jeminise.com+bright-teal-yellow-softball-comforter-set-premium-sports-theme|47934736007367|GALLERY|4 | C10: https://cdn.shopify.com/s/files/1/0792/5098/1063/files/66e753b90ce33322bda9902192b0d181e5f65b4823b1464fb51d32bee82398ed.jpg?v=1787245111 | D10: https://cdn.shopify.com/s/files/1/0792/5098/1063/files/66e753b90ce33322bda9902192b0d181e5f65b4823b1464fb51d32bee82398ed.jpg?v=1787245111 | E10: 47934736007367 | F10: 47934736007367 | H10: GALLERY | I10: DIRECT_ORIGINAL_IMAGE_REQA_R7 | J10: 2026-09-08T23:27:07.723474+07:00 | K10: Folded teal softball comforter showing patchwork print, softball graphics and white backing. | L10: Folded teal softball comforter showing patchwork print, softball graphics and white backing. | M10: Bright Teal Yellow Softball Comforter Set – Premium Sports Theme Bedding for Girls, Teens & Women Who Love Softball, Offered in Twin, Queen, King Bed Sizes | N10: SET | O10: Folded teal softball comforter with white backing | P10: FULL | Q10: FULL | R10: FULL | S10: FULL | T10: =IF(P10="FULL",40,IF(P10="PARTIAL",40/2,0))+IF(Q10="FULL",30,IF(Q10="PARTIAL",30/2,0))+IF(R10="FULL",20,IF(R10="PARTIAL",20/2,0))+IF(S10="FULL",10,IF(S10="PARTIAL",10/2,0)) | U10: =IF(P10="NOT_CHECKED",0,40)+IF(Q10="NOT_CHECKED",0,30)+IF(R10="NOT_CHECKED",0,20)+IF(S10="NOT_CHECKED",0,10) | V10: =IF(U10=100,T10,"") | W10: =T10 | X10: =T10+(100-U10) | Y10: [] | Z10: ["D:\\Shopify_Workspace\\jeminise_seo\\seo_runs\\jeminise.com\\20260906_234129\\qa\\20260908_230550\\images\\002_04_47934736007367.jpg", "https://cdn.shopify.com/s/files/1/0792/5098/1063/files/66e753b90ce33322bda9902192b0d181e5f65b4823b1464fb51d32bee82398ed.jpg?v=1787245111", "seo_runs\\jeminise.com\\20260906_234129\\evidence\\images\\2_bright-teal-yellow-softball-comforter-set-premium-sports-theme\\image_04_47934736007367.jpg; seo_runs\\jeminise.com\\20260906_234129\\evidence\\contact_sheets\\2_bright-teal-yellow-softball-comforter-set-premium-sports-theme.jpg"]
A11: jeminise.com+bright-teal-yellow-softball-comforter-set-premium-sports-theme | B11: jeminise.com+bright-teal-yellow-softball-comforter-set-premium-sports-theme|47934736040135|GALLERY|5 | C11: https://cdn.shopify.com/s/files/1/0792/5098/1063/files/a8d8145d1b6e7b4bbc3eb1dc71a100a3f3243648810f40f7f678de166dbfd428.jpg?v=1787245111 | D11: https://cdn.shopify.com/s/files/1/0792/5098/1063/files/a8d8145d1b6e7b4bbc3eb1dc71a100a3f3243648810f40f7f678de166dbfd428.jpg?v=1787245111 | E11: 47934736040135 | F11: 47934736040135 | H11: GALLERY | I11: DIRECT_ORIGINAL_IMAGE_REQA_R7 | J11: 2026-09-08T23:27:07.723474+07:00 | K11: Close-up of folded comforter edge with teal softball print on top and white backing underneath. | L11: Close-up of folded comforter edge with teal softball print on top and white backing underneath. | M11: Bright Teal Yellow Softball Comforter Set – Premium Sports Theme Bedding for Girls, Teens & Women Who Love Softball, Offered in Twin, Queen, King Bed Sizes | N11: SET | O11: Teal softball comforter white backing close-up | P11: FULL | Q11: FULL | R11: FULL | S11: FULL | T11: =IF(P11="FULL",40,IF(P11="PARTIAL",40/2,0))+IF(Q11="FULL",30,IF(Q11="PARTIAL",30/2,0))+IF(R11="FULL",20,IF(R11="PARTIAL",20/2,0))+IF(S11="FULL",10,IF(S11="PARTIAL",10/2,0)) | U11: =IF(P11="NOT_CHECKED",0,40)+IF(Q11="NOT_CHECKED",0,30)+IF(R11="NOT_CHECKED",0,20)+IF(S11="NOT_CHECKED",0,10) | V11: =IF(U11=100,T11,"") | W11: =T11 | X11: =T11+(100-U11) | Y11: [] | Z11: ["D:\\Shopify_Workspace\\jeminise_seo\\seo_runs\\jeminise.com\\20260906_234129\\qa\\20260908_230550\\images\\002_05_47934736040135.jpg", "https://cdn.shopify.com/s/files/1/0792/5098/1063/files/a8d8145d1b6e7b4bbc3eb1dc71a100a3f3243648810f40f7f678de166dbfd428.jpg?v=1787245111", "seo_runs\\jeminise.com\\20260906_234129\\evidence\\images\\2_bright-teal-yellow-softball-comforter-set-premium-sports-theme\\image_05_47934736040135.jpg; seo_runs\\jeminise.com\\20260906_234129\\evidence\\contact_sheets\\2_bright-teal-yellow-softball-comforter-set-premium-sports-theme.jpg"]
A12: jeminise.com+bright-teal-yellow-softball-comforter-set-premium-sports-theme | B12: jeminise.com+bright-teal-yellow-softball-comforter-set-premium-sports-theme|47934736072903|GALLERY|6 | C12: https://cdn.shopify.com/s/files/1/0792/5098/1063/files/b5c74b68d1b4eff2209b7123e3fbe61d1e31afd73aa5ba647e17c194e2e66c44_6ab5c586-a618-40f4-b48e-38e09e6a461b.jpg?v=1787245111 | D12: https://cdn.shopify.com/s/files/1/0792/5098/1063/files/b5c74b68d1b4eff2209b7123e3fbe61d1e31afd73aa5ba647e17c194e2e66c44_6ab5c586-a618-40f4-b48e-38e09e6a461b.jpg?v=1787245111 | E12: 47934736072903 | F12: 47934736072903 | H12: GALLERY | I12: DIRECT_ORIGINAL_IMAGE_REQA_R7 | J12: 2026-09-08T23:27:07.723474+07:00 | K12: Feature panel describing microfiber, cozy filling, lightweight feel and breathable warmth for the softball comforter. | L12: Feature panel describing microfiber, cozy filling, lightweight feel and breathable warmth for the softball comforter. | M12: Bright Teal Yellow Softball Comforter Set – Premium Sports Theme Bedding for Girls, Teens & Women Who Love Softball, Offered in Twin, Queen, King Bed Sizes | N12: SET | O12: Softball comforter microfiber feature panel | P12: FULL | Q12: FULL | R12: FULL | S12: FULL | T12: =IF(P12="FULL",40,IF(P12="PARTIAL",40/2,0))+IF(Q12="FULL",30,IF(Q12="PARTIAL",30/2,0))+IF(R12="FULL",20,IF(R12="PARTIAL",20/2,0))+IF(S12="FULL",10,IF(S12="PARTIAL",10/2,0)) | U12: =IF(P12="NOT_CHECKED",0,40)+IF(Q12="NOT_CHECKED",0,30)+IF(R12="NOT_CHECKED",0,20)+IF(S12="NOT_CHECKED",0,10) | V12: =IF(U12=100,T12,"") | W12: =T12 | X12: =T12+(100-U12) | Y12: [] | Z12: ["D:\\Shopify_Workspace\\jeminise_seo\\seo_runs\\jeminise.com\\20260906_234129\\qa\\20260908_230550\\images\\002_06_47934736072903.jpg", "https://cdn.shopify.com/s/files/1/0792/5098/1063/files/b5c74b68d1b4eff2209b7123e3fbe61d1e31afd73aa5ba647e17c194e2e66c44_6ab5c586-a618-40f4-b48e-38e09e6a461b.jpg?v=1787245111", "seo_runs\\jeminise.com\\20260906_234129\\evidence\\images\\2_bright-teal-yellow-softball-comforter-set-premium-sports-theme\\image_06_47934736072903.jpg; seo_runs\\jeminise.com\\20260906_234129\\evidence\\contact_sheets\\2_bright-teal-yellow-softball-comforter-set-premium-sports-theme.jpg"]
A13: jeminise.com+bright-teal-yellow-softball-comforter-set-premium-sports-theme | B13: jeminise.com+bright-teal-yellow-softball-comforter-set-premium-sports-theme|47934736105671|GALLERY|7 | C13: https://cdn.shopify.com/s/files/1/0792/5098/1063/files/a0ebf0c8e5cb1f2c8f924529805ea1d20494460dd41a740514b8862f5d5a2f4f_b03a920f-a52a-4b39-842e-77c13ca56137.jpg?v=1787245111 | D13: https://cdn.shopify.com/s/files/1/0792/5098/1063/files/a0ebf0c8e5cb1f2c8f924529805ea1d20494460dd41a740514b8862f5d5a2f4f_b03a920f-a52a-4b39-842e-77c13ca56137.jpg?v=1787245111 | E13: 47934736105671 | F13: 47934736105671 | H13: GALLERY | I13: DIRECT_ORIGINAL_IMAGE_REQA_R7 | J13: 2026-09-08T23:27:07.723474+07:00 | K13: Included-items panel showing one softball comforter and two coordinated pillowcases. | L13: Included-items panel showing one softball comforter and two coordinated pillowcases. | M13: Bright Teal Yellow Softball Comforter Set – Premium Sports Theme Bedding for Girls, Teens & Women Who Love Softball, Offered in Twin, Queen, King Bed Sizes | N13: SET | O13: Softball comforter and two pillowcases included | P13: FULL | Q13: FULL | R13: FULL | S13: FULL | T13: =IF(P13="FULL",40,IF(P13="PARTIAL",40/2,0))+IF(Q13="FULL",30,IF(Q13="PARTIAL",30/2,0))+IF(R13="FULL",20,IF(R13="PARTIAL",20/2,0))+IF(S13="FULL",10,IF(S13="PARTIAL",10/2,0)) | U13: =IF(P13="NOT_CHECKED",0,40)+IF(Q13="NOT_CHECKED",0,30)+IF(R13="NOT_CHECKED",0,20)+IF(S13="NOT_CHECKED",0,10) | V13: =IF(U13=100,T13,"") | W13: =T13 | X13: =T13+(100-U13) | Y13: [] | Z13: ["D:\\Shopify_Workspace\\jeminise_seo\\seo_runs\\jeminise.com\\20260906_234129\\qa\\20260908_230550\\images\\002_07_47934736105671.jpg", "https://cdn.shopify.com/s/files/1/0792/5098/1063/files/a0ebf0c8e5cb1f2c8f924529805ea1d20494460dd41a740514b8862f5d5a2f4f_b03a920f-a52a-4b39-842e-77c13ca56137.jpg?v=1787245111", "seo_runs\\jeminise.com\\20260906_234129\\evidence\\images\\2_bright-teal-yellow-softball-comforter-set-premium-sports-theme\\image_07_47934736105671.jpg; seo_runs\\jeminise.com\\20260906_234129\\evidence\\contact_sheets\\2_bright-teal-yellow-softball-comforter-set-premium-sports-theme.jpg"]
... A66: jeminise.com+christian-bedding-set-inspirational-bible-verse-comforte-design-01 | B66: jeminise.com+christian-bedding-set-inspirational-bible-verse-comforte-design-01|47933838196935|GALLERY|8 | C66: https://cdn.shopify.com/s/files/1/0792/5098/1063/files/d6b8438a259ef28ba839a68ba108f40464bc9629b0bc2168779fc7776c9cbffa.jpg?v=1787237695 | D66: https://cdn.shopify.com/s/files/1/0792/5098/1063/files/d6b8438a259ef28ba839a68ba108f40464bc9629b0bc2168779fc7776c9cbffa.jpg?v=1787237695 | E66: 47933838196935 | F66: 47933838196935 | H66: GALLERY | I66: DIRECT_ORIGINAL_IMAGE_REQA_R7 | J66: 2026-09-08T23:27:07.723474+07:00 | K66: Size dimension panel showing Twin, Full, Queen and King bedding dimensions. | L66: Size dimension panel showing Twin, Full, Queen and King bedding dimensions. | M66: Christian Bedding Set – Inspirational Bible Verse Comforter – Religious Bedding for Women, Faith Gift for Mom, Daughter, Sister, Birthday & Religious Gifts (God Says I am #1) | N66: SET | O66: Christian bedding size dimension chart | P66: FULL | Q66: FULL | R66: FULL | S66: FULL | T66: =IF(P66="FULL",40,IF(P66="PARTIAL",40/2,0))+IF(Q66="FULL",30,IF(Q66="PARTIAL",30/2,0))+IF(R66="FULL",20,IF(R66="PARTIAL",20/2,0))+IF(S66="FULL",10,IF(S66="PARTIAL",10/2,0)) | U66: =IF(P66="NOT_CHECKED",0,40)+IF(Q66="NOT_CHECKED",0,30)+IF(R66="NOT_CHECKED",0,20)+IF(S66="NOT_CHECKED",0,10) | V66: =IF(U66=100,T66,"") | W66: =T66 | X66: =T66+(100-U66) | Y66: [] | Z66: ["D:\\Shopify_Workspace\\jeminise_seo\\seo_runs\\jeminise.com\\20260906_234129\\qa\\20260908_230550\\images\\010_08_47933838196935.jpg", "https://cdn.shopify.com/s/files/1/0792/5098/1063/files/d6b8438a259ef28ba839a68ba108f40464bc9629b0bc2168779fc7776c9cbffa.jpg?v=1787237695", "seo_runs\\jeminise.com\\20260906_234129\\evidence\\images\\10_christian-bedding-set-inspirational-bible-verse-comforte-design-01\\image_08_47933838196935.jpg; seo_runs\\jeminise.com\\20260906_234129\\evidence\\contact_sheets\\10_christian-bedding-set-inspirational-bible-verse-comforte-design-01.jpg"]

Sheet QA_Issues
A1: issue_id | B1: product_key | C1: qa_image_key | D1: inventory_position | E1: severity | F1: field | G1: submitted_value | H1: source_observation | I1: reason | J1: recommended_fix | K1: supporting_evidence | L1: recheck_condition | M1: status_in_this_run
A2: R7-ISS-001-SIZE | B2: jeminise.com+autumn-cardinals-perched-above-large-sunflowers-quilt-with-cardinal-birds-9a3b408b20-9a3b408b20 | D2: 1 | E2: MAJOR | F2: description_proposed_html / selectable sizes | G2: The Cardinal Sunflower Autumn Quilt Set brings a warm fall look to the bedroom with red cardinals, oversized yellow sunflowers and orange leaf accents across the quilt and matching sham artwork. Design Details Red cardinal birds sit above large sunflower artwork on an autumn leaf background. The gallery includes a bed mockup, close-up quilt stitching, matching pillow sham artwork, a bedroom view and a size/component panel. Sizes and Set Details Shown size choices include Throw 60x70, Twin 70x80, Queen 80x90 and King 91x102. The panel shows one premium quilt with two standard shams available as optional add-ons. The quilt panel presents a soft, breathable fabric surface suitable for year-round bedroom use. | H2: Live selectors list Throw 60x70, Twin 68x86, Full 80x90, Queen 90x90 and King 102x91; r7 states Twin 70x80, omits Full, shifts Queen to 80x90 and reverses King dimensions. | I2: Customer-facing purchase dimensions conflict with the live selectable options. | J2: Replace the English size sentence with the exact live selector values and keep the image-panel discrepancy out of customer copy. | K2: https://jeminise.com/products/autumn-cardinals-perched-above-large-sunflowers-quilt-with-cardinal-birds-9a3b408b20-9a3b408b20; live_source_comparison.json; direct image review | L2: The description exactly matches the live size selector and explains any gallery-panel mismatch. | M2: OPEN
A3: R7-ISS-003-SIZE | B3: jeminise.com+cardinals-perched-beside-decorated-christmas-tree-patchwork-winter-quilt-7cd7bc46a0-7cd7bc46a0 | D3: 3 | E3: MAJOR | F3: description_proposed_html / selectable sizes | G3: Red cardinals sit beside a decorated Christmas tree with hearts, ornaments, snowflakes and I Am Always With You remembrance text. This quilt set brings a gentle memorial theme into holiday bedding. Design Details Holiday tree scene with red cardinals and memorial wording. Heart ornaments, snowflakes and matching pillow sham artwork are visible. Gallery includes a bed mockup, close-up quilt stitching, pillow sham artwork, room view and set-size panel. Sizes and Set Details Shown size choices include Throw 60x70, Twin 70x80, Queen 80x90 and King 91x102. The panel shows one premium quilt with two standard shams available as optional add-ons. Confirm the selected size and pillowcase choice before checkout. | H3: Live selectors list Throw 60x70, Twin 68x86, Full 80x90, Queen 90x90 and King 102x91; r7 states Twin 70x80, omits Full, shifts Queen to 80x90 and reverses King dimensions. | I3: Customer-facing purchase dimensions conflict with the live selectable options. | J3: Replace the English size sentence with the exact live selector values and keep the image-panel discrepancy out of customer copy. | K3: https://jeminise.com/products/cardinals-perched-beside-decorated-christmas-tree-patchwork-winter-quilt-7cd7bc46a0-7cd7bc46a0; live_source_comparison.json; direct image review | L3: The description exactly matches the live size selector and explains any gallery-panel mismatch. | M3: OPEN
A4: R7-ISS-004-SIZE | B4: jeminise.com+cardinals-perched-on-branch-with-roses-patchwork-winter-quilt-21ac904cd7-21ac904cd7 | D4: 4 | E4: MAJOR | F4: description_proposed_html / selectable sizes | G4: The Cardinal Roses Memorial Quilt Set uses a pair of cardinals on a branch with red roses, butterflies and I Am Always With You text for a softer remembrance bedding theme. Design Details The rose branch artwork separates this quilt from Christmas tree cardinal and general winter cardinal pages. The gallery includes the full bed mockup, close-up quilt texture, pillow sham, bedroom scene and size/component panel. Sizes and Set Details Shown size choices include Throw 60x70, Twin 70x80, Queen 80x90 and King 91x102. The panel shows one premium quilt with two standard shams available as optional add-ons. Use this product page for cardinal rose remembrance intent rather than broader Christmas cardinal queries. | H4: Live selectors list Throw 60x70, Twin 68x86, Full 80x90, Queen 90x90 and King 102x91; r7 states Twin 70x80, omits Full, shifts Queen to 80x90 and reverses King dimensions. | I4: Customer-facing purchase dimensions conflict with the live selectable options. | J4: Replace the English size sentence with the exact live selector values and keep the image-panel discrepancy out of customer copy. | K4: https://jeminise.com/products/cardinals-perched-on-branch-with-roses-patchwork-winter-quilt-21ac904cd7-21ac904cd7; live_source_comparison.json; direct image review | L4: The description exactly matches the live size selector and explains any gallery-panel mismatch. | M4: OPEN
A5: R7-ISS-004-EDITORIAL | B5: jeminise.com+cardinals-perched-on-branch-with-roses-patchwork-winter-quilt-21ac904cd7-21ac904cd7 | D5: 4 | E5: MAJOR | F5: description_proposed_html | G5: The Cardinal Roses Memorial Quilt Set uses a pair of cardinals on a branch with red roses, butterflies and I Am Always With You text for a softer remembrance bedding theme. Design Details The rose branch artwork separates this quilt from Christmas tree cardinal and general winter cardinal pages. The gallery includes the full bed mockup, close-up quilt texture, pillow sham, bedroom scene and size/component panel. Sizes and Set Details Shown size choices include Throw 60x70, Twin 70x80, Queen 80x90 and King 91x102. The panel shows one premium quilt with two standard shams available as optional add-ons. Use this product page for cardinal rose remembrance intent rather than broader Christmas cardinal queries. | H5: The final sentence says: 'Use this product page for cardinal rose remembrance intent rather than broader Christmas cardinal queries.' | I5: This is SEO/editorial guidance, not customer-facing storefront copy. | J5: Remove the internal intent instruction and end with a customer-facing sentence about the verified rose/cardinal remembrance design. | K5: https://jeminise.com/products/cardinals-perched-on-branch-with-roses-patchwork-winter-quilt-21ac904cd7-21ac904cd7; frozen r7 workbook | L5: No workflow, keyword-mapping or page-targeting language remains in the description. | M5: OPEN
