Workbook

Sheet QA_Summary
A1: metric | B1: value | C1: notes
A2: qa_run_id | B2: 20260908_183309 | C2: Independent QA run for batch 34 r3.
A3: qa_batch_id | B3: qa_batch_034_r3 | C3: Fixed scope inventory positions 331-338 only.
A4: source_workbook | B4: D:\Shopify_Workspace\jeminise_seo\resutls\jeminise.com\20260906_234129\revisions\qa_batch_034_r3\SEO_Product_Optimization_qa_batch_034_r3.xlsx | C4: Source workbook was not edited.
A5: source_sha256_start | B5: E8FF901F334297FAD3934DEA63775C95CF1BA9C5DFB1A80F7738B9C370EDC320 | C5: Snapshot hash matched at start.
A6: snapshot_workbook | B6: D:\Shopify_Workspace\jeminise_seo\seo_runs\jeminise.com\20260906_234129\qa\20260908_183309\source_snapshot\SEO_Product_Optimization_qa_batch_034_r3.xlsx | C6: Frozen copy used for QA.
A7: snapshot_sha256 | B7: E8FF901F334297FAD3934DEA63775C95CF1BA9C5DFB1A80F7738B9C370EDC320 | C7: Must match source hash.
A8: scope_counts | B8: 8 products; 57/57 images; 32 keyword rows; 8 buyer rows; 8 evidence rows | C8: Image coverage 100%; no replacement products.
A9: batch_final_score | B9: =AVERAGE('QA_Products'!$AA$2:$AA$9) | C9: Average of product final scores; no incomplete product skipped.
A10: batch_result | B10: =IF(COUNTIF('QA_Products'!$AB$2:$AB$9,"QA_PASS")=ROWS('QA_Products'!$AB$2:$AB$9),"PASSED","NOT_PASSED") | C10: Not passed unless every product is QA_PASS.
A11: status_counts | B11: ="PASS="&COUNTIF('QA_Products'!$AB$2:$AB$9,"QA_PASS")&"; REVISE="&COUNTIF('QA_Products'!$AB$2:$AB$9,"QA_REVISE")&"; FAIL="&COUNTIF('QA_Products'!$AB$2:$AB$9,"QA_FAIL")&"; INCOMPLETE="&COUNTIF('QA_Products'!$AB$2:$AB$9,"QA_INCOMPLETE") | C11: Rubric priority applied.
A12: severity_counts | B12: CRITICAL=0; MAJOR=11; MINOR=6; LIMITATION=8 | C12: Only open issues in this QA run.
A13: serp_queries | B13: 16 | C13: Two queries per product, US/English, URLs read recorded in serp_evidence.json.
A14: meta_description_policy | B14: 145-165 is editorial guidance, not hard fail | C14: r3 meta descriptions are complete at 112-124 characters and were not penalized on length alone.
A15: awaiting_confirmation | B15: TRUE | C15: Stop after batch 34; do not QA another batch automatically.

Sheet QA_Products
A1: qa_run_id | B1: qa_batch_id | C1: revision | D1: inventory_position | E1: product_key | F1: product_id | G1: handle | H1: url | I1: canonical_url | J1: title_current | K1: title_proposed | L1: meta_title_seo | M1: meta_description_seo | N1: primary_keyword | O1: expected_images | P1: live_image_count | Q1: workbook_image_count | R1: images_checked | S1: image_coverage | T1: image_inventory_complete | U1: page_read | V1: customizer_evidence | W1: verified_points | X1: assessed_weight | Y1: score_lower_bound | Z1: score_upper_bound | AA1: final_score | AB1: qa_status | AC1: critical_count | AD1: major_count | AE1: minor_count | AF1: limitation_count | AG1: source_changed | AH1: evidence_refs | AI1: issue_refs
A2: 20260908_183309 | B2: qa_batch_034_r3 | C2: r3 | D2: 331 | E2: jeminise.com+softball-themed-bedding-for-girls-and-women-bright-teal-yellow | F2: 8867218489543 | G2: softball-themed-bedding-for-girls-and-women-bright-teal-yellow | H2: https://jeminise.com/products/softball-themed-bedding-for-girls-and-women-bright-teal-yellow | I2: https://jeminise.com/products/softball-themed-bedding-for-girls-and-women-bright-teal-yellow | J2: Softball-Themed Bedding for Girls and Women – Bright Teal Yellow | K2: Vintage Yellow Softball Comforter Set | L2: Vintage Yellow Softball Comforter Set | M2: Shop vintage yellow softball comforter set with dark brown design, distressed softball, red stitching and number artwork. | N2: vintage yellow softball comforter set | O2: 7 | P2: 7 | Q2: 7 | R2: 7 | S2: 1 | T2: TRUE | U2: TRUE | V2: Custom Your Name (required, max 1000); Custom Your Number (required, max 1000) | W2: =SUMIF('QA_Criteria'!$D$2:$D$89,E2,'QA_Criteria'!$K$2:$K$89) | X2: =SUMIF('QA_Criteria'!$D$2:$D$89,E2,'QA_Criteria'!$L$2:$L$89) | Y2: =W2 | Z2: =W2+(100-X2) | AA2: =IF(AND(X2=100,S2=1,T2=TRUE),W2,"") | AB2: =IF(AC2>0,"QA_FAIL",IF(AA2="","QA_INCOMPLETE",IF(AA2<70,"QA_FAIL",IF(OR(AA2<85,AD2>0),"QA_REVISE","QA_PASS")))) | AC2: =COUNTIFS('QA_Issues'!$B$2:$B$26,E2,'QA_Issues'!$E$2:$E$26,"CRITICAL") | AD2: =COUNTIFS('QA_Issues'!$B$2:$B$26,E2,'QA_Issues'!$E$2:$E$26,"MAJOR") | AE2: =COUNTIFS('QA_Issues'!$B$2:$B$26,E2,'QA_Issues'!$E$2:$E$26,"MINOR") | AF2: =COUNTIFS('QA_Issues'!$B$2:$B$26,E2,'QA_Issues'!$E$2:$E$26,"LIMITATION") | AG2: NO_MATERIAL_PRODUCT_DRIFT; static HTML fetched with SSL-unverified retry | AH2: D:\Shopify_Workspace\jeminise_seo\seo_runs\jeminise.com\20260906_234129\qa\20260908_183309\live\331_softball-themed-bedding-for-girls-and-women-bright-teal-yellow.js.json; D:\Shopify_Workspace\jeminise_seo\seo_runs\jeminise.com\20260906_234129\qa\20260908_183309\live\331_softball-themed-bedding-for-girls-and-women-bright-teal-yellow.html; D:\Shopify_Workspace\jeminise_seo\seo_runs\jeminise.com\20260906_234129\qa\20260908_183309\serp_evidence.json | AI2: ISS-034-331-K1-SERP-NICHE;ISS-034-331-K2-CLUSTER;ISS-034-331-D2-CUSTOMER-COPY;ISS-034-331-E1-REVISION-TRACE
A3: 20260908_183309 | B3: qa_batch_034_r3 | C3: r3 | D3: 332 | E3: jeminise.com+sports-theme-softball-bedding-premium-teal-yellow-comforter-set-for | F3: 8867219505351 | G3: sports-theme-softball-bedding-premium-teal-yellow-comforter-set-for | H3: https://jeminise.com/products/sports-theme-softball-bedding-premium-teal-yellow-comforter-set-for | I3: https://jeminise.com/products/sports-theme-softball-bedding-premium-teal-yellow-comforter-set-for | J3: Sports Theme Softball Bedding – Premium Teal Yellow Comforter Set for | K3: Polka Dot Softball Comforter Set | L3: Polka Dot Softball Comforter Set | M3: Shop polka dot softball comforter set with black dots, teal stripe, paisley border, softball lettering and glove artwork. | N3: polka dot softball comforter set | O3: 7 | P3: 7 | Q3: 7 | R3: 7 | S3: 1 | T3: TRUE | U3: TRUE | V3: Custom Your Name (required, max 1000); Custom Your Number (required, max 1000) | W3: =SUMIF('QA_Criteria'!$D$2:$D$89,E3,'QA_Criteria'!$K$2:$K$89) | X3: =SUMIF('QA_Criteria'!$D$2:$D$89,E3,'QA_Criteria'!$L$2:$L$89) | Y3: =W3 | Z3: =W3+(100-X3) | AA3: =IF(AND(X3=100,S3=1,T3=TRUE),W3,"") | AB3: =IF(AC3>0,"QA_FAIL",IF(AA3="","QA_INCOMPLETE",IF(AA3<70,"QA_FAIL",IF(OR(AA3<85,AD3>0),"QA_REVISE","QA_PASS")))) | AC3: =COUNTIFS('QA_Issues'!$B$2:$B$26,E3,'QA_Issues'!$E$2:$E$26,"CRITICAL") | AD3: =COUNTIFS('QA_Issues'!$B$2:$B$26,E3,'QA_Issues'!$E$2:$E$26,"MAJOR") | AE3: =COUNTIFS('QA_Issues'!$B$2:$B$26,E3,'QA_Issues'!$E$2:$E$26,"MINOR") | AF3: =COUNTIFS('QA_Issues'!$B$2:$B$26,E3,'QA_Issues'!$E$2:$E$26,"LIMITATION") | AG3: NO_MATERIAL_PRODUCT_DRIFT; static HTML fetched with SSL-unverified retry | AH3: D:\Shopify_Workspace\jeminise_seo\seo_runs\jeminise.com\20260906_234129\qa\20260908_183309\live\332_sports-theme-softball-bedding-premium-teal-yellow-comforter-set-for.js.json; D:\Shopify_Workspace\jeminise_seo\seo_runs\jeminise.com\20260906_234129\qa\20260908_183309\live\332_sports-theme-softball-bedding-premium-teal-yellow-comforter-set-for.html; D:\Shopify_Workspace\jeminise_seo\seo_runs\jeminise.com\20260906_234129\qa\20260908_183309\serp_evidence.json | AI3: ISS-034-332-K1-SERP-WEAK;ISS-034-332-D2-CUSTOMER-COPY;ISS-034-332-E1-REVISION-TRACE
A4: 20260908_183309 | B4: qa_batch_034_r3 | C4: r3 | D4: 333 | E4: jeminise.com+teal-yellow-softball-comforter-set-vibrant-sports-bedroom-decor | F4: 8867218424007 | G4: teal-yellow-softball-comforter-set-vibrant-sports-bedroom-decor | H4: https://jeminise.com/products/teal-yellow-softball-comforter-set-vibrant-sports-bedroom-decor | I4: https://jeminise.com/products/teal-yellow-softball-comforter-set-vibrant-sports-bedroom-decor | J4: Teal & Yellow Softball Comforter Set – Vibrant Sports Bedroom Decor | K4: Fireball Softball Comforter Set | L4: Fireball Softball Comforter Set | M4: Shop fireball softball comforter set with orange and blue design, glowing yellow softball, flame ring and number artwork. | N4: fireball softball comforter set | O4: 7 | P4: 7 | Q4: 7 | R4: 7 | S4: 1 | T4: TRUE | U4: TRUE | V4: Custom Your Name (required, max 1000); Custom Your Number (required, max 1000) | W4: =SUMIF('QA_Criteria'!$D$2:$D$89,E4,'QA_Criteria'!$K$2:$K$89) | X4: =SUMIF('QA_Criteria'!$D$2:$D$89,E4,'QA_Criteria'!$L$2:$L$89) | Y4: =W4 | Z4: =W4+(100-X4) | AA4: =IF(AND(X4=100,S4=1,T4=TRUE),W4,"") | AB4: =IF(AC4>0,"QA_FAIL",IF(AA4="","QA_INCOMPLETE",IF(AA4<70,"QA_FAIL",IF(OR(AA4<85,AD4>0),"QA_REVISE","QA_PASS")))) | AC4: =COUNTIFS('QA_Issues'!$B$2:$B$26,E4,'QA_Issues'!$E$2:$E$26,"CRITICAL") | AD4: =COUNTIFS('QA_Issues'!$B$2:$B$26,E4,'QA_Issues'!$E$2:$E$26,"MAJOR") | AE4: =COUNTIFS('QA_Issues'!$B$2:$B$26,E4,'QA_Issues'!$E$2:$E$26,"MINOR") | AF4: =COUNTIFS('QA_Issues'!$B$2:$B$26,E4,'QA_Issues'!$E$2:$E$26,"LIMITATION") | AG4: NO_MATERIAL_PRODUCT_DRIFT; static HTML fetched with SSL-unverified retry | AH4: D:\Shopify_Workspace\jeminise_seo\seo_runs\jeminise.com\20260906_234129\qa\20260908_183309\live\333_teal-yellow-softball-comforter-set-vibrant-sports-bedroom-decor.js.json; D:\Shopify_Workspace\jeminise_seo\seo_runs\jeminise.com\20260906_234129\qa\20260908_183309\live\333_teal-yellow-softball-comforter-set-vibrant-sports-bedroom-decor.html; D:\Shopify_Workspace\jeminise_seo\seo_runs\jeminise.com\20260906_234129\qa\20260908_183309\serp_evidence.json | AI4: ISS-034-333-K1-SERP-NICHE;ISS-034-333-K2-CLUSTER;ISS-034-333-D2-CUSTOMER-COPY;ISS-034-333-E1-REVISION-TRACE
A5: 20260908_183309 | B5: qa_batch_034_r3 | C5: r3 | D5: 334 | E5: jeminise.com+teal-yellow-softball-bedding-set-stylish-sports-bedroom-decor | F5: 8867217965255 | G5: teal-yellow-softball-bedding-set-stylish-sports-bedroom-decor | H5: https://jeminise.com/products/teal-yellow-softball-bedding-set-stylish-sports-bedroom-decor | I5: https://jeminise.com/products/teal-yellow-softball-bedding-set-stylish-sports-bedroom-decor | J5: Teal Yellow Softball Bedding Set – Stylish Sports Bedroom Decor | K5: Pink Glove Softball Comforter Set | L5: Pink Glove Softball Comforter Set | M5: Shop pink glove softball comforter set with pink and gray design, red glove, yellow softball and number artwork. | N5: pink glove softball comforter set | O5: 14 | P5: 14 | Q5: 14 | R5: 14 | S5: 1 | T5: TRUE | U5: TRUE | V5: Custom Your Name (required, max 1000); Custom Your Number (required, max 1000) | W5: =SUMIF('QA_Criteria'!$D$2:$D$89,E5,'QA_Criteria'!$K$2:$K$89) | X5: =SUMIF('QA_Criteria'!$D$2:$D$89,E5,'QA_Criteria'!$L$2:$L$89) | Y5: =W5 | Z5: =W5+(100-X5) | AA5: =IF(AND(X5=100,S5=1,T5=TRUE),W5,"") | AB5: =IF(AC5>0,"QA_FAIL",IF(AA5="","QA_INCOMPLETE",IF(AA5<70,"QA_FAIL",IF(OR(AA5<85,AD5>0),"QA_REVISE","QA_PASS")))) | AC5: =COUNTIFS('QA_Issues'!$B$2:$B$26,E5,'QA_Issues'!$E$2:$E$26,"CRITICAL") | AD5: =COUNTIFS('QA_Issues'!$B$2:$B$26,E5,'QA_Issues'!$E$2:$E$26,"MAJOR") | AE5: =COUNTIFS('QA_Issues'!$B$2:$B$26,E5,'QA_Issues'!$E$2:$E$26,"MINOR") | AF5: =COUNTIFS('QA_Issues'!$B$2:$B$26,E5,'QA_Issues'!$E$2:$E$26,"LIMITATION") | AG5: NO_MATERIAL_PRODUCT_DRIFT; static HTML fetched with SSL-unverified retry | AH5: D:\Shopify_Workspace\jeminise_seo\seo_runs\jeminise.com\20260906_234129\qa\20260908_183309\live\334_teal-yellow-softball-bedding-set-stylish-sports-bedroom-decor.js.json; D:\Shopify_Workspace\jeminise_seo\seo_runs\jeminise.com\20260906_234129\qa\20260908_183309\live\334_teal-yellow-softball-bedding-set-stylish-sports-bedroom-decor.html; D:\Shopify_Workspace\jeminise_seo\seo_runs\jeminise.com\20260906_234129\qa\20260908_183309\serp_evidence.json | AI5: ISS-034-334-K2-CLUSTER;ISS-034-334-D2-CUSTOMER-COPY;ISS-034-334-E1-REVISION-TRACE;ISS-034-334-IMG-DUPLICATE-GALLERY
A6: 20260908_183309 | B6: qa_batch_034_r3 | C6: r3 | D6: 335 | E6: jeminise.com+tree-of-life-with-celtic-knot-roots-quilt-set-and-celtic-knot-borders-9482d2b2f5-9482d2b2f5 | F6: 8833358856391 | G6: tree-of-life-with-celtic-knot-roots-quilt-set-and-celtic-knot-borders-9482d2b2f5-9482d2b2f5 | H6: https://jeminise.com/products/tree-of-life-with-celtic-knot-roots-quilt-set-and-celtic-knot-borders-9482d2b2f5-9482d2b2f5 | I6: https://jeminise.com/products/tree-of-life-with-celtic-knot-roots-quilt-set-and-celtic-knot-borders-9482d2b2f5-9482d2b2f5 | J6: Tree of Life with Celtic Knot Roots Quilt Set And Celtic Knot Borders | K6: Celtic Tree of Life Quilt Set | L6: Celtic Tree of Life Quilt Set | M6: Shop Celtic Tree of Life quilt set with earth tone artwork, green tree, exposed knot roots, hills and Celtic borders. | N6: Celtic Tree of Life quilt set | O6: 7 | P6: 7 | Q6: 7 | R6: 7 | S6: 1 | T6: TRUE | U6: TRUE | V6: Customize Your Quilt (optional, max 1000) | W6: =SUMIF('QA_Criteria'!$D$2:$D$89,E6,'QA_Criteria'!$K$2:$K$89) | X6: =SUMIF('QA_Criteria'!$D$2:$D$89,E6,'QA_Criteria'!$L$2:$L$89) | Y6: =W6 | Z6: =W6+(100-X6) | AA6: =IF(AND(X6=100,S6=1,T6=TRUE),W6,"") | AB6: =IF(AC6>0,"QA_FAIL",IF(AA6="","QA_INCOMPLETE",IF(AA6<70,"QA_FAIL",IF(OR(AA6<85,AD6>0),"QA_REVISE","QA_PASS")))) | AC6: =COUNTIFS('QA_Issues'!$B$2:$B$26,E6,'QA_Issues'!$E$2:$E$26,"CRITICAL") | AD6: =COUNTIFS('QA_Issues'!$B$2:$B$26,E6,'QA_Issues'!$E$2:$E$26,"MAJOR") | AE6: =COUNTIFS('QA_Issues'!$B$2:$B$26,E6,'QA_Issues'!$E$2:$E$26,"MINOR") | AF6: =COUNTIFS('QA_Issues'!$B$2:$B$26,E6,'QA_Issues'!$E$2:$E$26,"LIMITATION") | AG6: NO_MATERIAL_PRODUCT_DRIFT; static HTML fetched with SSL-unverified retry | AH6: D:\Shopify_Workspace\jeminise_seo\seo_runs\jeminise.com\20260906_234129\qa\20260908_183309\live\335_tree-of-life-with-celtic-knot-roots-quilt-set-and-celtic-knot-borders-9482d2b2f5-9482d2b2f5.js.json; D:\Shopify_Workspace\jeminise_seo\seo_runs\jeminise.com\20260906_234129\qa\20260908_183309\live\335_tree-of-life-with-celtic-knot-roots-quilt-set-and-celtic-knot-borders-9482d2b2f5-9482d2b2f5.html; D:\Shopify_Workspace\jeminise_seo\seo_runs\jeminise.com\20260906_234129\qa\20260908_183309\serp_evidence.json | AI6: ISS-034-335-D2-CUSTOMER-COPY;ISS-034-335-E1-REVISION-TRACE
A7: 20260908_183309 | B7: qa_batch_034_r3 | C7: r3 | D7: 336 | E7: jeminise.com+winter-cardinal-on-berry-branch-patchwork-christmas-quilt-43ecda62b6-43ecda62b6 | F7: 8834730787015 | G7: winter-cardinal-on-berry-branch-patchwork-christmas-quilt-43ecda62b6-43ecda62b6 | H7: https://jeminise.com/products/winter-cardinal-on-berry-branch-patchwork-christmas-quilt-43ecda62b6-43ecda62b6 | I7: https://jeminise.com/products/winter-cardinal-on-berry-branch-patchwork-christmas-quilt-43ecda62b6-43ecda62b6 | J7: Winter Cardinal on Berry Branch Patchwork Christmas Quilt | K7: Winter Cardinal Berry Branch Quilt | L7: Winter Cardinal Berry Branch Quilt | M7: Shop winter cardinal berry branch quilt with red cardinal, berry branches, blue-gray leaves and snowy watercolor background. | N7: winter cardinal berry branch quilt | O7: 5 | P7: 5 | Q7: 5 | R7: 5 | S7: 1 | T7: TRUE | U7: TRUE | V7: Customize Your Quilt (optional, max 1000) | W7: =SUMIF('QA_Criteria'!$D$2:$D$89,E7,'QA_Criteria'!$K$2:$K$89) | X7: =SUMIF('QA_Criteria'!$D$2:$D$89,E7,'QA_Criteria'!$L$2:$L$89) | Y7: =W7 | Z7: =W7+(100-X7) | AA7: =IF(AND(X7=100,S7=1,T7=TRUE),W7,"") | AB7: =IF(AC7>0,"QA_FAIL",IF(AA7="","QA_INCOMPLETE",IF(AA7<70,"QA_FAIL",IF(OR(AA7<85,AD7>0),"QA_REVISE","QA_PASS")))) | AC7: =COUNTIFS('QA_Issues'!$B$2:$B$26,E7,'QA_Issues'!$E$2:$E$26,"CRITICAL") | AD7: =COUNTIFS('QA_Issues'!$B$2:$B$26,E7,'QA_Issues'!$E$2:$E$26,"MAJOR") | AE7: =COUNTIFS('QA_Issues'!$B$2:$B$26,E7,'QA_Issues'!$E$2:$E$26,"MINOR") | AF7: =COUNTIFS('QA_Issues'!$B$2:$B$26,E7,'QA_Issues'!$E$2:$E$26,"LIMITATION") | AG7: NO_MATERIAL_PRODUCT_DRIFT; static HTML fetched with SSL-unverified retry | AH7: D:\Shopify_Workspace\jeminise_seo\seo_runs\jeminise.com\20260906_234129\qa\20260908_183309\live\336_winter-cardinal-on-berry-branch-patchwork-christmas-quilt-43ecda62b6-43ecda62b6.js.json; D:\Shopify_Workspace\jeminise_seo\seo_runs\jeminise.com\20260906_234129\qa\20260908_183309\live\336_winter-cardinal-on-berry-branch-patchwork-christmas-quilt-43ecda62b6-43ecda62b6.html; D:\Shopify_Workspace\jeminise_seo\seo_runs\jeminise.com\20260906_234129\qa\20260908_183309\serp_evidence.json | AI7: ISS-034-336-D2-CUSTOMER-COPY;ISS-034-336-E1-REVISION-TRACE
A8: 20260908_183309 | B8: qa_batch_034_r3 | C8: r3 | D8: 337 | E8: jeminise.com+winter-cardinals-on-heart-shaped-berry-branches-patchwork-christmas-quilt-de1c648f60-de1c648f60 | F8: 8834734489799 | G8: winter-cardinals-on-heart-shaped-berry-branches-patchwork-christmas-quilt-de1c648f60-de1c648f60 | H8: https://jeminise.com/products/winter-cardinals-on-heart-shaped-berry-branches-patchwork-christmas-quilt-de1c648f60-de1c648f60 | I8: https://jeminise.com/products/winter-cardinals-on-heart-shaped-berry-branches-patchwork-christmas-quilt-de1c648f60-de1c648f60 | J8: Winter Cardinals on Heart Shaped Berry Branches Patchwork Christmas Quilt | K8: Heart Branch Cardinals Christmas Quilt | L8: Heart Branch Cardinals Christmas Quilt | M8: Shop heart branch cardinals Christmas quilt with two red cardinals, berry heart branches and snowy village scenery. | N8: heart branch cardinals Christmas quilt | O8: 5 | P8: 5 | Q8: 5 | R8: 5 | S8: 1 | T8: TRUE | U8: TRUE | V8: Customize Your Quilt (optional, max 1000) | W8: =SUMIF('QA_Criteria'!$D$2:$D$89,E8,'QA_Criteria'!$K$2:$K$89) | X8: =SUMIF('QA_Criteria'!$D$2:$D$89,E8,'QA_Criteria'!$L$2:$L$89) | Y8: =W8 | Z8: =W8+(100-X8) | AA8: =IF(AND(X8=100,S8=1,T8=TRUE),W8,"") | AB8: =IF(AC8>0,"QA_FAIL",IF(AA8="","QA_INCOMPLETE",IF(AA8<70,"QA_FAIL",IF(OR(AA8<85,AD8>0),"QA_REVISE","QA_PASS")))) | AC8: =COUNTIFS('QA_Issues'!$B$2:$B$26,E8,'QA_Issues'!$E$2:$E$26,"CRITICAL") | AD8: =COUNTIFS('QA_Issues'!$B$2:$B$26,E8,'QA_Issues'!$E$2:$E$26,"MAJOR") | AE8: =COUNTIFS('QA_Issues'!$B$2:$B$26,E8,'QA_Issues'!$E$2:$E$26,"MINOR") | AF8: =COUNTIFS('QA_Issues'!$B$2:$B$26,E8,'QA_Issues'!$E$2:$E$26,"LIMITATION") | AG8: NO_MATERIAL_PRODUCT_DRIFT; static HTML fetched with SSL-unverified retry | AH8: D:\Shopify_Workspace\jeminise_seo\seo_runs\jeminise.com\20260906_234129\qa\20260908_183309\live\337_winter-cardinals-on-heart-shaped-berry-branches-patchwork-christmas-quilt-de1c648f60-de1c648f60.js.json; D:\Shopify_Workspace\jeminise_seo\seo_runs\jeminise.com\20260906_234129\qa\20260908_183309\live\337_winter-cardinals-on-heart-shaped-berry-branches-patchwork-christmas-quilt-de1c648f60-de1c648f60.html; D:\Shopify_Workspace\jeminise_seo\seo_runs\jeminise.com\20260906_234129\qa\20260908_183309\serp_evidence.json | AI8: ISS-034-337-K1-SERP-WEAK;ISS-034-337-D2-CUSTOMER-COPY;ISS-034-337-E1-REVISION-TRACE
A9: 20260908_183309 | B9: qa_batch_034_r3 | C9: r3 | D9: 338 | E9: jeminise.com+winter-cat-and-cardinal-sitting-on-snowy-patchwork-christmas-quilt-82f86611f4-82f86611f4 | F9: 8834725576903 | G9: winter-cat-and-cardinal-sitting-on-snowy-patchwork-christmas-quilt-82f86611f4-82f86611f4 | H9: https://jeminise.com/products/winter-cat-and-cardinal-sitting-on-snowy-patchwork-christmas-quilt-82f86611f4-82f86611f4 | I9: https://jeminise.com/products/winter-cat-and-cardinal-sitting-on-snowy-patchwork-christmas-quilt-82f86611f4-82f86611f4 | J9: Winter Cat and Cardinal Sitting on Snowy Patchwork Christmas Quilt | K9: Winter Cat Cardinal Christmas Quilt | L9: Winter Cat Cardinal Christmas Quilt | M9: Shop winter cat cardinal Christmas quilt with gray kitten, red cardinal, snowy branches and It's Well With My Soul text. | N9: winter cat cardinal Christmas quilt | O9: 5 | P9: 5 | Q9: 5 | R9: 5 | S9: 1 | T9: TRUE | U9: TRUE | V9: Customize Your Quilt (optional, max 1000) | W9: =SUMIF('QA_Criteria'!$D$2:$D$89,E9,'QA_Criteria'!$K$2:$K$89) | X9: =SUMIF('QA_Criteria'!$D$2:$D$89,E9,'QA_Criteria'!$L$2:$L$89) | Y9: =W9 | Z9: =W9+(100-X9) | AA9: =IF(AND(X9=100,S9=1,T9=TRUE),W9,"") | AB9: =IF(AC9>0,"QA_FAIL",IF(AA9="","QA_INCOMPLETE",IF(AA9<70,"QA_FAIL",IF(OR(AA9<85,AD9>0),"QA_REVISE","QA_PASS")))) | AC9: =COUNTIFS('QA_Issues'!$B$2:$B$26,E9,'QA_Issues'!$E$2:$E$26,"CRITICAL") | AD9: =COUNTIFS('QA_Issues'!$B$2:$B$26,E9,'QA_Issues'!$E$2:$E$26,"MAJOR") | AE9: =COUNTIFS('QA_Issues'!$B$2:$B$26,E9,'QA_Issues'!$E$2:$E$26,"MINOR") | AF9: =COUNTIFS('QA_Issues'!$B$2:$B$26,E9,'QA_Issues'!$E$2:$E$26,"LIMITATION") | AG9: NO_MATERIAL_PRODUCT_DRIFT; static HTML fetched with SSL-unverified retry | AH9: D:\Shopify_Workspace\jeminise_seo\seo_runs\jeminise.com\20260906_234129\qa\20260908_183309\live\338_winter-cat-and-cardinal-sitting-on-snowy-patchwork-christmas-quilt-82f86611f4-82f86611f4.js.json; D:\Shopify_Workspace\jeminise_seo\seo_runs\jeminise.com\20260906_234129\qa\20260908_183309\live\338_winter-cat-and-cardinal-sitting-on-snowy-patchwork-christmas-quilt-82f86611f4-82f86611f4.html; D:\Shopify_Workspace\jeminise_seo\seo_runs\jeminise.com\20260906_234129\qa\20260908_183309\serp_evidence.json | AI9: ISS-034-338-K1-SERP-NICHE;ISS-034-338-D2-CUSTOMER-COPY;ISS-034-338-E1-REVISION-TRACE

Sheet QA_Criteria
A1: qa_run_id | B1: qa_batch_id | C1: revision | D1: product_key | E1: inventory_position | F1: criterion_id | G1: criterion_name | H1: weight | I1: assessment | J1: rating | K1: earned_points | L1: assessed_weight | M1: reason | N1: evidence_refs | O1: issue_refs | P1: suggested_fix_en
A2: 20260908_183309 | B2: qa_batch_034_r3 | C2: r3 | D2: jeminise.com+softball-themed-bedding-for-girls-and-women-bright-teal-yellow | E2: 331 | F2: P1 | G2: Product identity/source match | H2: 15 | I2: FULL | J2: =IF(F2="I1",AVERAGEIF('QA_Images'!$D$2:$D$58,D2,'QA_Images'!$AA$2:$AA$58)/100,IF(I2="FULL",1,IF(I2="PARTIAL",0.5,IF(I2="FAIL",0,"")))) | K2: =IF(J2="",0,H2*J2) | L2: =IF(F2="I1",20*AVERAGEIF('QA_Images'!$D$2:$D$58,D2,'QA_Images'!$AB$2:$AB$58)/100,IF(I2="NOT_CHECKED",0,H2)) | M2: Product identity locked by inventory product_key, handle and product_id; live product JSON matched handle/id and expected image count for position 331. | N2: live json/html; D:\Shopify_Workspace\jeminise_seo\seo_runs\jeminise.com\20260906_234129\qa\20260908_183309\serp_evidence.json; D:\Shopify_Workspace\jeminise_seo\seo_runs\jeminise.com\20260906_234129\qa\20260908_183309\visual_observations.json
A3: 20260908_183309 | B3: qa_batch_034_r3 | C3: r3 | D3: jeminise.com+softball-themed-bedding-for-girls-and-women-bright-teal-yellow | E3: 331 | F3: P2 | G3: Facts, offer and customization | H3: 10 | I3: FULL | J3: =IF(F3="I1",AVERAGEIF('QA_Images'!$D$2:$D$58,D3,'QA_Images'!$AA$2:$AA$58)/100,IF(I3="FULL",1,IF(I3="PARTIAL",0.5,IF(I3="FAIL",0,"")))) | K3: =IF(J3="",0,H3*J3) | L3: =IF(F3="I1",20*AVERAGEIF('QA_Images'!$D$2:$D$58,D3,'QA_Images'!$AB$2:$AB$58)/100,IF(I3="NOT_CHECKED",0,H3)) | M3: Offer facts verified from live JSON/options and full HTML customizer config: options Choose Comforter Size, Pillowcases; customizer labels ['Custom Your Name', 'Custom Your Number']. | N3: live json/html; D:\Shopify_Workspace\jeminise_seo\seo_runs\jeminise.com\20260906_234129\qa\20260908_183309\serp_evidence.json; D:\Shopify_Workspace\jeminise_seo\seo_runs\jeminise.com\20260906_234129\qa\20260908_183309\visual_observations.json
A4: 20260908_183309 | B4: qa_batch_034_r3 | C4: r3 | D4: jeminise.com+softball-themed-bedding-for-girls-and-women-bright-teal-yellow | E4: 331 | F4: K1 | G4: Primary keyword evidence | H4: 10 | I4: PARTIAL | J4: =IF(F4="I1",AVERAGEIF('QA_Images'!$D$2:$D$58,D4,'QA_Images'!$AA$2:$AA$58)/100,IF(I4="FULL",1,IF(I4="PARTIAL",0.5,IF(I4="FAIL",0,"")))) | K4: =IF(J4="",0,H4*J4) | L4: =IF(F4="I1",20*AVERAGEIF('QA_Images'!$D$2:$D$58,D4,'QA_Images'!$AB$2:$AB$58)/100,IF(I4="NOT_CHECKED",0,H4)) | M4: Primary keyword is truthful to the visual motif, but current SERP evidence is mostly broad/related rather than strong exact-match finished product evidence. | N4: live json/html; D:\Shopify_Workspace\jeminise_seo\seo_runs\jeminise.com\20260906_234129\qa\20260908_183309\serp_evidence.json; D:\Shopify_Workspace\jeminise_seo\seo_runs\jeminise.com\20260906_234129\qa\20260908_183309\visual_observations.json | O4: ISS-034-331-K1-SERP-NICHE;ISS-034-331-K2-CLUSTER
A5: 20260908_183309 | B5: qa_batch_034_r3 | C5: r3 | D5: jeminise.com+softball-themed-bedding-for-girls-and-women-bright-teal-yellow | E5: 331 | F5: K2 | G5: Intent/cannibalization separation | H5: 5 | I5: PARTIAL | J5: =IF(F5="I1",AVERAGEIF('QA_Images'!$D$2:$D$58,D5,'QA_Images'!$AA$2:$AA$58)/100,IF(I5="FULL",1,IF(I5="PARTIAL",0.5,IF(I5="FAIL",0,"")))) | K5: =IF(J5="",0,H5*J5) | L5: =IF(F5="I1",20*AVERAGEIF('QA_Images'!$D$2:$D$58,D5,'QA_Images'!$AB$2:$AB$58)/100,IF(I5="NOT_CHECKED",0,H5)) | M5: Keyword differentiation exists by motif, but nearby products in the same softball/cardinal cluster share broad secondary terms and mapping rationale is repetitive. | N5: live json/html; D:\Shopify_Workspace\jeminise_seo\seo_runs\jeminise.com\20260906_234129\qa\20260908_183309\serp_evidence.json; D:\Shopify_Workspace\jeminise_seo\seo_runs\jeminise.com\20260906_234129\qa\20260908_183309\visual_observations.json | O5: ISS-034-331-K1-SERP-NICHE;ISS-034-331-K2-CLUSTER
A6: 20260908_183309 | B6: qa_batch_034_r3 | C6: r3 | D6: jeminise.com+softball-themed-bedding-for-girls-and-women-bright-teal-yellow | E6: 331 | F6: K3 | G6: No unsupported keyword-volume claim | H6: 5 | I6: FULL | J6: =IF(F6="I1",AVERAGEIF('QA_Images'!$D$2:$D$58,D6,'QA_Images'!$AA$2:$AA$58)/100,IF(I6="FULL",1,IF(I6="PARTIAL",0.5,IF(I6="FAIL",0,"")))) | K6: =IF(J6="",0,H6*J6) | L6: =IF(F6="I1",20*AVERAGEIF('QA_Images'!$D$2:$D$58,D6,'QA_Images'!$AB$2:$AB$58)/100,IF(I6="NOT_CHECKED",0,H6)) | M6: No search-volume or ranking claim is made; keyword evidence is correctly limited as SERP_ONLY. | N6: live json/html; D:\Shopify_Workspace\jeminise_seo\seo_runs\jeminise.com\20260906_234129\qa\20260908_183309\serp_evidence.json; D:\Shopify_Workspace\jeminise_seo\seo_runs\jeminise.com\20260906_234129\qa\20260908_183309\visual_observations.json | O6: ISS-034-331-K1-SERP-NICHE;ISS-034-331-K2-CLUSTER
A7: 20260908_183309 | B7: qa_batch_034_r3 | C7: r3 | D7: jeminise.com+softball-themed-bedding-for-girls-and-women-bright-teal-yellow | E7: 331 | F7: T1 | G7: SEO title/meta title | H7: 10 | I7: FULL | J7: =IF(F7="I1",AVERAGEIF('QA_Images'!$D$2:$D$58,D7,'QA_Images'!$AA$2:$AA$58)/100,IF(I7="FULL",1,IF(I7="PARTIAL",0.5,IF(I7="FAIL",0,"")))) | K7: =IF(J7="",0,H7*J7) | L7: =IF(F7="I1",20*AVERAGEIF('QA_Images'!$D$2:$D$58,D7,'QA_Images'!$AB$2:$AB$58)/100,IF(I7="NOT_CHECKED",0,H7)) | M7: meta_title_seo is concise, readable, and maps to the verified motif/product type. | N7: live json/html; D:\Shopify_Workspace\jeminise_seo\seo_runs\jeminise.com\20260906_234129\qa\20260908_183309\serp_evidence.json; D:\Shopify_Workspace\jeminise_seo\seo_runs\jeminise.com\20260906_234129\qa\20260908_183309\visual_observations.json
A8: 20260908_183309 | B8: qa_batch_034_r3 | C8: r3 | D8: jeminise.com+softball-themed-bedding-for-girls-and-women-bright-teal-yellow | E8: 331 | F8: T2 | G8: Product title/H1 proposal | H8: 5 | I8: FULL | J8: =IF(F8="I1",AVERAGEIF('QA_Images'!$D$2:$D$58,D8,'QA_Images'!$AA$2:$AA$58)/100,IF(I8="FULL",1,IF(I8="PARTIAL",0.5,IF(I8="FAIL",0,"")))) | K8: =IF(J8="",0,H8*J8) | L8: =IF(F8="I1",20*AVERAGEIF('QA_Images'!$D$2:$D$58,D8,'QA_Images'!$AB$2:$AB$58)/100,IF(I8="NOT_CHECKED",0,H8)) | M8: title_proposed is publishable as a clean H1/title replacement and fixes the current truncated or mojibake-heavy storefront title. | N8: live json/html; D:\Shopify_Workspace\jeminise_seo\seo_runs\jeminise.com\20260906_234129\qa\20260908_183309\serp_evidence.json; D:\Shopify_Workspace\jeminise_seo\seo_runs\jeminise.com\20260906_234129\qa\20260908_183309\visual_observations.json
A9: 20260908_183309 | B9: qa_batch_034_r3 | C9: r3 | D9: jeminise.com+softball-themed-bedding-for-girls-and-women-bright-teal-yellow | E9: 331 | F9: D1 | G9: Meta description | H9: 5 | I9: FULL | J9: =IF(F9="I1",AVERAGEIF('QA_Images'!$D$2:$D$58,D9,'QA_Images'!$AA$2:$AA$58)/100,IF(I9="FULL",1,IF(I9="PARTIAL",0.5,IF(I9="FAIL",0,"")))) | K9: =IF(J9="",0,H9*J9) | L9: =IF(F9="I1",20*AVERAGEIF('QA_Images'!$D$2:$D$58,D9,'QA_Images'!$AB$2:$AB$58)/100,IF(I9="NOT_CHECKED",0,H9)) | M9: meta_description_seo no longer has hard truncation or dangling ending; length is below 145 but complete and meaningful, so no automatic penalty for character count. | N9: live json/html; D:\Shopify_Workspace\jeminise_seo\seo_runs\jeminise.com\20260906_234129\qa\20260908_183309\serp_evidence.json; D:\Shopify_Workspace\jeminise_seo\seo_runs\jeminise.com\20260906_234129\qa\20260908_183309\visual_observations.json
A10: 20260908_183309 | B10: qa_batch_034_r3 | C10: r3 | D10: jeminise.com+softball-themed-bedding-for-girls-and-women-bright-teal-yellow | E10: 331 | F10: D2 | G10: Description HTML | H10: 10 | I10: PARTIAL | J10: =IF(F10="I1",AVERAGEIF('QA_Images'!$D$2:$D$58,D10,'QA_Images'!$AA$2:$AA$58)/100,IF(I10="FULL",1,IF(I10="PARTIAL",0.5,IF(I10="FAIL",0,"")))) | K10: =IF(J10="",0,H10*J10) | L10: =IF(F10="I1",20*AVERAGEIF('QA_Images'!$D$2:$D$58,D10,'QA_Images'!$AB$2:$AB$58)/100,IF(I10="NOT_CHECKED",0,H10)) | M10: Description facts mostly match live/product evidence, but the body still contains editorial/process phrasing and generic gallery wording that should not ship as final storefront copy. | N10: live json/html; D:\Shopify_Workspace\jeminise_seo\seo_runs\jeminise.com\20260906_234129\qa\20260908_183309\serp_evidence.json; D:\Shopify_Workspace\jeminise_seo\seo_runs\jeminise.com\20260906_234129\qa\20260908_183309\visual_observations.json | O10: ISS-034-331-D2-CUSTOMER-COPY | P10: Rewrite as customer-facing English body copy for Vintage Yellow Softball Comforter Set; remove “The copy stays specific...” and avoid process-style gallery wording.
A11: 20260908_183309 | B11: qa_batch_034_r3 | C11: r3 | D11: jeminise.com+softball-themed-bedding-for-girls-and-women-bright-teal-yellow | E11: 331 | F11: I1 | G11: Image/alt QA aggregate | H11: 20 | I11: DERIVED_FROM_IMAGES | J11: =IF(F11="I1",AVERAGEIF('QA_Images'!$D$2:$D$58,D11,'QA_Images'!$AA$2:$AA$58)/100,IF(I11="FULL",1,IF(I11="PARTIAL",0.5,IF(I11="FAIL",0,"")))) | K11: =IF(J11="",0,H11*J11) | L11: =IF(F11="I1",20*AVERAGEIF('QA_Images'!$D$2:$D$58,D11,'QA_Images'!$AB$2:$AB$58)/100,IF(I11="NOT_CHECKED",0,H11)) | M11: Derived from QA_Images average for this product; all images were opened directly in this run. | N11: live json/html; D:\Shopify_Workspace\jeminise_seo\seo_runs\jeminise.com\20260906_234129\qa\20260908_183309\serp_evidence.json; D:\Shopify_Workspace\jeminise_seo\seo_runs\jeminise.com\20260906_234129\qa\20260908_183309\visual_observations.json
A12: 20260908_183309 | B12: qa_batch_034_r3 | C12: r3 | D12: jeminise.com+softball-themed-bedding-for-girls-and-women-bright-teal-yellow | E12: 331 | F12: E1 | G12: Evidence chain and traceability | H12: 5 | I12: PARTIAL | J12: =IF(F12="I1",AVERAGEIF('QA_Images'!$D$2:$D$58,D12,'QA_Images'!$AA$2:$AA$58)/100,IF(I12="FULL",1,IF(I12="PARTIAL",0.5,IF(I12="FAIL",0,"")))) | K12: =IF(J12="",0,H12*J12) | L12: =IF(F12="I1",20*AVERAGEIF('QA_Images'!$D$2:$D$58,D12,'QA_Images'!$AB$2:$AB$58)/100,IF(I12="NOT_CHECKED",0,H12)) | M12: Evidence chain exists, but workbook traceability still carries r2/contact-sheet wording while the actual source file is r3; this QA run compensates with new live/image/SERP evidence. | N12: live json/html; D:\Shopify_Workspace\jeminise_seo\seo_runs\jeminise.com\20260906_234129\qa\20260908_183309\serp_evidence.json; D:\Shopify_Workspace\jeminise_seo\seo_runs\jeminise.com\20260906_234129\qa\20260908_183309\visual_observations.json | O12: ISS-034-331-E1-REVISION-TRACE
A13: 20260908_183309 | B13: qa_batch_034_r3 | C13: r3 | D13: jeminise.com+sports-theme-softball-bedding-premium-teal-yellow-comforter-set-for | E13: 332 | F13: P1 | G13: Product identity/source match | H13: 15 | I13: FULL | J13: =IF(F13="I1",AVERAGEIF('QA_Images'!$D$2:$D$58,D13,'QA_Images'!$AA$2:$AA$58)/100,IF(I13="FULL",1,IF(I13="PARTIAL",0.5,IF(I13="FAIL",0,"")))) | K13: =IF(J13="",0,H13*J13) | L13: =IF(F13="I1",20*AVERAGEIF('QA_Images'!$D$2:$D$58,D13,'QA_Images'!$AB$2:$AB$58)/100,IF(I13="NOT_CHECKED",0,H13)) | M13: Product identity locked by inventory product_key, handle and product_id; live product JSON matched handle/id and expected image count for position 332. | N13: live json/html; D:\Shopify_Workspace\jeminise_seo\seo_runs\jeminise.com\20260906_234129\qa\20260908_183309\serp_evidence.json; D:\Shopify_Workspace\jeminise_seo\seo_runs\jeminise.com\20260906_234129\qa\20260908_183309\visual_observations.json
A14: 20260908_183309 | B14: qa_batch_034_r3 | C14: r3 | D14: jeminise.com+sports-theme-softball-bedding-premium-teal-yellow-comforter-set-for | E14: 332 | F14: P2 | G14: Facts, offer and customization | H14: 10 | I14: FULL | J14: =IF(F14="I1",AVERAGEIF('QA_Images'!$D$2:$D$58,D14,'QA_Images'!$AA$2:$AA$58)/100,IF(I14="FULL",1,IF(I14="PARTIAL",0.5,IF(I14="FAIL",0,"")))) | K14: =IF(J14="",0,H14*J14) | L14: =IF(F14="I1",20*AVERAGEIF('QA_Images'!$D$2:$D$58,D14,'QA_Images'!$AB$2:$AB$58)/100,IF(I14="NOT_CHECKED",0,H14)) | M14: Offer facts verified from live JSON/options and full HTML customizer config: options Choose Comforter Size, Pillowcases; customizer labels ['Custom Your Name', 'Custom Your Number']. | N14: live json/html; D:\Shopify_Workspace\jeminise_seo\seo_runs\jeminise.com\20260906_234129\qa\20260908_183309\serp_evidence.json; D:\Shopify_Workspace\jeminise_seo\seo_runs\jeminise.com\20260906_234129\qa\20260908_183309\visual_observations.json
A15: 20260908_183309 | B15: qa_batch_034_r3 | C15: r3 | D15: jeminise.com+sports-theme-softball-bedding-premium-teal-yellow-comforter-set-for | E15: 332 | F15: K1 | G15: Primary keyword evidence | H15: 10 | I15: PARTIAL | J15: =IF(F15="I1",AVERAGEIF('QA_Images'!$D$2:$D$58,D15,'QA_Images'!$AA$2:$AA$58)/100,IF(I15="FULL",1,IF(I15="PARTIAL",0.5,IF(I15="FAIL",0,"")))) | K15: =IF(J15="",0,H15*J15) | L15: =IF(F15="I1",20*AVERAGEIF('QA_Images'!$D$2:$D$58,D15,'QA_Images'!$AB$2:$AB$58)/100,IF(I15="NOT_CHECKED",0,H15)) | M15: Primary keyword combines a very specific motif with a broad product type; live SERP splits into adjacent intents and exact finished-product support is weak. | N15: live json/html; D:\Shopify_Workspace\jeminise_seo\seo_runs\jeminise.com\20260906_234129\qa\20260908_183309\serp_evidence.json; D:\Shopify_Workspace\jeminise_seo\seo_runs\jeminise.com\20260906_234129\qa\20260908_183309\visual_observations.json | O15: ISS-034-332-K1-SERP-WEAK
A16: 20260908_183309 | B16: qa_batch_034_r3 | C16: r3 | D16: jeminise.com+sports-theme-softball-bedding-premium-teal-yellow-comforter-set-for | E16: 332 | F16: K2 | G16: Intent/cannibalization separation | H16: 5 | I16: PARTIAL | J16: =IF(F16="I1",AVERAGEIF('QA_Images'!$D$2:$D$58,D16,'QA_Images'!$AA$2:$AA$58)/100,IF(I16="FULL",1,IF(I16="PARTIAL",0.5,IF(I16="FAIL",0,"")))) | K16: =IF(J16="",0,H16*J16) | L16: =IF(F16="I1",20*AVERAGEIF('QA_Images'!$D$2:$D$58,D16,'QA_Images'!$AB$2:$AB$58)/100,IF(I16="NOT_CHECKED",0,H16)) | M16: Keyword differentiation exists by motif, but nearby products in the same softball/cardinal cluster share broad secondary terms and mapping rationale is repetitive. | N16: live json/html; D:\Shopify_Workspace\jeminise_seo\seo_runs\jeminise.com\20260906_234129\qa\20260908_183309\serp_evidence.json; D:\Shopify_Workspace\jeminise_seo\seo_runs\jeminise.com\20260906_234129\qa\20260908_183309\visual_observations.json | O16: ISS-034-332-K1-SERP-WEAK
A17: 20260908_183309 | B17: qa_batch_034_r3 | C17: r3 | D17: jeminise.com+sports-theme-softball-bedding-premium-teal-yellow-comforter-set-for | E17: 332 | F17: K3 | G17: No unsupported keyword-volume claim | H17: 5 | I17: FULL | J17: =IF(F17="I1",AVERAGEIF('QA_Images'!$D$2:$D$58,D17,'QA_Images'!$AA$2:$AA$58)/100,IF(I17="FULL",1,IF(I17="PARTIAL",0.5,IF(I17="FAIL",0,"")))) | K17: =IF(J17="",0,H17*J17) | L17: =IF(F17="I1",20*AVERAGEIF('QA_Images'!$D$2:$D$58,D17,'QA_Images'!$AB$2:$AB$58)/100,IF(I17="NOT_CHECKED",0,H17)) | M17: No search-volume or ranking claim is made; keyword evidence is correctly limited as SERP_ONLY. | N17: live json/html; D:\Shopify_Workspace\jeminise_seo\seo_runs\jeminise.com\20260906_234129\qa\20260908_183309\serp_evidence.json; D:\Shopify_Workspace\jeminise_seo\seo_runs\jeminise.com\20260906_234129\qa\20260908_183309\visual_observations.json | O17: ISS-034-332-K1-SERP-WEAK
A18: 20260908_183309 | B18: qa_batch_034_r3 | C18: r3 | D18: jeminise.com+sports-theme-softball-bedding-premium-teal-yellow-comforter-set-for | E18: 332 | F18: T1 | G18: SEO title/meta title | H18: 10 | I18: FULL | J18: =IF(F18="I1",AVERAGEIF('QA_Images'!$D$2:$D$58,D18,'QA_Images'!$AA$2:$AA$58)/100,IF(I18="FULL",1,IF(I18="PARTIAL",0.5,IF(I18="FAIL",0,"")))) | K18: =IF(J18="",0,H18*J18) | L18: =IF(F18="I1",20*AVERAGEIF('QA_Images'!$D$2:$D$58,D18,'QA_Images'!$AB$2:$AB$58)/100,IF(I18="NOT_CHECKED",0,H18)) | M18: meta_title_seo is concise, readable, and maps to the verified motif/product type. | N18: live json/html; D:\Shopify_Workspace\jeminise_seo\seo_runs\jeminise.com\20260906_234129\qa\20260908_183309\serp_evidence.json; D:\Shopify_Workspace\jeminise_seo\seo_runs\jeminise.com\20260906_234129\qa\20260908_183309\visual_observations.json
A19: 20260908_183309 | B19: qa_batch_034_r3 | C19: r3 | D19: jeminise.com+sports-theme-softball-bedding-premium-teal-yellow-comforter-set-for | E19: 332 | F19: T2 | G19: Product title/H1 proposal | H19: 5 | I19: FULL | J19: =IF(F19="I1",AVERAGEIF('QA_Images'!$D$2:$D$58,D19,'QA_Images'!$AA$2:$AA$58)/100,IF(I19="FULL",1,IF(I19="PARTIAL",0.5,IF(I19="FAIL",0,"")))) | K19: =IF(J19="",0,H19*J19) | L19: =IF(F19="I1",20*AVERAGEIF('QA_Images'!$D$2:$D$58,D19,'QA_Images'!$AB$2:$AB$58)/100,IF(I19="NOT_CHECKED",0,H19)) | M19: title_proposed is publishable as a clean H1/title replacement and fixes the current truncated or mojibake-heavy storefront title. | N19: live json/html; D:\Shopify_Workspace\jeminise_seo\seo_runs\jeminise.com\20260906_234129\qa\20260908_183309\serp_evidence.json; D:\Shopify_Workspace\jeminise_seo\seo_runs\jeminise.com\20260906_234129\qa\20260908_183309\visual_observations.json
A20: 20260908_183309 | B20: qa_batch_034_r3 | C20: r3 | D20: jeminise.com+sports-theme-softball-bedding-premium-teal-yellow-comforter-set-for | E20: 332 | F20: D1 | G20: Meta description | H20: 5 | I20: FULL | J20: =IF(F20="I1",AVERAGEIF('QA_Images'!$D$2:$D$58,D20,'QA_Images'!$AA$2:$AA$58)/100,IF(I20="FULL",1,IF(I20="PARTIAL",0.5,IF(I20="FAIL",0,"")))) | K20: =IF(J20="",0,H20*J20) | L20: =IF(F20="I1",20*AVERAGEIF('QA_Images'!$D$2:$D$58,D20,'QA_Images'!$AB$2:$AB$58)/100,IF(I20="NOT_CHECKED",0,H20)) | M20: meta_description_seo no longer has hard truncation or dangling ending; length is below 145 but complete and meaningful, so no automatic penalty for character count. | N20: live json/html; D:\Shopify_Workspace\jeminise_seo\seo_runs\jeminise.com\20260906_234129\qa\20260908_183309\serp_evidence.json; D:\Shopify_Workspace\jeminise_seo\seo_runs\jeminise.com\20260906_234129\qa\20260908_183309\visual_observations.json
A21: 20260908_183309 | B21: qa_batch_034_r3 | C21: r3 | D21: jeminise.com+sports-theme-softball-bedding-premium-teal-yellow-comforter-set-for | E21: 332 | F21: D2 | G21: Description HTML | H21: 10 | I21: PARTIAL | J21: =IF(F21="I1",AVERAGEIF('QA_Images'!$D$2:$D$58,D21,'QA_Images'!$AA$2:$AA$58)/100,IF(I21="FULL",1,IF(I21="PARTIAL",0.5,IF(I21="FAIL",0,"")))) | K21: =IF(J21="",0,H21*J21) | L21: =IF(F21="I1",20*AVERAGEIF('QA_Images'!$D$2:$D$58,D21,'QA_Images'!$AB$2:$AB$58)/100,IF(I21="NOT_CHECKED",0,H21)) | M21: Description facts mostly match live/product evidence, but the body still contains editorial/process phrasing and generic gallery wording that should not ship as final storefront copy. | N21: live json/html; D:\Shopify_Workspace\jeminise_seo\seo_runs\jeminise.com\20260906_234129\qa\20260908_183309\serp_evidence.json; D:\Shopify_Workspace\jeminise_seo\seo_runs\jeminise.com\20260906_234129\qa\20260908_183309\visual_observations.json | O21: ISS-034-332-D2-CUSTOMER-COPY | P21: Rewrite as customer-facing English body copy for Polka Dot Softball Comforter Set; remove “The copy stays specific...” and avoid process-style gallery wording.
A22: 20260908_183309 | B22: qa_batch_034_r3 | C22: r3 | D22: jeminise.com+sports-theme-softball-bedding-premium-teal-yellow-comforter-set-for | E22: 332 | F22: I1 | G22: Image/alt QA aggregate | H22: 20 | I22: DERIVED_FROM_IMAGES | J22: =IF(F22="I1",AVERAGEIF('QA_Images'!$D$2:$D$58,D22,'QA_Images'!$AA$2:$AA$58)/100,IF(I22="FULL",1,IF(I22="PARTIAL",0.5,IF(I22="FAIL",0,"")))) | K22: =IF(J22="",0,H22*J22) | L22: =IF(F22="I1",20*AVERAGEIF('QA_Images'!$D$2:$D$58,D22,'QA_Images'!$AB$2:$AB$58)/100,IF(I22="NOT_CHECKED",0,H22)) | M22: Derived from QA_Images average for this product; all images were opened directly in this run. | N22: live json/html; D:\Shopify_Workspace\jeminise_seo\seo_runs\jeminise.com\20260906_234129\qa\20260908_183309\serp_evidence.json; D:\Shopify_Workspace\jeminise_seo\seo_runs\jeminise.com\20260906_234129\qa\20260908_183309\visual_observations.json
A23: 20260908_183309 | B23: qa_batch_034_r3 | C23: r3 | D23: jeminise.com+sports-theme-softball-bedding-premium-teal-yellow-comforter-set-for | E23: 332 | F23: E1 | G23: Evidence chain and traceability | H23: 5 | I23: PARTIAL | J23: =IF(F23="I1",AVERAGEIF('QA_Images'!$D$2:$D$58,D23,'QA_Images'!$AA$2:$AA$58)/100,IF(I23="FULL",1,IF(I23="PARTIAL",0.5,IF(I23="FAIL",0,"")))) | K23: =IF(J23="",0,H23*J23) | L23: =IF(F23="I1",20*AVERAGEIF('QA_Images'!$D$2:$D$58,D23,'QA_Images'!$AB$2:$AB$58)/100,IF(I23="NOT_CHECKED",0,H23)) | M23: Evidence chain exists, but workbook traceability still carries r2/contact-sheet wording while the actual source file is r3; this QA run compensates with new live/image/SERP evidence. | N23: live json/html; D:\Shopify_Workspace\jeminise_seo\seo_runs\jeminise.com\20260906_234129\qa\20260908_183309\serp_evidence.json; D:\Shopify_Workspace\jeminise_seo\seo_runs\jeminise.com\20260906_234129\qa\20260908_183309\visual_observations.json | O23: ISS-034-332-E1-REVISION-TRACE
A24: 20260908_183309 | B24: qa_batch_034_r3 | C24: r3 | D24: jeminise.com+teal-yellow-softball-comforter-set-vibrant-sports-bedroom-decor | E24: 333 | F24: P1 | G24: Product identity/source match | H24: 15 | I24: FULL | J24: =IF(F24="I1",AVERAGEIF('QA_Images'!$D$2:$D$58,D24,'QA_Images'!$AA$2:$AA$58)/100,IF(I24="FULL",1,IF(I24="PARTIAL",0.5,IF(I24="FAIL",0,"")))) | K24: =IF(J24="",0,H24*J24) | L24: =IF(F24="I1",20*AVERAGEIF('QA_Images'!$D$2:$D$58,D24,'QA_Images'!$AB$2:$AB$58)/100,IF(I24="NOT_CHECKED",0,H24)) | M24: Product identity locked by inventory product_key, handle and product_id; live product JSON matched handle/id and expected image count for position 333. | N24: live json/html; D:\Shopify_Workspace\jeminise_seo\seo_runs\jeminise.com\20260906_234129\qa\20260908_183309\serp_evidence.json; D:\Shopify_Workspace\jeminise_seo\seo_runs\jeminise.com\20260906_234129\qa\20260908_183309\visual_observations.json
A25: 20260908_183309 | B25: qa_batch_034_r3 | C25: r3 | D25: jeminise.com+teal-yellow-softball-comforter-set-vibrant-sports-bedroom-decor | E25: 333 | F25: P2 | G25: Facts, offer and customization | H25: 10 | I25: FULL | J25: =IF(F25="I1",AVERAGEIF('QA_Images'!$D$2:$D$58,D25,'QA_Images'!$AA$2:$AA$58)/100,IF(I25="FULL",1,IF(I25="PARTIAL",0.5,IF(I25="FAIL",0,"")))) | K25: =IF(J25="",0,H25*J25) | L25: =IF(F25="I1",20*AVERAGEIF('QA_Images'!$D$2:$D$58,D25,'QA_Images'!$AB$2:$AB$58)/100,IF(I25="NOT_CHECKED",0,H25)) | M25: Offer facts verified from live JSON/options and full HTML customizer config: options Choose Comforter Size, Pillowcases; customizer labels ['Custom Your Name', 'Custom Your Number']. | N25: live json/html; D:\Shopify_Workspace\jeminise_seo\seo_runs\jeminise.com\20260906_234129\qa\20260908_183309\serp_evidence.json; D:\Shopify_Workspace\jeminise_seo\seo_runs\jeminise.com\20260906_234129\qa\20260908_183309\visual_observations.json
A26: 20260908_183309 | B26: qa_batch_034_r3 | C26: r3 | D26: jeminise.com+teal-yellow-softball-comforter-set-vibrant-sports-bedroom-decor | E26: 333 | F26: K1 | G26: Primary keyword evidence | H26: 10 | I26: PARTIAL | J26: =IF(F26="I1",AVERAGEIF('QA_Images'!$D$2:$D$58,D26,'QA_Images'!$AA$2:$AA$58)/100,IF(I26="FULL",1,IF(I26="PARTIAL",0.5,IF(I26="FAIL",0,"")))) | K26: =IF(J26="",0,H26*J26) | L26: =IF(F26="I1",20*AVERAGEIF('QA_Images'!$D$2:$D$58,D26,'QA_Images'!$AB$2:$AB$58)/100,IF(I26="NOT_CHECKED",0,H26)) | M26: Primary keyword is truthful to the visual motif, but current SERP evidence is mostly broad/related rather than strong exact-match finished product evidence. | N26: live json/html; D:\Shopify_Workspace\jeminise_seo\seo_runs\jeminise.com\20260906_234129\qa\20260908_183309\serp_evidence.json; D:\Shopify_Workspace\jeminise_seo\seo_runs\jeminise.com\20260906_234129\qa\20260908_183309\visual_observations.json | O26: ISS-034-333-K1-SERP-NICHE;ISS-034-333-K2-CLUSTER
A27: 20260908_183309 | B27: qa_batch_034_r3 | C27: r3 | D27: jeminise.com+teal-yellow-softball-comforter-set-vibrant-sports-bedroom-decor | E27: 333 | F27: K2 | G27: Intent/cannibalization separation | H27: 5 | I27: PARTIAL | J27: =IF(F27="I1",AVERAGEIF('QA_Images'!$D$2:$D$58,D27,'QA_Images'!$AA$2:$AA$58)/100,IF(I27="FULL",1,IF(I27="PARTIAL",0.5,IF(I27="FAIL",0,"")))) | K27: =IF(J27="",0,H27*J27) | L27: =IF(F27="I1",20*AVERAGEIF('QA_Images'!$D$2:$D$58,D27,'QA_Images'!$AB$2:$AB$58)/100,IF(I27="NOT_CHECKED",0,H27)) | M27: Keyword differentiation exists by motif, but nearby products in the same softball/cardinal cluster share broad secondary terms and mapping rationale is repetitive. | N27: live json/html; D:\Shopify_Workspace\jeminise_seo\seo_runs\jeminise.com\20260906_234129\qa\20260908_183309\serp_evidence.json; D:\Shopify_Workspace\jeminise_seo\seo_runs\jeminise.com\20260906_234129\qa\20260908_183309\visual_observations.json | O27: ISS-034-333-K1-SERP-NICHE;ISS-034-333-K2-CLUSTER
A28: 20260908_183309 | B28: qa_batch_034_r3 | C28: r3 | D28: jeminise.com+teal-yellow-softball-comforter-set-vibrant-sports-bedroom-decor | E28: 333 | F28: K3 | G28: No unsupported keyword-volume claim | H28: 5 | I28: FULL | J28: =IF(F28="I1",AVERAGEIF('QA_Images'!$D$2:$D$58,D28,'QA_Images'!$AA$2:$AA$58)/100,IF(I28="FULL",1,IF(I28="PARTIAL",0.5,IF(I28="FAIL",0,"")))) | K28: =IF(J28="",0,H28*J28) | L28: =IF(F28="I1",20*AVERAGEIF('QA_Images'!$D$2:$D$58,D28,'QA_Images'!$AB$2:$AB$58)/100,IF(I28="NOT_CHECKED",0,H28)) | M28: No search-volume or ranking claim is made; keyword evidence is correctly limited as SERP_ONLY. | N28: live json/html; D:\Shopify_Workspace\jeminise_seo\seo_runs\jeminise.com\20260906_234129\qa\20260908_183309\serp_evidence.json; D:\Shopify_Workspace\jeminise_seo\seo_runs\jeminise.com\20260906_234129\qa\20260908_183309\visual_observations.json | O28: ISS-034-333-K1-SERP-NICHE;ISS-034-333-K2-CLUSTER
A29: 20260908_183309 | B29: qa_batch_034_r3 | C29: r3 | D29: jeminise.com+teal-yellow-softball-comforter-set-vibrant-sports-bedroom-decor | E29: 333 | F29: T1 | G29: SEO title/meta title | H29: 10 | I29: FULL | J29: =IF(F29="I1",AVERAGEIF('QA_Images'!$D$2:$D$58,D29,'QA_Images'!$AA$2:$AA$58)/100,IF(I29="FULL",1,IF(I29="PARTIAL",0.5,IF(I29="FAIL",0,"")))) | K29: =IF(J29="",0,H29*J29) | L29: =IF(F29="I1",20*AVERAGEIF('QA_Images'!$D$2:$D$58,D29,'QA_Images'!$AB$2:$AB$58)/100,IF(I29="NOT_CHECKED",0,H29)) | M29: meta_title_seo is concise, readable, and maps to the verified motif/product type. | N29: live json/html; D:\Shopify_Workspace\jeminise_seo\seo_runs\jeminise.com\20260906_234129\qa\20260908_183309\serp_evidence.json; D:\Shopify_Workspace\jeminise_seo\seo_runs\jeminise.com\20260906_234129\qa\20260908_183309\visual_observations.json
A30: 20260908_183309 | B30: qa_batch_034_r3 | C30: r3 | D30: jeminise.com+teal-yellow-softball-comforter-set-vibrant-sports-bedroom-decor | E30: 333 | F30: T2 | G30: Product title/H1 proposal | H30: 5 | I30: FULL | J30: =IF(F30="I1",AVERAGEIF('QA_Images'!$D$2:$D$58,D30,'QA_Images'!$AA$2:$AA$58)/100,IF(I30="FULL",1,IF(I30="PARTIAL",0.5,IF(I30="FAIL",0,"")))) | K30: =IF(J30="",0,H30*J30) | L30: =IF(F30="I1",20*AVERAGEIF('QA_Images'!$D$2:$D$58,D30,'QA_Images'!$AB$2:$AB$58)/100,IF(I30="NOT_CHECKED",0,H30)) | M30: title_proposed is publishable as a clean H1/title replacement and fixes the current truncated or mojibake-heavy storefront title. | N30: live json/html; D:\Shopify_Workspace\jeminise_seo\seo_runs\jeminise.com\20260906_234129\qa\20260908_183309\serp_evidence.json; D:\Shopify_Workspace\jeminise_seo\seo_runs\jeminise.com\20260906_234129\qa\20260908_183309\visual_observations.json
A31: 20260908_183309 | B31: qa_batch_034_r3 | C31: r3 | D31: jeminise.com+teal-yellow-softball-comforter-set-vibrant-sports-bedroom-decor | E31: 333 | F31: D1 | G31: Meta description | H31: 5 | I31: FULL | J31: =IF(F31="I1",AVERAGEIF('QA_Images'!$D$2:$D$58,D31,'QA_Images'!$AA$2:$AA$58)/100,IF(I31="FULL",1,IF(I31="PARTIAL",0.5,IF(I31="FAIL",0,"")))) | K31: =IF(J31="",0,H31*J31) | L31: =IF(F31="I1",20*AVERAGEIF('QA_Images'!$D$2:$D$58,D31,'QA_Images'!$AB$2:$AB$58)/100,IF(I31="NOT_CHECKED",0,H31)) | M31: meta_description_seo no longer has hard truncation or dangling ending; length is below 145 but complete and meaningful, so no automatic penalty for character count. | N31: live json/html; D:\Shopify_Workspace\jeminise_seo\seo_runs\jeminise.com\20260906_234129\qa\20260908_183309\serp_evidence.json; D:\Shopify_Workspace\jeminise_seo\seo_runs\jeminise.com\20260906_234129\qa\20260908_183309\visual_observations.json
A32: 20260908_183309 | B32: qa_batch_034_r3 | C32: r3 | D32: jeminise.com+teal-yellow-softball-comforter-set-vibrant-sports-bedroom-decor | E32: 333 | F32: D2 | G32: Description HTML | H32: 10 | I32: PARTIAL | J32: =IF(F32="I1",AVERAGEIF('QA_Images'!$D$2:$D$58,D32,'QA_Images'!$AA$2:$AA$58)/100,IF(I32="FULL",1,IF(I32="PARTIAL",0.5,IF(I32="FAIL",0,"")))) | K32: =IF(J32="",0,H32*J32) | L32: =IF(F32="I1",20*AVERAGEIF('QA_Images'!$D$2:$D$58,D32,'QA_Images'!$AB$2:$AB$58)/100,IF(I32="NOT_CHECKED",0,H32)) | M32: Description facts mostly match live/product evidence, but the body still contains editorial/process phrasing and generic gallery wording that should not ship as final storefront copy. | N32: live json/html; D:\Shopify_Workspace\jeminise_seo\seo_runs\jeminise.com\20260906_234129\qa\20260908_183309\serp_evidence.json; D:\Shopify_Workspace\jeminise_seo\seo_runs\jeminise.com\20260906_234129\qa\20260908_183309\visual_observations.json | O32: ISS-034-333-D2-CUSTOMER-COPY | P32: Rewrite as customer-facing English body copy for Fireball Softball Comforter Set; remove “The copy stays specific...” and avoid process-style gallery wording.
A33: 20260908_183309 | B33: qa_batch_034_r3 | C33: r3 | D33: jeminise.com+teal-yellow-softball-comforter-set-vibrant-sports-bedroom-decor | E33: 333 | F33: I1 | G33: Image/alt QA aggregate | H33: 20 | I33: DERIVED_FROM_IMAGES | J33: =IF(F33="I1",AVERAGEIF('QA_Images'!$D$2:$D$58,D33,'QA_Images'!$AA$2:$AA$58)/100,IF(I33="FULL",1,IF(I33="PARTIAL",0.5,IF(I33="FAIL",0,"")))) | K33: =IF(J33="",0,H33*J33) | L33: =IF(F33="I1",20*AVERAGEIF('QA_Images'!$D$2:$D$58,D33,'QA_Images'!$AB$2:$AB$58)/100,IF(I33="NOT_CHECKED",0,H33)) | M33: Derived from QA_Images average for this product; all images were opened directly in this run. | N33: live json/html; D:\Shopify_Workspace\jeminise_seo\seo_runs\jeminise.com\20260906_234129\qa\20260908_183309\serp_evidence.json; D:\Shopify_Workspace\jeminise_seo\seo_runs\jeminise.com\20260906_234129\qa\20260908_183309\visual_observations.json
A34: 20260908_183309 | B34: qa_batch_034_r3 | C34: r3 | D34: jeminise.com+teal-yellow-softball-comforter-set-vibrant-sports-bedroom-decor | E34: 333 | F34: E1 | G34: Evidence chain and traceability | H34: 5 | I34: PARTIAL | J34: =IF(F34="I1",AVERAGEIF('QA_Images'!$D$2:$D$58,D34,'QA_Images'!$AA$2:$AA$58)/100,IF(I34="FULL",1,IF(I34="PARTIAL",0.5,IF(I34="FAIL",0,"")))) | K34: =IF(J34="",0,H34*J34) | L34: =IF(F34="I1",20*AVERAGEIF('QA_Images'!$D$2:$D$58,D34,'QA_Images'!$AB$2:$AB$58)/100,IF(I34="NOT_CHECKED",0,H34)) | M34: Evidence chain exists, but workbook traceability still carries r2/contact-sheet wording while the actual source file is r3; this QA run compensates with new live/image/SERP evidence. | N34: live json/html; D:\Shopify_Workspace\jeminise_seo\seo_runs\jeminise.com\20260906_234129\qa\20260908_183309\serp_evidence.json; D:\Shopify_Workspace\jeminise_seo\seo_runs\jeminise.com\20260906_234129\qa\20260908_183309\visual_observations.json | O34: ISS-034-333-E1-REVISION-TRACE
A35: 20260908_183309 | B35: qa_batch_034_r3 | C35: r3 | D35: jeminise.com+teal-yellow-softball-bedding-set-stylish-sports-bedroom-decor | E35: 334 | F35: P1 | G35: Product identity/source match | H35: 15 | I35: FULL | J35: =IF(F35="I1",AVERAGEIF('QA_Images'!$D$2:$D$58,D35,'QA_Images'!$AA$2:$AA$58)/100,IF(I35="FULL",1,IF(I35="PARTIAL",0.5,IF(I35="FAIL",0,"")))) | K35: =IF(J35="",0,H35*J35) | L35: =IF(F35="I1",20*AVERAGEIF('QA_Images'!$D$2:$D$58,D35,'QA_Images'!$AB$2:$AB$58)/100,IF(I35="NOT_CHECKED",0,H35)) | M35: Product identity locked by inventory product_key, handle and product_id; live product JSON matched handle/id and expected image count for position 334. | N35: live json/html; D:\Shopify_Workspace\jeminise_seo\seo_runs\jeminise.com\20260906_234129\qa\20260908_183309\serp_evidence.json; D:\Shopify_Workspace\jeminise_seo\seo_runs\jeminise.com\20260906_234129\qa\20260908_183309\visual_observations.json
A36: 20260908_183309 | B36: qa_batch_034_r3 | C36: r3 | D36: jeminise.com+teal-yellow-softball-bedding-set-stylish-sports-bedroom-decor | E36: 334 | F36: P2 | G36: Facts, offer and customization | H36: 10 | I36: FULL | J36: =IF(F36="I1",AVERAGEIF('QA_Images'!$D$2:$D$58,D36,'QA_Images'!$AA$2:$AA$58)/100,IF(I36="FULL",1,IF(I36="PARTIAL",0.5,IF(I36="FAIL",0,"")))) | K36: =IF(J36="",0,H36*J36) | L36: =IF(F36="I1",20*AVERAGEIF('QA_Images'!$D$2:$D$58,D36,'QA_Images'!$AB$2:$AB$58)/100,IF(I36="NOT_CHECKED",0,H36)) | M36: Offer facts verified from live JSON/options and full HTML customizer config: options Choose Comforter Size, Pillowcases; customizer labels ['Custom Your Name', 'Custom Your Number']. | N36: live json/html; D:\Shopify_Workspace\jeminise_seo\seo_runs\jeminise.com\20260906_234129\qa\20260908_183309\serp_evidence.json; D:\Shopify_Workspace\jeminise_seo\seo_runs\jeminise.com\20260906_234129\qa\20260908_183309\visual_observations.json
A37: 20260908_183309 | B37: qa_batch_034_r3 | C37: r3 | D37: jeminise.com+teal-yellow-softball-bedding-set-stylish-sports-bedroom-decor | E37: 334 | F37: K1 | G37: Primary keyword evidence | H37: 10 | I37: FULL | J37: =IF(F37="I1",AVERAGEIF('QA_Images'!$D$2:$D$58,D37,'QA_Images'!$AA$2:$AA$58)/100,IF(I37="FULL",1,IF(I37="PARTIAL",0.5,IF(I37="FAIL",0,"")))) | K37: =IF(J37="",0,H37*J37) | L37: =IF(F37="I1",20*AVERAGEIF('QA_Images'!$D$2:$D$58,D37,'QA_Images'!$AB$2:$AB$58)/100,IF(I37="NOT_CHECKED",0,H37)) | M37: Primary keyword has readable commercial SERP support and maps to the visible motif/product type without unsupported volume claims. | N37: live json/html; D:\Shopify_Workspace\jeminise_seo\seo_runs\jeminise.com\20260906_234129\qa\20260908_183309\serp_evidence.json; D:\Shopify_Workspace\jeminise_seo\seo_runs\jeminise.com\20260906_234129\qa\20260908_183309\visual_observations.json | O37: ISS-034-334-K2-CLUSTER
A38: 20260908_183309 | B38: qa_batch_034_r3 | C38: r3 | D38: jeminise.com+teal-yellow-softball-bedding-set-stylish-sports-bedroom-decor | E38: 334 | F38: K2 | G38: Intent/cannibalization separation | H38: 5 | I38: PARTIAL | J38: =IF(F38="I1",AVERAGEIF('QA_Images'!$D$2:$D$58,D38,'QA_Images'!$AA$2:$AA$58)/100,IF(I38="FULL",1,IF(I38="PARTIAL",0.5,IF(I38="FAIL",0,"")))) | K38: =IF(J38="",0,H38*J38) | L38: =IF(F38="I1",20*AVERAGEIF('QA_Images'!$D$2:$D$58,D38,'QA_Images'!$AB$2:$AB$58)/100,IF(I38="NOT_CHECKED",0,H38)) | M38: Keyword differentiation exists by motif, but nearby products in the same softball/cardinal cluster share broad secondary terms and mapping rationale is repetitive. | N38: live json/html; D:\Shopify_Workspace\jeminise_seo\seo_runs\jeminise.com\20260906_234129\qa\20260908_183309\serp_evidence.json; D:\Shopify_Workspace\jeminise_seo\seo_runs\jeminise.com\20260906_234129\qa\20260908_183309\visual_observations.json | O38: ISS-034-334-K2-CLUSTER
A39: 20260908_183309 | B39: qa_batch_034_r3 | C39: r3 | D39: jeminise.com+teal-yellow-softball-bedding-set-stylish-sports-bedroom-decor | E39: 334 | F39: K3 | G39: No unsupported keyword-volume claim | H39: 5 | I39: FULL | J39: =IF(F39="I1",AVERAGEIF('QA_Images'!$D$2:$D$58,D39,'QA_Images'!$AA$2:$AA$58)/100,IF(I39="FULL",1,IF(I39="PARTIAL",0.5,IF(I39="FAIL",0,"")))) | K39: =IF(J39="",0,H39*J39) | L39: =IF(F39="I1",20*AVERAGEIF('QA_Images'!$D$2:$D$58,D39,'QA_Images'!$AB$2:$AB$58)/100,IF(I39="NOT_CHECKED",0,H39)) | M39: No search-volume or ranking claim is made; keyword evidence is correctly limited as SERP_ONLY. | N39: live json/html; D:\Shopify_Workspace\jeminise_seo\seo_runs\jeminise.com\20260906_234129\qa\20260908_183309\serp_evidence.json; D:\Shopify_Workspace\jeminise_seo\seo_runs\jeminise.com\20260906_234129\qa\20260908_183309\visual_observations.json | O39: ISS-034-334-K2-CLUSTER
A40: 20260908_183309 | B40: qa_batch_034_r3 | C40: r3 | D40: jeminise.com+teal-yellow-softball-bedding-set-stylish-sports-bedroom-decor | E40: 334 | F40: T1 | G40: SEO title/meta title | H40: 10 | I40: FULL | J40: =IF(F40="I1",AVERAGEIF('QA_Images'!$D$2:$D$58,D40,'QA_Images'!$AA$2:$AA$58)/100,IF(I40="FULL",1,IF(I40="PARTIAL",0.5,IF(I40="FAIL",0,"")))) | K40: =IF(J40="",0,H40*J40) | L40: =IF(F40="I1",20*AVERAGEIF('QA_Images'!$D$2:$D$58,D40,'QA_Images'!$AB$2:$AB$58)/100,IF(I40="NOT_CHECKED",0,H40)) | M40: meta_title_seo is concise, readable, and maps to the verified motif/product type. | N40: live json/html; D:\Shopify_Workspace\jeminise_seo\seo_runs\jeminise.com\20260906_234129\qa\20260908_183309\serp_evidence.json; D:\Shopify_Workspace\jeminise_seo\seo_runs\jeminise.com\20260906_234129\qa\20260908_183309\visual_observations.json
...

Sheet QA_Images
A1: qa_run_id | B1: qa_batch_id | C1: revision | D1: product_key | E1: inventory_position | F1: handle | G1: qa_image_key | H1: media_id | I1: image_location | J1: image_number | K1: image_url_source | L1: image_url_workbook | M1: local_path | N1: source_opened | O1: visual_checked | P1: image_present_in_live | Q1: image_present_in_workbook | R1: submitted_observation | S1: qa_observation | T1: alt_action | U1: alt_current | V1: alt_effective | W1: IM1 | X1: IM2 | Y1: IM3 | Z1: IM4 | AA1: image_verified_points | AB1: image_assessed_weight | AC1: image_final_score | AD1: image_score_lower_bound | AE1: image_score_upper_bound | AF1: issue_refs | AG1: evidence_refs
