Workbook

Sheet QA_Summary
A1: metric | B1: value | C1: definition
A2: shop_domain | B2: jeminise.com | C2: Shop being audited.
A3: qa_run_id | B3: 20260908_101455 | C3: New independent QA run.
A4: qa_batch_id | B4: qa_batch_016 | C4: Fixed inventory positions 151-160.
A5: revision | B5: r3 | C5: Revision under independent QA.
A6: market_language | B6: United States / English | C6: QA locale and content language.
A7: source_workbook | B7: D:\Shopify_Workspace\jeminise_seo\resutls\jeminise.com\20260906_234129\revisions\qa_batch_016_r3\SEO_Product_Optimization_qa_batch_016_r3.xlsx | C7: Frozen source workbook.
A8: source_sha256 | B8: 222E407ED2D5DE355924919CAB060C215CC109CD68127C14D7FB292237A45ABE | C8: SHA-256 at freeze.
A9: scope | B9: 10 products, 71/71 images | C9: Product and image baseline.
A10: batch_score | B10: 80 | C10: Mean of ten independently assessed product scores.
A11: status_counts | B11: {"QA_REVISE": 7, "QA_PASS": 3} | C11: Rubric status counts.
A12: issue_counts | B12: {"MINOR": 50, "LIMITATION": 10} | C12: Severity counts.
A13: awaiting_confirmation | B13: TRUE | C13: Stop before batch 17.

Sheet QA_Products
A1: inventory_position | B1: product_key | C1: url | D1: handle | E1: product_id | F1: revision | G1: verified_points | H1: assessed_weight | I1: score_lower_bound | J1: score_upper_bound | K1: final_score | L1: qa_status | M1: keyword_evidence_level | N1: images_expected | O1: images_checked | P1: image_inventory_complete | Q1: image_coverage | R1: critical_count | S1: major_count | T1: minor_count | U1: limitation_count | V1: issue_refs | W1: evidence_refs
A2: 151 | B2: jeminise.com+giraffe-patchwork-style-printed-quilt-animal-patchwork-bedding | C2: https://jeminise.com/products/giraffe-patchwork-style-printed-quilt-animal-patchwork-bedding | D2: giraffe-patchwork-style-printed-quilt-animal-patchwork-bedding | E2: 8867094364359 | F2: r3 | G2: =SUMIF(QA_Criteria!A:A,B2,QA_Criteria!F:F) | H2: =SUMIF(QA_Criteria!A:A,B2,QA_Criteria!G:G) | K2: =IF(AND(H2=100,Q2=1,O2=N2),G2,"") | L2: =IF(R2>0,"QA_FAIL",IF(K2="","QA_INCOMPLETE",IF(K2<70,"QA_FAIL",IF(OR(K2<85,S2>0),"QA_REVISE","QA_PASS")))) | M2: SERP_ONLY | N2: 7 | O2: 7 | P2: TRUE | Q2: 1 | R2: 0 | S2: 0 | T2: 5 | U2: 1 | V2: ISSUE-0001; ISSUE-0002; ISSUE-0003; ISSUE-0031; ISSUE-0032; ISSUE-0033 | W2: evidence_batch_016_151; live_product_json/151.json; serp_evidence.json
A3: 152 | B3: jeminise.com+horse-patchwork-pattern-quilt-set-vintage-animal-quilt-printed | C3: https://jeminise.com/products/horse-patchwork-pattern-quilt-set-vintage-animal-quilt-printed | D3: horse-patchwork-pattern-quilt-set-vintage-animal-quilt-printed | E3: 8867094626503 | F3: r3 | G3: =SUMIF(QA_Criteria!A:A,B3,QA_Criteria!F:F) | H3: =SUMIF(QA_Criteria!A:A,B3,QA_Criteria!G:G) | K3: =IF(AND(H3=100,Q3=1,O3=N3),G3,"") | L3: =IF(R3>0,"QA_FAIL",IF(K3="","QA_INCOMPLETE",IF(K3<70,"QA_FAIL",IF(OR(K3<85,S3>0),"QA_REVISE","QA_PASS")))) | M3: SERP_ONLY | N3: 7 | O3: 7 | P3: TRUE | Q3: 1 | R3: 0 | S3: 0 | T3: 4 | U3: 1 | V3: ISSUE-0004; ISSUE-0005; ISSUE-0034; ISSUE-0035; ISSUE-0036 | W3: evidence_batch_016_152; live_product_json/152.json; serp_evidence.json
A4: 153 | B4: jeminise.com+horse-patchwork-pattern-quilt-animal-farmhouse-quilt-set-patchwork | C4: https://jeminise.com/products/horse-patchwork-pattern-quilt-animal-farmhouse-quilt-set-patchwork | D4: horse-patchwork-pattern-quilt-animal-farmhouse-quilt-set-patchwork | E4: 8867095642311 | F4: r3 | G4: =SUMIF(QA_Criteria!A:A,B4,QA_Criteria!F:F) | H4: =SUMIF(QA_Criteria!A:A,B4,QA_Criteria!G:G) | K4: =IF(AND(H4=100,Q4=1,O4=N4),G4,"") | L4: =IF(R4>0,"QA_FAIL",IF(K4="","QA_INCOMPLETE",IF(K4<70,"QA_FAIL",IF(OR(K4<85,S4>0),"QA_REVISE","QA_PASS")))) | M4: SERP_ONLY | N4: 7 | O4: 7 | P4: TRUE | Q4: 1 | R4: 0 | S4: 0 | T4: 4 | U4: 1 | V4: ISSUE-0006; ISSUE-0007; ISSUE-0037; ISSUE-0038; ISSUE-0039 | W4: evidence_batch_016_153; live_product_json/153.json; serp_evidence.json
A5: 154 | B5: jeminise.com+i-am-who-he-says-i-am-christian-scripture-blanket-inspirational | C5: https://jeminise.com/products/i-am-who-he-says-i-am-christian-scripture-blanket-inspirational | D5: i-am-who-he-says-i-am-christian-scripture-blanket-inspirational | E5: 8860132835527 | F5: r3 | G5: =SUMIF(QA_Criteria!A:A,B5,QA_Criteria!F:F) | H5: =SUMIF(QA_Criteria!A:A,B5,QA_Criteria!G:G) | K5: =IF(AND(H5=100,Q5=1,O5=N5),G5,"") | L5: =IF(R5>0,"QA_FAIL",IF(K5="","QA_INCOMPLETE",IF(K5<70,"QA_FAIL",IF(OR(K5<85,S5>0),"QA_REVISE","QA_PASS")))) | M5: SERP_ONLY | N5: 8 | O5: 8 | P5: TRUE | Q5: 1 | R5: 0 | S5: 0 | T5: 6 | U5: 1 | V5: ISSUE-0008; ISSUE-0009; ISSUE-0010; ISSUE-0011; ISSUE-0040; ISSUE-0041; ISSUE-0042 | W5: evidence_batch_016_154; live_product_json/154.json; serp_evidence.json
A6: 155 | B6: jeminise.com+nature-and-mythology-tree-of-life-quilt-set-with-twisted-tree-trunk-ceb2e637d5-ceb2e637d5 | C6: https://jeminise.com/products/nature-and-mythology-tree-of-life-quilt-set-with-twisted-tree-trunk-ceb2e637d5-ceb2e637d5 | D6: nature-and-mythology-tree-of-life-quilt-set-with-twisted-tree-trunk-ceb2e637d5-ceb2e637d5 | E6: 8833343815879 | F6: r3 | G6: =SUMIF(QA_Criteria!A:A,B6,QA_Criteria!F:F) | H6: =SUMIF(QA_Criteria!A:A,B6,QA_Criteria!G:G) | K6: =IF(AND(H6=100,Q6=1,O6=N6),G6,"") | L6: =IF(R6>0,"QA_FAIL",IF(K6="","QA_INCOMPLETE",IF(K6<70,"QA_FAIL",IF(OR(K6<85,S6>0),"QA_REVISE","QA_PASS")))) | M6: SERP_ONLY | N6: 7 | O6: 7 | P6: TRUE | Q6: 1 | R6: 0 | S6: 0 | T6: 4 | U6: 1 | V6: ISSUE-0012; ISSUE-0013; ISSUE-0043; ISSUE-0044; ISSUE-0045 | W6: evidence_batch_016_155; live_product_json/155.json; serp_evidence.json
A7: 156 | B7: jeminise.com+nature-tree-of-life-quilt-set-with-blooming-tree-and-bedroom-and-exposed-roots-d5450715a6-d5450715a6 | C7: https://jeminise.com/products/nature-tree-of-life-quilt-set-with-blooming-tree-and-bedroom-and-exposed-roots-d5450715a6-d5450715a6 | D7: nature-tree-of-life-quilt-set-with-blooming-tree-and-bedroom-and-exposed-roots-d5450715a6-d5450715a6 | E7: 8833359675591 | F7: r3 | G7: =SUMIF(QA_Criteria!A:A,B7,QA_Criteria!F:F) | H7: =SUMIF(QA_Criteria!A:A,B7,QA_Criteria!G:G) | K7: =IF(AND(H7=100,Q7=1,O7=N7),G7,"") | L7: =IF(R7>0,"QA_FAIL",IF(K7="","QA_INCOMPLETE",IF(K7<70,"QA_FAIL",IF(OR(K7<85,S7>0),"QA_REVISE","QA_PASS")))) | M7: SERP_ONLY | N7: 7 | O7: 7 | P7: TRUE | Q7: 1 | R7: 0 | S7: 0 | T7: 4 | U7: 1 | V7: ISSUE-0014; ISSUE-0015; ISSUE-0046; ISSUE-0047; ISSUE-0048 | W7: evidence_batch_016_156; live_product_json/156.json; serp_evidence.json
A8: 157 | B8: jeminise.com+nature-tree-of-life-quilt-set-with-stained-glass-pattern-and-bedroom-2eedde5b65-2eedde5b65 | C8: https://jeminise.com/products/nature-tree-of-life-quilt-set-with-stained-glass-pattern-and-bedroom-2eedde5b65-2eedde5b65 | D8: nature-tree-of-life-quilt-set-with-stained-glass-pattern-and-bedroom-2eedde5b65-2eedde5b65 | E8: 8833360691399 | F8: r3 | G8: =SUMIF(QA_Criteria!A:A,B8,QA_Criteria!F:F) | H8: =SUMIF(QA_Criteria!A:A,B8,QA_Criteria!G:G) | K8: =IF(AND(H8=100,Q8=1,O8=N8),G8,"") | L8: =IF(R8>0,"QA_FAIL",IF(K8="","QA_INCOMPLETE",IF(K8<70,"QA_FAIL",IF(OR(K8<85,S8>0),"QA_REVISE","QA_PASS")))) | M8: SERP_ONLY | N8: 7 | O8: 7 | P8: TRUE | Q8: 1 | R8: 0 | S8: 0 | T8: 4 | U8: 1 | V8: ISSUE-0016; ISSUE-0017; ISSUE-0049; ISSUE-0050; ISSUE-0051 | W8: evidence_batch_016_157; live_product_json/157.json; serp_evidence.json
A9: 158 | B9: jeminise.com+norse-mythology-mjolnir-with-skull-within-circular-celtic-quilt-621115581a-621115581a | C9: https://jeminise.com/products/norse-mythology-mjolnir-with-skull-within-circular-celtic-quilt-621115581a-621115581a | D9: norse-mythology-mjolnir-with-skull-within-circular-celtic-quilt-621115581a-621115581a | E9: 8834805203143 | F9: r3 | G9: =SUMIF(QA_Criteria!A:A,B9,QA_Criteria!F:F) | H9: =SUMIF(QA_Criteria!A:A,B9,QA_Criteria!G:G) | K9: =IF(AND(H9=100,Q9=1,O9=N9),G9,"") | L9: =IF(R9>0,"QA_FAIL",IF(K9="","QA_INCOMPLETE",IF(K9<70,"QA_FAIL",IF(OR(K9<85,S9>0),"QA_REVISE","QA_PASS")))) | M9: SERP_ONLY | N9: 7 | O9: 7 | P9: TRUE | Q9: 1 | R9: 0 | S9: 0 | T9: 4 | U9: 1 | V9: ISSUE-0018; ISSUE-0019; ISSUE-0052; ISSUE-0053; ISSUE-0054 | W9: evidence_batch_016_158; live_product_json/158.json; serp_evidence.json
A10: 159 | B10: jeminise.com+norse-mythology-quilt-with-ravens-b8220cc38c-b8220cc38c | C10: https://jeminise.com/products/norse-mythology-quilt-with-ravens-b8220cc38c-b8220cc38c | D10: norse-mythology-quilt-with-ravens-b8220cc38c-b8220cc38c | E10: 8834807234759 | F10: r3 | G10: =SUMIF(QA_Criteria!A:A,B10,QA_Criteria!F:F) | H10: =SUMIF(QA_Criteria!A:A,B10,QA_Criteria!G:G) | K10: =IF(AND(H10=100,Q10=1,O10=N10),G10,"") | L10: =IF(R10>0,"QA_FAIL",IF(K10="","QA_INCOMPLETE",IF(K10<70,"QA_FAIL",IF(OR(K10<85,S10>0),"QA_REVISE","QA_PASS")))) | M10: SERP_ONLY | N10: 7 | O10: 7 | P10: TRUE | Q10: 1 | R10: 0 | S10: 0 | T10: 8 | U10: 1 | V10: ISSUE-0020; ISSUE-0021; ISSUE-0022; ISSUE-0023; ISSUE-0024; ISSUE-0025; ISSUE-0055; ISSUE-0056; ISSUE-0057 | W10: evidence_batch_016_159; live_product_json/159.json; serp_evidence.json
A11: 160 | B11: jeminise.com+norse-mythology-raven-centered-within-runic-circle-comforter-ab76500bc1-ab76500bc1 | C11: https://jeminise.com/products/norse-mythology-raven-centered-within-runic-circle-comforter-ab76500bc1-ab76500bc1 | D11: norse-mythology-raven-centered-within-runic-circle-comforter-ab76500bc1-ab76500bc1 | E11: 8834809528519 | F11: r3 | G11: =SUMIF(QA_Criteria!A:A,B11,QA_Criteria!F:F) | H11: =SUMIF(QA_Criteria!A:A,B11,QA_Criteria!G:G) | K11: =IF(AND(H11=100,Q11=1,O11=N11),G11,"") | L11: =IF(R11>0,"QA_FAIL",IF(K11="","QA_INCOMPLETE",IF(K11<70,"QA_FAIL",IF(OR(K11<85,S11>0),"QA_REVISE","QA_PASS")))) | M11: SERP_ONLY | N11: 7 | O11: 7 | P11: TRUE | Q11: 1 | R11: 0 | S11: 0 | T11: 7 | U11: 1 | V11: ISSUE-0026; ISSUE-0027; ISSUE-0028; ISSUE-0029; ISSUE-0030; ISSUE-0058; ISSUE-0059; ISSUE-0060 | W11: evidence_batch_016_160; live_product_json/160.json; serp_evidence.json

Sheet QA_Criteria
A1: product_key | B1: criterion_id | C1: weight | D1: assessment | E1: rating | F1: earned_points | G1: assessed_weight | H1: reason | I1: evidence_refs | J1: issue_refs
A2: jeminise.com+giraffe-patchwork-style-printed-quilt-animal-patchwork-bedding | B2: P1 | C2: 15 | D2: PARTIAL | F2: =IF(D2="FULL",C2,IF(D2="PARTIAL",C2*0.5,0)) | G2: =IF(OR(D2="FULL",D2="PARTIAL"),C2,0) | H2: Live product.js ID/handle and frozen workbook identity were checked independently. | I2: evidence_batch_016_151; live_product_json/151.json; serp_evidence.json | J2: ISSUE-0031; ISSUE-0032; ISSUE-0033
A3: jeminise.com+giraffe-patchwork-style-printed-quilt-animal-patchwork-bedding | B3: P2 | C3: 10 | D3: PARTIAL | F3: =IF(D3="FULL",C3,IF(D3="PARTIAL",C3*0.5,0)) | G3: =IF(OR(D3="FULL",D3="PARTIAL"),C3,0) | H3: Variants, options and customization wording were compared with the live product data. | I3: evidence_batch_016_151; live_product_json/151.json; serp_evidence.json | J3: ISSUE-0031; ISSUE-0032; ISSUE-0033
A4: jeminise.com+giraffe-patchwork-style-printed-quilt-animal-patchwork-bedding | B4: K1 | C4: 10 | D4: FULL | F4: =IF(D4="FULL",C4,IF(D4="PARTIAL",C4*0.5,0)) | G4: =IF(OR(D4="FULL",D4="PARTIAL"),C4,0) | H4: Primary keyword was checked for product-level US purchase intent. | I4: evidence_batch_016_151; live_product_json/151.json; serp_evidence.json | J4: ISSUE-0031; ISSUE-0032; ISSUE-0033
A5: jeminise.com+giraffe-patchwork-style-printed-quilt-animal-patchwork-bedding | B5: K2 | C5: 5 | D5: PARTIAL | F5: =IF(D5="FULL",C5,IF(D5="PARTIAL",C5*0.5,0)) | G5: =IF(OR(D5="FULL",D5="PARTIAL"),C5,0) | H5: Comparator URLs and nearby intent were assessed for this product only. | I5: evidence_batch_016_151; live_product_json/151.json; serp_evidence.json | J5: ISSUE-0031; ISSUE-0032; ISSUE-0033
A6: jeminise.com+giraffe-patchwork-style-printed-quilt-animal-patchwork-bedding | B6: K3 | C6: 5 | D6: PARTIAL | F6: =IF(D6="FULL",C6,IF(D6="PARTIAL",C6*0.5,0)) | G6: =IF(OR(D6="FULL",D6="PARTIAL"),C6,0) | H6: Public SERP evidence was rechecked; no volume claim was made. | I6: evidence_batch_016_151; live_product_json/151.json; serp_evidence.json | J6: ISSUE-0031; ISSUE-0032; ISSUE-0033
A7: jeminise.com+giraffe-patchwork-style-printed-quilt-animal-patchwork-bedding | B7: T1 | C7: 10 | D7: FULL | F7: =IF(D7="FULL",C7,IF(D7="PARTIAL",C7*0.5,0)) | G7: =IF(OR(D7="FULL",D7="PARTIAL"),C7,0) | H7: Meta title length and visible motif/product type were checked. | I7: evidence_batch_016_151; live_product_json/151.json; serp_evidence.json | J7: ISSUE-0031; ISSUE-0032; ISSUE-0033
A8: jeminise.com+giraffe-patchwork-style-printed-quilt-animal-patchwork-bedding | B8: T2 | C8: 5 | D8: FULL | F8: =IF(D8="FULL",C8,IF(D8="PARTIAL",C8*0.5,0)) | G8: =IF(OR(D8="FULL",D8="PARTIAL"),C8,0) | H8: Proposed title was checked against the verified design and product type. | I8: evidence_batch_016_151; live_product_json/151.json; serp_evidence.json | J8: ISSUE-0031; ISSUE-0032; ISSUE-0033
A9: jeminise.com+giraffe-patchwork-style-printed-quilt-animal-patchwork-bedding | B9: D1 | C9: 5 | D9: FULL | F9: =IF(D9="FULL",C9,IF(D9="PARTIAL",C9*0.5,0)) | G9: =IF(OR(D9="FULL",D9="PARTIAL"),C9,0) | H9: Description HTML was checked for publish readiness and process language. | I9: evidence_batch_016_151; live_product_json/151.json; serp_evidence.json | J9: ISSUE-0031; ISSUE-0032; ISSUE-0033
A10: jeminise.com+giraffe-patchwork-style-printed-quilt-animal-patchwork-bedding | B10: D2 | C10: 10 | D10: PARTIAL | F10: =IF(D10="FULL",C10,IF(D10="PARTIAL",C10*0.5,0)) | G10: =IF(OR(D10="FULL",D10="PARTIAL"),C10,0) | H10: Description coverage was checked against verified design, options and constraints. | I10: evidence_batch_016_151; live_product_json/151.json; serp_evidence.json | J10: ISSUE-0031; ISSUE-0032; ISSUE-0033
A11: jeminise.com+giraffe-patchwork-style-printed-quilt-animal-patchwork-bedding | B11: I1 | C11: 20 | D11: FULL | F11: =IF(D11="FULL",C11,IF(D11="PARTIAL",C11*0.5,0)) | G11: =IF(OR(D11="FULL",D11="PARTIAL"),C11,0) | H11: Derived from the mean of this product's independently checked image rows. | I11: evidence_batch_016_151; live_product_json/151.json; serp_evidence.json | J11: ISSUE-0031; ISSUE-0032; ISSUE-0033
A12: jeminise.com+giraffe-patchwork-style-printed-quilt-animal-patchwork-bedding | B12: E1 | C12: 5 | D12: PARTIAL | F12: =IF(D12="FULL",C12,IF(D12="PARTIAL",C12*0.5,0)) | G12: =IF(OR(D12="FULL",D12="PARTIAL"),C12,0) | H12: Evidence references are traceable; no admin approval/export was assumed. | I12: evidence_batch_016_151; live_product_json/151.json; serp_evidence.json | J12: ISSUE-0031; ISSUE-0032; ISSUE-0033
A13: jeminise.com+horse-patchwork-pattern-quilt-set-vintage-animal-quilt-printed | B13: P1 | C13: 15 | D13: PARTIAL | F13: =IF(D13="FULL",C13,IF(D13="PARTIAL",C13*0.5,0)) | G13: =IF(OR(D13="FULL",D13="PARTIAL"),C13,0) | H13: Live product.js ID/handle and frozen workbook identity were checked independently. | I13: evidence_batch_016_152; live_product_json/152.json; serp_evidence.json | J13: ISSUE-0034; ISSUE-0035; ISSUE-0036
... A111: jeminise.com+norse-mythology-raven-centered-within-runic-circle-comforter-ab76500bc1-ab76500bc1 | B111: E1 | C111: 5 | D111: PARTIAL | F111: =IF(D111="FULL",C111,IF(D111="PARTIAL",C111*0.5,0)) | G111: =IF(OR(D111="FULL",D111="PARTIAL"),C111,0) | H111: Evidence references are traceable; no admin approval/export was assumed. | I111: evidence_batch_016_160; live_product_json/160.json; serp_evidence.json | J111: ISSUE-0058; ISSUE-0059; ISSUE-0060

Sheet QA_Images
A1: product_key | B1: qa_image_key | C1: image_url_source | D1: image_url_workbook | E1: media_id | F1: workbook_image_id | G1: variant | H1: image_location | I1: check_method | J1: checked_at | K1: qa_observation | L1: submitted_observation | M1: storefront_alt_observed | N1: alt_action | O1: alt_effective | P1: IM1 | Q1: IM2 | R1: IM3 | S1: IM4 | T1: image_verified_points | U1: image_assessed_weight | V1: image_final_score | W1: image_score_lower_bound | X1: image_score_upper_bound | Y1: issue_refs | Z1: evidence_refs
A2: jeminise.com+giraffe-patchwork-style-printed-quilt-animal-patchwork-bedding | B2: img_9b392deb2c5a82b9 | C2: https://cdn.shopify.com/s/files/1/0792/5098/1063/files/603c040a548d71a824cef1c6f7a26003ffc38ac45191f307365700954d9f5728.jpg?v=1787233635 | D2: https://cdn.shopify.com/s/files/1/0792/5098/1063/files/603c040a548d71a824cef1c6f7a26003ffc38ac45191f307365700954d9f5728.jpg?v=1787233635 | E2: 47933456285895 | F2: 47933456285895 | H2: GALLERY | I2: DIRECT_VIEW_IMAGE_TOOL | J2: 2026-09-08T10:14:58+07:00 | K2: Opened directly at readable resolution: D:\Shopify_Workspace\jeminise_seo\seo_runs\jeminise.com\20260906_234129\qa\20260908_101455\images\151_01.jpg; independently checked motif/composition against workbook row. | L2: Bedroom mockup of blue mosaic giraffe quilt with orange giraffe portrait with matching shams. | M2: Giraffe Patchwork Style Printed Quilt, Animal Patchwork Bedding - Farmhouse Quilt Set, Premium Pattern Printed Quilts Giraffe Bedspread, Giraffe Bedding Set | N2: SET | O2: Blue mosaic giraffe quilt set | P2: FULL | Q2: FULL | R2: PARTIAL | S2: FULL | Y2: ISSUE-0001 | Z2: D:\Shopify_Workspace\jeminise_seo\seo_runs\jeminise.com\20260906_234129\qa\20260908_101455\images\151_01.jpg; media_id=47933456285895
A3: jeminise.com+giraffe-patchwork-style-printed-quilt-animal-patchwork-bedding | B3: img_db7a2abf86517be1 | C3: https://cdn.shopify.com/s/files/1/0792/5098/1063/files/288d07bcbdbe668f4ecb93c1608db02380c59dd8d38601892d0aead8bc180702.jpg?v=1787233635 | D3: https://cdn.shopify.com/s/files/1/0792/5098/1063/files/288d07bcbdbe668f4ecb93c1608db02380c59dd8d38601892d0aead8bc180702.jpg?v=1787233635 | E3: 47933456318663 | F3: 47933456318663 | H3: GALLERY | I3: DIRECT_VIEW_IMAGE_TOOL | J3: 2026-09-08T10:14:58+07:00 | K3: Opened directly at readable resolution: D:\Shopify_Workspace\jeminise_seo\seo_runs\jeminise.com\20260906_234129\qa\20260908_101455\images\151_02.jpg; independently checked motif/composition against workbook row. | L3: Room mockup of blue mosaic giraffe quilt with orange giraffe portrait with premium printed craft callout and fabric inset. | M3: Giraffe Patchwork Style Printed Quilt, Animal Patchwork Bedding - Farmhouse Quilt Set, Premium Pattern Printed Quilts Giraffe Bedspread, Giraffe Bedding Set | N3: SET | O3: Blue mosaic giraffe quilt set room mockup | P3: FULL | Q3: FULL | R3: FULL | S3: FULL | Z3: D:\Shopify_Workspace\jeminise_seo\seo_runs\jeminise.com\20260906_234129\qa\20260908_101455\images\151_02.jpg; media_id=47933456318663
A4: jeminise.com+giraffe-patchwork-style-printed-quilt-animal-patchwork-bedding | B4: img_e43a39b20e37bab3 | C4: https://cdn.shopify.com/s/files/1/0792/5098/1063/files/bd0c76c837967938b4d577ff893ef9c2e807756bc0b37ab9ebf7238cca4042bd.jpg?v=1787233635 | D4: https://cdn.shopify.com/s/files/1/0792/5098/1063/files/bd0c76c837967938b4d577ff893ef9c2e807756bc0b37ab9ebf7238cca4042bd.jpg?v=1787233635 | E4: 47933456351431 | F4: 47933456351431 | H4: GALLERY | I4: DIRECT_VIEW_IMAGE_TOOL | J4: 2026-09-08T10:14:58+07:00 | K4: Opened directly at readable resolution: D:\Shopify_Workspace\jeminise_seo\seo_runs\jeminise.com\20260906_234129\qa\20260908_101455\images\151_03.jpg; independently checked motif/composition against workbook row. | L4: Optional pillow shams panel showing blue mosaic giraffe quilt with orange giraffe portrait. | M4: Giraffe Patchwork Style Printed Quilt, Animal Patchwork Bedding - Farmhouse Quilt Set, Premium Pattern Printed Quilts Giraffe Bedspread, Giraffe Bedding Set | N4: SET | O4: Blue mosaic giraffe quilt set pillow shams | P4: FULL | Q4: FULL | R4: FULL | S4: FULL | Z4: D:\Shopify_Workspace\jeminise_seo\seo_runs\jeminise.com\20260906_234129\qa\20260908_101455\images\151_03.jpg; media_id=47933456351431
A5: jeminise.com+giraffe-patchwork-style-printed-quilt-animal-patchwork-bedding | B5: img_190a5ab48a5e524d | C5: https://cdn.shopify.com/s/files/1/0792/5098/1063/files/f5a5d13d5344a2d7adef506d08259b82c77867e7098b93b86898cdf6c1f1eeb8.jpg?v=1787233635 | D5: https://cdn.shopify.com/s/files/1/0792/5098/1063/files/f5a5d13d5344a2d7adef506d08259b82c77867e7098b93b86898cdf6c1f1eeb8.jpg?v=1787233635 | E5: 47933456384199 | F5: 47933456384199 | H5: GALLERY | I5: DIRECT_VIEW_IMAGE_TOOL | J5: 2026-09-08T10:14:58+07:00 | K5: Opened directly at readable resolution: D:\Shopify_Workspace\jeminise_seo\seo_runs\jeminise.com\20260906_234129\qa\20260908_101455\images\151_04.jpg; independently checked motif/composition against workbook row. | L5: High-quality fabric panel showing blue mosaic giraffe quilt with orange giraffe portrait with quilt detail and pillow mockup. | M5: Giraffe Patchwork Style Printed Quilt, Animal Patchwork Bedding - Farmhouse Quilt Set, Premium Pattern Printed Quilts Giraffe Bedspread, Giraffe Bedding Set | N5: SET | O5: Blue mosaic giraffe quilt set fabric detail panel | P5: FULL | Q5: FULL | R5: FULL | S5: FULL | Z5: D:\Shopify_Workspace\jeminise_seo\seo_runs\jeminise.com\20260906_234129\qa\20260908_101455\images\151_04.jpg; media_id=47933456384199
A6: jeminise.com+giraffe-patchwork-style-printed-quilt-animal-patchwork-bedding | B6: img_d7731867129c0664 | C6: https://cdn.shopify.com/s/files/1/0792/5098/1063/files/a60c14e85b916d148be08985c5fbd6a5131443f5c719a991bd7b0e819566b7cf.jpg?v=1787233635 | D6: https://cdn.shopify.com/s/files/1/0792/5098/1063/files/a60c14e85b916d148be08985c5fbd6a5131443f5c719a991bd7b0e819566b7cf.jpg?v=1787233635 | E6: 47933456416967 | F6: 47933456416967 | H6: GALLERY | I6: DIRECT_VIEW_IMAGE_TOOL | J6: 2026-09-08T10:14:58+07:00 | K6: Opened directly at readable resolution: D:\Shopify_Workspace\jeminise_seo\seo_runs\jeminise.com\20260906_234129\qa\20260908_101455\images\151_05.jpg; independently checked motif/composition against workbook row. | L6: Premium quilt set size chart showing available bed sizes and measurements. | M6: Giraffe Patchwork Style Printed Quilt, Animal Patchwork Bedding - Farmhouse Quilt Set, Premium Pattern Printed Quilts Giraffe Bedspread, Giraffe Bedding Set | N6: SET | O6: Quilt set size chart | P6: FULL | Q6: FULL | R6: PARTIAL | S6: FULL | Y6: ISSUE-0002 | Z6: D:\Shopify_Workspace\jeminise_seo\seo_runs\jeminise.com\20260906_234129\qa\20260908_101455\images\151_05.jpg; media_id=47933456416967
A7: jeminise.com+giraffe-patchwork-style-printed-quilt-animal-patchwork-bedding | B7: img_5d8ad93523cc8cc3 | C7: https://cdn.shopify.com/s/files/1/0792/5098/1063/files/1981b27c6fedf88c3cb44a9ba34f2731ecaf38e935e82614835b12142e1c6a31.jpg?v=1787233635 | D7: https://cdn.shopify.com/s/files/1/0792/5098/1063/files/1981b27c6fedf88c3cb44a9ba34f2731ecaf38e935e82614835b12142e1c6a31.jpg?v=1787233635 | E7: 47933456449735 | F7: 47933456449735 | H7: GALLERY | I7: DIRECT_VIEW_IMAGE_TOOL | J7: 2026-09-08T10:14:58+07:00 | K7: Opened directly at readable resolution: D:\Shopify_Workspace\jeminise_seo\seo_runs\jeminise.com\20260906_234129\qa\20260908_101455\images\151_06.jpg; independently checked motif/composition against workbook row. | L7: Bedspread features panel showing quilt layers and anti-wrinkle, anti-static and machine-washable icons. | M7: Giraffe Patchwork Style Printed Quilt, Animal Patchwork Bedding - Farmhouse Quilt Set, Premium Pattern Printed Quilts Giraffe Bedspread, Giraffe Bedding Set | N7: SET | O7: Quilt construction feature panel | P7: FULL | Q7: FULL | R7: PARTIAL | S7: FULL | Y7: ISSUE-0003 | Z7: D:\Shopify_Workspace\jeminise_seo\seo_runs\jeminise.com\20260906_234129\qa\20260908_101455\images\151_06.jpg; media_id=47933456449735
A8: jeminise.com+giraffe-patchwork-style-printed-quilt-animal-patchwork-bedding | B8: img_f238615aa97cdd95 | C8: https://cdn.shopify.com/s/files/1/0792/5098/1063/files/c3434f966cfbdf098091125e6432da488e48020e005baf7613b44ceb3d691a8e.jpg?v=1787233635 | D8: https://cdn.shopify.com/s/files/1/0792/5098/1063/files/c3434f966cfbdf098091125e6432da488e48020e005baf7613b44ceb3d691a8e.jpg?v=1787233635 | E8: 47933456482503 | F8: 47933456482503 | H8: GALLERY | I8: DIRECT_VIEW_IMAGE_TOOL | J8: 2026-09-08T10:14:58+07:00 | K8: Opened directly at readable resolution: D:\Shopify_Workspace\jeminise_seo\seo_runs\jeminise.com\20260906_234129\qa\20260908_101455\images\151_07.jpg; independently checked motif/composition against workbook row. | L8: Second bedroom mockup of blue mosaic giraffe quilt with orange giraffe portrait with matching shams. | M8: Giraffe Patchwork Style Printed Quilt, Animal Patchwork Bedding - Farmhouse Quilt Set, Premium Pattern Printed Quilts Giraffe Bedspread, Giraffe Bedding Set | N8: SET | O8: Blue mosaic giraffe quilt set bedroom mockup | P8: FULL | Q8: FULL | R8: FULL | S8: FULL | Z8: D:\Shopify_Workspace\jeminise_seo\seo_runs\jeminise.com\20260906_234129\qa\20260908_101455\images\151_07.jpg; media_id=47933456482503
A9: jeminise.com+horse-patchwork-pattern-quilt-set-vintage-animal-quilt-printed | B9: img_04778e6c637fa5ca | C9: https://cdn.shopify.com/s/files/1/0792/5098/1063/files/6af34be75f66e81fc6baf14d54a155fe69d04261be33ea9d8242b2b79aa2796b.jpg?v=1787233650 | D9: https://cdn.shopify.com/s/files/1/0792/5098/1063/files/6af34be75f66e81fc6baf14d54a155fe69d04261be33ea9d8242b2b79aa2796b.jpg?v=1787233650 | E9: 47933458415815 | F9: 47933458415815 | H9: GALLERY | I9: DIRECT_VIEW_IMAGE_TOOL | J9: 2026-09-08T10:14:58+07:00 | K9: Opened directly at readable resolution: D:\Shopify_Workspace\jeminise_seo\seo_runs\jeminise.com\20260906_234129\qa\20260908_101455\images\152_01.jpg; independently checked motif/composition against workbook row. | L9: Bedroom mockup of vintage horse quilt with red-orange circular frame and flowing mane with matching shams. | M9: Horse Patchwork Pattern Quilt Set, Vintage Animal Quilt Printed Patchwork Style, Horse Printed Bedset Full Queen Size Quilts Bedspread, Best Gift for Bedroom Decor | N9: SET | O9: Vintage circle horse quilt set | P9: FULL | Q9: FULL | R9: PARTIAL | S9: FULL | Y9: ISSUE-0004 | Z9: D:\Shopify_Workspace\jeminise_seo\seo_runs\jeminise.com\20260906_234129\qa\20260908_101455\images\152_01.jpg; media_id=47933458415815
A10: jeminise.com+horse-patchwork-pattern-quilt-set-vintage-animal-quilt-printed | B10: img_c1220d2062ed7cf8 | C10: https://cdn.shopify.com/s/files/1/0792/5098/1063/files/7965222b1165a822ac3995c4ff11f6015e83672c0952cae690bcc35c02047cdf.jpg?v=1787233650 | D10: https://cdn.shopify.com/s/files/1/0792/5098/1063/files/7965222b1165a822ac3995c4ff11f6015e83672c0952cae690bcc35c02047cdf.jpg?v=1787233650 | E10: 47933458448583 | F10: 47933458448583 | H10: GALLERY | I10: DIRECT_VIEW_IMAGE_TOOL | J10: 2026-09-08T10:14:58+07:00 | K10: Opened directly at readable resolution: D:\Shopify_Workspace\jeminise_seo\seo_runs\jeminise.com\20260906_234129\qa\20260908_101455\images\152_02.jpg; independently checked motif/composition against workbook row. | L10: Room mockup of vintage horse quilt with red-orange circular frame and flowing mane with premium printed craft callout and fabric inset. | M10: Horse Patchwork Pattern Quilt Set, Vintage Animal Quilt Printed Patchwork Style, Horse Printed Bedset Full Queen Size Quilts Bedspread, Best Gift for Bedroom Decor | N10: SET | O10: Vintage circle horse quilt set room mockup | P10: FULL | Q10: FULL | R10: FULL | S10: FULL | Z10: D:\Shopify_Workspace\jeminise_seo\seo_runs\jeminise.com\20260906_234129\qa\20260908_101455\images\152_02.jpg; media_id=47933458448583
A11: jeminise.com+horse-patchwork-pattern-quilt-set-vintage-animal-quilt-printed | B11: img_27046b944b83d085 | C11: https://cdn.shopify.com/s/files/1/0792/5098/1063/files/079cec84e8f4643fe4fc5313cc8d480684d4308ee77013bfae2a6f1de077713a.jpg?v=1787233650 | D11: https://cdn.shopify.com/s/files/1/0792/5098/1063/files/079cec84e8f4643fe4fc5313cc8d480684d4308ee77013bfae2a6f1de077713a.jpg?v=1787233650 | E11: 47933458481351 | F11: 47933458481351 | H11: GALLERY | I11: DIRECT_VIEW_IMAGE_TOOL | J11: 2026-09-08T10:14:58+07:00 | K11: Opened directly at readable resolution: D:\Shopify_Workspace\jeminise_seo\seo_runs\jeminise.com\20260906_234129\qa\20260908_101455\images\152_03.jpg; independently checked motif/composition against workbook row. | L11: Optional pillow shams panel showing vintage horse quilt with red-orange circular frame and flowing mane. | M11: Horse Patchwork Pattern Quilt Set, Vintage Animal Quilt Printed Patchwork Style, Horse Printed Bedset Full Queen Size Quilts Bedspread, Best Gift for Bedroom Decor | N11: SET | O11: Vintage circle horse quilt set pillow shams | P11: FULL | Q11: FULL | R11: FULL | S11: FULL | Z11: D:\Shopify_Workspace\jeminise_seo\seo_runs\jeminise.com\20260906_234129\qa\20260908_101455\images\152_03.jpg; media_id=47933458481351
A12: jeminise.com+horse-patchwork-pattern-quilt-set-vintage-animal-quilt-printed | B12: img_a640c8ae6090bb03 | C12: https://cdn.shopify.com/s/files/1/0792/5098/1063/files/e5737c32c3e36b9f2ef4b89a1ccd09485c37705d9ffc1b3553bcb7e3c1ea0107.jpg?v=1787233649 | D12: https://cdn.shopify.com/s/files/1/0792/5098/1063/files/e5737c32c3e36b9f2ef4b89a1ccd09485c37705d9ffc1b3553bcb7e3c1ea0107.jpg?v=1787233649 | E12: 47933458514119 | F12: 47933458514119 | H12: GALLERY | I12: DIRECT_VIEW_IMAGE_TOOL | J12: 2026-09-08T10:14:58+07:00 | K12: Opened directly at readable resolution: D:\Shopify_Workspace\jeminise_seo\seo_runs\jeminise.com\20260906_234129\qa\20260908_101455\images\152_04.jpg; independently checked motif/composition against workbook row. | L12: High-quality fabric panel showing vintage horse quilt with red-orange circular frame and flowing mane with quilt detail and pillow mockup. | M12: Horse Patchwork Pattern Quilt Set, Vintage Animal Quilt Printed Patchwork Style, Horse Printed Bedset Full Queen Size Quilts Bedspread, Best Gift for Bedroom Decor | N12: SET | O12: Vintage circle horse quilt set fabric detail panel | P12: FULL | Q12: FULL | R12: FULL | S12: FULL | Z12: D:\Shopify_Workspace\jeminise_seo\seo_runs\jeminise.com\20260906_234129\qa\20260908_101455\images\152_04.jpg; media_id=47933458514119
A13: jeminise.com+horse-patchwork-pattern-quilt-set-vintage-animal-quilt-printed | B13: img_6bfc617830c7701f | C13: https://cdn.shopify.com/s/files/1/0792/5098/1063/files/79ab35939240f2b72f138699920030b81bef2ec0652b0503f4158443a5a766ce.jpg?v=1787233650 | D13: https://cdn.shopify.com/s/files/1/0792/5098/1063/files/79ab35939240f2b72f138699920030b81bef2ec0652b0503f4158443a5a766ce.jpg?v=1787233650 | E13: 47933458546887 | F13: 47933458546887 | H13: GALLERY | I13: DIRECT_VIEW_IMAGE_TOOL | J13: 2026-09-08T10:14:58+07:00 | K13: Opened directly at readable resolution: D:\Shopify_Workspace\jeminise_seo\seo_runs\jeminise.com\20260906_234129\qa\20260908_101455\images\152_05.jpg; independently checked motif/composition against workbook row. | L13: Premium quilt set size chart showing available bed sizes and measurements. | M13: Horse Patchwork Pattern Quilt Set, Vintage Animal Quilt Printed Patchwork Style, Horse Printed Bedset Full Queen Size Quilts Bedspread, Best Gift for Bedroom Decor | N13: SET | O13: Quilt set size chart for red orange circular horse patchwork quilt set | P13: FULL | Q13: FULL | R13: PARTIAL | S13: FULL | Y13: ISSUE-0005 | Z13: D:\Shopify_Workspace\jeminise_seo\seo_runs\jeminise.com\20260906_234129\qa\20260908_101455\images\152_05.jpg; media_id=47933458546887
A14: jeminise.com+horse-patchwork-pattern-quilt-set-vintage-animal-quilt-printed | B14: img_e2c9283973db8225 | C14: https://cdn.shopify.com/s/files/1/0792/5098/1063/files/aa0186266f9f40306112cd5b9a538722d1a191d3fc2ca0612a55040475d58c38.jpg?v=1787233649 | D14: https://cdn.shopify.com/s/files/1/0792/5098/1063/files/aa0186266f9f40306112cd5b9a538722d1a191d3fc2ca0612a55040475d58c38.jpg?v=1787233649 | E14: 47933458579655 | F14: 47933458579655 | H14: GALLERY | I14: DIRECT_VIEW_IMAGE_TOOL | J14: 2026-09-08T10:14:58+07:00 | K14: Opened directly at readable resolution: D:\Shopify_Workspace\jeminise_seo\seo_runs\jeminise.com\20260906_234129\qa\20260908_101455\images\152_06.jpg; independently checked motif/composition against workbook row. | L14: Bedspread features panel showing quilt layers and anti-wrinkle, anti-static and machine-washable icons. | M14: Horse Patchwork Pattern Quilt Set, Vintage Animal Quilt Printed Patchwork Style, Horse Printed Bedset Full Queen Size Quilts Bedspread, Best Gift for Bedroom Decor | N14: SET | O14: Quilt construction feature panel for red orange circular horse patchwork quilt set | P14: FULL | Q14: FULL | R14: FULL | S14: FULL | Z14: D:\Shopify_Workspace\jeminise_seo\seo_runs\jeminise.com\20260906_234129\qa\20260908_101455\images\152_06.jpg; media_id=47933458579655
A15: jeminise.com+horse-patchwork-pattern-quilt-set-vintage-animal-quilt-printed | B15: img_b00620a61ba7e120 | C15: https://cdn.shopify.com/s/files/1/0792/5098/1063/files/2cd4d2b6fdd2d1c9745f55497855adffb6ff7e81eb6a7214987147cf013ce827.jpg?v=1787233649 | D15: https://cdn.shopify.com/s/files/1/0792/5098/1063/files/2cd4d2b6fdd2d1c9745f55497855adffb6ff7e81eb6a7214987147cf013ce827.jpg?v=1787233649 | E15: 47933458612423 | F15: 47933458612423 | H15: GALLERY | I15: DIRECT_VIEW_IMAGE_TOOL | J15: 2026-09-08T10:14:58+07:00 | K15: Opened directly at readable resolution: D:\Shopify_Workspace\jeminise_seo\seo_runs\jeminise.com\20260906_234129\qa\20260908_101455\images\152_07.jpg; independently checked motif/composition against workbook row. | L15: Second bedroom mockup of vintage horse quilt with red-orange circular frame and flowing mane with matching shams. | M15: Horse Patchwork Pattern Quilt Set, Vintage Animal Quilt Printed Patchwork Style, Horse Printed Bedset Full Queen Size Quilts Bedspread, Best Gift for Bedroom Decor | N15: SET | O15: Vintage circle horse quilt set bedroom mockup | P15: FULL | Q15: FULL | R15: FULL | S15: FULL | Z15: D:\Shopify_Workspace\jeminise_seo\seo_runs\jeminise.com\20260906_234129\qa\20260908_101455\images\152_07.jpg; media_id=47933458612423
A16: jeminise.com+horse-patchwork-pattern-quilt-animal-farmhouse-quilt-set-patchwork | B16: img_60dfd3720f0dcee1 | C16: https://cdn.shopify.com/s/files/1/0792/5098/1063/files/308fce3bc8e7b3da92f3a34fe3e3b89808e57502942118ab0f1ef711df9ac3b6.jpg?v=1787233723 | D16: https://cdn.shopify.com/s/files/1/0792/5098/1063/files/308fce3bc8e7b3da92f3a34fe3e3b89808e57502942118ab0f1ef711df9ac3b6.jpg?v=1787233723 | E16: 47933466837191 | F16: 47933466837191 | H16: GALLERY | I16: DIRECT_VIEW_IMAGE_TOOL | J16: 2026-09-08T10:14:58+07:00 | K16: Opened directly at readable resolution: D:\Shopify_Workspace\jeminise_seo\seo_runs\jeminise.com\20260906_234129\qa\20260908_101455\images\153_01.jpg; independently checked motif/composition against workbook row. | L16: Bedroom mockup of yellow horse patchwork quilt with colorful horse portrait and black mane with matching shams. | M16: Horse Patchwork Pattern Quilt, Animal Farmhouse Quilt Set Patchwork Style, Premium Pattern Printed Quilts, Bedding Present for Mother Christmas | N16: SET | O16: Yellow horse patchwork quilt | P16: FULL | Q16: FULL | R16: PARTIAL | S16: FULL | Y16: ISSUE-0006 | Z16: D:\Shopify_Workspace\jeminise_seo\seo_runs\jeminise.com\20260906_234129\qa\20260908_101455\images\153_01.jpg; media_id=47933466837191
A17: jeminise.com+horse-patchwork-pattern-quilt-animal-farmhouse-quilt-set-patchwork | B17: img_a13efc908a9b6f17 | C17: https://cdn.shopify.com/s/files/1/0792/5098/1063/files/4c5608b305efa3e05d5395aef58ab5eea48b4babb25f41d2af8ffbd1ea6b6b86.jpg?v=1787233723 | D17: https://cdn.shopify.com/s/files/1/0792/5098/1063/files/4c5608b305efa3e05d5395aef58ab5eea48b4babb25f41d2af8ffbd1ea6b6b86.jpg?v=1787233723 | E17: 47933466869959 | F17: 47933466869959 | H17: GALLERY | I17: DIRECT_VIEW_IMAGE_TOOL | J17: 2026-09-08T10:14:58+07:00 | K17: Opened directly at readable resolution: D:\Shopify_Workspace\jeminise_seo\seo_runs\jeminise.com\20260906_234129\qa\20260908_101455\images\153_02.jpg; independently checked motif/composition against workbook row. | L17: Room mockup of yellow horse patchwork quilt with colorful horse portrait and black mane with premium printed craft callout and fabric inset. | M17: Horse Patchwork Pattern Quilt, Animal Farmhouse Quilt Set Patchwork Style, Premium Pattern Printed Quilts, Bedding Present for Mother Christmas | N17: SET | O17: Yellow horse patchwork quilt room mockup | P17: FULL | Q17: FULL | R17: FULL | S17: FULL | Z17: D:\Shopify_Workspace\jeminise_seo\seo_runs\jeminise.com\20260906_234129\qa\20260908_101455\images\153_02.jpg; media_id=47933466869959
A18: jeminise.com+horse-patchwork-pattern-quilt-animal-farmhouse-quilt-set-patchwork | B18: img_94dc902be7fc22ad | C18: https://cdn.shopify.com/s/files/1/0792/5098/1063/files/9a2b9ef1afcd9cb9765c66f3bbe3b1767562b0d4b38297a684fc9070228f522a.jpg?v=1787233724 | D18: https://cdn.shopify.com/s/files/1/0792/5098/1063/files/9a2b9ef1afcd9cb9765c66f3bbe3b1767562b0d4b38297a684fc9070228f522a.jpg?v=1787233724 | E18: 47933466902727 | F18: 47933466902727 | H18: GALLERY | I18: DIRECT_VIEW_IMAGE_TOOL | J18: 2026-09-08T10:14:58+07:00 | K18: Opened directly at readable resolution: D:\Shopify_Workspace\jeminise_seo\seo_runs\jeminise.com\20260906_234129\qa\20260908_101455\images\153_03.jpg; independently checked motif/composition against workbook row. | L18: Optional pillow shams panel showing yellow horse patchwork quilt with colorful horse portrait and black mane. | M18: Horse Patchwork Pattern Quilt, Animal Farmhouse Quilt Set Patchwork Style, Premium Pattern Printed Quilts, Bedding Present for Mother Christmas | N18: SET | O18: Yellow horse patchwork quilt pillow shams | P18: FULL | Q18: FULL | R18: FULL | S18: FULL | Z18: D:\Shopify_Workspace\jeminise_seo\seo_runs\jeminise.com\20260906_234129\qa\20260908_101455\images\153_03.jpg; media_id=47933466902727
A19: jeminise.com+horse-patchwork-pattern-quilt-animal-farmhouse-quilt-set-patchwork | B19: img_9a313b321f37fec1 | C19: https://cdn.shopify.com/s/files/1/0792/5098/1063/files/49c22dfbbbf1132a9e5952d7da89abe81fe14242a946fdcb5ae96cc1616990f9.jpg?v=1787233723 | D19: https://cdn.shopify.com/s/files/1/0792/5098/1063/files/49c22dfbbbf1132a9e5952d7da89abe81fe14242a946fdcb5ae96cc1616990f9.jpg?v=1787233723 | E19: 47933466935495 | F19: 47933466935495 | H19: GALLERY | I19: DIRECT_VIEW_IMAGE_TOOL | J19: 2026-09-08T10:14:58+07:00 | K19: Opened directly at readable resolution: D:\Shopify_Workspace\jeminise_seo\seo_runs\jeminise.com\20260906_234129\qa\20260908_101455\images\153_04.jpg; independently checked motif/composition against workbook row. | L19: High-quality fabric panel showing yellow horse patchwork quilt with colorful horse portrait and black mane with quilt detail and pillow mockup. | M19: Horse Patchwork Pattern Quilt, Animal Farmhouse Quilt Set Patchwork Style, Premium Pattern Printed Quilts, Bedding Present for Mother Christmas | N19: SET | O19: Yellow horse patchwork quilt fabric detail panel | P19: FULL | Q19: FULL | R19: FULL | S19: FULL | Z19: D:\Shopify_Workspace\jeminise_seo\seo_runs\jeminise.com\20260906_234129\qa\20260908_101455\images\153_04.jpg; media_id=47933466935495
A20: jeminise.com+horse-patchwork-pattern-quilt-animal-farmhouse-quilt-set-patchwork | B20: img_4c9a1ab419662d21 | C20: https://cdn.shopify.com/s/files/1/0792/5098/1063/files/9b8a19c9c955be13a8e92d9b72e0dc4de1fe85b37978007b8089d81c3f82285f.jpg?v=1787233723 | D20: https://cdn.shopify.com/s/files/1/0792/5098/1063/files/9b8a19c9c955be13a8e92d9b72e0dc4de1fe85b37978007b8089d81c3f82285f.jpg?v=1787233723 | E20: 47933466968263 | F20: 47933466968263 | H20: GALLERY | I20: DIRECT_VIEW_IMAGE_TOOL | J20: 2026-09-08T10:14:58+07:00 | K20: Opened directly at readable resolution: D:\Shopify_Workspace\jeminise_seo\seo_runs\jeminise.com\20260906_234129\qa\20260908_101455\images\153_05.jpg; independently checked motif/composition against workbook row. | L20: Premium quilt set size chart showing available bed sizes and measurements. | M20: Horse Patchwork Pattern Quilt, Animal Farmhouse Quilt Set Patchwork Style, Premium Pattern Printed Quilts, Bedding Present for Mother Christmas | N20: SET | O20: Quilt set size chart for yellow colorful horse portrait patchwork quilt set | P20: FULL | Q20: FULL | R20: PARTIAL | S20: FULL | Y20: ISSUE-0007 | Z20: D:\Shopify_Workspace\jeminise_seo\seo_runs\jeminise.com\20260906_234129\qa\20260908_101455\images\153_05.jpg; media_id=47933466968263
A21: jeminise.com+horse-patchwork-pattern-quilt-animal-farmhouse-quilt-set-patchwork | B21: img_3c721eb15706778e | C21: https://cdn.shopify.com/s/files/1/0792/5098/1063/files/3316ea0a19642b5165e039218da8442aff4a629226311379497ae4b8c335a66a.jpg?v=1787233723 | D21: https://cdn.shopify.com/s/files/1/0792/5098/1063/files/3316ea0a19642b5165e039218da8442aff4a629226311379497ae4b8c335a66a.jpg?v=1787233723 | E21: 47933467001031 | F21: 47933467001031 | H21: GALLERY | I21: DIRECT_VIEW_IMAGE_TOOL | J21: 2026-09-08T10:14:58+07:00 | K21: Opened directly at readable resolution: D:\Shopify_Workspace\jeminise_seo\seo_runs\jeminise.com\20260906_234129\qa\20260908_101455\images\153_06.jpg; independently checked motif/composition against workbook row. | L21: Bedspread features panel showing quilt layers and anti-wrinkle, anti-static and machine-washable icons. | M21: Horse Patchwork Pattern Quilt, Animal Farmhouse Quilt Set Patchwork Style, Premium Pattern Printed Quilts, Bedding Present for Mother Christmas | N21: SET | O21: Quilt construction feature panel for yellow colorful horse portrait patchwork quilt set | P21: FULL | Q21: FULL | R21: FULL | S21: FULL | Z21: D:\Shopify_Workspace\jeminise_seo\seo_runs\jeminise.com\20260906_234129\qa\20260908_101455\images\153_06.jpg; media_id=47933467001031
A22: jeminise.com+horse-patchwork-pattern-quilt-animal-farmhouse-quilt-set-patchwork | B22: img_ec943f2664dc771d | C22: https://cdn.shopify.com/s/files/1/0792/5098/1063/files/54a6d1664220c3febcad4acc6e2fbea0a63d75b9f24dbec12bb9432b2d09bcb2.jpg?v=1787233723 | D22: https://cdn.shopify.com/s/files/1/0792/5098/1063/files/54a6d1664220c3febcad4acc6e2fbea0a63d75b9f24dbec12bb9432b2d09bcb2.jpg?v=1787233723 | E22: 47933467033799 | F22: 47933467033799 | H22: GALLERY | I22: DIRECT_VIEW_IMAGE_TOOL | J22: 2026-09-08T10:14:58+07:00 | K22: Opened directly at readable resolution: D:\Shopify_Workspace\jeminise_seo\seo_runs\jeminise.com\20260906_234129\qa\20260908_101455\images\153_07.jpg; independently checked motif/composition against workbook row. | L22: Second bedroom mockup of yellow horse patchwork quilt with colorful horse portrait and black mane with matching shams. | M22: Horse Patchwork Pattern Quilt, Animal Farmhouse Quilt Set Patchwork Style, Premium Pattern Printed Quilts, Bedding Present for Mother Christmas | N22: SET | O22: Yellow horse patchwork quilt bedroom mockup | P22: FULL | Q22: FULL | R22: FULL | S22: FULL | Z22: D:\Shopify_Workspace\jeminise_seo\seo_runs\jeminise.com\20260906_234129\qa\20260908_101455\images\153_07.jpg; media_id=47933467033799
A23: jeminise.com+i-am-who-he-says-i-am-christian-scripture-blanket-inspirational | B23: img_41c6df7fe4178ca3 | C23: https://cdn.shopify.com/s/files/1/0792/5098/1063/files/6737389aad72a58c884a7adf23d056ba2152a97cc0c1fb9d53091e1333692b0d.jpg?v=1786596878 | D23: https://cdn.shopify.com/s/files/1/0792/5098/1063/files/6737389aad72a58c884a7adf23d056ba2152a97cc0c1fb9d53091e1333692b0d.jpg?v=1786596878 | E23: 47830600581319 | F23: 47830600581319 | H23: GALLERY | I23: DIRECT_VIEW_IMAGE_TOOL | J23: 2026-09-08T10:14:58+07:00 | K23: Opened directly at readable resolution: D:\Shopify_Workspace\jeminise_seo\seo_runs\jeminise.com\20260906_234129\qa\20260908_101455\images\154_01.jpg; independently checked motif/composition against workbook row. | L23: Person holding white Christian scripture blanket with I Am Who He Says I Am text. | M23: I Am Who He Says I Am Christian Scripture Blanket – Inspirational Bible Verse Faith Gift | N23: SET | O23: I Am Who He Says I Am scripture blanket | P23: FULL | Q23: FULL | R23: FULL | S23: FULL | Z23: D:\Shopify_Workspace\jeminise_seo\seo_runs\jeminise.com\20260906_234129\qa\20260908_101455\images\154_01.jpg; media_id=47830600581319
A24: jeminise.com+i-am-who-he-says-i-am-christian-scripture-blanket-inspirational | B24: img_24e5fe377d3de137 | C24: https://cdn.shopify.com/s/files/1/0792/5098/1063/files/38e48a2c4df64140448da5d8f66681b92c0275a27fa88ab1054cdc4e98a006b3.jpg?v=1786596878 | D24: https://cdn.shopify.com/s/files/1/0792/5098/1063/files/38e48a2c4df64140448da5d8f66681b92c0275a27fa88ab1054cdc4e98a006b3.jpg?v=1786596878 | E24: 47830600614087 | F24: 47830600614087 | H24: GALLERY | I24: DIRECT_VIEW_IMAGE_TOOL | J24: 2026-09-08T10:14:58+07:00 | K24: Opened directly at readable resolution: D:\Shopify_Workspace\jeminise_seo\seo_runs\jeminise.com\20260906_234129\qa\20260908_101455\images\154_02.jpg; independently checked motif/composition against workbook row. | L24: Christian scripture blanket draped on sofa with green and gold typography. | M24: I Am Who He Says I Am Christian Scripture Blanket – Inspirational Bible Verse Faith Gift | N24: SET | O24: Christian scripture blanket on sofa | P24: FULL | Q24: FULL | R24: FULL | S24: FULL | Z24: D:\Shopify_Workspace\jeminise_seo\seo_runs\jeminise.com\20260906_234129\qa\20260908_101455\images\154_02.jpg; media_id=47830600614087
A25: jeminise.com+i-am-who-he-says-i-am-christian-scripture-blanket-inspirational | B25: img_16337c347cb2bfda | C25: https://cdn.shopify.com/s/files/1/0792/5098/1063/files/2ca6551881fb1d1ab0efe08303e1154ff3f85ba3e00e35937a533847c41f5262.jpg?v=1786596878 | D25: https://cdn.shopify.com/s/files/1/0792/5098/1063/files/2ca6551881fb1d1ab0efe08303e1154ff3f85ba3e00e35937a533847c41f5262.jpg?v=1786596878 | E25: 47830600646855 | F25: 47830600646855 | H25: GALLERY | I25: DIRECT_VIEW_IMAGE_TOOL | J25: 2026-09-08T10:14:58+07:00 | K25: Opened directly at readable resolution: D:\Shopify_Workspace\jeminise_seo\seo_runs\jeminise.com\20260906_234129\qa\20260908_101455\images\154_03.jpg; independently checked motif/composition against workbook row. | L25: Blanket style and size panel showing I Am Who He Says I Am design and use-case icons. | M25: I Am Who He Says I Am Christian Scripture Blanket – Inspirational Bible Verse Faith Gift | N25: SET | O25: Scripture blanket style and size panel | P25: FULL | Q25: FULL | R25: FULL | S25: FULL | Z25: D:\Shopify_Workspace\jeminise_seo\seo_runs\jeminise.com\20260906_234129\qa\20260908_101455\images\154_03.jpg; media_id=47830600646855
A26: jeminise.com+i-am-who-he-says-i-am-christian-scripture-blanket-inspirational | B26: img_69d23a5113fe6435 | C26: https://cdn.shopify.com/s/files/1/0792/5098/1063/files/ba094da7e3e316e0dcd2d183aed4f9880c36a1f53ce80c5c9e907b46ef05dd78.jpg?v=1786596878 | D26: https://cdn.shopify.com/s/files/1/0792/5098/1063/files/ba094da7e3e316e0dcd2d183aed4f9880c36a1f53ce80c5c9e907b46ef05dd78.jpg?v=1786596878 | E26: 47830600679623 | F26: 47830600679623 | H26: GALLERY | I26: DIRECT_VIEW_IMAGE_TOOL | J26: 2026-09-08T10:14:58+07:00 | K26: Opened directly at readable resolution: D:\Shopify_Workspace\jeminise_seo\seo_runs\jeminise.com\20260906_234129\qa\20260908_101455\images\154_04.jpg; independently checked motif/composition against workbook row. | L26: Close-up collage showing printed scripture typography and white fleece texture. | M26: I Am Who He Says I Am Christian Scripture Blanket – Inspirational Bible Verse Faith Gift | N26: SET | O26: Christian blanket fleece close-up | P26: FULL | Q26: FULL | R26: PARTIAL | S26: FULL | Y26: ISSUE-0008 | Z26: D:\Shopify_Workspace\jeminise_seo\seo_runs\jeminise.com\20260906_234129\qa\20260908_101455\images\154_04.jpg; media_id=47830600679623
A27: jeminise.com+i-am-who-he-says-i-am-christian-scripture-blanket-inspirational | B27: img_87cfc6af06ad303d | C27: https://cdn.shopify.com/s/files/1/0792/5098/1063/files/24974bb9397010b531aa60a45c84a921fe5f733f09ed246d5668bd13e02edf65.jpg?v=1786596878 | D27: https://cdn.shopify.com/s/files/1/0792/5098/1063/files/24974bb9397010b531aa60a45c84a921fe5f733f09ed246d5668bd13e02edf65.jpg?v=1786596878 | E27: 47830600712391 | F27: 47830600712391 | H27: GALLERY | I27: DIRECT_VIEW_IMAGE_TOOL | J27: 2026-09-08T10:14:58+07:00 | K27: Opened directly at readable resolution: D:\Shopify_Workspace\jeminise_seo\seo_runs\jeminise.com\20260906_234129\qa\20260908_101455\images\154_05.jpg; independently checked motif/composition against workbook row. | L27: I Am Who He Says I Am blanket draped over a living room sofa. | M27: I Am Who He Says I Am Christian Scripture Blanket – Inspirational Bible Verse Faith Gift | N27: SET | O27: Inspirational Christian blanket on sofa | P27: FULL | Q27: FULL | R27: FULL | S27: FULL | Z27: D:\Shopify_Workspace\jeminise_seo\seo_runs\jeminise.com\20260906_234129\qa\20260908_101455\images\154_05.jpg; media_id=47830600712391
A28: jeminise.com+i-am-who-he-says-i-am-christian-scripture-blanket-inspirational | B28: img_c559c2ad7c4a5f7f | C28: https://cdn.shopify.com/s/files/1/0792/5098/1063/files/4ce06f4e7733ae5cf5414a2771a8829b59c43fcfb02b8014356d3defc0c426bb.jpg?v=1786596878 | D28: https://cdn.shopify.com/s/files/1/0792/5098/1063/files/4ce06f4e7733ae5cf5414a2771a8829b59c43fcfb02b8014356d3defc0c426bb.jpg?v=1786596878 | E28: 47830600745159 | F28: 47830600745159 | H28: GALLERY | I28: DIRECT_VIEW_IMAGE_TOOL | J28: 2026-09-08T10:14:58+07:00 | K28: Opened directly at readable resolution: D:\Shopify_Workspace\jeminise_seo\seo_runs\jeminise.com\20260906_234129\qa\20260908_101455\images\154_06.jpg; independently checked motif/composition against workbook row. | L28: Lifestyle image of scripture blanket used while reading with a small dog nearby. | M28: I Am Who He Says I Am Christian Scripture Blanket – Inspirational Bible Verse Faith Gift | N28: SET | O28: Scripture blanket reading lifestyle image | P28: FULL | Q28: PARTIAL | R28: FULL | S28: FULL | Y28: ISSUE-0009 | Z28: D:\Shopify_Workspace\jeminise_seo\seo_runs\jeminise.com\20260906_234129\qa\20260908_101455\images\154_06.jpg; media_id=47830600745159
A29: jeminise.com+i-am-who-he-says-i-am-christian-scripture-blanket-inspirational | B29: img_d972fe731f146602 | C29: https://cdn.shopify.com/s/files/1/0792/5098/1063/files/23c272951a2d07d2fbdcf04ab4208521c5b23847228641a73cd3924699638d91.jpg?v=1786596878 | D29: https://cdn.shopify.com/s/files/1/0792/5098/1063/files/23c272951a2d07d2fbdcf04ab4208521c5b23847228641a73cd3924699638d91.jpg?v=1786596878 | E29: 47830600777927 | F29: 47830600777927 | H29: GALLERY | I29: DIRECT_VIEW_IMAGE_TOOL | J29: 2026-09-08T10:14:58+07:00 | K29: Opened directly at readable resolution: D:\Shopify_Workspace\jeminise_seo\seo_runs\jeminise.com\20260906_234129\qa\20260908_101455\images\154_07.jpg; independently checked motif/composition against workbook row. | L29: Close view of scripture blanket beside an open book and cup. | M29: I Am Who He Says I Am Christian Scripture Blanket – Inspirational Bible Verse Faith Gift | N29: SET | O29: Bible verse blanket close-up | P29: FULL | Q29: FULL | R29: PARTIAL | S29: FULL | Y29: ISSUE-0010 | Z29: D:\Shopify_Workspace\jeminise_seo\seo_runs\jeminise.com\20260906_234129\qa\20260908_101455\images\154_07.jpg; media_id=47830600777927
A30: jeminise.com+i-am-who-he-says-i-am-christian-scripture-blanket-inspirational | B30: img_41665ac7f310f597 | C30: https://cdn.shopify.com/s/files/1/0792/5098/1063/files/938f6556bff4367008c210f8e9026830c80f31da6c23dd60bdac3cc424976220.jpg?v=1786596878 | D30: https://cdn.shopify.com/s/files/1/0792/5098/1063/files/938f6556bff4367008c210f8e9026830c80f31da6c23dd60bdac3cc424976220.jpg?v=1786596878 | E30: 47830600810695 | F30: 47830600810695 | H30: GALLERY | I30: DIRECT_VIEW_IMAGE_TOOL | J30: 2026-09-08T10:14:58+07:00 | K30: Opened directly at readable resolution: D:\Shopify_Workspace\jeminise_seo\seo_runs\jeminise.com\20260906_234129\qa\20260908_101455\images\154_08.jpg; independently checked motif/composition against workbook row. | L30: Fleece blanket feature panel listing machine washable, soft and warm, dense stitching and 260GSM fleece. | M30: I Am Who He Says I Am Christian Scripture Blanket – Inspirational Bible Verse Faith Gift | N30: SET | O30: Fleece blanket feature panel | P30: FULL | Q30: FULL | R30: PARTIAL | S30: FULL | Y30: ISSUE-0011 | Z30: D:\Shopify_Workspace\jeminise_seo\seo_runs\jeminise.com\20260906_234129\qa\20260908_101455\images\154_08.jpg; media_id=47830600810695
A31: jeminise.com+nature-and-mythology-tree-of-life-quilt-set-with-twisted-tree-trunk-ceb2e637d5-ceb2e637d5 | B31: img_4c540bd77f602504 | C31: https://cdn.shopify.com/s/files/1/0792/5098/1063/files/0d785f9d31ce0e89974aacf5b9eaa683a70fa09eff8afaf8a37bfe59e9dde191.jpg?v=1785047001 | D31: https://cdn.shopify.com/s/files/1/0792/5098/1063/files/0d785f9d31ce0e89974aacf5b9eaa683a70fa09eff8afaf8a37bfe59e9dde191.jpg?v=1785047001 | E31: 47531904336071 | F31: 47531904336071 | H31: GALLERY | I31: DIRECT_VIEW_IMAGE_TOOL | J31: 2026-09-08T10:14:58+07:00 | K31: Opened directly at readable resolution: D:\Shopify_Workspace\jeminise_seo\seo_runs\jeminise.com\20260906_234129\qa\20260908_101455\images\155_01.jpg; independently checked motif/composition against workbook row. | L31: Bedroom mockup of cream twisted Tree of Life quilt with green leaves and matching shams. | M31: Nature and Mythology Tree of Life Quilt Set With Twisted Tree Trunk | N31: SET | O31: Cream twisted Tree of Life quilt set | P31: FULL | Q31: FULL | R31: FULL | S31: FULL | Z31: D:\Shopify_Workspace\jeminise_seo\seo_runs\jeminise.com\20260906_234129\qa\20260908_101455\images\155_01.jpg; media_id=47531904336071
A32: jeminise.com+nature-and-mythology-tree-of-life-quilt-set-with-twisted-tree-trunk-ceb2e637d5-ceb2e637d5 | B32: img_ffdeb3847ac032ed | C32: https://cdn.shopify.com/s/files/1/0792/5098/1063/files/d5bd9f652f632cf45ab2af5391fd3c037d26f0c15c1117c753e06da2d771ded7.jpg?v=1785047001 | D32: https://cdn.shopify.com/s/files/1/0792/5098/1063/files/d5bd9f652f632cf45ab2af5391fd3c037d26f0c15c1117c753e06da2d771ded7.jpg?v=1785047001 | E32: 47531904368839 | F32: 47531904368839 | H32: GALLERY | I32: DIRECT_VIEW_IMAGE_TOOL | J32: 2026-09-08T10:14:58+07:00 | K32: Opened directly at readable resolution: D:\Shopify_Workspace\jeminise_seo\seo_runs\jeminise.com\20260906_234129\qa\20260908_101455\images\155_02.jpg; independently checked motif/composition against workbook row. | L32: Optional pillow shams panel showing cream Tree of Life artwork and feature icons. | M32: Nature and Mythology Tree of Life Quilt Set With Twisted Tree Trunk | N32: SET | O32: Cream Tree of Life pillow shams | P32: FULL | Q32: FULL | R32: PARTIAL | S32: FULL | Y32: ISSUE-0012 | Z32: D:\Shopify_Workspace\jeminise_seo\seo_runs\jeminise.com\20260906_234129\qa\20260908_101455\images\155_02.jpg; media_id=47531904368839
A33: jeminise.com+nature-and-mythology-tree-of-life-quilt-set-with-twisted-tree-trunk-ceb2e637d5-ceb2e637d5 | B33: img_cb35db4dc6390935 | C33: https://cdn.shopify.com/s/files/1/0792/5098/1063/files/5ac2def02ca55ef91b1041dbb5f2e346a96f55aedcc9e89c3c6faf8b8780fd0c.jpg?v=1785047001 | D33: https://cdn.shopify.com/s/files/1/0792/5098/1063/files/5ac2def02ca55ef91b1041dbb5f2e346a96f55aedcc9e89c3c6faf8b8780fd0c.jpg?v=1785047001 | E33: 47531904401607 | F33: 47531904401607 | H33: GALLERY | I33: DIRECT_VIEW_IMAGE_TOOL | J33: 2026-09-08T10:14:58+07:00 | K33: Opened directly at readable resolution: D:\Shopify_Workspace\jeminise_seo\seo_runs\jeminise.com\20260906_234129\qa\20260908_101455\images\155_03.jpg; independently checked motif/composition against workbook row. | L33: High-quality fabric panel showing cream Tree of Life quilt detail and pillow mockup. | M33: Nature and Mythology Tree of Life Quilt Set With Twisted Tree Trunk | N33: SET | O33: Cream Tree of Life quilt fabric panel | P33: FULL | Q33: FULL | R33: FULL | S33: FULL | Z33: D:\Shopify_Workspace\jeminise_seo\seo_runs\jeminise.com\20260906_234129\qa\20260908_101455\images\155_03.jpg; media_id=47531904401607
A34: jeminise.com+nature-and-mythology-tree-of-life-quilt-set-with-twisted-tree-trunk-ceb2e637d5-ceb2e637d5 | B34: img_da0eefadfc42011b | C34: https://cdn.shopify.com/s/files/1/0792/5098/1063/files/5afbb8bfe8e0f2cae9c66e8395b79c83ed47af3be8b96e283dbe30499951b424.jpg?v=1785047001 | D34: https://cdn.shopify.com/s/files/1/0792/5098/1063/files/5afbb8bfe8e0f2cae9c66e8395b79c83ed47af3be8b96e283dbe30499951b424.jpg?v=1785047001 | E34: 47531904434375 | F34: 47531904434375 | H34: GALLERY | I34: DIRECT_VIEW_IMAGE_TOOL | J34: 2026-09-08T10:14:58+07:00 | K34: Opened directly at readable resolution: D:\Shopify_Workspace\jeminise_seo\seo_runs\jeminise.com\20260906_234129\qa\20260908_101455\images\155_04.jpg; independently checked motif/composition against workbook row. | L34: Premium quilt set size chart showing available bed sizes and measurements. | M34: Nature and Mythology Tree of Life Quilt Set With Twisted Tree Trunk | N34: SET | O34: Quilt set size chart for cream green twisted Tree of Life quilt set | P34: FULL | Q34: FULL | R34: PARTIAL | S34: FULL | Y34: ISSUE-0013 | Z34: D:\Shopify_Workspace\jeminise_seo\seo_runs\jeminise.com\20260906_234129\qa\20260908_101455\images\155_04.jpg; media_id=47531904434375
A35: jeminise.com+nature-and-mythology-tree-of-life-quilt-set-with-twisted-tree-trunk-ceb2e637d5-ceb2e637d5 | B35: img_bc9efa6ef07b6544 | C35: https://cdn.shopify.com/s/files/1/0792/5098/1063/files/62ee0da0af41f45fddaf42d7df1e5bf17744c92cf93d37e7d07c02b9a51b139f.jpg?v=1785047001 | D35: https://cdn.shopify.com/s/files/1/0792/5098/1063/files/62ee0da0af41f45fddaf42d7df1e5bf17744c92cf93d37e7d07c02b9a51b139f.jpg?v=1785047001 | E35: 47531904467143 | F35: 47531904467143 | H35: GALLERY | I35: DIRECT_VIEW_IMAGE_TOOL | J35: 2026-09-08T10:14:58+07:00 | K35: Opened directly at readable resolution: D:\Shopify_Workspace\jeminise_seo\seo_runs\jeminise.com\20260906_234129\qa\20260908_101455\images\155_05.jpg; independently checked motif/composition against workbook row. | L35: Bedspread features panel showing quilt layers and anti-wrinkle, anti-static and machine-washable icons. | M35: Nature and Mythology Tree of Life Quilt Set With Twisted Tree Trunk | N35: SET | O35: Quilt construction feature panel for cream green twisted Tree of Life quilt set | P35: FULL | Q35: FULL | R35: FULL | S35: FULL | Z35: D:\Shopify_Workspace\jeminise_seo\seo_runs\jeminise.com\20260906_234129\qa\20260908_101455\images\155_05.jpg; media_id=47531904467143
A36: jeminise.com+nature-and-mythology-tree-of-life-quilt-set-with-twisted-tree-trunk-ceb2e637d5-ceb2e637d5 | B36: img_056f2ba116a9da9b | C36: https://cdn.shopify.com/s/files/1/0792/5098/1063/files/03f28650af251cefed46d5c9bc0bb8932f18d148f35526a7c91c998985ab4231.jpg?v=1785047001 | D36: https://cdn.shopify.com/s/files/1/0792/5098/1063/files/03f28650af251cefed46d5c9bc0bb8932f18d148f35526a7c91c998985ab4231.jpg?v=1785047001 | E36: 47531904499911 | F36: 47531904499911 | H36: GALLERY | I36: DIRECT_VIEW_IMAGE_TOOL | J36: 2026-09-08T10:14:58+07:00 | K36: Opened directly at readable resolution: D:\Shopify_Workspace\jeminise_seo\seo_runs\jeminise.com\20260906_234129\qa\20260908_101455\images\155_06.jpg; independently checked motif/composition against workbook row. | L36: Second bedroom mockup of cream twisted Tree of Life quilt with matching shams. | M36: Nature and Mythology Tree of Life Quilt Set With Twisted Tree Trunk | N36: SET | O36: Cream twisted tree quilt bedroom mockup | P36: FULL | Q36: FULL | R36: FULL | S36: FULL | Z36: D:\Shopify_Workspace\jeminise_seo\seo_runs\jeminise.com\20260906_234129\qa\20260908_101455\images\155_06.jpg; media_id=47531904499911
