Workbook

Sheet QA_Summary
A1: qa_run_id | B1: batch_name | C1: auditor | D1: market | E1: language | F1: review_date | G1: total_products | H1: total_images | I1: assessed_weight | J1: average_score | K1: overall_status | L1: qa_pass_count | M1: qa_revise_count | N1: qa_fail_count | O1: qa_incomplete_count
A2: 20260908_143500 | B2: qa_batch_023_r2 | C2: Antigravity Independent QA Assistant | D2: United States | E2: English | F2: 2026-09-08 | G2: 10 | H2: 70 | I2: 100 | J2: =AVERAGE(QA_Products!V2:V11) | K2: =IF(QA_Products!X2="QA_REVISE","QA_REVISE","QA_PASS") | L2: =COUNTIF(QA_Products!X2:X11,"QA_PASS") | M2: =COUNTIF(QA_Products!X2:X11,"QA_REVISE") | N2: =COUNTIF(QA_Products!X2:X11,"QA_FAIL") | O2: =COUNTIF(QA_Products!X2:X11,"QA_INCOMPLETE")

Sheet QA_Products
A1: qa_product_id | B1: product_key | C1: inventory_position | D1: Handle | E1: title_proposed | F1: primary_keyword | G1: product_type | H1: page_read | I1: image_count | J1: P1_score | K1: P2_score | L1: K1_score | M1: K2_score | N1: K3_score | O1: T1_score | P1: T2_score | Q1: D1_score | R1: D2_score | S1: I1_score | T1: E1_score | U1: assessed_weight | V1: final_score | W1: lower_bound | X1: qa_status | Y1: defect_summary
A2: PRODQA-0001 | B2: jeminise.com+personalized-basketball-hoop-with-net-close-up-blanket-with-name-and-number-cc637164fc-cc637164fc | C2: 221 | D2: personalized-basketball-hoop-with-net-close-up-blanket-with-name-and-number-cc637164fc-cc637164fc | E2: Custom Basketball Hoop Blanket | F2: custom basketball hoop blanket | G2: Blanket | H2: TRUE | I2: 8 | J2: 15 | K2: 10 | L2: 10 | M2: 5 | N2: 5 | O2: 10 | P2: 5 | Q2: 3 | R2: 7 | S2: 20 | T2: 5 | U2: 100 | V2: =SUM(J2:T2) | W2: =U2 | X2: =IF(V2>=85,"QA_REVISE",IF(V2>=70,"QA_REVISE","QA_FAIL")) | Y2: D1: Meta description hard-truncated at 155 chars (MINOR). D2: Description contains boilerplate leakage and lacks detailed material/care/options specs (MAJOR). D2 incorrectly mentions product type selection for single-option blanket.
A3: PRODQA-0002 | B3: jeminise.com+personalized-basketball-next-to-athletic-shoes-blanket-with-name-and-number-dfbf4fde2f-dfbf4fde2f | C3: 222 | D3: personalized-basketball-next-to-athletic-shoes-blanket-with-name-and-number-dfbf4fde2f-dfbf4fde2f | E3: Custom Basketball Shoes Blanket | F3: custom basketball shoes blanket | G3: Blanket | H3: TRUE | I3: 8 | J3: 15 | K3: 10 | L3: 10 | M3: 5 | N3: 5 | O3: 10 | P3: 5 | Q3: 3 | R3: 7 | S3: 20 | T3: 5 | U3: 100 | V3: =SUM(J3:T3) | W3: =U3 | X3: =IF(V3>=85,"QA_REVISE",IF(V3>=70,"QA_REVISE","QA_FAIL")) | Y3: D1: Meta description hard-truncated at 155 chars (MINOR). D2: Description contains boilerplate leakage and lacks detailed material/care/options specs (MAJOR). D2 incorrectly mentions product type selection for single-option blanket.
A4: PRODQA-0003 | B4: jeminise.com+personalized-basketball-on-court-lines-comforter-name-number-303fbd50f6-303fbd50f6 | C4: 223 | D4: personalized-basketball-on-court-lines-comforter-name-number-303fbd50f6-303fbd50f6 | E4: Custom Court Lines Basketball Comforter | F4: custom court lines basketball comforter | G4: Comforter | H4: TRUE | I4: 7 | J4: 15 | K4: 10 | L4: 10 | M4: 5 | N4: 5 | O4: 10 | P4: 5 | Q4: 3 | R4: 7 | S4: 20 | T4: 5 | U4: 100 | V4: =SUM(J4:T4) | W4: =U4 | X4: =IF(V4>=85,"QA_REVISE",IF(V4>=70,"QA_REVISE","QA_FAIL")) | Y4: D1: Meta description hard-truncated at 155 chars (MINOR). D2: Description contains boilerplate leakage and lacks detailed material/care/options specs (MAJOR).
A5: PRODQA-0004 | B5: jeminise.com+personalized-basketball-on-court-perspective-comforter-with-name-and-number-1acfbe4260-1acfbe4260 | C5: 224 | D5: personalized-basketball-on-court-perspective-comforter-with-name-and-number-1acfbe4260-1acfbe4260 | E5: Custom Basketball Court Perspective Comforter | F5: custom basketball court perspective comforter | G5: Comforter | H5: TRUE | I5: 5 | J5: 15 | K5: 10 | L5: 10 | M5: 5 | N5: 5 | O5: 10 | P5: 5 | Q5: 3 | R5: 7 | S5: 20 | T5: 5 | U5: 100 | V5: =SUM(J5:T5) | W5: =U5 | X5: =IF(V5>=85,"QA_REVISE",IF(V5>=70,"QA_REVISE","QA_FAIL")) | Y5: D1: Meta description hard-truncated at 155 chars (MINOR). D2: Description contains boilerplate leakage and lacks detailed material/care/options specs (MAJOR).
A6: PRODQA-0005 | B6: jeminise.com+personalized-basketball-on-hardwood-court-comforter-with-name-and-number-8aee799947-8aee799947 | C6: 225 | D6: personalized-basketball-on-hardwood-court-comforter-with-name-and-number-8aee799947-8aee799947 | E6: Custom Hardwood Court Basketball Comforter | F6: custom hardwood court basketball comforter | G6: Comforter | H6: TRUE | I6: 5 | J6: 15 | K6: 10 | L6: 10 | M6: 5 | N6: 5 | O6: 10 | P6: 5 | Q6: 3 | R6: 7 | S6: 20 | T6: 5 | U6: 100 | V6: =SUM(J6:T6) | W6: =U6 | X6: =IF(V6>=85,"QA_REVISE",IF(V6>=70,"QA_REVISE","QA_FAIL")) | Y6: D1: Meta description hard-truncated at 155 chars (MINOR). D2: Description contains boilerplate leakage and lacks detailed material/care/options specs (MAJOR).
A7: PRODQA-0006 | B7: jeminise.com+personalized-neon-basketball-player-blanket-788fb6ae63-788fb6ae63 | C7: 226 | D7: personalized-neon-basketball-player-blanket-788fb6ae63-788fb6ae63 | E7: Custom Neon Basketball Player Blanket | F7: custom neon basketball player blanket | G7: Blanket | H7: TRUE | I7: 8 | J7: 15 | K7: 10 | L7: 10 | M7: 5 | N7: 5 | O7: 10 | P7: 5 | Q7: 3 | R7: 7 | S7: 20 | T7: 5 | U7: 100 | V7: =SUM(J7:T7) | W7: =U7 | X7: =IF(V7>=85,"QA_REVISE",IF(V7>=70,"QA_REVISE","QA_FAIL")) | Y7: D1: Meta description hard-truncated at 155 chars (MINOR). D2: Description contains boilerplate leakage and lacks detailed material/care/options specs (MAJOR). D2 incorrectly mentions product type selection for single-option blanket.
A8: PRODQA-0007 | B8: jeminise.com+personalized-basketball-player-front-blanket-with-name-and-number-258e7f9e2e-258e7f9e2e | C8: 227 | D8: personalized-basketball-player-front-blanket-with-name-and-number-258e7f9e2e-258e7f9e2e | E8: Custom Flaming Basketball Player Blanket | F8: custom flaming basketball player blanket | G8: Blanket | H8: TRUE | I8: 8 | J8: 15 | K8: 10 | L8: 10 | M8: 5 | N8: 5 | O8: 10 | P8: 5 | Q8: 3 | R8: 7 | S8: 20 | T8: 5 | U8: 100 | V8: =SUM(J8:T8) | W8: =U8 | X8: =IF(V8>=85,"QA_REVISE",IF(V8>=70,"QA_REVISE","QA_FAIL")) | Y8: D1: Meta description hard-truncated at 155 chars (MINOR). D2: Description contains boilerplate leakage and lacks detailed material/care/options specs (MAJOR). D2 incorrectly mentions product type selection for single-option blanket.
A9: PRODQA-0008 | B9: jeminise.com+personalized-basketball-player-silhouette-blanket-with-name-and-number-35f8822fba-35f8822fba | C9: 228 | D9: personalized-basketball-player-silhouette-blanket-with-name-and-number-35f8822fba-35f8822fba | E9: Custom Dribbling Silhouette Basketball Blanket | F9: custom dribbling silhouette basketball blanket | G9: Blanket | H9: TRUE | I9: 8 | J9: 15 | K9: 10 | L9: 10 | M9: 5 | N9: 5 | O9: 10 | P9: 5 | Q9: 3 | R9: 7 | S9: 20 | T9: 5 | U9: 100 | V9: =SUM(J9:T9) | W9: =U9 | X9: =IF(V9>=85,"QA_REVISE",IF(V9>=70,"QA_REVISE","QA_FAIL")) | Y9: D1: Meta description hard-truncated at 155 chars (MINOR). D2: Description contains boilerplate leakage and lacks detailed material/care/options specs (MAJOR). D2 incorrectly mentions product type selection for single-option blanket.
A10: PRODQA-0009 | B10: jeminise.com+personalized-basketball-players-and-hoops-comforter-with-name-and-number-ff13bad888-ff13bad888 | C10: 229 | D10: personalized-basketball-players-and-hoops-comforter-with-name-and-number-ff13bad888-ff13bad888 | E10: Custom Basketball Collage Comforter | F10: custom basketball collage comforter | G10: Comforter | H10: TRUE | I10: 7 | J10: 15 | K10: 10 | L10: 10 | M10: 5 | N10: 5 | O10: 10 | P10: 5 | Q10: 3 | R10: 7 | S10: 20 | T10: 5 | U10: 100 | V10: =SUM(J10:T10) | W10: =U10 | X10: =IF(V10>=85,"QA_REVISE",IF(V10>=70,"QA_REVISE","QA_FAIL")) | Y10: D1: Meta description hard-truncated at 155 chars (MINOR). D2: Description contains boilerplate leakage and lacks detailed material/care/options specs (MAJOR).
A11: PRODQA-0010 | B11: jeminise.com+personalized-basketball-shattered-glass-comforter-with-name-and-number-353fc0c17e-353fc0c17e | C11: 230 | D11: personalized-basketball-shattered-glass-comforter-with-name-and-number-353fc0c17e-353fc0c17e | E11: Custom Shattered Glass Basketball Comforter | F11: custom shattered glass basketball comforter | G11: Comforter | H11: TRUE | I11: 6 | J11: 15 | K11: 10 | L11: 10 | M11: 5 | N11: 5 | O11: 10 | P11: 5 | Q11: 3 | R11: 7 | S11: 20 | T11: 5 | U11: 100 | V11: =SUM(J11:T11) | W11: =U11 | X11: =IF(V11>=85,"QA_REVISE",IF(V11>=70,"QA_REVISE","QA_FAIL")) | Y11: D1: Meta description hard-truncated at 155 chars (MINOR). D2: Description contains boilerplate leakage and lacks detailed material/care/options specs (MAJOR). D2 lacks clarification that pillow shams are optional add-ons.

Sheet QA_Criteria
A1: criteria_eval_id | B1: product_key | C1: criterion_id | D1: criterion_name | E1: max_weight | F1: awarded_score | G1: status | H1: observation | I1: evidence_reference
A2: CRIT-0001 | B2: jeminise.com+personalized-basketball-hoop-with-net-close-up-blanket-with-name-and-number-cc637164fc-cc637164fc | C2: P1 | D2: Product Identification | E2: 15 | F2: 15 | G2: PASS | H2: Identified exact product form factor, material texture, and sports artwork motif. | I2: Direct live storefront and image audit
A3: CRIT-0002 | B3: jeminise.com+personalized-basketball-hoop-with-net-close-up-blanket-with-name-and-number-cc637164fc-cc637164fc | C3: P2 | D3: Taxonomy & Configuration | E3: 10 | F3: 10 | G3: PASS | H3: Matches Shopify collection taxonomy and variants configuration structure. | I3: Shopify product type and options audit
A4: CRIT-0003 | B4: jeminise.com+personalized-basketball-hoop-with-net-close-up-blanket-with-name-and-number-cc637164fc-cc637164fc | C4: K1 | D4: Primary Keyword Intent | E4: 10 | F4: 10 | G4: PASS | H4: Primary keyword aligns with US commercial intent for personalized sports gifts. | I4: US Google SERP queries and search demand
A5: CRIT-0004 | B5: jeminise.com+personalized-basketball-hoop-with-net-close-up-blanket-with-name-and-number-cc637164fc-cc637164fc | C5: K2 | D5: Secondary Keyword Depth | E5: 5 | F5: 5 | G5: PASS | H5: Comprehensive coverage of natural long-tail search variations without keyword stuffing. | I5: Keyword_Map audit and SERP verification
A6: CRIT-0005 | B6: jeminise.com+personalized-basketball-hoop-with-net-close-up-blanket-with-name-and-number-cc637164fc-cc637164fc | C6: K3 | D6: Search Intent Alignment | E6: 5 | F6: 5 | G6: PASS | H6: Intent matches youth and sports decor gift purchases; limitations explicitly stated. | I6: Buyer_Search_Research analysis
A7: CRIT-0006 | B7: jeminise.com+personalized-basketball-hoop-with-net-close-up-blanket-with-name-and-number-cc637164fc-cc637164fc | C7: T1 | D7: SEO Title Quality | E7: 10 | F7: 10 | G7: PASS | H7: Concise, descriptive title with primary keyword in leading position. | I7: Title audit and character count check
A8: CRIT-0007 | B8: jeminise.com+personalized-basketball-hoop-with-net-close-up-blanket-with-name-and-number-cc637164fc-cc637164fc | C8: T2 | D8: Meta Title & Branding | E8: 5 | F8: 5 | G8: PASS | H8: Under 60 characters with proper naming structure. | I8: Meta title length and structure audit
A9: CRIT-0008 | B9: jeminise.com+personalized-basketball-hoop-with-net-close-up-blanket-with-name-and-number-cc637164fc-cc637164fc | C9: D1 | D9: Meta Description SEO | E9: 5 | F9: 3 | G9: PARTIAL | H9: Meta description hard-truncated at exactly 155 chars ending in 'ber, selectable' with broken phrasing. | I9: meta_description_seo character count and boundary check
A10: CRIT-0009 | B10: jeminise.com+personalized-basketball-hoop-with-net-close-up-blanket-with-name-and-number-cc637164fc-cc637164fc | C10: D2 | D10: Product Description HTML | E10: 10 | F10: 7 | G10: PARTIAL | H10: Description contains boilerplate leakage ('The copy stays specific...', 'Gallery images include...'), lacks essential fabric/care specs. Contradictorily instructs users to select 'product type and size' for single-option blanket. | I10: description_proposed_html code inspection
A11: CRIT-0010 | B11: jeminise.com+personalized-basketball-hoop-with-net-close-up-blanket-with-name-and-number-cc637164fc-cc637164fc | C11: I1 | D11: Gallery Image Quality | E11: 20 | F11: 20 | G11: PASS | H11: 100% of images verified with bit-for-bit SHA256 integrity and accurate alt text. | I11: Direct pixel visual audit across gallery images
A12: CRIT-0011 | B12: jeminise.com+personalized-basketball-hoop-with-net-close-up-blanket-with-name-and-number-cc637164fc-cc637164fc | C12: E1 | D12: Evidence Completeness | E12: 5 | F12: 5 | G12: PASS | H12: Complete audit evidence across local images, customizer fields, and 20 US SERP queries. | I12: Live storefront, local image files, and SERP verification
A13: CRIT-0012 | B13: jeminise.com+personalized-basketball-next-to-athletic-shoes-blanket-with-name-and-number-dfbf4fde2f-dfbf4fde2f | C13: P1 | D13: Product Identification | E13: 15 | F13: 15 | G13: PASS | H13: Identified exact product form factor, material texture, and sports artwork motif. | I13: Direct live storefront and image audit
... A111: CRIT-0110 | B111: jeminise.com+personalized-basketball-shattered-glass-comforter-with-name-and-number-353fc0c17e-353fc0c17e | C111: E1 | D111: Evidence Completeness | E111: 5 | F111: 5 | G111: PASS | H111: Complete audit evidence across local images, customizer fields, and 20 US SERP queries. | I111: Live storefront, local image files, and SERP verification

Sheet QA_Images
A1: qa_image_id | B1: product_key | C1: Handle | D1: image_number | E1: media_id | F1: filename | G1: dimensions | H1: size_bytes | I1: sha256 | J1: IM1_score | K1: IM2_score | L1: IM3_score | M1: IM4_score | N1: image_final_score | O1: qa_status | P1: visual_observation | Q1: alt_text_review
A2: IMGQA-0001 | B2: jeminise.com+personalized-basketball-hoop-with-net-close-up-blanket-with-name-and-number-cc637164fc-cc637164fc | C2: personalized-basketball-hoop-with-net-close-up-blanket-with-name-and-number-cc637164fc-cc637164fc | D2: 1 | E2: 47538875728071 | F2: 221_01.jpg | G2: 1000x1000 | H2: 118807 | I2: 3dd9f7946998407a3d92fb5221065d55aa043d25887b41c2742e911d242c044a | J2: 40 | K2: 30 | L2: 20 | M2: 10 | N2: =SUM(J2:M2) | O2: =IF(N2>=85,"PASS",IF(N2>=70,"REVISE","FAIL")) | P2: Direct visual review verified: Blanket flat mockup with close-up hoop, white net, sample name Justin and number 23. | Q2: Alt text verified: Custom basketball hoop blanket flat view
A3: IMGQA-0002 | B3: jeminise.com+personalized-basketball-hoop-with-net-close-up-blanket-with-name-and-number-cc637164fc-cc637164fc | C3: personalized-basketball-hoop-with-net-close-up-blanket-with-name-and-number-cc637164fc-cc637164fc | D3: 2 | E3: 47538875760839 | F3: 221_02.jpg | G3: 1000x1000 | H3: 203315 | I3: 36fbbe5dc34eedee6c29eceab10286ed3f8be9651e2becde8057c3470ba74547 | J3: 40 | K3: 30 | L3: 20 | M3: 10 | N3: =SUM(J3:M3) | O3: =IF(N3>=85,"PASS",IF(N3>=70,"REVISE","FAIL")) | P3: Direct visual review verified: Person holds the basketball hoop blanket in a living room with the same sample name and number. | Q3: Alt text verified: Basketball hoop blanket held in living room
A4: IMGQA-0003 | B4: jeminise.com+personalized-basketball-hoop-with-net-close-up-blanket-with-name-and-number-cc637164fc-cc637164fc | C4: personalized-basketball-hoop-with-net-close-up-blanket-with-name-and-number-cc637164fc-cc637164fc | D4: 3 | E4: 47538875793607 | F4: 221_03.jpg | G4: 1000x1000 | H4: 145744 | I4: 41a49d1b148e5f62ff138bd7081020fe252b78d8530008c4dc3f15156f7fa46b | J4: 40 | K4: 30 | L4: 20 | M4: 10 | N4: =SUM(J4:M4) | O4: =IF(N4>=85,"PASS",IF(N4>=70,"REVISE","FAIL")) | P4: Direct visual review verified: Blanket size chart showing 40x30 through 80x60 options with scale figure. | Q4: Alt text verified: Basketball hoop blanket size chart
A5: IMGQA-0004 | B5: jeminise.com+personalized-basketball-hoop-with-net-close-up-blanket-with-name-and-number-cc637164fc-cc637164fc | C5: personalized-basketball-hoop-with-net-close-up-blanket-with-name-and-number-cc637164fc-cc637164fc | D5: 4 | E5: 47538875826375 | F5: 221_04.jpg | G5: 1000x1000 | H5: 166148 | I5: 8331d743bc454025a1a8fa265a8d98e33c2eb0a9ca6f7563359ee4588dfd669d | J5: 40 | K5: 30 | L5: 20 | M5: 10 | N5: =SUM(J5:M5) | O5: =IF(N5>=85,"PASS",IF(N5>=70,"REVISE","FAIL")) | P5: Direct visual review verified: Basketball hoop blanket draped across a sofa under a window. | Q5: Alt text verified: Basketball hoop blanket on sofa
A6: IMGQA-0005 | B6: jeminise.com+personalized-basketball-hoop-with-net-close-up-blanket-with-name-and-number-cc637164fc-cc637164fc | C6: personalized-basketball-hoop-with-net-close-up-blanket-with-name-and-number-cc637164fc-cc637164fc | D6: 5 | E6: 47538875859143 | F6: 221_05.jpg | G6: 1000x1000 | H6: 126598 | I6: 6a4988d2398e319aafc9536a6dba8f5b3dc33dab0c18cf537d2cc4067da3abe9 | J6: 40 | K6: 30 | L6: 20 | M6: 10 | N6: =SUM(J6:M6) | O6: =IF(N6>=85,"PASS",IF(N6>=70,"REVISE","FAIL")) | P6: Direct visual review verified: Feature panel overlays close-up blanket artwork with fluffy, quality and no-shedding callouts. | Q6: Alt text verified: Basketball hoop blanket feature panel
A7: IMGQA-0006 | B7: jeminise.com+personalized-basketball-hoop-with-net-close-up-blanket-with-name-and-number-cc637164fc-cc637164fc | C7: personalized-basketball-hoop-with-net-close-up-blanket-with-name-and-number-cc637164fc-cc637164fc | D7: 6 | E7: 47538875891911 | F7: 221_06.jpg | G7: 1000x1000 | H7: 241151 | I7: 72b454fb1016ad443b451babfbc8d5280c8db871a69561c6055d744f9b4a1deb | J7: 40 | K7: 30 | L7: 20 | M7: 10 | N7: =SUM(J7:M7) | O7: =IF(N7>=85,"PASS",IF(N7>=70,"REVISE","FAIL")) | P7: Direct visual review verified: Folded blanket and fabric/care collage with breathable, skin-friendly and machine washable callouts. | Q7: Alt text verified: Basketball hoop blanket fabric care panel
A8: IMGQA-0007 | B8: jeminise.com+personalized-basketball-hoop-with-net-close-up-blanket-with-name-and-number-cc637164fc-cc637164fc | C8: personalized-basketball-hoop-with-net-close-up-blanket-with-name-and-number-cc637164fc-cc637164fc | D8: 7 | E8: 47538875924679 | F8: 221_07.jpg | G8: 1000x1000 | H8: 247275 | I8: b74f4112edee696948194ba8da84060fec14392c8fcbce818cb4dfe7d20b8c1b | J8: 40 | K8: 30 | L8: 20 | M8: 10 | N8: =SUM(J8:M8) | O8: =IF(N8>=85,"PASS",IF(N8>=70,"REVISE","FAIL")) | P8: Direct visual review verified: Custom blanket size guide showing bed placement examples and width/length table. | Q8: Alt text verified: Basketball hoop blanket bed size guide
A9: IMGQA-0008 | B9: jeminise.com+personalized-basketball-hoop-with-net-close-up-blanket-with-name-and-number-cc637164fc-cc637164fc | C9: personalized-basketball-hoop-with-net-close-up-blanket-with-name-and-number-cc637164fc-cc637164fc | D9: 8 | E9: 47538875957447 | F9: 221_08.jpg | G9: 1000x1000 | H9: 133716 | I9: 7fd39fe1be76b1371fa86eb20c45cd7f1bf76df61b7d21ae815fd286230502c2 | J9: 40 | K9: 30 | L9: 20 | M9: 10 | N9: =SUM(J9:M9) | O9: =IF(N9>=85,"PASS",IF(N9>=70,"REVISE","FAIL")) | P9: Direct visual review verified: Lifestyle image with adult and child reading under the basketball hoop blanket. | Q9: Alt text verified: Basketball hoop blanket family lifestyle image
A10: IMGQA-0009 | B10: jeminise.com+personalized-basketball-next-to-athletic-shoes-blanket-with-name-and-number-dfbf4fde2f-dfbf4fde2f | C10: personalized-basketball-next-to-athletic-shoes-blanket-with-name-and-number-dfbf4fde2f-dfbf4fde2f | D10: 1 | E10: 47538986451143 | F10: 222_01.jpg | G10: 1000x1000 | H10: 109911 | I10: 44057120f5f3cb148f7674d6526ea6a16eb606d8c76553d152aec7fb09105fa5 | J10: 40 | K10: 30 | L10: 20 | M10: 10 | N10: =SUM(J10:M10) | O10: =IF(N10>=85,"PASS",IF(N10>=70,"REVISE","FAIL")) | P10: Direct visual review verified: Blanket flat mockup with dark basketball and athletic shoes artwork, sample name Emery and number 33. | Q10: Alt text verified: Custom basketball shoes blanket flat view
A11: IMGQA-0010 | B11: jeminise.com+personalized-basketball-next-to-athletic-shoes-blanket-with-name-and-number-dfbf4fde2f-dfbf4fde2f | C11: personalized-basketball-next-to-athletic-shoes-blanket-with-name-and-number-dfbf4fde2f-dfbf4fde2f | D11: 2 | E11: 47538986483911 | F11: 222_02.jpg | G11: 1000x1000 | H11: 179671 | I11: e856eeb24add5f8439ec140d56cdc8bec800459ac1ce84e833b76fcd204fc3f4 | J11: 40 | K11: 30 | L11: 20 | M11: 10 | N11: =SUM(J11:M11) | O11: =IF(N11>=85,"PASS",IF(N11>=70,"REVISE","FAIL")) | P11: Direct visual review verified: Person holds basketball shoes blanket in a living room setting. | Q11: Alt text verified: Basketball shoes blanket held in living room
A12: IMGQA-0011 | B12: jeminise.com+personalized-basketball-next-to-athletic-shoes-blanket-with-name-and-number-dfbf4fde2f-dfbf4fde2f | C12: personalized-basketball-next-to-athletic-shoes-blanket-with-name-and-number-dfbf4fde2f-dfbf4fde2f | D12: 3 | E12: 47538986516679 | F12: 222_03.jpg | G12: 1000x1000 | H12: 107625 | I12: 8abc316aab330a6e4f046b472513328f7a3cef89beaf4cbf7d323258a46324f8 | J12: 40 | K12: 30 | L12: 20 | M12: 10 | N12: =SUM(J12:M12) | O12: =IF(N12>=85,"PASS",IF(N12>=70,"REVISE","FAIL")) | P12: Direct visual review verified: Size chart panel showing four blanket sizes with basketball shoes artwork. | Q12: Alt text verified: Basketball shoes blanket size chart
A13: IMGQA-0012 | B13: jeminise.com+personalized-basketball-next-to-athletic-shoes-blanket-with-name-and-number-dfbf4fde2f-dfbf4fde2f | C13: personalized-basketball-next-to-athletic-shoes-blanket-with-name-and-number-dfbf4fde2f-dfbf4fde2f | D13: 4 | E13: 47538986549447 | F13: 222_04.jpg | G13: 1000x1000 | H13: 130994 | I13: 6a97e4d058aefbc5e47e873d306a9fe7de2b0556f1b7dfd923307716f2566a12 | J13: 40 | K13: 30 | L13: 20 | M13: 10 | N13: =SUM(J13:M13) | O13: =IF(N13>=85,"PASS",IF(N13>=70,"REVISE","FAIL")) | P13: Direct visual review verified: Feature panel over ball-and-shoes artwork with fluffy, high-quality and no-pilling callouts. | Q13: Alt text verified: Basketball shoes blanket feature panel
... A71: IMGQA-0070 | B71: jeminise.com+personalized-basketball-shattered-glass-comforter-with-name-and-number-353fc0c17e-353fc0c17e | C71: personalized-basketball-shattered-glass-comforter-with-name-and-number-353fc0c17e-353fc0c17e | D71: 6 | E71: 47538169970887 | F71: 230_06.jpg | G71: 1000x1000 | H71: 45320 | I71: 2f82ab909cc6fdfa1cf987f335fcf2383e82468125fc30be36b116bf90311a88 | J71: 40 | K71: 30 | L71: 20 | M71: 10 | N71: =SUM(J71:M71) | O71: =IF(N71>=85,"PASS",IF(N71>=70,"REVISE","FAIL")) | P71: Direct visual review verified: Size dimension panel showing twin, full, queen and king bed diagrams. | Q71: Alt text verified: Shattered glass basketball comforter size panel

Sheet QA_Issues
A1: issue_id | B1: product_key | C1: qa_image_key | D1: severity | E1: field | F1: submitted_value | G1: source_observation | H1: reason | I1: recommended_fix | J1: supporting_evidence | K1: recheck_condition | L1: reconciliation_status
A2: ISSUE-0001 | B2: jeminise.com+personalized-basketball-hoop-with-net-close-up-blanket-with-name-and-number-cc637164fc-cc637164fc | D2: MAJOR | E2: description_proposed_html | F2: <p>Custom Basketball Hoop Blanket features dark blanket artwork with a close-up glowing basketball hoop, white net, sample name and jersey number. The copy stays specific to the visible basketball artwork, product form and selectable options for this exact item.</p><h3>Design Details</h3><ul><li>Artwork: dark blanket artwork with a close-up glowing basketball hoop, white net, sample name and jersey number.</li><li>Gallery images include the main mockup plus size, feature, care, bedding-type or lifestyle panels where shown.</li></ul><h3>Options and Fit</h3><ul><li>Available option groups: Choose Your Size.</li><li>Personalization uses a optional Custom Name field, 1-200 characters. Personalization uses a optional Custom Number field, 1-20 characters. Names and numbers visible in mockups are sample artwork unless the matching input is entered.</li><li>Select the product type and size shown on the product page before checkout.</li></ul> | G2: Shopify storefront live inspection, customizer audit, and description_proposed_html review. | H2: Product description contains internal prompt boilerplate leakage ('The copy stays specific...', 'Gallery images include...'), lacks essential specifications (material composition, exact dimensions, care guidelines), and has option discrepancies. Description incorrectly instructs shoppers to select 'product type and size' when blanket only offers 'Choose Your Size'. | I2: <p>Custom Basketball Hoop Blanket brings courtside excitement and cozy warmth to your bedroom or living space. Featuring dark blanket artwork featuring a close-up glowing basketball hoop with crisp white net cords, this custom sports throw blanket makes an exceptional personalized gift for basketball players, coaches, and dedicated fans.</p> <h3>Artwork & Personalization</h3> <ul> <li><strong>Design Motif:</strong> Dark blanket artwork featuring a close-up glowing basketball hoop with crisp white net cords.</li> <li><strong>Custom Name Field:</strong> Optional custom name entry (1–200 characters). Enter your recipient's name or leave blank/enter "No" if no name is desired.</li> <li><strong>Custom Number Field:</strong> Optional jersey number entry (1–20 characters). Personalize with a favorite team or player number, or enter "No" for unnumbered artwork.</li> <li><strong>Mockup Preview Note:</strong> Sample names and numbers shown in gallery mockups are illustrative examples and will be replaced with your exact custom text.</li> </ul> <h3>Premium Fabric Options</h3> <ul> <li><strong>Ultra-Soft Fleece:</strong> Lightweight, smooth-faced polyester fleece with vibrant full-color printing; ideal for all-season relaxing, road trips, and game day.</li> <li><strong>Plush Sherpa Fleece:</strong> Premium dual-layer construction featuring a smooth printed front paired with a thick, fluffy faux-sherpa lining for maximum warmth.</li> </ul> <h3>Available Sizes</h3> <ul> <li><strong>40" x 30" (Baby / Lap):</strong> Compact size for cribs, strollers, toddlers, or lap coverage.</li> <li><strong>50" x 40" (Small / Youth):</strong> Perfect throw size for kids, gaming chairs, or travel.</li> <li><strong>60" x 50" (Medium / Teen):</strong> Versatile couch throw blanket for teens and movie nights.</li> <li><strong>80" x 60" (Large / Adult):</strong> Generous full-coverage blanket for twin/queen beds and lounging.</li> </ul> <h3>Care Instructions</h3> <ul> <li>Machine wash cold separately on gentle cycle with mild detergent.</li> <li>Tumble dry on low heat or hang air-dry without heat to maintain plush softness.</li> <li>Do not bleach, do not iron, and avoid fabric softeners.</li> </ul> | J2: Evidence files page.html, product.json, and customizer_audit.json. | K2: Publish-ready HTML description free of boilerplate, with accurate options instructions, dimensions, and fabric specs. | L2: OPEN_NEEDS_REVISION
A3: ISSUE-0002 | B3: jeminise.com+personalized-basketball-next-to-athletic-shoes-blanket-with-name-and-number-dfbf4fde2f-dfbf4fde2f | D3: MAJOR | E3: description_proposed_html | F3: <p>Custom Basketball Shoes Blanket features dark blanket artwork with a basketball beside worn athletic shoes, script sample name and jersey number. The copy stays specific to the visible basketball artwork, product form and selectable options for this exact item.</p><h3>Design Details</h3><ul><li>Artwork: dark blanket artwork with a basketball beside worn athletic shoes, script sample name and jersey number.</li><li>Gallery images include the main mockup plus size, feature, care, bedding-type or lifestyle panels where shown.</li></ul><h3>Options and Fit</h3><ul><li>Available option groups: Choose Your Size.</li><li>Personalization uses a optional Custom Name field, 1-200 characters. Personalization uses a optional Custom Number field, 1-20 characters. Names and numbers visible in mockups are sample artwork unless the matching input is entered.</li><li>Select the product type and size shown on the product page before checkout.</li></ul> | G3: Shopify storefront live inspection, customizer audit, and description_proposed_html review. | H3: Product description contains internal prompt boilerplate leakage ('The copy stays specific...', 'Gallery images include...'), lacks essential specifications (material composition, exact dimensions, care guidelines), and has option discrepancies. Description incorrectly instructs shoppers to select 'product type and size' when blanket only offers 'Choose Your Size'. | I3: <p>Custom Basketball Shoes Blanket brings courtside excitement and cozy warmth to your bedroom or living space. Featuring dark blanket artwork highlighting a basketball resting alongside well-worn athletic basketball shoes, this custom sports throw blanket makes an exceptional personalized gift for basketball players, coaches, and dedicated fans.</p> <h3>Artwork & Personalization</h3> <ul> <li><strong>Design Motif:</strong> Dark blanket artwork highlighting a basketball resting alongside well-worn athletic basketball shoes.</li> <li><strong>Custom Name Field:</strong> Optional custom name entry (1–200 characters). Enter your recipient's name or leave blank/enter "No" if no name is desired.</li> <li><strong>Custom Number Field:</strong> Optional jersey number entry (1–20 characters). Personalize with a favorite team or player number, or enter "No" for unnumbered artwork.</li> <li><strong>Mockup Preview Note:</strong> Sample names and numbers shown in gallery mockups are illustrative examples and will be replaced with your exact custom text.</li> </ul> <h3>Premium Fabric Options</h3> <ul> <li><strong>Ultra-Soft Fleece:</strong> Lightweight, smooth-faced polyester fleece with vibrant full-color printing; ideal for all-season relaxing, road trips, and game day.</li> <li><strong>Plush Sherpa Fleece:</strong> Premium dual-layer construction featuring a smooth printed front paired with a thick, fluffy faux-sherpa lining for maximum warmth.</li> </ul> <h3>Available Sizes</h3> <ul> <li><strong>40" x 30" (Baby / Lap):</strong> Compact size for cribs, strollers, toddlers, or lap coverage.</li> <li><strong>50" x 40" (Small / Youth):</strong> Perfect throw size for kids, gaming chairs, or travel.</li> <li><strong>60" x 50" (Medium / Teen):</strong> Versatile couch throw blanket for teens and movie nights.</li> <li><strong>80" x 60" (Large / Adult):</strong> Generous full-coverage blanket for twin/queen beds and lounging.</li> </ul> <h3>Care Instructions</h3> <ul> <li>Machine wash cold separately on gentle cycle with mild detergent.</li> <li>Tumble dry on low heat or hang air-dry without heat to maintain plush softness.</li> <li>Do not bleach, do not iron, and avoid fabric softeners.</li> </ul> | J3: Evidence files page.html, product.json, and customizer_audit.json. | K3: Publish-ready HTML description free of boilerplate, with accurate options instructions, dimensions, and fabric specs. | L3: OPEN_NEEDS_REVISION
A4: ISSUE-0003 | B4: jeminise.com+personalized-basketball-on-court-lines-comforter-name-number-303fbd50f6-303fbd50f6 | D4: MAJOR | E4: description_proposed_html | F4: <p>Custom Court Lines Basketball Comforter features black comforter with gold court lines, basketball graphics, cracked texture, sample name and jersey number. The copy stays specific to the visible basketball artwork, product form and selectable options for this exact item.</p><h3>Design Details</h3><ul><li>Artwork: black comforter with gold court lines, basketball graphics, cracked texture, sample name and jersey number.</li><li>Gallery images include the main mockup plus size, feature, care, bedding-type or lifestyle panels where shown.</li></ul><h3>Options and Fit</h3><ul><li>Available option groups: Choose Product Type + Size, Choose Pillowcases, Additional Sheet Cover (Flat Sheet).</li><li>Personalization uses a required Customize Your Name field, 1-30 characters. Personalization uses a required Customize Your Number field, 1-5 characters. Names and numbers visible in mockups are sample artwork unless the matching input is entered.</li><li>Select the product type and size shown on the product page before checkout.</li></ul> | G4: Shopify storefront live inspection, customizer audit, and description_proposed_html review. | H4: Product description contains internal prompt boilerplate leakage ('The copy stays specific...', 'Gallery images include...'), lacks essential specifications (material composition, exact dimensions, care guidelines), and has option discrepancies. | I4: <p>Custom Court Lines Basketball Comforter transforms any bedroom into the ultimate sports retreat. Featuring bold black and gold court lines with authentic cracked arena court texture and basketball graphic elements, this personalized bedding ensemble delivers bold courtside style and all-season sleeping comfort.</p> <h3>Design & Customization</h3> <ul> <li><strong>Artwork Motif:</strong> Bold black and gold court lines with authentic cracked arena court texture and basketball graphic elements. High-definition 3D digital print on ultra-soft polyester microfiber.</li> <li><strong>Customize Your Name:</strong> Required personalization field (1–30 characters). Enter the player's name or enter "NO" if you prefer uncustomized bedding.</li> <li><strong>Customize Your Number:</strong> Required jersey number field (1–5 characters, e.g., "10" or "23"). Enter "NO" for a clean graphic without numbers.</li> <li><strong>Sample Display Note:</strong> Names and numbers displayed in gallery mockups demonstrate custom layout placement and will be replaced with your submission.</li> </ul> <h3>Bedding Type & Configuration Options</h3> <ul> <li><strong>Duvet Cover:</strong> Lightweight protective cover equipped with a concealed bottom zipper closure and interior corner ties to secure your duvet insert (insert not included).</li> <li><strong>Comforter:</strong> Ready-to-use plush bedspread filled with lightweight down-alternative microfiber batting for cozy, year-round warmth.</li> <li><strong>Available Bed Sizes:</strong> Twin (68" x 88"), Full (78" x 88"), Queen (88" x 88"), and King (104" x 88").</li> <li><strong>Optional Pillowcases:</strong> Matching pillowcases are optional add-ons selectable via 'Choose Pillowcases' (None, 1, or 2 pillowcases) and are not included when 'None' is selected.</li> <li><strong>Optional Sheet Cover:</strong> Add an optional flat sheet matching your selected bedding dimensions via 'Additional Sheet Cover (Flat Sheet)'.</li> </ul> <h3>Material & Care</h3> <ul> <li>100% premium brushed polyester microfiber; breathable, hypoallergenic, and wrinkle-resistant.</li> <li>Machine wash cold on gentle cycle; tumble dry low or air dry. Do not bleach or dry clean.</li> </ul> | J4: Evidence files page.html, product.json, and customizer_audit.json. | K4: Publish-ready HTML description free of boilerplate, with accurate options instructions, dimensions, and fabric specs. | L4: OPEN_NEEDS_REVISION
A5: ISSUE-0004 | B5: jeminise.com+personalized-basketball-on-court-perspective-comforter-with-name-and-number-1acfbe4260-1acfbe4260 | D5: MAJOR | E5: description_proposed_html | F5: <p>Custom Basketball Court Perspective Comforter features black and red court-perspective comforter with a large basketball, sample name and jersey number. The copy stays specific to the visible basketball artwork, product form and selectable options for this exact item.</p><h3>Design Details</h3><ul><li>Artwork: black and red court-perspective comforter with a large basketball, sample name and jersey number.</li><li>Gallery images include the main mockup plus size, feature, care, bedding-type or lifestyle panels where shown.</li></ul><h3>Options and Fit</h3><ul><li>Available option groups: Choose Product Type + Size, Choose Pillowcases, Additional Sheet Cover (Flat Sheet).</li><li>Personalization uses a required Customize Your Name field, 1-30 characters. Personalization uses a required Customize Your Number field, 1-5 characters. Names and numbers visible in mockups are sample artwork unless the matching input is entered.</li><li>Select the product type and size shown on the product page before checkout.</li></ul> | G5: Shopify storefront live inspection, customizer audit, and description_proposed_html review. | H5: Product description contains internal prompt boilerplate leakage ('The copy stays specific...', 'Gallery images include...'), lacks essential specifications (material composition, exact dimensions, care guidelines), and has option discrepancies. | I5: <p>Custom Basketball Court Perspective Comforter transforms any bedroom into the ultimate sports retreat. Featuring dramatic perspective-angle court layout in black and red sports tones with a prominent basketball graphic, this personalized bedding ensemble delivers bold courtside style and all-season sleeping comfort.</p> <h3>Design & Customization</h3> <ul> <li><strong>Artwork Motif:</strong> Dramatic perspective-angle court layout in black and red sports tones with a prominent basketball graphic. High-definition 3D digital print on ultra-soft polyester microfiber.</li> <li><strong>Customize Your Name:</strong> Required personalization field (1–30 characters). Enter the player's name or enter "NO" if you prefer uncustomized bedding.</li> <li><strong>Customize Your Number:</strong> Required jersey number field (1–5 characters, e.g., "10" or "23"). Enter "NO" for a clean graphic without numbers.</li> <li><strong>Sample Display Note:</strong> Names and numbers displayed in gallery mockups demonstrate custom layout placement and will be replaced with your submission.</li> </ul> <h3>Bedding Type & Configuration Options</h3> <ul> <li><strong>Duvet Cover:</strong> Lightweight protective cover equipped with a concealed bottom zipper closure and interior corner ties to secure your duvet insert (insert not included).</li> <li><strong>Comforter:</strong> Ready-to-use plush bedspread filled with lightweight down-alternative microfiber batting for cozy, year-round warmth.</li> <li><strong>Available Bed Sizes:</strong> Twin (68" x 88"), Full (78" x 88"), Queen (88" x 88"), and King (104" x 88").</li> <li><strong>Optional Pillowcases:</strong> Matching pillowcases are optional add-ons selectable via 'Choose Pillowcases' (None, 1, or 2 pillowcases) and are not included when 'None' is selected.</li> <li><strong>Optional Sheet Cover:</strong> Add an optional flat sheet matching your selected bedding dimensions via 'Additional Sheet Cover (Flat Sheet)'.</li> </ul> <h3>Material & Care</h3> <ul> <li>100% premium brushed polyester microfiber; breathable, hypoallergenic, and wrinkle-resistant.</li> <li>Machine wash cold on gentle cycle; tumble dry low or air dry. Do not bleach or dry clean.</li> </ul> | J5: Evidence files page.html, product.json, and customizer_audit.json. | K5: Publish-ready HTML description free of boilerplate, with accurate options instructions, dimensions, and fabric specs. | L5: OPEN_NEEDS_REVISION
A6: ISSUE-0005 | B6: jeminise.com+personalized-basketball-on-hardwood-court-comforter-with-name-and-number-8aee799947-8aee799947 | D6: MAJOR | E6: description_proposed_html | F6: <p>Custom Hardwood Court Basketball Comforter features blue and gold hardwood-court comforter with a large basketball, sample name and jersey number. The copy stays specific to the visible basketball artwork, product form and selectable options for this exact item.</p><h3>Design Details</h3><ul><li>Artwork: blue and gold hardwood-court comforter with a large basketball, sample name and jersey number.</li><li>Gallery images include the main mockup plus size, feature, care, bedding-type or lifestyle panels where shown.</li></ul><h3>Options and Fit</h3><ul><li>Available option groups: Choose Product Type + Size, Choose Pillowcases, Additional Sheet Cover (Flat Sheet).</li><li>Personalization uses a required Customize Your Name field, 1-30 characters. Personalization uses a required Customize Your Number field, 1-5 characters. Names and numbers visible in mockups are sample artwork unless the matching input is entered.</li><li>Select the product type and size shown on the product page before checkout.</li></ul> | G6: Shopify storefront live inspection, customizer audit, and description_proposed_html review. | H6: Product description contains internal prompt boilerplate leakage ('The copy stays specific...', 'Gallery images include...'), lacks essential specifications (material composition, exact dimensions, care guidelines), and has option discrepancies. | I6: <p>Custom Hardwood Court Basketball Comforter transforms any bedroom into the ultimate sports retreat. Featuring blue and gold arena court artwork with a realistic hardwood floor printed texture and large basketball, this personalized bedding ensemble delivers bold courtside style and all-season sleeping comfort.</p> <h3>Design & Customization</h3> <ul> <li><strong>Artwork Motif:</strong> Blue and gold arena court artwork with a realistic hardwood floor printed texture and large basketball. High-definition 3D digital print on ultra-soft polyester microfiber.</li> <li><strong>Customize Your Name:</strong> Required personalization field (1–30 characters). Enter the player's name or enter "NO" if you prefer uncustomized bedding.</li> <li><strong>Customize Your Number:</strong> Required jersey number field (1–5 characters, e.g., "10" or "23"). Enter "NO" for a clean graphic without numbers.</li> <li><strong>Sample Display Note:</strong> Names and numbers displayed in gallery mockups demonstrate custom layout placement and will be replaced with your submission.</li> </ul> <h3>Bedding Type & Configuration Options</h3> <ul> <li><strong>Duvet Cover:</strong> Lightweight protective cover equipped with a concealed bottom zipper closure and interior corner ties to secure your duvet insert (insert not included).</li> <li><strong>Comforter:</strong> Ready-to-use plush bedspread filled with lightweight down-alternative microfiber batting for cozy, year-round warmth.</li> <li><strong>Available Bed Sizes:</strong> Twin (68" x 88"), Full (78" x 88"), Queen (88" x 88"), and King (104" x 88").</li> <li><strong>Optional Pillowcases:</strong> Matching pillowcases are optional add-ons selectable via 'Choose Pillowcases' (None, 1, or 2 pillowcases) and are not included when 'None' is selected.</li> <li><strong>Optional Sheet Cover:</strong> Add an optional flat sheet matching your selected bedding dimensions via 'Additional Sheet Cover (Flat Sheet)'.</li> </ul> <h3>Material & Care</h3> <ul> <li>100% premium brushed polyester microfiber; breathable, hypoallergenic, and wrinkle-resistant.</li> <li>Machine wash cold on gentle cycle; tumble dry low or air dry. Do not bleach or dry clean.</li> </ul> | J6: Evidence files page.html, product.json, and customizer_audit.json. | K6: Publish-ready HTML description free of boilerplate, with accurate options instructions, dimensions, and fabric specs. | L6: OPEN_NEEDS_REVISION
A7: ISSUE-0006 | B7: jeminise.com+personalized-neon-basketball-player-blanket-788fb6ae63-788fb6ae63 | D7: MAJOR | E7: description_proposed_html | F7: <p>Custom Neon Basketball Player Blanket features dark blanket with neon-style dunking player silhouette, hoop, sample name and jersey number. The copy stays specific to the visible basketball artwork, product form and selectable options for this exact item.</p><h3>Design Details</h3><ul><li>Artwork: dark blanket with neon-style dunking player silhouette, hoop, sample name and jersey number.</li><li>Gallery images include the main mockup plus size, feature, care, bedding-type or lifestyle panels where shown.</li></ul><h3>Options and Fit</h3><ul><li>Available option groups: Choose Your Size.</li><li>Personalization uses a optional Custom Name field, 1-200 characters. Personalization uses a optional Custom Number field, 1-20 characters. Names and numbers visible in mockups are sample artwork unless the matching input is entered.</li><li>Select the product type and size shown on the product page before checkout.</li></ul> | G7: Shopify storefront live inspection, customizer audit, and description_proposed_html review. | H7: Product description contains internal prompt boilerplate leakage ('The copy stays specific...', 'Gallery images include...'), lacks essential specifications (material composition, exact dimensions, care guidelines), and has option discrepancies. Description incorrectly instructs shoppers to select 'product type and size' when blanket only offers 'Choose Your Size'. | I7: <p>Custom Neon Basketball Player Blanket brings courtside excitement and cozy warmth to your bedroom or living space. Featuring electrifying neon-style player silhouette frozen in a powerful slam dunk beside a neon basketball hoop, this custom sports throw blanket makes an exceptional personalized gift for basketball players, coaches, and dedicated fans.</p> <h3>Artwork & Personalization</h3> <ul> <li><strong>Design Motif:</strong> Electrifying neon-style player silhouette frozen in a powerful slam dunk beside a neon basketball hoop.</li> <li><strong>Custom Name Field:</strong> Optional custom name entry (1–200 characters). Enter your recipient's name or leave blank/enter "No" if no name is desired.</li> <li><strong>Custom Number Field:</strong> Optional jersey number entry (1–20 characters). Personalize with a favorite team or player number, or enter "No" for unnumbered artwork.</li> <li><strong>Mockup Preview Note:</strong> Sample names and numbers shown in gallery mockups are illustrative examples and will be replaced with your exact custom text.</li> </ul> <h3>Premium Fabric Options</h3> <ul> <li><strong>Ultra-Soft Fleece:</strong> Lightweight, smooth-faced polyester fleece with vibrant full-color printing; ideal for all-season relaxing, road trips, and game day.</li> <li><strong>Plush Sherpa Fleece:</strong> Premium dual-layer construction featuring a smooth printed front paired with a thick, fluffy faux-sherpa lining for maximum warmth.</li> </ul> <h3>Available Sizes</h3> <ul> <li><strong>40" x 30" (Baby / Lap):</strong> Compact size for cribs, strollers, toddlers, or lap coverage.</li> <li><strong>50" x 40" (Small / Youth):</strong> Perfect throw size for kids, gaming chairs, or travel.</li> <li><strong>60" x 50" (Medium / Teen):</strong> Versatile couch throw blanket for teens and movie nights.</li> <li><strong>80" x 60" (Large / Adult):</strong> Generous full-coverage blanket for twin/queen beds and lounging.</li> </ul> <h3>Care Instructions</h3> <ul> <li>Machine wash cold separately on gentle cycle with mild detergent.</li> <li>Tumble dry on low heat or hang air-dry without heat to maintain plush softness.</li> <li>Do not bleach, do not iron, and avoid fabric softeners.</li> </ul> | J7: Evidence files page.html, product.json, and customizer_audit.json. | K7: Publish-ready HTML description free of boilerplate, with accurate options instructions, dimensions, and fabric specs. | L7: OPEN_NEEDS_REVISION
A8: ISSUE-0007 | B8: jeminise.com+personalized-basketball-player-front-blanket-with-name-and-number-258e7f9e2e-258e7f9e2e | D8: MAJOR | E8: description_proposed_html | F8: <p>Custom Flaming Basketball Player Blanket features red and navy blanket with a front-facing dribbling player, flame effect, sample name and jersey number. The copy stays specific to the visible basketball artwork, product form and selectable options for this exact item.</p><h3>Design Details</h3><ul><li>Artwork: red and navy blanket with a front-facing dribbling player, flame effect, sample name and jersey number.</li><li>Gallery images include the main mockup plus size, feature, care, bedding-type or lifestyle panels where shown.</li></ul><h3>Options and Fit</h3><ul><li>Available option groups: Choose Your Size.</li><li>Personalization uses a optional Custom Name field, 1-200 characters. Personalization uses a optional Custom Number field, 1-20 characters. Names and numbers visible in mockups are sample artwork unless the matching input is entered.</li><li>Select the product type and size shown on the product page before checkout.</li></ul> | G8: Shopify storefront live inspection, customizer audit, and description_proposed_html review. | H8: Product description contains internal prompt boilerplate leakage ('The copy stays specific...', 'Gallery images include...'), lacks essential specifications (material composition, exact dimensions, care guidelines), and has option discrepancies. Description incorrectly instructs shoppers to select 'product type and size' when blanket only offers 'Choose Your Size'. | I8: <p>Custom Flaming Basketball Player Blanket brings courtside excitement and cozy warmth to your bedroom or living space. Featuring action-packed front-facing dribbling basketball player engulfed in vibrant flame and fire effects, this custom sports throw blanket makes an exceptional personalized gift for basketball players, coaches, and dedicated fans.</p> <h3>Artwork & Personalization</h3> <ul> <li><strong>Design Motif:</strong> Action-packed front-facing dribbling basketball player engulfed in vibrant flame and fire effects.</li> <li><strong>Custom Name Field:</strong> Optional custom name entry (1–200 characters). Enter your recipient's name or leave blank/enter "No" if no name is desired.</li> <li><strong>Custom Number Field:</strong> Optional jersey number entry (1–20 characters). Personalize with a favorite team or player number, or enter "No" for unnumbered artwork.</li> <li><strong>Mockup Preview Note:</strong> Sample names and numbers shown in gallery mockups are illustrative examples and will be replaced with your exact custom text.</li> </ul> <h3>Premium Fabric Options</h3> <ul> <li><strong>Ultra-Soft Fleece:</strong> Lightweight, smooth-faced polyester fleece with vibrant full-color printing; ideal for all-season relaxing, road trips, and game day.</li> <li><strong>Plush Sherpa Fleece:</strong> Premium dual-layer construction featuring a smooth printed front paired with a thick, fluffy faux-sherpa lining for maximum warmth.</li> </ul> <h3>Available Sizes</h3> <ul> <li><strong>40" x 30" (Baby / Lap):</strong> Compact size for cribs, strollers, toddlers, or lap coverage.</li> <li><strong>50" x 40" (Small / Youth):</strong> Perfect throw size for kids, gaming chairs, or travel.</li> <li><strong>60" x 50" (Medium / Teen):</strong> Versatile couch throw blanket for teens and movie nights.</li> <li><strong>80" x 60" (Large / Adult):</strong> Generous full-coverage blanket for twin/queen beds and lounging.</li> </ul> <h3>Care Instructions</h3> <ul> <li>Machine wash cold separately on gentle cycle with mild detergent.</li> <li>Tumble dry on low heat or hang air-dry without heat to maintain plush softness.</li> <li>Do not bleach, do not iron, and avoid fabric softeners.</li> </ul> | J8: Evidence files page.html, product.json, and customizer_audit.json. | K8: Publish-ready HTML description free of boilerplate, with accurate options instructions, dimensions, and fabric specs. | L8: OPEN_NEEDS_REVISION
A9: ISSUE-0008 | B9: jeminise.com+personalized-basketball-player-silhouette-blanket-with-name-and-number-35f8822fba-35f8822fba | D9: MAJOR | E9: description_proposed_html | F9: <p>Custom Dribbling Silhouette Basketball Blanket features gray and orange blanket with a black dribbling player silhouette, oversized ball, sample name and jersey number. The copy stays specific to the visible basketball artwork, product form and selectable options for this exact item.</p><h3>Design Details</h3><ul><li>Artwork: gray and orange blanket with a black dribbling player silhouette, oversized ball, sample name and jersey number.</li><li>Gallery images include the main mockup plus size, feature, care, bedding-type or lifestyle panels where shown.</li></ul><h3>Options and Fit</h3><ul><li>Available option groups: Choose Your Size.</li><li>Personalization uses a optional Custom Name field, 1-200 characters. Personalization uses a optional Custom Number field, 1-20 characters. Names and numbers visible in mockups are sample artwork unless the matching input is entered.</li><li>Select the product type and size shown on the product page before checkout.</li></ul> | G9: Shopify storefront live inspection, customizer audit, and description_proposed_html review. | H9: Product description contains internal prompt boilerplate leakage ('The copy stays specific...', 'Gallery images include...'), lacks essential specifications (material composition, exact dimensions, care guidelines), and has option discrepancies. Description incorrectly instructs shoppers to select 'product type and size' when blanket only offers 'Choose Your Size'. | I9: <p>Custom Dribbling Silhouette Basketball Blanket brings courtside excitement and cozy warmth to your bedroom or living space. Featuring modern minimalist black dribbler silhouette against sleek gray and orange court graphics with an oversized ball, this custom sports throw blanket makes an exceptional personalized gift for basketball players, coaches, and dedicated fans.</p> <h3>Artwork & Personalization</h3> <ul> <li><strong>Design Motif:</strong> Modern minimalist black dribbler silhouette against sleek gray and orange court graphics with an oversized ball.</li> <li><strong>Custom Name Field:</strong> Optional custom name entry (1–200 characters). Enter your recipient's name or leave blank/enter "No" if no name is desired.</li> <li><strong>Custom Number Field:</strong> Optional jersey number entry (1–20 characters). Personalize with a favorite team or player number, or enter "No" for unnumbered artwork.</li> <li><strong>Mockup Preview Note:</strong> Sample names and numbers shown in gallery mockups are illustrative examples and will be replaced with your exact custom text.</li> </ul> <h3>Premium Fabric Options</h3> <ul> <li><strong>Ultra-Soft Fleece:</strong> Lightweight, smooth-faced polyester fleece with vibrant full-color printing; ideal for all-season relaxing, road trips, and game day.</li> <li><strong>Plush Sherpa Fleece:</strong> Premium dual-layer construction featuring a smooth printed front paired with a thick, fluffy faux-sherpa lining for maximum warmth.</li> </ul> <h3>Available Sizes</h3> <ul> <li><strong>40" x 30" (Baby / Lap):</strong> Compact size for cribs, strollers, toddlers, or lap coverage.</li> <li><strong>50" x 40" (Small / Youth):</strong> Perfect throw size for kids, gaming chairs, or travel.</li> <li><strong>60" x 50" (Medium / Teen):</strong> Versatile couch throw blanket for teens and movie nights.</li> <li><strong>80" x 60" (Large / Adult):</strong> Generous full-coverage blanket for twin/queen beds and lounging.</li> </ul> <h3>Care Instructions</h3> <ul> <li>Machine wash cold separately on gentle cycle with mild detergent.</li> <li>Tumble dry on low heat or hang air-dry without heat to maintain plush softness.</li> <li>Do not bleach, do not iron, and avoid fabric softeners.</li> </ul> | J9: Evidence files page.html, product.json, and customizer_audit.json. | K9: Publish-ready HTML description free of boilerplate, with accurate options instructions, dimensions, and fabric specs. | L9: OPEN_NEEDS_REVISION
A10: ISSUE-0009 | B10: jeminise.com+personalized-basketball-players-and-hoops-comforter-with-name-and-number-ff13bad888-ff13bad888 | D10: MAJOR | E10: description_proposed_html | F10: <p>Custom Basketball Collage Comforter features black, gray and orange comforter collage with basketballs, hoops, player silhouettes, sample name and jersey number. The copy stays specific to the visible basketball artwork, product form and selectable options for this exact item.</p><h3>Design Details</h3><ul><li>Artwork: black, gray and orange comforter collage with basketballs, hoops, player silhouettes, sample name and jersey number.</li><li>Gallery images include the main mockup plus size, feature, care, bedding-type or lifestyle panels where shown.</li></ul><h3>Options and Fit</h3><ul><li>Available option groups: Choose Product Type + Size, Choose Pillowcases, Additional Sheet Cover (Flat Sheet).</li><li>Personalization uses a required Customize Your Name field, 1-30 characters. Personalization uses a required Customize Your Number field, 1-5 characters. Names and numbers visible in mockups are sample artwork unless the matching input is entered.</li><li>Select the product type and size shown on the product page before checkout.</li></ul> | G10: Shopify storefront live inspection, customizer audit, and description_proposed_html review. | H10: Product description contains internal prompt boilerplate leakage ('The copy stays specific...', 'Gallery images include...'), lacks essential specifications (material composition, exact dimensions, care guidelines), and has option discrepancies. | I10: <p>Custom Basketball Collage Comforter transforms any bedroom into the ultimate sports retreat. Featuring dynamic multi-panel basketball collage showcasing basketballs, hoops, backboards, and athletic player silhouettes, this personalized bedding ensemble delivers bold courtside style and all-season sleeping comfort.</p> <h3>Design & Customization</h3> <ul> <li><strong>Artwork Motif:</strong> Dynamic multi-panel basketball collage showcasing basketballs, hoops, backboards, and athletic player silhouettes. High-definition 3D digital print on ultra-soft polyester microfiber.</li> <li><strong>Customize Your Name:</strong> Required personalization field (1–30 characters). Enter the player's name or enter "NO" if you prefer uncustomized bedding.</li> <li><strong>Customize Your Number:</strong> Required jersey number field (1–5 characters, e.g., "10" or "23"). Enter "NO" for a clean graphic without numbers.</li> <li><strong>Sample Display Note:</strong> Names and numbers displayed in gallery mockups demonstrate custom layout placement and will be replaced with your submission.</li> </ul> <h3>Bedding Type & Configuration Options</h3> <ul> <li><strong>Duvet Cover:</strong> Lightweight protective cover equipped with a concealed bottom zipper closure and interior corner ties to secure your duvet insert (insert not included).</li> <li><strong>Comforter:</strong> Ready-to-use plush bedspread filled with lightweight down-alternative microfiber batting for cozy, year-round warmth.</li> <li><strong>Available Bed Sizes:</strong> Twin (68" x 88"), Full (78" x 88"), Queen (88" x 88"), and King (104" x 88").</li> <li><strong>Optional Pillowcases:</strong> Matching pillowcases are optional add-ons selectable via 'Choose Pillowcases' (None, 1, or 2 pillowcases) and are not included when 'None' is selected.</li> <li><strong>Optional Sheet Cover:</strong> Add an optional flat sheet matching your selected bedding dimensions via 'Additional Sheet Cover (Flat Sheet)'.</li> </ul> <h3>Material & Care</h3> <ul> <li>100% premium brushed polyester microfiber; breathable, hypoallergenic, and wrinkle-resistant.</li> <li>Machine wash cold on gentle cycle; tumble dry low or air dry. Do not bleach or dry clean.</li> </ul> | J10: Evidence files page.html, product.json, and customizer_audit.json. | K10: Publish-ready HTML description free of boilerplate, with accurate options instructions, dimensions, and fabric specs. | L10: OPEN_NEEDS_REVISION
