Workbook

Sheet QA_Summary
A1: metric | B1: value | C1: definition
A2: rubric_version | B2: prompt_qa.md v1.0 / prompt.md v2.4 | C2: Independent r6 QA; scoring calculated from current observations.
A3: source_workbook | B3: resutls/jeminise.com/20260906_234129/revisions/qa_batch_003_r6/SEO_Product_Optimization_qa_batch_003_r6.xlsx | C3: Frozen r6 source; not edited.
A4: source_sha256_at_freeze_and_handoff | B4: 95AF231168F94DD35DBCB3B374F40DB2CE7EE17A768C22FF0FB1D99BE48C5C5A | C4: Hash before and after QA.
A5: qa_run_id | B5: 20260909_120000 | C5: New independent QA run.
A6: batch_id | B6: qa_batch_003_r6 | C6: Inventory positions 21-30 locked by product_key.
A7: products_checked | B7: 10 | C7: Official product keys from inventory.csv and workbook.
A8: images_checked | B8: 50/50 | C8: All 50 downloaded at 1200x1200; no failed image fetch.
A9: criteria_rows | B9: 110 | C9: 11 product criteria x 10 products; product rubric total weight 100.
A10: keyword_rows | B10: 40 | C10: 4 Keyword_Map rows per locked product.
A11: buyer_rows | B11: 10 | C11: 1 Buyer_Search_Research row per locked product.
A12: evidence_rows | B12: 10 | C12: 1 Product_Evidence row per locked product.
A13: batch_final_score | B13: =AVERAGE('QA_Products'!$K$2:$K$11) -> 73.25 | C13: Average of product final scores; formula-driven.
A14: batch_result | B14: =IF(COUNTIF('QA_Products'!$L$2:$L$11,"QA_PASS")=ROWS('QA_Products'!$L$2:$L$11),"PASSED","NOT_PASSED") -> NOT_PASSED | C14: All-pass gate; formula-driven.
A15: status_counts | B15: =COUNTIF('QA_Products'!$L$2:$L$11,"QA_PASS")&" PASS; "&COUNTIF('QA_Products'!$L$2:$L$11,"QA_REVISE")&" REVISE; "&COUNTIF('QA_Products'!$L$2:$L$11,"QA_FAIL")&" FAIL; "&COUNTIF('QA_Products'!$L$2:$L$11,"QA_INCOMPLETE")&" INCOMPLETE" -> PASS=1; REVISE=2; FAIL=7; INCOMPLETE=0 | C15: Status formula.
A16: live_source_changed | B16: FALSE | C16: All 10 live product JSON/HTML reads completed; no source_changed flag inferred from missing admin export.
A17: awaiting_confirmation | B17: TRUE | C17: Stop after batch 03; do not advance to batch 04.

Sheet QA_Products
A1: inventory_position | B1: product_key | C1: url | D1: handle | E1: product_id | F1: revision | G1: verified_points | H1: assessed_weight | I1: score_lower_bound | J1: score_upper_bound | K1: final_score | L1: qa_status | M1: keyword_evidence_level | N1: images_expected | O1: images_checked | P1: image_inventory_complete | Q1: image_coverage | R1: critical_count | S1: major_count | T1: minor_count | U1: limitation_count | V1: issue_refs | W1: evidence_refs
A2: 21 | B2: jeminise.com+christmas-bedding-quilt-soft-microfiber-holiday-bedsprea-design-05 | C2: https://jeminise.com/products/christmas-bedding-quilt-soft-microfiber-holiday-bedsprea-design-05 | D2: christmas-bedding-quilt-soft-microfiber-holiday-bedsprea-design-05 | E2: 8867157835975 | F2: r6 | G2: =SUMIF('QA_Criteria'!$A$2:$A$111,B2,'QA_Criteria'!$F$2:$F$111) -> 90 | H2: =SUMIF('QA_Criteria'!$A$2:$A$111,B2,'QA_Criteria'!$G$2:$G$111) -> 100 | I2: =G2 -> 90 | J2: =G2+(100-H2) -> 90 | K2: =IF(AND(H2=100,Q2=1,P2=TRUE),G2,"") -> 90 | L2: =IF(R2>0,"QA_FAIL",IF(K2="","QA_INCOMPLETE",IF(K2<70,"QA_FAIL",IF(OR(K2<85,S2>0),"QA_REVISE","QA_PASS")))) -> QA_PASS | M2: SERP_ONLY | N2: 5 | O2: 5 | P2: TRUE | Q2: 1 | R2: =COUNTIFS('QA_Issues'!$B$2:$B$21,B2,'QA_Issues'!$D$2:$D$21,"CRITICAL") -> 0 | S2: =COUNTIFS('QA_Issues'!$B$2:$B$21,B2,'QA_Issues'!$D$2:$D$21,"MAJOR") -> 0 | T2: =COUNTIFS('QA_Issues'!$B$2:$B$21,B2,'QA_Issues'!$D$2:$D$21,"MINOR") -> 0 | U2: =COUNTIFS('QA_Issues'!$B$2:$B$21,B2,'QA_Issues'!$D$2:$D$21,"LIMITATION") -> 0 | V2: [] | W2: ["evidence_batch_003_021", "https://jeminise.com/products/christmas-bedding-quilt-soft-microfiber-holiday-bedsprea-design-05", "serp_qa_021"]
A3: 22 | B3: jeminise.com+christmas-bedding-quilt-soft-microfiber-holiday-bedsprea-design-06 | C3: https://jeminise.com/products/christmas-bedding-quilt-soft-microfiber-holiday-bedsprea-design-06 | D3: christmas-bedding-quilt-soft-microfiber-holiday-bedsprea-design-06 | E3: 8867157868743 | F3: r6 | G3: =SUMIF('QA_Criteria'!$A$2:$A$111,B3,'QA_Criteria'!$F$2:$F$111) -> 67.5 | H3: =SUMIF('QA_Criteria'!$A$2:$A$111,B3,'QA_Criteria'!$G$2:$G$111) -> 100 | I3: =G3 -> 67.5 | J3: =G3+(100-H3) -> 67.5 | K3: =IF(AND(H3=100,Q3=1,P3=TRUE),G3,"") -> 67.5 | L3: =IF(R3>0,"QA_FAIL",IF(K3="","QA_INCOMPLETE",IF(K3<70,"QA_FAIL",IF(OR(K3<85,S3>0),"QA_REVISE","QA_PASS")))) -> QA_FAIL | M3: SERP_ONLY | N3: 5 | O3: 5 | P3: TRUE | Q3: 1 | R3: =COUNTIFS('QA_Issues'!$B$2:$B$21,B3,'QA_Issues'!$D$2:$D$21,"CRITICAL") -> 0 | S3: =COUNTIFS('QA_Issues'!$B$2:$B$21,B3,'QA_Issues'!$D$2:$D$21,"MAJOR") -> 1 | T3: =COUNTIFS('QA_Issues'!$B$2:$B$21,B3,'QA_Issues'!$D$2:$D$21,"MINOR") -> 1 | U3: =COUNTIFS('QA_Issues'!$B$2:$B$21,B3,'QA_Issues'!$D$2:$D$21,"LIMITATION") -> 0 | V3: ["R6-ISS-022-PERS"] | W3: ["evidence_batch_003_022", "https://jeminise.com/products/christmas-bedding-quilt-soft-microfiber-holiday-bedsprea-design-06", "serp_qa_022"]
A4: 23 | B4: jeminise.com+christmas-bedding-quilt-soft-microfiber-holiday-bedsprea-design-08 | C4: https://jeminise.com/products/christmas-bedding-quilt-soft-microfiber-holiday-bedsprea-design-08 | D4: christmas-bedding-quilt-soft-microfiber-holiday-bedsprea-design-08 | E4: 8867157999815 | F4: r6 | G4: =SUMIF('QA_Criteria'!$A$2:$A$111,B4,'QA_Criteria'!$F$2:$F$111) -> 67.5 | H4: =SUMIF('QA_Criteria'!$A$2:$A$111,B4,'QA_Criteria'!$G$2:$G$111) -> 100 | I4: =G4 -> 67.5 | J4: =G4+(100-H4) -> 67.5 | K4: =IF(AND(H4=100,Q4=1,P4=TRUE),G4,"") -> 67.5 | L4: =IF(R4>0,"QA_FAIL",IF(K4="","QA_INCOMPLETE",IF(K4<70,"QA_FAIL",IF(OR(K4<85,S4>0),"QA_REVISE","QA_PASS")))) -> QA_FAIL | M4: SERP_ONLY | N4: 5 | O4: 5 | P4: TRUE | Q4: 1 | R4: =COUNTIFS('QA_Issues'!$B$2:$B$21,B4,'QA_Issues'!$D$2:$D$21,"CRITICAL") -> 0 | S4: =COUNTIFS('QA_Issues'!$B$2:$B$21,B4,'QA_Issues'!$D$2:$D$21,"MAJOR") -> 1 | T4: =COUNTIFS('QA_Issues'!$B$2:$B$21,B4,'QA_Issues'!$D$2:$D$21,"MINOR") -> 1 | U4: =COUNTIFS('QA_Issues'!$B$2:$B$21,B4,'QA_Issues'!$D$2:$D$21,"LIMITATION") -> 0 | V4: ["R6-ISS-023-PERS"] | W4: ["evidence_batch_003_023", "https://jeminise.com/products/christmas-bedding-quilt-soft-microfiber-holiday-bedsprea-design-08", "serp_qa_023"]
A5: 24 | B5: jeminise.com+christmas-bedding-quilt-soft-microfiber-holiday-bedsprea-design-09 | C5: https://jeminise.com/products/christmas-bedding-quilt-soft-microfiber-holiday-bedsprea-design-09 | D5: christmas-bedding-quilt-soft-microfiber-holiday-bedsprea-design-09 | E5: 8867158393031 | F5: r6 | G5: =SUMIF('QA_Criteria'!$A$2:$A$111,B5,'QA_Criteria'!$F$2:$F$111) -> 67.5 | H5: =SUMIF('QA_Criteria'!$A$2:$A$111,B5,'QA_Criteria'!$G$2:$G$111) -> 100 | I5: =G5 -> 67.5 | J5: =G5+(100-H5) -> 67.5 | K5: =IF(AND(H5=100,Q5=1,P5=TRUE),G5,"") -> 67.5 | L5: =IF(R5>0,"QA_FAIL",IF(K5="","QA_INCOMPLETE",IF(K5<70,"QA_FAIL",IF(OR(K5<85,S5>0),"QA_REVISE","QA_PASS")))) -> QA_FAIL | M5: SERP_ONLY | N5: 5 | O5: 5 | P5: TRUE | Q5: 1 | R5: =COUNTIFS('QA_Issues'!$B$2:$B$21,B5,'QA_Issues'!$D$2:$D$21,"CRITICAL") -> 0 | S5: =COUNTIFS('QA_Issues'!$B$2:$B$21,B5,'QA_Issues'!$D$2:$D$21,"MAJOR") -> 1 | T5: =COUNTIFS('QA_Issues'!$B$2:$B$21,B5,'QA_Issues'!$D$2:$D$21,"MINOR") -> 1 | U5: =COUNTIFS('QA_Issues'!$B$2:$B$21,B5,'QA_Issues'!$D$2:$D$21,"LIMITATION") -> 0 | V5: ["R6-ISS-024-PERS"] | W5: ["evidence_batch_003_024", "https://jeminise.com/products/christmas-bedding-quilt-soft-microfiber-holiday-bedsprea-design-09", "serp_qa_024"]
A6: 25 | B6: jeminise.com+christmas-bedding-quilt-soft-microfiber-holiday-bedsprea-design-10 | C6: https://jeminise.com/products/christmas-bedding-quilt-soft-microfiber-holiday-bedsprea-design-10 | D6: christmas-bedding-quilt-soft-microfiber-holiday-bedsprea-design-10 | E6: 8867157737671 | F6: r6 | G6: =SUMIF('QA_Criteria'!$A$2:$A$111,B6,'QA_Criteria'!$F$2:$F$111) -> 67.5 | H6: =SUMIF('QA_Criteria'!$A$2:$A$111,B6,'QA_Criteria'!$G$2:$G$111) -> 100 | I6: =G6 -> 67.5 | J6: =G6+(100-H6) -> 67.5 | K6: =IF(AND(H6=100,Q6=1,P6=TRUE),G6,"") -> 67.5 | L6: =IF(R6>0,"QA_FAIL",IF(K6="","QA_INCOMPLETE",IF(K6<70,"QA_FAIL",IF(OR(K6<85,S6>0),"QA_REVISE","QA_PASS")))) -> QA_FAIL | M6: SERP_ONLY | N6: 5 | O6: 5 | P6: TRUE | Q6: 1 | R6: =COUNTIFS('QA_Issues'!$B$2:$B$21,B6,'QA_Issues'!$D$2:$D$21,"CRITICAL") -> 0 | S6: =COUNTIFS('QA_Issues'!$B$2:$B$21,B6,'QA_Issues'!$D$2:$D$21,"MAJOR") -> 1 | T6: =COUNTIFS('QA_Issues'!$B$2:$B$21,B6,'QA_Issues'!$D$2:$D$21,"MINOR") -> 1 | U6: =COUNTIFS('QA_Issues'!$B$2:$B$21,B6,'QA_Issues'!$D$2:$D$21,"LIMITATION") -> 0 | V6: ["R6-ISS-025-PERS"] | W6: ["evidence_batch_003_025", "https://jeminise.com/products/christmas-bedding-quilt-soft-microfiber-holiday-bedsprea-design-10", "serp_qa_025"]
A7: 26 | B7: jeminise.com+christmas-bedding-quilt-soft-microfiber-holiday-bedsprea-design-11 | C7: https://jeminise.com/products/christmas-bedding-quilt-soft-microfiber-holiday-bedsprea-design-11 | D7: christmas-bedding-quilt-soft-microfiber-holiday-bedsprea-design-11 | E7: 8867158261959 | F7: r6 | G7: =SUMIF('QA_Criteria'!$A$2:$A$111,B7,'QA_Criteria'!$F$2:$F$111) -> 67.5 | H7: =SUMIF('QA_Criteria'!$A$2:$A$111,B7,'QA_Criteria'!$G$2:$G$111) -> 100 | I7: =G7 -> 67.5 | J7: =G7+(100-H7) -> 67.5 | K7: =IF(AND(H7=100,Q7=1,P7=TRUE),G7,"") -> 67.5 | L7: =IF(R7>0,"QA_FAIL",IF(K7="","QA_INCOMPLETE",IF(K7<70,"QA_FAIL",IF(OR(K7<85,S7>0),"QA_REVISE","QA_PASS")))) -> QA_FAIL | M7: SERP_ONLY | N7: 5 | O7: 5 | P7: TRUE | Q7: 1 | R7: =COUNTIFS('QA_Issues'!$B$2:$B$21,B7,'QA_Issues'!$D$2:$D$21,"CRITICAL") -> 0 | S7: =COUNTIFS('QA_Issues'!$B$2:$B$21,B7,'QA_Issues'!$D$2:$D$21,"MAJOR") -> 1 | T7: =COUNTIFS('QA_Issues'!$B$2:$B$21,B7,'QA_Issues'!$D$2:$D$21,"MINOR") -> 1 | U7: =COUNTIFS('QA_Issues'!$B$2:$B$21,B7,'QA_Issues'!$D$2:$D$21,"LIMITATION") -> 0 | V7: ["R6-ISS-026-PERS"] | W7: ["evidence_batch_003_026", "https://jeminise.com/products/christmas-bedding-quilt-soft-microfiber-holiday-bedsprea-design-11", "serp_qa_026"]
A8: 27 | B8: jeminise.com+christmas-bedding-quilt-soft-microfiber-holiday-bedsprea-design-12 | C8: https://jeminise.com/products/christmas-bedding-quilt-soft-microfiber-holiday-bedsprea-design-12 | D8: christmas-bedding-quilt-soft-microfiber-holiday-bedsprea-design-12 | E8: 8867157803207 | F8: r6 | G8: =SUMIF('QA_Criteria'!$A$2:$A$111,B8,'QA_Criteria'!$F$2:$F$111) -> 67.5 | H8: =SUMIF('QA_Criteria'!$A$2:$A$111,B8,'QA_Criteria'!$G$2:$G$111) -> 100 | I8: =G8 -> 67.5 | J8: =G8+(100-H8) -> 67.5 | K8: =IF(AND(H8=100,Q8=1,P8=TRUE),G8,"") -> 67.5 | L8: =IF(R8>0,"QA_FAIL",IF(K8="","QA_INCOMPLETE",IF(K8<70,"QA_FAIL",IF(OR(K8<85,S8>0),"QA_REVISE","QA_PASS")))) -> QA_FAIL | M8: SERP_ONLY | N8: 5 | O8: 5 | P8: TRUE | Q8: 1 | R8: =COUNTIFS('QA_Issues'!$B$2:$B$21,B8,'QA_Issues'!$D$2:$D$21,"CRITICAL") -> 0 | S8: =COUNTIFS('QA_Issues'!$B$2:$B$21,B8,'QA_Issues'!$D$2:$D$21,"MAJOR") -> 1 | T8: =COUNTIFS('QA_Issues'!$B$2:$B$21,B8,'QA_Issues'!$D$2:$D$21,"MINOR") -> 1 | U8: =COUNTIFS('QA_Issues'!$B$2:$B$21,B8,'QA_Issues'!$D$2:$D$21,"LIMITATION") -> 0 | V8: ["R6-ISS-027-PERS"] | W8: ["evidence_batch_003_027", "https://jeminise.com/products/christmas-bedding-quilt-soft-microfiber-holiday-bedsprea-design-12", "serp_qa_027"]
A9: 28 | B9: jeminise.com+christmas-bedding-quilt-soft-microfiber-holiday-bedspread | C9: https://jeminise.com/products/christmas-bedding-quilt-soft-microfiber-holiday-bedspread | D9: christmas-bedding-quilt-soft-microfiber-holiday-bedspread | E9: 8867157704903 | F9: r6 | G9: =SUMIF('QA_Criteria'!$A$2:$A$111,B9,'QA_Criteria'!$F$2:$F$111) -> 67.5 | H9: =SUMIF('QA_Criteria'!$A$2:$A$111,B9,'QA_Criteria'!$G$2:$G$111) -> 100 | I9: =G9 -> 67.5 | J9: =G9+(100-H9) -> 67.5 | K9: =IF(AND(H9=100,Q9=1,P9=TRUE),G9,"") -> 67.5 | L9: =IF(R9>0,"QA_FAIL",IF(K9="","QA_INCOMPLETE",IF(K9<70,"QA_FAIL",IF(OR(K9<85,S9>0),"QA_REVISE","QA_PASS")))) -> QA_FAIL | M9: SERP_ONLY | N9: 5 | O9: 5 | P9: TRUE | Q9: 1 | R9: =COUNTIFS('QA_Issues'!$B$2:$B$21,B9,'QA_Issues'!$D$2:$D$21,"CRITICAL") -> 0 | S9: =COUNTIFS('QA_Issues'!$B$2:$B$21,B9,'QA_Issues'!$D$2:$D$21,"MAJOR") -> 1 | T9: =COUNTIFS('QA_Issues'!$B$2:$B$21,B9,'QA_Issues'!$D$2:$D$21,"MINOR") -> 1 | U9: =COUNTIFS('QA_Issues'!$B$2:$B$21,B9,'QA_Issues'!$D$2:$D$21,"LIMITATION") -> 0 | V9: ["R6-ISS-028-PERS"] | W9: ["evidence_batch_003_028", "https://jeminise.com/products/christmas-bedding-quilt-soft-microfiber-holiday-bedspread", "serp_qa_028"]
A10: 29 | B10: jeminise.com+christmas-cardinal-on-branch-within-patchwork-winter-quilt-892d70543a-892d70543a | C10: https://jeminise.com/products/christmas-cardinal-on-branch-within-patchwork-winter-quilt-892d70543a-892d70543a | D10: christmas-cardinal-on-branch-within-patchwork-winter-quilt-892d70543a-892d70543a | E10: 8834708111559 | F10: r6 | G10: =SUMIF('QA_Criteria'!$A$2:$A$111,B10,'QA_Criteria'!$F$2:$F$111) -> 85 | H10: =SUMIF('QA_Criteria'!$A$2:$A$111,B10,'QA_Criteria'!$G$2:$G$111) -> 100 | I10: =G10 -> 85 | J10: =G10+(100-H10) -> 85 | K10: =IF(AND(H10=100,Q10=1,P10=TRUE),G10,"") -> 85 | L10: =IF(R10>0,"QA_FAIL",IF(K10="","QA_INCOMPLETE",IF(K10<70,"QA_FAIL",IF(OR(K10<85,S10>0),"QA_REVISE","QA_PASS")))) -> QA_REVISE | M10: SERP_ONLY | N10: 5 | O10: 5 | P10: TRUE | Q10: 1 | R10: =COUNTIFS('QA_Issues'!$B$2:$B$21,B10,'QA_Issues'!$D$2:$D$21,"CRITICAL") -> 0 | S10: =COUNTIFS('QA_Issues'!$B$2:$B$21,B10,'QA_Issues'!$D$2:$D$21,"MAJOR") -> 1 | T10: =COUNTIFS('QA_Issues'!$B$2:$B$21,B10,'QA_Issues'!$D$2:$D$21,"MINOR") -> 0 | U10: =COUNTIFS('QA_Issues'!$B$2:$B$21,B10,'QA_Issues'!$D$2:$D$21,"LIMITATION") -> 0 | V10: ["R6-ISS-029-PERS"] | W10: ["evidence_batch_003_029", "https://jeminise.com/products/christmas-cardinal-on-branch-within-patchwork-winter-quilt-892d70543a-892d70543a", "serp_qa_029"]
A11: 30 | B11: jeminise.com+christmas-cardinal-perched-on-branch-within-wreath-patchwork-winter-quilt-9e7c0b5896-9e7c0b5896 | C11: https://jeminise.com/products/christmas-cardinal-perched-on-branch-within-wreath-patchwork-winter-quilt-9e7c0b5896-9e7c0b5896 | D11: christmas-cardinal-perched-on-branch-within-wreath-patchwork-winter-quilt-9e7c0b5896-9e7c0b5896 | E11: 8834727805127 | F11: r6 | G11: =SUMIF('QA_Criteria'!$A$2:$A$111,B11,'QA_Criteria'!$F$2:$F$111) -> 85 | H11: =SUMIF('QA_Criteria'!$A$2:$A$111,B11,'QA_Criteria'!$G$2:$G$111) -> 100 | I11: =G11 -> 85 | J11: =G11+(100-H11) -> 85 | K11: =IF(AND(H11=100,Q11=1,P11=TRUE),G11,"") -> 85 | L11: =IF(R11>0,"QA_FAIL",IF(K11="","QA_INCOMPLETE",IF(K11<70,"QA_FAIL",IF(OR(K11<85,S11>0),"QA_REVISE","QA_PASS")))) -> QA_REVISE | M11: SERP_ONLY | N11: 5 | O11: 5 | P11: TRUE | Q11: 1 | R11: =COUNTIFS('QA_Issues'!$B$2:$B$21,B11,'QA_Issues'!$D$2:$D$21,"CRITICAL") -> 0 | S11: =COUNTIFS('QA_Issues'!$B$2:$B$21,B11,'QA_Issues'!$D$2:$D$21,"MAJOR") -> 1 | T11: =COUNTIFS('QA_Issues'!$B$2:$B$21,B11,'QA_Issues'!$D$2:$D$21,"MINOR") -> 0 | U11: =COUNTIFS('QA_Issues'!$B$2:$B$21,B11,'QA_Issues'!$D$2:$D$21,"LIMITATION") -> 0 | V11: ["R6-ISS-030-PERS"] | W11: ["evidence_batch_003_030", "https://jeminise.com/products/christmas-cardinal-perched-on-branch-within-wreath-patchwork-winter-quilt-9e7c0b5896-9e7c0b5896", "serp_qa_030"]

Sheet QA_Criteria
A1: product_key | B1: criterion_id | C1: weight | D1: assessment | E1: rating | F1: earned_points | G1: assessed_weight | H1: reason | I1: evidence_refs | J1: issue_refs | K1: revision
A2: jeminise.com+christmas-bedding-quilt-soft-microfiber-holiday-bedsprea-design-05 | B2: P1 | C2: 15 | D2: FULL | E2: =IF(B2="I1",AVERAGEIF('QA_Images'!$A$2:$A$51,A2,'QA_Images'!$T$2:$T$51)/100,IF(D2="FULL",1,IF(D2="PARTIAL",0.5,IF(D2="FAIL",0,"")))) -> 1 | F2: =IF(E2="",0,C2*E2) -> 15 | G2: =IF(B2="I1",20*AVERAGEIF('QA_Images'!$A$2:$A$51,A2,'QA_Images'!$U$2:$U$51)/100,IF(D2="NOT_CHECKED",0,C2)) -> 15 | H2: Live JSON id/handle, live H1 and all five current gallery images match the selected motif; personalization wording is not accepted without a live control. | I2: ["evidence_batch_003_021", "https://jeminise.com/products/christmas-bedding-quilt-soft-microfiber-holiday-bedsprea-design-05", "serp_qa_021"] | J2: [] | K2: r6
A3: jeminise.com+christmas-bedding-quilt-soft-microfiber-holiday-bedsprea-design-05 | B3: P2 | C3: 10 | D3: FULL | E3: =IF(B3="I1",AVERAGEIF('QA_Images'!$A$2:$A$51,A3,'QA_Images'!$T$2:$T$51)/100,IF(D3="FULL",1,IF(D3="PARTIAL",0.5,IF(D3="FAIL",0,"")))) -> 1 | F3: =IF(E3="",0,C3*E3) -> 10 | G3: =IF(B3="I1",20*AVERAGEIF('QA_Images'!$A$2:$A$51,A3,'QA_Images'!$U$2:$U$51)/100,IF(D3="NOT_CHECKED",0,C3)) -> 10 | H3: Live JSON has 15 variants, five quilt sizes and three pillowcase choices. A live 1-text-input control is evidenced only at positions 21, 29 and 30; r6 personalization claims elsewhere are unsupported. | I3: ["evidence_batch_003_021", "https://jeminise.com/products/christmas-bedding-quilt-soft-microfiber-holiday-bedsprea-design-05", "serp_qa_021"] | J3: [] | K3: r6
A4: jeminise.com+christmas-bedding-quilt-soft-microfiber-holiday-bedsprea-design-05 | B4: K1 | C4: 10 | D4: PARTIAL | E4: =IF(B4="I1",AVERAGEIF('QA_Images'!$A$2:$A$51,A4,'QA_Images'!$T$2:$T$51)/100,IF(D4="FULL",1,IF(D4="PARTIAL",0.5,IF(D4="FAIL",0,"")))) -> 0.5 | F4: =IF(E4="",0,C4*E4) -> 5 | G4: =IF(B4="I1",20*AVERAGEIF('QA_Images'!$A$2:$A$51,A4,'QA_Images'!$U$2:$U$51)/100,IF(D4="NOT_CHECKED",0,C4)) -> 10 | H4: Two US-English SERP queries per product were read. Motif terms distinguish candy cane gingerbread, village gingerbread, black tree, vintage tree, birdhouse/cardinal and snowman counts. | I4: ["evidence_batch_003_021", "https://jeminise.com/products/christmas-bedding-quilt-soft-microfiber-holiday-bedsprea-design-05", "serp_qa_021"] | J4: [] | K4: r6
A5: jeminise.com+christmas-bedding-quilt-soft-microfiber-holiday-bedsprea-design-05 | B5: K2 | C5: 5 | D5: PARTIAL | E5: =IF(B5="I1",AVERAGEIF('QA_Images'!$A$2:$A$51,A5,'QA_Images'!$T$2:$T$51)/100,IF(D5="FULL",1,IF(D5="PARTIAL",0.5,IF(D5="FAIL",0,"")))) -> 0.5 | F5: =IF(E5="",0,C5*E5) -> 2.5 | G5: =IF(B5="I1",20*AVERAGEIF('QA_Images'!$A$2:$A$51,A5,'QA_Images'!$U$2:$U$51)/100,IF(D5="NOT_CHECKED",0,C5)) -> 5 | H5: SERP results support commercial/product intent, but comparator results were read without hard-pinned search-service locale. | I5: ["evidence_batch_003_021", "https://jeminise.com/products/christmas-bedding-quilt-soft-microfiber-holiday-bedsprea-design-05", "serp_qa_021"] | J5: [] | K5: r6
A6: jeminise.com+christmas-bedding-quilt-soft-microfiber-holiday-bedsprea-design-05 | B6: K3 | C6: 5 | D6: PARTIAL | E6: =IF(B6="I1",AVERAGEIF('QA_Images'!$A$2:$A$51,A6,'QA_Images'!$T$2:$T$51)/100,IF(D6="FULL",1,IF(D6="PARTIAL",0.5,IF(D6="FAIL",0,"")))) -> 0.5 | F6: =IF(E6="",0,C6*E6) -> 2.5 | G6: =IF(B6="I1",20*AVERAGEIF('QA_Images'!$A$2:$A$51,A6,'QA_Images'!$U$2:$U$51)/100,IF(D6="NOT_CHECKED",0,C6)) -> 5 | H6: No search-volume claim is made; evidence is SERP_ONLY and therefore only partial for demand validation. | I6: ["evidence_batch_003_021", "https://jeminise.com/products/christmas-bedding-quilt-soft-microfiber-holiday-bedsprea-design-05", "serp_qa_021"] | J6: [] | K6: r6
A7: jeminise.com+christmas-bedding-quilt-soft-microfiber-holiday-bedsprea-design-05 | B7: T1 | C7: 10 | D7: FULL | E7: =IF(B7="I1",AVERAGEIF('QA_Images'!$A$2:$A$51,A7,'QA_Images'!$T$2:$T$51)/100,IF(D7="FULL",1,IF(D7="PARTIAL",0.5,IF(D7="FAIL",0,"")))) -> 1 | F7: =IF(E7="",0,C7*E7) -> 10 | G7: =IF(B7="I1",20*AVERAGEIF('QA_Images'!$A$2:$A$51,A7,'QA_Images'!$U$2:$U$51)/100,IF(D7="NOT_CHECKED",0,C7)) -> 10 | H7: Proposed SEO title is specific English copy; “Personalized” is not accepted for positions 22-28 without a live control. | I7: ["evidence_batch_003_021", "https://jeminise.com/products/christmas-bedding-quilt-soft-microfiber-holiday-bedsprea-design-05", "serp_qa_021"] | J7: [] | K7: r6
A8: jeminise.com+christmas-bedding-quilt-soft-microfiber-holiday-bedsprea-design-05 | B8: T2 | C8: 5 | D8: FULL | E8: =IF(B8="I1",AVERAGEIF('QA_Images'!$A$2:$A$51,A8,'QA_Images'!$T$2:$T$51)/100,IF(D8="FULL",1,IF(D8="PARTIAL",0.5,IF(D8="FAIL",0,"")))) -> 1 | F8: =IF(E8="",0,C8*E8) -> 5 | G8: =IF(B8="I1",20*AVERAGEIF('QA_Images'!$A$2:$A$51,A8,'QA_Images'!$U$2:$U$51)/100,IF(D8="NOT_CHECKED",0,C8)) -> 5 | H8: Proposed H1/title intent is distinct and avoids the live encoding/truncation issue. | I8: ["evidence_batch_003_021", "https://jeminise.com/products/christmas-bedding-quilt-soft-microfiber-holiday-bedsprea-design-05", "serp_qa_021"] | J8: [] | K8: r6
A9: jeminise.com+christmas-bedding-quilt-soft-microfiber-holiday-bedsprea-design-05 | B9: D1 | C9: 5 | D9: FULL | E9: =IF(B9="I1",AVERAGEIF('QA_Images'!$A$2:$A$51,A9,'QA_Images'!$T$2:$T$51)/100,IF(D9="FULL",1,IF(D9="PARTIAL",0.5,IF(D9="FAIL",0,"")))) -> 1 | F9: =IF(E9="",0,C9*E9) -> 5 | G9: =IF(B9="I1",20*AVERAGEIF('QA_Images'!$A$2:$A$51,A9,'QA_Images'!$U$2:$U$51)/100,IF(D9="NOT_CHECKED",0,C9)) -> 5 | H9: Proposed metadata is complete, customer-facing and supported by the motif evidence; 145-165 is an editorial target only. | I9: ["evidence_batch_003_021", "https://jeminise.com/products/christmas-bedding-quilt-soft-microfiber-holiday-bedsprea-design-05", "serp_qa_021"] | J9: [] | K9: r6
A10: jeminise.com+christmas-bedding-quilt-soft-microfiber-holiday-bedsprea-design-05 | B10: D2 | C10: 10 | D10: FULL | E10: =IF(B10="I1",AVERAGEIF('QA_Images'!$A$2:$A$51,A10,'QA_Images'!$T$2:$T$51)/100,IF(D10="FULL",1,IF(D10="PARTIAL",0.5,IF(D10="FAIL",0,"")))) -> 1 | F10: =IF(E10="",0,C10*E10) -> 10 | G10: =IF(B10="I1",20*AVERAGEIF('QA_Images'!$A$2:$A$51,A10,'QA_Images'!$U$2:$U$51)/100,IF(D10="NOT_CHECKED",0,C10)) -> 10 | H10: r6 description is customer-facing and removes process/QA wording. Position 29-30 incorrectly deny a live personalization field; other claims of a name field are unsupported where no live control was found. | I10: ["evidence_batch_003_021", "https://jeminise.com/products/christmas-bedding-quilt-soft-microfiber-holiday-bedsprea-design-05", "serp_qa_021"] | J10: [] | K10: r6
A11: jeminise.com+christmas-bedding-quilt-soft-microfiber-holiday-bedsprea-design-05 | B11: I1 | C11: 20 | D11: DERIVED | E11: =IF(B11="I1",AVERAGEIF('QA_Images'!$A$2:$A$51,A11,'QA_Images'!$T$2:$T$51)/100,IF(D11="FULL",1,IF(D11="PARTIAL",0.5,IF(D11="FAIL",0,"")))) -> 1 | F11: =IF(E11="",0,C11*E11) -> 20 | G11: =IF(B11="I1",20*AVERAGEIF('QA_Images'!$A$2:$A$51,A11,'QA_Images'!$U$2:$U$51)/100,IF(D11="NOT_CHECKED",0,C11)) -> 20 | H11: Derived from the 5 images belonging to this product only; all 20 image rubric points are passed. | I11: ["evidence_batch_003_021", "https://jeminise.com/products/christmas-bedding-quilt-soft-microfiber-holiday-bedsprea-design-05", "serp_qa_021"] | J11: [] | K11: r6
A12: jeminise.com+christmas-bedding-quilt-soft-microfiber-holiday-bedsprea-design-05 | B12: E1 | C12: 5 | D12: FULL | E12: =IF(B12="I1",AVERAGEIF('QA_Images'!$A$2:$A$51,A12,'QA_Images'!$T$2:$T$51)/100,IF(D12="FULL",1,IF(D12="PARTIAL",0.5,IF(D12="FAIL",0,"")))) -> 1 | F12: =IF(E12="",0,C12*E12) -> 5 | G12: =IF(B12="I1",20*AVERAGEIF('QA_Images'!$A$2:$A$51,A12,'QA_Images'!$U$2:$U$51)/100,IF(D12="NOT_CHECKED",0,C12)) -> 5 | H12: Product key, handle, ID, URL and evidence links reconcile to the locked inventory rows and live snapshot. | I12: ["evidence_batch_003_021", "https://jeminise.com/products/christmas-bedding-quilt-soft-microfiber-holiday-bedsprea-design-05", "serp_qa_021"] | J12: [] | K12: r6
A13: jeminise.com+christmas-bedding-quilt-soft-microfiber-holiday-bedsprea-design-06 | B13: P1 | C13: 15 | D13: PARTIAL | E13: =IF(B13="I1",AVERAGEIF('QA_Images'!$A$2:$A$51,A13,'QA_Images'!$T$2:$T$51)/100,IF(D13="FULL",1,IF(D13="PARTIAL",0.5,IF(D13="FAIL",0,"")))) -> 0.5 | F13: =IF(E13="",0,C13*E13) -> 7.5 | G13: =IF(B13="I1",20*AVERAGEIF('QA_Images'!$A$2:$A$51,A13,'QA_Images'!$U$2:$U$51)/100,IF(D13="NOT_CHECKED",0,C13)) -> 15 | H13: Live JSON id/handle, live H1 and all five current gallery images match the selected motif; personalization wording is not accepted without a live control. | I13: ["evidence_batch_003_022", "https://jeminise.com/products/christmas-bedding-quilt-soft-microfiber-holiday-bedsprea-design-06", "serp_qa_022"] | J13: ["R6-ISS-022-PERS"] | K13: r6
... A111: jeminise.com+christmas-cardinal-perched-on-branch-within-wreath-patchwork-winter-quilt-9e7c0b5896-9e7c0b5896 | B111: E1 | C111: 5 | D111: FULL | E111: =IF(B111="I1",AVERAGEIF('QA_Images'!$A$2:$A$51,A111,'QA_Images'!$T$2:$T$51)/100,IF(D111="FULL",1,IF(D111="PARTIAL",0.5,IF(D111="FAIL",0,"")))) -> 1 | F111: =IF(E111="",0,C111*E111) -> 5 | G111: =IF(B111="I1",20*AVERAGEIF('QA_Images'!$A$2:$A$51,A111,'QA_Images'!$U$2:$U$51)/100,IF(D111="NOT_CHECKED",0,C111)) -> 5 | H111: Product key, handle, ID, URL and evidence links reconcile to the locked inventory rows and live snapshot. | I111: ["evidence_batch_003_030", "https://jeminise.com/products/christmas-cardinal-perched-on-branch-within-wreath-patchwork-winter-quilt-9e7c0b5896-9e7c0b5896", "serp_qa_030"] | J111: ["R6-ISS-030-PERS"] | K111: r6

Sheet QA_Images
A1: product_key | B1: qa_image_key | C1: image_url_source | D1: image_url_workbook | E1: media_id | F1: workbook_image_id | G1: variant | H1: image_location | I1: check_method | J1: checked_at | K1: qa_observation | L1: submitted_observation | M1: storefront_alt_observed | N1: alt_action | O1: alt_effective | P1: IM1 | Q1: IM2 | R1: IM3 | S1: IM4 | T1: image_verified_points | U1: image_assessed_weight | V1: image_final_score | W1: image_score_lower_bound | X1: image_score_upper_bound | Y1: issue_refs | Z1: evidence_refs | AA1: revision
A2: jeminise.com+christmas-bedding-quilt-soft-microfiber-holiday-bedsprea-design-05 | B2: jeminise.com+christmas-bedding-quilt-soft-microfiber-holiday-bedsprea-design-05|media:47934032314567|pos:1|url:b08a03300b49 | C2: https://cdn.shopify.com/s/files/1/0792/5098/1063/files/7db6811c66637965300a2e7b9c74cbf013694f223ecb0c00a52fba2970fa6e22.jpg?v=1787239304 | D2: https://cdn.shopify.com/s/files/1/0792/5098/1063/files/7db6811c66637965300a2e7b9c74cbf013694f223ecb0c00a52fba2970fa6e22.jpg?v=1787239304 | E2: 47934032314567 | F2: https://cdn.shopify.com/s/files/1/0792/5098/1063/files/7db6811c66637965300a2e7b9c74cbf013694f223ecb0c00a52fba2970fa6e22.jpg?v=1787239304 | H2: GALLERY | I2: DIRECT_URL_DOWNLOAD_1200PX + VISUAL_READ | J2: 2026-09-09T12:00:00+07:00 | K2: Front bedroom mockup showing the primary quilt motif and coordinated shams. | L2: Gingerbread candy cane Christmas quilt bed mockup with cream background, green border and matching shams. | M2: Christmas Bedding Quilt – Soft Microfiber Holiday Bedspread, Lightweight Winter Bedding, Cozy Xmas Quilts for Couch, Bedroom & Seasonal Home Decorations (Christmas Quilt-DS05) | N2: SET | O2: Gingerbread candy cane Christmas quilt set on bed | P2: FULL | Q2: FULL | R2: FULL | S2: FULL | T2: =IF(P2="FULL",40,IF(P2="PARTIAL",40/2,0))+IF(Q2="FULL",30,IF(Q2="PARTIAL",30/2,0))+IF(R2="FULL",20,IF(R2="PARTIAL",20/2,0))+IF(S2="FULL",10,IF(S2="PARTIAL",10/2,0)) -> 100 | U2: =IF(P2="NOT_CHECKED",0,40)+IF(Q2="NOT_CHECKED",0,30)+IF(R2="NOT_CHECKED",0,20)+IF(S2="NOT_CHECKED",0,10) -> 100 | V2: =IF(U2=100,T2,"") -> 100 | W2: =T2 -> 100 | X2: =T2+(100-U2) -> 100 | Y2: [] | Z2: ["evidence_batch_003_021", "https://jeminise.com/products/christmas-bedding-quilt-soft-microfiber-holiday-bedsprea-design-05", "https://cdn.shopify.com/s/files/1/0792/5098/1063/files/7db6811c66637965300a2e7b9c74cbf013694f223ecb0c00a52fba2970fa6e22.jpg?v=1787239304"] | AA2: r6
A3: jeminise.com+christmas-bedding-quilt-soft-microfiber-holiday-bedsprea-design-05 | B3: jeminise.com+christmas-bedding-quilt-soft-microfiber-holiday-bedsprea-design-05|media:47934032347335|pos:2|url:e85b6a4b3f8b | C3: https://cdn.shopify.com/s/files/1/0792/5098/1063/files/16c248973ae48e0a9cc4448f2002965ba9049a188545c2818d9f66e2db24f2a5.jpg?v=1787239304 | D3: https://cdn.shopify.com/s/files/1/0792/5098/1063/files/16c248973ae48e0a9cc4448f2002965ba9049a188545c2818d9f66e2db24f2a5.jpg?v=1787239304 | E3: 47934032347335 | F3: https://cdn.shopify.com/s/files/1/0792/5098/1063/files/16c248973ae48e0a9cc4448f2002965ba9049a188545c2818d9f66e2db24f2a5.jpg?v=1787239304 | H3: GALLERY | I3: DIRECT_URL_DOWNLOAD_1200PX + VISUAL_READ | J3: 2026-09-09T12:00:00+07:00 | K3: Angled bedroom mockup confirming the same motif across the set. | L3: Bedroom mockup showing gingerbread candy cane quilt with coordinated pillow shams. | M3: Christmas Bedding Quilt – Soft Microfiber Holiday Bedspread, Lightweight Winter Bedding, Cozy Xmas Quilts for Couch, Bedroom & Seasonal Home Decorations (Christmas Quilt-DS05) | N3: SET | O3: Gingerbread candy cane quilt bedroom mockup | P3: FULL | Q3: FULL | R3: FULL | S3: FULL | T3: =IF(P3="FULL",40,IF(P3="PARTIAL",40/2,0))+IF(Q3="FULL",30,IF(Q3="PARTIAL",30/2,0))+IF(R3="FULL",20,IF(R3="PARTIAL",20/2,0))+IF(S3="FULL",10,IF(S3="PARTIAL",10/2,0)) -> 100 | U3: =IF(P3="NOT_CHECKED",0,40)+IF(Q3="NOT_CHECKED",0,30)+IF(R3="NOT_CHECKED",0,20)+IF(S3="NOT_CHECKED",0,10) -> 100 | V3: =IF(U3=100,T3,"") -> 100 | W3: =T3 -> 100 | X3: =T3+(100-U3) -> 100 | Y3: [] | Z3: ["evidence_batch_003_021", "https://jeminise.com/products/christmas-bedding-quilt-soft-microfiber-holiday-bedsprea-design-05", "https://cdn.shopify.com/s/files/1/0792/5098/1063/files/16c248973ae48e0a9cc4448f2002965ba9049a188545c2818d9f66e2db24f2a5.jpg?v=1787239304"] | AA3: r6
A4: jeminise.com+christmas-bedding-quilt-soft-microfiber-holiday-bedsprea-design-05 | B4: jeminise.com+christmas-bedding-quilt-soft-microfiber-holiday-bedsprea-design-05|media:47934032380103|pos:3|url:29d666c5e011 | C4: https://cdn.shopify.com/s/files/1/0792/5098/1063/files/323ea5e3469590e61df70a45da30caeee15b2197d409a07ec242f1425c067466.jpg?v=1787239304 | D4: https://cdn.shopify.com/s/files/1/0792/5098/1063/files/323ea5e3469590e61df70a45da30caeee15b2197d409a07ec242f1425c067466.jpg?v=1787239304 | E4: 47934032380103 | F4: https://cdn.shopify.com/s/files/1/0792/5098/1063/files/323ea5e3469590e61df70a45da30caeee15b2197d409a07ec242f1425c067466.jpg?v=1787239304 | H4: GALLERY | I4: DIRECT_URL_DOWNLOAD_1200PX + VISUAL_READ | J4: 2026-09-09T12:00:00+07:00 | K4: Isolated pillow sham showing the coordinated printed artwork. | L4: Close-up of gingerbread face, green bow, candy cane stripes and visible quilt stitching. | M4: Christmas Bedding Quilt – Soft Microfiber Holiday Bedspread, Lightweight Winter Bedding, Cozy Xmas Quilts for Couch, Bedroom & Seasonal Home Decorations (Christmas Quilt-DS05) | N4: SET | O4: Gingerbread candy cane quilt stitching close-up | P4: FULL | Q4: FULL | R4: FULL | S4: FULL | T4: =IF(P4="FULL",40,IF(P4="PARTIAL",40/2,0))+IF(Q4="FULL",30,IF(Q4="PARTIAL",30/2,0))+IF(R4="FULL",20,IF(R4="PARTIAL",20/2,0))+IF(S4="FULL",10,IF(S4="PARTIAL",10/2,0)) -> 100 | U4: =IF(P4="NOT_CHECKED",0,40)+IF(Q4="NOT_CHECKED",0,30)+IF(R4="NOT_CHECKED",0,20)+IF(S4="NOT_CHECKED",0,10) -> 100 | V4: =IF(U4=100,T4,"") -> 100 | W4: =T4 -> 100 | X4: =T4+(100-U4) -> 100 | Y4: [] | Z4: ["evidence_batch_003_021", "https://jeminise.com/products/christmas-bedding-quilt-soft-microfiber-holiday-bedsprea-design-05", "https://cdn.shopify.com/s/files/1/0792/5098/1063/files/323ea5e3469590e61df70a45da30caeee15b2197d409a07ec242f1425c067466.jpg?v=1787239304"] | AA4: r6
A5: jeminise.com+christmas-bedding-quilt-soft-microfiber-holiday-bedsprea-design-05 | B5: jeminise.com+christmas-bedding-quilt-soft-microfiber-holiday-bedsprea-design-05|media:47934032412871|pos:4|url:619738ede07a | C5: https://cdn.shopify.com/s/files/1/0792/5098/1063/files/a9d73f05a5624e29d69e9f45c9035fc8ce6d17dce0280be079f2697dfabb6a95.jpg?v=1787239304 | D5: https://cdn.shopify.com/s/files/1/0792/5098/1063/files/a9d73f05a5624e29d69e9f45c9035fc8ce6d17dce0280be079f2697dfabb6a95.jpg?v=1787239304 | E5: 47934032412871 | F5: https://cdn.shopify.com/s/files/1/0792/5098/1063/files/a9d73f05a5624e29d69e9f45c9035fc8ce6d17dce0280be079f2697dfabb6a95.jpg?v=1787239304 | H5: GALLERY | I5: DIRECT_URL_DOWNLOAD_1200PX + VISUAL_READ | J5: 2026-09-09T12:00:00+07:00 | K5: Close-up of printed surface and visible quilting texture. | L5: Matching pillow sham with gingerbread cookie, candy cane and decorative green border. | M5: Christmas Bedding Quilt – Soft Microfiber Holiday Bedspread, Lightweight Winter Bedding, Cozy Xmas Quilts for Couch, Bedroom & Seasonal Home Decorations (Christmas Quilt-DS05) | N5: SET | O5: Gingerbread candy cane Christmas pillow sham | P5: FULL | Q5: FULL | R5: FULL | S5: FULL | T5: =IF(P5="FULL",40,IF(P5="PARTIAL",40/2,0))+IF(Q5="FULL",30,IF(Q5="PARTIAL",30/2,0))+IF(R5="FULL",20,IF(R5="PARTIAL",20/2,0))+IF(S5="FULL",10,IF(S5="PARTIAL",10/2,0)) -> 100 | U5: =IF(P5="NOT_CHECKED",0,40)+IF(Q5="NOT_CHECKED",0,30)+IF(R5="NOT_CHECKED",0,20)+IF(S5="NOT_CHECKED",0,10) -> 100 | V5: =IF(U5=100,T5,"") -> 100 | W5: =T5 -> 100 | X5: =T5+(100-U5) -> 100 | Y5: [] | Z5: ["evidence_batch_003_021", "https://jeminise.com/products/christmas-bedding-quilt-soft-microfiber-holiday-bedsprea-design-05", "https://cdn.shopify.com/s/files/1/0792/5098/1063/files/a9d73f05a5624e29d69e9f45c9035fc8ce6d17dce0280be079f2697dfabb6a95.jpg?v=1787239304"] | AA5: r6
A6: jeminise.com+christmas-bedding-quilt-soft-microfiber-holiday-bedsprea-design-05 | B6: jeminise.com+christmas-bedding-quilt-soft-microfiber-holiday-bedsprea-design-05|media:47934032445639|pos:5|url:7a3c5ef848c7 | C6: https://cdn.shopify.com/s/files/1/0792/5098/1063/files/0461d860e029a4d27649c56e37e256172572e09064aab3d6823b9226c1ee8c9b.jpg?v=1787239304 | D6: https://cdn.shopify.com/s/files/1/0792/5098/1063/files/0461d860e029a4d27649c56e37e256172572e09064aab3d6823b9226c1ee8c9b.jpg?v=1787239304 | E6: 47934032445639 | F6: https://cdn.shopify.com/s/files/1/0792/5098/1063/files/0461d860e029a4d27649c56e37e256172572e09064aab3d6823b9226c1ee8c9b.jpg?v=1787239304 | H6: GALLERY | I6: DIRECT_URL_DOWNLOAD_1200PX + VISUAL_READ | J6: 2026-09-09T12:00:00+07:00 | K6: Included-components and size graphic with quilt/sham options and dimensions. | L6: Size and component panel showing one premium quilt and two optional standard shams. | M6: Christmas Bedding Quilt – Soft Microfiber Holiday Bedspread, Lightweight Winter Bedding, Cozy Xmas Quilts for Couch, Bedroom & Seasonal Home Decorations (Christmas Quilt-DS05) | N6: SET | O6: Gingerbread candy cane quilt size and sham options | P6: FULL | Q6: FULL | R6: FULL | S6: FULL | T6: =IF(P6="FULL",40,IF(P6="PARTIAL",40/2,0))+IF(Q6="FULL",30,IF(Q6="PARTIAL",30/2,0))+IF(R6="FULL",20,IF(R6="PARTIAL",20/2,0))+IF(S6="FULL",10,IF(S6="PARTIAL",10/2,0)) -> 100 | U6: =IF(P6="NOT_CHECKED",0,40)+IF(Q6="NOT_CHECKED",0,30)+IF(R6="NOT_CHECKED",0,20)+IF(S6="NOT_CHECKED",0,10) -> 100 | V6: =IF(U6=100,T6,"") -> 100 | W6: =T6 -> 100 | X6: =T6+(100-U6) -> 100 | Y6: [] | Z6: ["evidence_batch_003_021", "https://jeminise.com/products/christmas-bedding-quilt-soft-microfiber-holiday-bedsprea-design-05", "https://cdn.shopify.com/s/files/1/0792/5098/1063/files/0461d860e029a4d27649c56e37e256172572e09064aab3d6823b9226c1ee8c9b.jpg?v=1787239304"] | AA6: r6
A7: jeminise.com+christmas-bedding-quilt-soft-microfiber-holiday-bedsprea-design-06 | B7: jeminise.com+christmas-bedding-quilt-soft-microfiber-holiday-bedsprea-design-06|media:47934035427527|pos:1|url:cb51ce7f517a | C7: https://cdn.shopify.com/s/files/1/0792/5098/1063/files/72e69cf5279e1503866df817e765ec4b9528ac9d374090ff6a383b64dc802f0f.jpg?v=1787239327 | D7: https://cdn.shopify.com/s/files/1/0792/5098/1063/files/72e69cf5279e1503866df817e765ec4b9528ac9d374090ff6a383b64dc802f0f.jpg?v=1787239327 | E7: 47934035427527 | F7: https://cdn.shopify.com/s/files/1/0792/5098/1063/files/72e69cf5279e1503866df817e765ec4b9528ac9d374090ff6a383b64dc802f0f.jpg?v=1787239327 | H7: GALLERY | I7: DIRECT_URL_DOWNLOAD_1200PX + VISUAL_READ | J7: 2026-09-09T12:00:00+07:00 | K7: Front bedroom mockup showing the primary quilt motif and coordinated shams. | L7: Black Christmas tree quilt bed mockup with decorated tree, gift boxes, dark border and matching shams. | M7: Christmas Bedding Quilt – Soft Microfiber Holiday Bedspread, Lightweight Winter Bedding, Cozy Xmas Quilts for Couch, Bedroom & Seasonal Home Decorations (Christmas Quilt-DS06) | N7: SET | O7: Black Christmas tree quilt set on bed | P7: FULL | Q7: FULL | R7: FULL | S7: FULL | T7: =IF(P7="FULL",40,IF(P7="PARTIAL",40/2,0))+IF(Q7="FULL",30,IF(Q7="PARTIAL",30/2,0))+IF(R7="FULL",20,IF(R7="PARTIAL",20/2,0))+IF(S7="FULL",10,IF(S7="PARTIAL",10/2,0)) -> 100 | U7: =IF(P7="NOT_CHECKED",0,40)+IF(Q7="NOT_CHECKED",0,30)+IF(R7="NOT_CHECKED",0,20)+IF(S7="NOT_CHECKED",0,10) -> 100 | V7: =IF(U7=100,T7,"") -> 100 | W7: =T7 -> 100 | X7: =T7+(100-U7) -> 100 | Y7: [] | Z7: ["evidence_batch_003_022", "https://jeminise.com/products/christmas-bedding-quilt-soft-microfiber-holiday-bedsprea-design-06", "https://cdn.shopify.com/s/files/1/0792/5098/1063/files/72e69cf5279e1503866df817e765ec4b9528ac9d374090ff6a383b64dc802f0f.jpg?v=1787239327"] | AA7: r6
A8: jeminise.com+christmas-bedding-quilt-soft-microfiber-holiday-bedsprea-design-06 | B8: jeminise.com+christmas-bedding-quilt-soft-microfiber-holiday-bedsprea-design-06|media:47934035460295|pos:2|url:dd41e8e27081 | C8: https://cdn.shopify.com/s/files/1/0792/5098/1063/files/1f0bc53734f9d184eafeba37de9d2d68714be1c73b540fbe08ef60be1bc69fa5.jpg?v=1787239327 | D8: https://cdn.shopify.com/s/files/1/0792/5098/1063/files/1f0bc53734f9d184eafeba37de9d2d68714be1c73b540fbe08ef60be1bc69fa5.jpg?v=1787239327 | E8: 47934035460295 | F8: https://cdn.shopify.com/s/files/1/0792/5098/1063/files/1f0bc53734f9d184eafeba37de9d2d68714be1c73b540fbe08ef60be1bc69fa5.jpg?v=1787239327 | H8: GALLERY | I8: DIRECT_URL_DOWNLOAD_1200PX + VISUAL_READ | J8: 2026-09-09T12:00:00+07:00 | K8: Angled bedroom mockup confirming the same motif across the set. | L8: Bedroom mockup showing black Christmas tree quilt with presents and coordinated pillow shams. | M8: Christmas Bedding Quilt – Soft Microfiber Holiday Bedspread, Lightweight Winter Bedding, Cozy Xmas Quilts for Couch, Bedroom & Seasonal Home Decorations (Christmas Quilt-DS06) | N8: SET | O8: Black Christmas tree quilt bedroom mockup | P8: FULL | Q8: FULL | R8: FULL | S8: FULL | T8: =IF(P8="FULL",40,IF(P8="PARTIAL",40/2,0))+IF(Q8="FULL",30,IF(Q8="PARTIAL",30/2,0))+IF(R8="FULL",20,IF(R8="PARTIAL",20/2,0))+IF(S8="FULL",10,IF(S8="PARTIAL",10/2,0)) -> 100 | U8: =IF(P8="NOT_CHECKED",0,40)+IF(Q8="NOT_CHECKED",0,30)+IF(R8="NOT_CHECKED",0,20)+IF(S8="NOT_CHECKED",0,10) -> 100 | V8: =IF(U8=100,T8,"") -> 100 | W8: =T8 -> 100 | X8: =T8+(100-U8) -> 100 | Y8: [] | Z8: ["evidence_batch_003_022", "https://jeminise.com/products/christmas-bedding-quilt-soft-microfiber-holiday-bedsprea-design-06", "https://cdn.shopify.com/s/files/1/0792/5098/1063/files/1f0bc53734f9d184eafeba37de9d2d68714be1c73b540fbe08ef60be1bc69fa5.jpg?v=1787239327"] | AA8: r6
A9: jeminise.com+christmas-bedding-quilt-soft-microfiber-holiday-bedsprea-design-06 | B9: jeminise.com+christmas-bedding-quilt-soft-microfiber-holiday-bedsprea-design-06|media:47934035493063|pos:3|url:b71845e1cb14 | C9: https://cdn.shopify.com/s/files/1/0792/5098/1063/files/9f875161013c7183bc18456508e00b3634194100adb029e0ff7c1be3bada05cf.jpg?v=1787239327 | D9: https://cdn.shopify.com/s/files/1/0792/5098/1063/files/9f875161013c7183bc18456508e00b3634194100adb029e0ff7c1be3bada05cf.jpg?v=1787239327 | E9: 47934035493063 | F9: https://cdn.shopify.com/s/files/1/0792/5098/1063/files/9f875161013c7183bc18456508e00b3634194100adb029e0ff7c1be3bada05cf.jpg?v=1787239327 | H9: GALLERY | I9: DIRECT_URL_DOWNLOAD_1200PX + VISUAL_READ | J9: 2026-09-09T12:00:00+07:00 | K9: Isolated pillow sham showing the coordinated printed artwork. | L9: Matching pillow sham with Christmas tree, presents and dark holiday border. | M9: Christmas Bedding Quilt – Soft Microfiber Holiday Bedspread, Lightweight Winter Bedding, Cozy Xmas Quilts for Couch, Bedroom & Seasonal Home Decorations (Christmas Quilt-DS06) | N9: SET | O9: Black Christmas tree quilt pillow sham | P9: FULL | Q9: FULL | R9: FULL | S9: FULL | T9: =IF(P9="FULL",40,IF(P9="PARTIAL",40/2,0))+IF(Q9="FULL",30,IF(Q9="PARTIAL",30/2,0))+IF(R9="FULL",20,IF(R9="PARTIAL",20/2,0))+IF(S9="FULL",10,IF(S9="PARTIAL",10/2,0)) -> 100 | U9: =IF(P9="NOT_CHECKED",0,40)+IF(Q9="NOT_CHECKED",0,30)+IF(R9="NOT_CHECKED",0,20)+IF(S9="NOT_CHECKED",0,10) -> 100 | V9: =IF(U9=100,T9,"") -> 100 | W9: =T9 -> 100 | X9: =T9+(100-U9) -> 100 | Y9: [] | Z9: ["evidence_batch_003_022", "https://jeminise.com/products/christmas-bedding-quilt-soft-microfiber-holiday-bedsprea-design-06", "https://cdn.shopify.com/s/files/1/0792/5098/1063/files/9f875161013c7183bc18456508e00b3634194100adb029e0ff7c1be3bada05cf.jpg?v=1787239327"] | AA9: r6
A10: jeminise.com+christmas-bedding-quilt-soft-microfiber-holiday-bedsprea-design-06 | B10: jeminise.com+christmas-bedding-quilt-soft-microfiber-holiday-bedsprea-design-06|media:47934035525831|pos:4|url:f90c7c262fe3 | C10: https://cdn.shopify.com/s/files/1/0792/5098/1063/files/de596ab0879cec52ad5e2a96c2ef7ec529fa83fcec514ad55907502143e123a0.jpg?v=1787239327 | D10: https://cdn.shopify.com/s/files/1/0792/5098/1063/files/de596ab0879cec52ad5e2a96c2ef7ec529fa83fcec514ad55907502143e123a0.jpg?v=1787239327 | E10: 47934035525831 | F10: https://cdn.shopify.com/s/files/1/0792/5098/1063/files/de596ab0879cec52ad5e2a96c2ef7ec529fa83fcec514ad55907502143e123a0.jpg?v=1787239327 | H10: GALLERY | I10: DIRECT_URL_DOWNLOAD_1200PX + VISUAL_READ | J10: 2026-09-09T12:00:00+07:00 | K10: Close-up of printed surface and visible quilting texture. | L10: Close-up of decorated Christmas tree branches, ornaments and visible quilt stitching on a dark background. | M10: Christmas Bedding Quilt – Soft Microfiber Holiday Bedspread, Lightweight Winter Bedding, Cozy Xmas Quilts for Couch, Bedroom & Seasonal Home Decorations (Christmas Quilt-DS06) | N10: SET | O10: Black Christmas tree quilt stitching close-up | P10: FULL | Q10: FULL | R10: FULL | S10: FULL | T10: =IF(P10="FULL",40,IF(P10="PARTIAL",40/2,0))+IF(Q10="FULL",30,IF(Q10="PARTIAL",30/2,0))+IF(R10="FULL",20,IF(R10="PARTIAL",20/2,0))+IF(S10="FULL",10,IF(S10="PARTIAL",10/2,0)) -> 100 | U10: =IF(P10="NOT_CHECKED",0,40)+IF(Q10="NOT_CHECKED",0,30)+IF(R10="NOT_CHECKED",0,20)+IF(S10="NOT_CHECKED",0,10) -> 100 | V10: =IF(U10=100,T10,"") -> 100 | W10: =T10 -> 100 | X10: =T10+(100-U10) -> 100 | Y10: [] | Z10: ["evidence_batch_003_022", "https://jeminise.com/products/christmas-bedding-quilt-soft-microfiber-holiday-bedsprea-design-06", "https://cdn.shopify.com/s/files/1/0792/5098/1063/files/de596ab0879cec52ad5e2a96c2ef7ec529fa83fcec514ad55907502143e123a0.jpg?v=1787239327"] | AA10: r6
A11: jeminise.com+christmas-bedding-quilt-soft-microfiber-holiday-bedsprea-design-06 | B11: jeminise.com+christmas-bedding-quilt-soft-microfiber-holiday-bedsprea-design-06|media:47934035558599|pos:5|url:9ae25546be15 | C11: https://cdn.shopify.com/s/files/1/0792/5098/1063/files/c551c6c00f378c8ae6d61af5e53faaf79a1375863eefd1febffb9ecee0e3e4c9.jpg?v=1787239327 | D11: https://cdn.shopify.com/s/files/1/0792/5098/1063/files/c551c6c00f378c8ae6d61af5e53faaf79a1375863eefd1febffb9ecee0e3e4c9.jpg?v=1787239327 | E11: 47934035558599 | F11: https://cdn.shopify.com/s/files/1/0792/5098/1063/files/c551c6c00f378c8ae6d61af5e53faaf79a1375863eefd1febffb9ecee0e3e4c9.jpg?v=1787239327 | H11: GALLERY | I11: DIRECT_URL_DOWNLOAD_1200PX + VISUAL_READ | J11: 2026-09-09T12:00:00+07:00 | K11: Included-components and size graphic with quilt/sham options and dimensions. | L11: Size and component panel showing one premium quilt and two optional standard shams. | M11: Christmas Bedding Quilt – Soft Microfiber Holiday Bedspread, Lightweight Winter Bedding, Cozy Xmas Quilts for Couch, Bedroom & Seasonal Home Decorations (Christmas Quilt-DS06) | N11: SET | O11: Black Christmas tree quilt size and sham options | P11: FULL | Q11: FULL | R11: FULL | S11: FULL | T11: =IF(P11="FULL",40,IF(P11="PARTIAL",40/2,0))+IF(Q11="FULL",30,IF(Q11="PARTIAL",30/2,0))+IF(R11="FULL",20,IF(R11="PARTIAL",20/2,0))+IF(S11="FULL",10,IF(S11="PARTIAL",10/2,0)) -> 100 | U11: =IF(P11="NOT_CHECKED",0,40)+IF(Q11="NOT_CHECKED",0,30)+IF(R11="NOT_CHECKED",0,20)+IF(S11="NOT_CHECKED",0,10) -> 100 | V11: =IF(U11=100,T11,"") -> 100 | W11: =T11 -> 100 | X11: =T11+(100-U11) -> 100 | Y11: [] | Z11: ["evidence_batch_003_022", "https://jeminise.com/products/christmas-bedding-quilt-soft-microfiber-holiday-bedsprea-design-06", "https://cdn.shopify.com/s/files/1/0792/5098/1063/files/c551c6c00f378c8ae6d61af5e53faaf79a1375863eefd1febffb9ecee0e3e4c9.jpg?v=1787239327"] | AA11: r6
A12: jeminise.com+christmas-bedding-quilt-soft-microfiber-holiday-bedsprea-design-08 | B12: jeminise.com+christmas-bedding-quilt-soft-microfiber-holiday-bedsprea-design-08|media:47934036541639|pos:1|url:8903ed0cf00b | C12: https://cdn.shopify.com/s/files/1/0792/5098/1063/files/46ac5bc18554d3c8eef4fcfd803278c3caa3d66a0c5dad038cb8e03d55416938.jpg?v=1787239336 | D12: https://cdn.shopify.com/s/files/1/0792/5098/1063/files/46ac5bc18554d3c8eef4fcfd803278c3caa3d66a0c5dad038cb8e03d55416938.jpg?v=1787239336 | E12: 47934036541639 | F12: https://cdn.shopify.com/s/files/1/0792/5098/1063/files/46ac5bc18554d3c8eef4fcfd803278c3caa3d66a0c5dad038cb8e03d55416938.jpg?v=1787239336 | H12: GALLERY | I12: DIRECT_URL_DOWNLOAD_1200PX + VISUAL_READ | J12: 2026-09-09T12:00:00+07:00 | K12: Front bedroom mockup showing the primary quilt motif and coordinated shams. | L12: Winter cardinal birdhouse quilt bed mockup with red cardinals, snowy birdhouse and matching shams. | M12: Christmas Bedding Quilt – Soft Microfiber Holiday Bedspread, Lightweight Winter Bedding, Cozy Xmas Quilts for Couch, Bedroom & Seasonal Home Decorations (Christmas Quilt-DS08) | N12: SET | O12: Winter cardinal birdhouse quilt set on bed | P12: FULL | Q12: FULL | R12: FULL | S12: FULL | T12: =IF(P12="FULL",40,IF(P12="PARTIAL",40/2,0))+IF(Q12="FULL",30,IF(Q12="PARTIAL",30/2,0))+IF(R12="FULL",20,IF(R12="PARTIAL",20/2,0))+IF(S12="FULL",10,IF(S12="PARTIAL",10/2,0)) -> 100 | U12: =IF(P12="NOT_CHECKED",0,40)+IF(Q12="NOT_CHECKED",0,30)+IF(R12="NOT_CHECKED",0,20)+IF(S12="NOT_CHECKED",0,10) -> 100 | V12: =IF(U12=100,T12,"") -> 100 | W12: =T12 -> 100 | X12: =T12+(100-U12) -> 100 | Y12: [] | Z12: ["evidence_batch_003_023", "https://jeminise.com/products/christmas-bedding-quilt-soft-microfiber-holiday-bedsprea-design-08", "https://cdn.shopify.com/s/files/1/0792/5098/1063/files/46ac5bc18554d3c8eef4fcfd803278c3caa3d66a0c5dad038cb8e03d55416938.jpg?v=1787239336"] | AA12: r6
A13: jeminise.com+christmas-bedding-quilt-soft-microfiber-holiday-bedsprea-design-08 | B13: jeminise.com+christmas-bedding-quilt-soft-microfiber-holiday-bedsprea-design-08|media:47934036574407|pos:2|url:406ad8c09e7e | C13: https://cdn.shopify.com/s/files/1/0792/5098/1063/files/6253d0d99a44a39ec73a70fccf1fd5474c4304769ed308a2bce71e6ae7fc6773.jpg?v=1787239336 | D13: https://cdn.shopify.com/s/files/1/0792/5098/1063/files/6253d0d99a44a39ec73a70fccf1fd5474c4304769ed308a2bce71e6ae7fc6773.jpg?v=1787239336 | E13: 47934036574407 | F13: https://cdn.shopify.com/s/files/1/0792/5098/1063/files/6253d0d99a44a39ec73a70fccf1fd5474c4304769ed308a2bce71e6ae7fc6773.jpg?v=1787239336 | H13: GALLERY | I13: DIRECT_URL_DOWNLOAD_1200PX + VISUAL_READ | J13: 2026-09-09T12:00:00+07:00 | K13: Angled bedroom mockup confirming the same motif across the set. | L13: Bedroom mockup showing red cardinals around a snowy birdhouse on a pale winter quilt. | M13: Christmas Bedding Quilt – Soft Microfiber Holiday Bedspread, Lightweight Winter Bedding, Cozy Xmas Quilts for Couch, Bedroom & Seasonal Home Decorations (Christmas Quilt-DS08) | N13: SET | O13: Winter cardinal birdhouse quilt bedroom mockup | P13: FULL | Q13: FULL | R13: FULL | S13: FULL | T13: =IF(P13="FULL",40,IF(P13="PARTIAL",40/2,0))+IF(Q13="FULL",30,IF(Q13="PARTIAL",30/2,0))+IF(R13="FULL",20,IF(R13="PARTIAL",20/2,0))+IF(S13="FULL",10,IF(S13="PARTIAL",10/2,0)) -> 100 | U13: =IF(P13="NOT_CHECKED",0,40)+IF(Q13="NOT_CHECKED",0,30)+IF(R13="NOT_CHECKED",0,20)+IF(S13="NOT_CHECKED",0,10) -> 100 | V13: =IF(U13=100,T13,"") -> 100 | W13: =T13 -> 100 | X13: =T13+(100-U13) -> 100 | Y13: [] | Z13: ["evidence_batch_003_023", "https://jeminise.com/products/christmas-bedding-quilt-soft-microfiber-holiday-bedsprea-design-08", "https://cdn.shopify.com/s/files/1/0792/5098/1063/files/6253d0d99a44a39ec73a70fccf1fd5474c4304769ed308a2bce71e6ae7fc6773.jpg?v=1787239336"] | AA13: r6
... A51: jeminise.com+christmas-cardinal-perched-on-branch-within-wreath-patchwork-winter-quilt-9e7c0b5896-9e7c0b5896 | B51: jeminise.com+christmas-cardinal-perched-on-branch-within-wreath-patchwork-winter-quilt-9e7c0b5896-9e7c0b5896|media:47540041121991|pos:5|url:8aaff82f0ee4 | C51: https://cdn.shopify.com/s/files/1/0792/5098/1063/files/b3f4b380fddc0b4717e5a8960ebd73a239442861c5a0cc84575c35c7339c41e1.jpg?v=1785099457 | D51: https://cdn.shopify.com/s/files/1/0792/5098/1063/files/b3f4b380fddc0b4717e5a8960ebd73a239442861c5a0cc84575c35c7339c41e1.jpg?v=1785099457 | E51: 47540041121991 | F51: https://cdn.shopify.com/s/files/1/0792/5098/1063/files/b3f4b380fddc0b4717e5a8960ebd73a239442861c5a0cc84575c35c7339c41e1.jpg?v=1785099457 | H51: GALLERY | I51: DIRECT_URL_DOWNLOAD_1200PX + VISUAL_READ | J51: 2026-09-09T12:00:00+07:00 | K51: Included-components and size graphic with quilt/sham options and dimensions. | L51: Size and component panel showing one premium quilt and two optional standard shams. | M51: Christmas Cardinal Perched on Branch Within Wreath Patchwork Winter Quilt | N51: SET | O51: Cardinal wreath quilt size and sham options | P51: FULL | Q51: FULL | R51: FULL | S51: FULL | T51: =IF(P51="FULL",40,IF(P51="PARTIAL",40/2,0))+IF(Q51="FULL",30,IF(Q51="PARTIAL",30/2,0))+IF(R51="FULL",20,IF(R51="PARTIAL",20/2,0))+IF(S51="FULL",10,IF(S51="PARTIAL",10/2,0)) -> 100 | U51: =IF(P51="NOT_CHECKED",0,40)+IF(Q51="NOT_CHECKED",0,30)+IF(R51="NOT_CHECKED",0,20)+IF(S51="NOT_CHECKED",0,10) -> 100 | V51: =IF(U51=100,T51,"") -> 100 | W51: =T51 -> 100 | X51: =T51+(100-U51) -> 100 | Y51: [] | Z51: ["evidence_batch_003_030", "https://jeminise.com/products/christmas-cardinal-perched-on-branch-within-wreath-patchwork-winter-quilt-9e7c0b5896-9e7c0b5896", "https://cdn.shopify.com/s/files/1/0792/5098/1063/files/b3f4b380fddc0b4717e5a8960ebd73a239442861c5a0cc84575c35c7339c41e1.jpg?v=1785099457"] | AA51: r6

Sheet QA_Issues
A1: issue_id | B1: product_key | C1: qa_image_key | D1: severity | E1: field | F1: submitted_value | G1: source_observation | H1: reason | I1: recommended_fix | J1: supporting_evidence | K1: recheck_condition | L1: history_status
A2: R6-ISS-021-PERS | B2: jeminise.com+christmas-bedding-quilt-soft-microfiber-holiday-bedsprea-design-05 | D2: MAJOR | E2: personalization_control | F2: No personalization field claimed in r6 description | G2: Live HTML/product JSON shows a 1 text input only for positions 21, 29 and 30; live options otherwise show size and pillowcase selectors only. | H2: r6 customer-facing copy does not match the exact live personalization control state. | I2: Verify the Shopify customizer and either add the exact control or remove Personalized/name-field claims; for 29-30 rewrite the description to reflect the live control. | J2: https://jeminise.com/products/christmas-bedding-quilt-soft-microfiber-holiday-bedsprea-design-05; seo_runs/jeminise.com/20260906_234129/qa/20260909_120000/source_snapshot/live/21_christmas-bedding-quilt-soft-microfiber-holiday-bedsprea-design-05.js.json | K2: Re-read live JSON and rendered product form after correction. | L2: REGRESSED
A3: R6-ISS-022-PERS | B3: jeminise.com+christmas-bedding-quilt-soft-microfiber-holiday-bedsprea-design-06 | D3: MAJOR | E3: personalization_control | F3: Personalized title/name-field claim | G3: Live HTML/product JSON shows a 1 text input only for positions 21, 29 and 30; live options otherwise show size and pillowcase selectors only. | H3: r6 customer-facing copy does not match the exact live personalization control state. | I3: Verify the Shopify customizer and either add the exact control or remove Personalized/name-field claims; for 29-30 rewrite the description to reflect the live control. | J3: https://jeminise.com/products/christmas-bedding-quilt-soft-microfiber-holiday-bedsprea-design-06; seo_runs/jeminise.com/20260906_234129/qa/20260909_120000/source_snapshot/live/22_christmas-bedding-quilt-soft-microfiber-holiday-bedsprea-design-06.js.json | K3: Re-read live JSON and rendered product form after correction. | L3: REGRESSED
A4: R6-ISS-023-PERS | B4: jeminise.com+christmas-bedding-quilt-soft-microfiber-holiday-bedsprea-design-08 | D4: MAJOR | E4: personalization_control | F4: Personalized title/name-field claim | G4: Live HTML/product JSON shows a 1 text input only for positions 21, 29 and 30; live options otherwise show size and pillowcase selectors only. | H4: r6 customer-facing copy does not match the exact live personalization control state. | I4: Verify the Shopify customizer and either add the exact control or remove Personalized/name-field claims; for 29-30 rewrite the description to reflect the live control. | J4: https://jeminise.com/products/christmas-bedding-quilt-soft-microfiber-holiday-bedsprea-design-08; seo_runs/jeminise.com/20260906_234129/qa/20260909_120000/source_snapshot/live/23_christmas-bedding-quilt-soft-microfiber-holiday-bedsprea-design-08.js.json | K4: Re-read live JSON and rendered product form after correction. | L4: REGRESSED
A5: R6-ISS-024-PERS | B5: jeminise.com+christmas-bedding-quilt-soft-microfiber-holiday-bedsprea-design-09 | D5: MAJOR | E5: personalization_control | F5: Personalized title/name-field claim | G5: Live HTML/product JSON shows a 1 text input only for positions 21, 29 and 30; live options otherwise show size and pillowcase selectors only. | H5: r6 customer-facing copy does not match the exact live personalization control state. | I5: Verify the Shopify customizer and either add the exact control or remove Personalized/name-field claims; for 29-30 rewrite the description to reflect the live control. | J5: https://jeminise.com/products/christmas-bedding-quilt-soft-microfiber-holiday-bedsprea-design-09; seo_runs/jeminise.com/20260906_234129/qa/20260909_120000/source_snapshot/live/24_christmas-bedding-quilt-soft-microfiber-holiday-bedsprea-design-09.js.json | K5: Re-read live JSON and rendered product form after correction. | L5: REGRESSED
A6: R6-ISS-025-PERS | B6: jeminise.com+christmas-bedding-quilt-soft-microfiber-holiday-bedsprea-design-10 | D6: MAJOR | E6: personalization_control | F6: Personalized title/name-field claim | G6: Live HTML/product JSON shows a 1 text input only for positions 21, 29 and 30; live options otherwise show size and pillowcase selectors only. | H6: r6 customer-facing copy does not match the exact live personalization control state. | I6: Verify the Shopify customizer and either add the exact control or remove Personalized/name-field claims; for 29-30 rewrite the description to reflect the live control. | J6: https://jeminise.com/products/christmas-bedding-quilt-soft-microfiber-holiday-bedsprea-design-10; seo_runs/jeminise.com/20260906_234129/qa/20260909_120000/source_snapshot/live/25_christmas-bedding-quilt-soft-microfiber-holiday-bedsprea-design-10.js.json | K6: Re-read live JSON and rendered product form after correction. | L6: REGRESSED
A7: R6-ISS-026-PERS | B7: jeminise.com+christmas-bedding-quilt-soft-microfiber-holiday-bedsprea-design-11 | D7: MAJOR | E7: personalization_control | F7: Personalized title/name-field claim | G7: Live HTML/product JSON shows a 1 text input only for positions 21, 29 and 30; live options otherwise show size and pillowcase selectors only. | H7: r6 customer-facing copy does not match the exact live personalization control state. | I7: Verify the Shopify customizer and either add the exact control or remove Personalized/name-field claims; for 29-30 rewrite the description to reflect the live control. | J7: https://jeminise.com/products/christmas-bedding-quilt-soft-microfiber-holiday-bedsprea-design-11; seo_runs/jeminise.com/20260906_234129/qa/20260909_120000/source_snapshot/live/26_christmas-bedding-quilt-soft-microfiber-holiday-bedsprea-design-11.js.json | K7: Re-read live JSON and rendered product form after correction. | L7: REGRESSED
A8: R6-ISS-027-PERS | B8: jeminise.com+christmas-bedding-quilt-soft-microfiber-holiday-bedsprea-design-12 | D8: MAJOR | E8: personalization_control | F8: Personalized title/name-field claim | G8: Live HTML/product JSON shows a 1 text input only for positions 21, 29 and 30; live options otherwise show size and pillowcase selectors only. | H8: r6 customer-facing copy does not match the exact live personalization control state. | I8: Verify the Shopify customizer and either add the exact control or remove Personalized/name-field claims; for 29-30 rewrite the description to reflect the live control. | J8: https://jeminise.com/products/christmas-bedding-quilt-soft-microfiber-holiday-bedsprea-design-12; seo_runs/jeminise.com/20260906_234129/qa/20260909_120000/source_snapshot/live/27_christmas-bedding-quilt-soft-microfiber-holiday-bedsprea-design-12.js.json | K8: Re-read live JSON and rendered product form after correction. | L8: REGRESSED
A9: R6-ISS-028-PERS | B9: jeminise.com+christmas-bedding-quilt-soft-microfiber-holiday-bedspread | D9: MAJOR | E9: personalization_control | F9: Personalized title/name-field claim | G9: Live HTML/product JSON shows a 1 text input only for positions 21, 29 and 30; live options otherwise show size and pillowcase selectors only. | H9: r6 customer-facing copy does not match the exact live personalization control state. | I9: Verify the Shopify customizer and either add the exact control or remove Personalized/name-field claims; for 29-30 rewrite the description to reflect the live control. | J9: https://jeminise.com/products/christmas-bedding-quilt-soft-microfiber-holiday-bedspread; seo_runs/jeminise.com/20260906_234129/qa/20260909_120000/source_snapshot/live/28_christmas-bedding-quilt-soft-microfiber-holiday-bedspread.js.json | K9: Re-read live JSON and rendered product form after correction. | L9: REGRESSED
A10: R6-ISS-029-PERS | B10: jeminise.com+christmas-cardinal-on-branch-within-patchwork-winter-quilt-892d70543a-892d70543a | D10: MAJOR | E10: personalization_control | F10: No personalization field claimed in r6 description | G10: Live HTML/product JSON shows a 1 text input only for positions 21, 29 and 30; live options otherwise show size and pillowcase selectors only. | H10: r6 customer-facing copy does not match the exact live personalization control state. | I10: Verify the Shopify customizer and either add the exact control or remove Personalized/name-field claims; for 29-30 rewrite the description to reflect the live control. | J10: https://jeminise.com/products/christmas-cardinal-on-branch-within-patchwork-winter-quilt-892d70543a-892d70543a; seo_runs/jeminise.com/20260906_234129/qa/20260909_120000/source_snapshot/live/29_christmas-cardinal-on-branch-within-patchwork-winter-quilt-892d70543a-892d70543a.js.json | K10: Re-read live JSON and rendered product form after correction. | L10: PERSISTS
A11: R6-ISS-030-PERS | B11: jeminise.com+christmas-cardinal-perched-on-branch-within-wreath-patchwork-winter-quilt-9e7c0b5896-9e7c0b5896 | D11: MAJOR | E11: personalization_control | F11: No personalization field claimed in r6 description | G11: Live HTML/product JSON shows a 1 text input only for positions 21, 29 and 30; live options otherwise show size and pillowcase selectors only. | H11: r6 customer-facing copy does not match the exact live personalization control state. | I11: Verify the Shopify customizer and either add the exact control or remove Personalized/name-field claims; for 29-30 rewrite the description to reflect the live control. | J11: https://jeminise.com/products/christmas-cardinal-perched-on-branch-within-wreath-patchwork-winter-quilt-9e7c0b5896-9e7c0b5896; seo_runs/jeminise.com/20260906_234129/qa/20260909_120000/source_snapshot/live/30_christmas-cardinal-perched-on-branch-within-wreath-patchwork-winter-quilt-9e7c0b5896-9e7c0b5896.js.json | K11: Re-read live JSON and rendered product form after correction. | L11: PERSISTS
