Workbook

Sheet QA_Summary
A1: metric | B1: value | C1: definition
A2: shop_domain | B2: jeminise.com | C2: Shop being QAed.
A3: source_run_id | B3: 20260906_234129 | C3: Original SEO drafting run.
A4: qa_run_id | B4: 20260907_212312 | C4: QA run folder for this corrected rerun.
A5: qa_batch_id | B5: qa_batch_017 | C5: Batch being independently checked.
A6: revision | B6: r1 | C6: Initial independent QA revision for qa_batch_017.
A7: source_workbook | B7: D:\Shopify_Workspace\jeminise_seo\resutls\jeminise.com\20260906_234129\batches\SEO_Product_Optimization_through_batch_017.xlsx | C7: Frozen workbook source path.
A8: source_sha256 | B8: 65F8C48D63E55BA5F6B311B33EF5ED1FBFEAB99A148B84E45592C180C8CD9132 | C8: SHA-256 at freeze/final handoff time.
A9: snapshot_sha256 | B9: 65F8C48D63E55BA5F6B311B33EF5ED1FBFEAB99A148B84E45592C180C8CD9132 | C9: SHA-256 of workbook copy in source_snapshot.
A10: scope | B10: 10 products, 62/62 images | C10: Batch scope and image coverage.
A11: batch_final_score | B11: =AVERAGE('QA_Products'!$K$2:$K$11) | C11: Formula-driven average final score in workbook.
A12: batch_result | B12: =IF(COUNTIF('QA_Products'!$L$2:$L$11,"QA_PASS")=ROWS('QA_Products'!$L$2:$L$11),"PASSED","NOT_PASSED") | C12: PASSED only if all products are QA_PASS.
A13: status_counts | B13: ="PASS="&COUNTIF('QA_Products'!$L$2:$L$11,"QA_PASS")&"; REVISE="&COUNTIF('QA_Products'!$L$2:$L$11,"QA_REVISE")&"; FAIL="&COUNTIF('QA_Products'!$L$2:$L$11,"QA_FAIL")&"; INCOMPLETE="&COUNTIF('QA_Products'!$L$2:$L$11,"QA_INCOMPLETE") | C13: Product QA status counts.
A14: issue_counts | B14: CRITICAL=0; MAJOR=21; MINOR=61; LIMITATION=10 | C14: Issue severity counts.
A15: awaiting_confirmation | B15: TRUE | C15: Do not QA next batch until user confirms.

Sheet QA_Products
A1: inventory_position | B1: product_key | C1: url | D1: handle | E1: product_id | F1: revision | G1: verified_points | H1: assessed_weight | I1: score_lower_bound | J1: score_upper_bound | K1: final_score | L1: qa_status | M1: keyword_evidence_level | N1: images_expected | O1: images_checked | P1: image_inventory_complete | Q1: image_coverage | R1: critical_count | S1: major_count | T1: minor_count | U1: limitation_count | V1: issue_refs | W1: evidence_refs
A2: 161 | B2: jeminise.com+norse-mythology-raven-within-celtic-knot-frame-quilt-906ee24d68-906ee24d68 | C2: https://jeminise.com/products/norse-mythology-raven-within-celtic-knot-frame-quilt-906ee24d68-906ee24d68 | D2: norse-mythology-raven-within-celtic-knot-frame-quilt-906ee24d68-906ee24d68 | E2: 8834806218951 | F2: r1 | G2: =SUMIF('QA_Criteria'!$A$2:$A$111,B2,'QA_Criteria'!$F$2:$F$111) | H2: =SUMIF('QA_Criteria'!$A$2:$A$111,B2,'QA_Criteria'!$G$2:$G$111) | I2: =G2 | J2: =G2+(100-H2) | K2: =IF(AND(H2=100,Q2=1,P2=TRUE),G2,"") | L2: =IF(R2>0,"QA_FAIL",IF(K2="","QA_INCOMPLETE",IF(K2<70,"QA_FAIL",IF(OR(K2<85,S2>0),"QA_REVISE","QA_PASS")))) | M2: SERP_ONLY | N2: 7 | O2: 7 | P2: TRUE | Q2: 1 | R2: =COUNTIFS('QA_Issues'!$B$2:$B$93,B2,'QA_Issues'!$D$2:$D$93,"CRITICAL") | S2: =COUNTIFS('QA_Issues'!$B$2:$B$93,B2,'QA_Issues'!$D$2:$D$93,"MAJOR") | T2: =COUNTIFS('QA_Issues'!$B$2:$B$93,B2,'QA_Issues'!$D$2:$D$93,"MINOR") | U2: =COUNTIFS('QA_Issues'!$B$2:$B$93,B2,'QA_Issues'!$D$2:$D$93,"LIMITATION") | V2: ISSUE-0001; ISSUE-0002; ISSUE-0003; ISSUE-0004; ISSUE-0005; ISSUE-0006; ISSUE-0007; ISSUE-0008; ISSUE-0009; ISSUE-0010 | W2: evidence_batch_017_161; live_source_comparison; customizer_audit; serp_evidence
A3: 162 | B3: jeminise.com+norse-mythology-viking-shield-with-crossed-axes-quilt-ca630a284e-ca630a284e | C3: https://jeminise.com/products/norse-mythology-viking-shield-with-crossed-axes-quilt-ca630a284e-ca630a284e | D3: norse-mythology-viking-shield-with-crossed-axes-quilt-ca630a284e-ca630a284e | E3: 8834808512711 | F3: r1 | G3: =SUMIF('QA_Criteria'!$A$2:$A$111,B3,'QA_Criteria'!$F$2:$F$111) | H3: =SUMIF('QA_Criteria'!$A$2:$A$111,B3,'QA_Criteria'!$G$2:$G$111) | I3: =G3 | J3: =G3+(100-H3) | K3: =IF(AND(H3=100,Q3=1,P3=TRUE),G3,"") | L3: =IF(R3>0,"QA_FAIL",IF(K3="","QA_INCOMPLETE",IF(K3<70,"QA_FAIL",IF(OR(K3<85,S3>0),"QA_REVISE","QA_PASS")))) | M3: SERP_ONLY | N3: 7 | O3: 7 | P3: TRUE | Q3: 1 | R3: =COUNTIFS('QA_Issues'!$B$2:$B$93,B3,'QA_Issues'!$D$2:$D$93,"CRITICAL") | S3: =COUNTIFS('QA_Issues'!$B$2:$B$93,B3,'QA_Issues'!$D$2:$D$93,"MAJOR") | T3: =COUNTIFS('QA_Issues'!$B$2:$B$93,B3,'QA_Issues'!$D$2:$D$93,"MINOR") | U3: =COUNTIFS('QA_Issues'!$B$2:$B$93,B3,'QA_Issues'!$D$2:$D$93,"LIMITATION") | V3: ISSUE-0011; ISSUE-0012; ISSUE-0013; ISSUE-0014; ISSUE-0015; ISSUE-0016; ISSUE-0017; ISSUE-0018; ISSUE-0019; ISSUE-0020; ISSUE-0021 | W3: evidence_batch_017_162; live_source_comparison; customizer_audit; serp_evidence
A4: 163 | B4: jeminise.com+owl-patchwork-pattern-quilt-set-animals-quilt-set-style-owl-nights | C4: https://jeminise.com/products/owl-patchwork-pattern-quilt-set-animals-quilt-set-style-owl-nights | D4: owl-patchwork-pattern-quilt-set-animals-quilt-set-style-owl-nights | E4: 8867095118023 | F4: r1 | G4: =SUMIF('QA_Criteria'!$A$2:$A$111,B4,'QA_Criteria'!$F$2:$F$111) | H4: =SUMIF('QA_Criteria'!$A$2:$A$111,B4,'QA_Criteria'!$G$2:$G$111) | I4: =G4 | J4: =G4+(100-H4) | K4: =IF(AND(H4=100,Q4=1,P4=TRUE),G4,"") | L4: =IF(R4>0,"QA_FAIL",IF(K4="","QA_INCOMPLETE",IF(K4<70,"QA_FAIL",IF(OR(K4<85,S4>0),"QA_REVISE","QA_PASS")))) | M4: SERP_ONLY | N4: 7 | O4: 7 | P4: TRUE | Q4: 1 | R4: =COUNTIFS('QA_Issues'!$B$2:$B$93,B4,'QA_Issues'!$D$2:$D$93,"CRITICAL") | S4: =COUNTIFS('QA_Issues'!$B$2:$B$93,B4,'QA_Issues'!$D$2:$D$93,"MAJOR") | T4: =COUNTIFS('QA_Issues'!$B$2:$B$93,B4,'QA_Issues'!$D$2:$D$93,"MINOR") | U4: =COUNTIFS('QA_Issues'!$B$2:$B$93,B4,'QA_Issues'!$D$2:$D$93,"LIMITATION") | V4: ISSUE-0022; ISSUE-0023; ISSUE-0024; ISSUE-0025; ISSUE-0026; ISSUE-0027; ISSUE-0028; ISSUE-0029; ISSUE-0030; ISSUE-0031 | W4: evidence_batch_017_163; live_source_comparison; customizer_audit; serp_evidence
A5: 164 | B5: jeminise.com+pamnest-twin-halloween-comforter-set-with-sheets-5-pieces-design-01 | C5: https://jeminise.com/products/pamnest-twin-halloween-comforter-set-with-sheets-5-pieces-design-01 | D5: pamnest-twin-halloween-comforter-set-with-sheets-5-pieces-design-01 | E5: 8879778791623 | F5: r1 | G5: =SUMIF('QA_Criteria'!$A$2:$A$111,B5,'QA_Criteria'!$F$2:$F$111) | H5: =SUMIF('QA_Criteria'!$A$2:$A$111,B5,'QA_Criteria'!$G$2:$G$111) | I5: =G5 | J5: =G5+(100-H5) | K5: =IF(AND(H5=100,Q5=1,P5=TRUE),G5,"") | L5: =IF(R5>0,"QA_FAIL",IF(K5="","QA_INCOMPLETE",IF(K5<70,"QA_FAIL",IF(OR(K5<85,S5>0),"QA_REVISE","QA_PASS")))) | M5: SERP_ONLY | N5: 6 | O5: 6 | P5: TRUE | Q5: 1 | R5: =COUNTIFS('QA_Issues'!$B$2:$B$93,B5,'QA_Issues'!$D$2:$D$93,"CRITICAL") | S5: =COUNTIFS('QA_Issues'!$B$2:$B$93,B5,'QA_Issues'!$D$2:$D$93,"MAJOR") | T5: =COUNTIFS('QA_Issues'!$B$2:$B$93,B5,'QA_Issues'!$D$2:$D$93,"MINOR") | U5: =COUNTIFS('QA_Issues'!$B$2:$B$93,B5,'QA_Issues'!$D$2:$D$93,"LIMITATION") | V5: ISSUE-0032; ISSUE-0033; ISSUE-0034; ISSUE-0035; ISSUE-0036; ISSUE-0037; ISSUE-0038; ISSUE-0039; ISSUE-0040 | W5: evidence_batch_017_164; live_source_comparison; customizer_audit; serp_evidence
A6: 165 | B6: jeminise.com+pamnest-twin-halloween-comforter-set-with-sheets-5-pieces-design-02 | C6: https://jeminise.com/products/pamnest-twin-halloween-comforter-set-with-sheets-5-pieces-design-02 | D6: pamnest-twin-halloween-comforter-set-with-sheets-5-pieces-design-02 | E6: 8879778889927 | F6: r1 | G6: =SUMIF('QA_Criteria'!$A$2:$A$111,B6,'QA_Criteria'!$F$2:$F$111) | H6: =SUMIF('QA_Criteria'!$A$2:$A$111,B6,'QA_Criteria'!$G$2:$G$111) | I6: =G6 | J6: =G6+(100-H6) | K6: =IF(AND(H6=100,Q6=1,P6=TRUE),G6,"") | L6: =IF(R6>0,"QA_FAIL",IF(K6="","QA_INCOMPLETE",IF(K6<70,"QA_FAIL",IF(OR(K6<85,S6>0),"QA_REVISE","QA_PASS")))) | M6: SERP_ONLY | N6: 5 | O6: 5 | P6: TRUE | Q6: 1 | R6: =COUNTIFS('QA_Issues'!$B$2:$B$93,B6,'QA_Issues'!$D$2:$D$93,"CRITICAL") | S6: =COUNTIFS('QA_Issues'!$B$2:$B$93,B6,'QA_Issues'!$D$2:$D$93,"MAJOR") | T6: =COUNTIFS('QA_Issues'!$B$2:$B$93,B6,'QA_Issues'!$D$2:$D$93,"MINOR") | U6: =COUNTIFS('QA_Issues'!$B$2:$B$93,B6,'QA_Issues'!$D$2:$D$93,"LIMITATION") | V6: ISSUE-0041; ISSUE-0042; ISSUE-0043; ISSUE-0044; ISSUE-0045; ISSUE-0046; ISSUE-0047 | W6: evidence_batch_017_165; live_source_comparison; customizer_audit; serp_evidence
A7: 166 | B7: jeminise.com+pamnest-twin-halloween-comforter-set-with-sheets-5-pieces-design-03 | C7: https://jeminise.com/products/pamnest-twin-halloween-comforter-set-with-sheets-5-pieces-design-03 | D7: pamnest-twin-halloween-comforter-set-with-sheets-5-pieces-design-03 | E7: 8879779217607 | F7: r1 | G7: =SUMIF('QA_Criteria'!$A$2:$A$111,B7,'QA_Criteria'!$F$2:$F$111) | H7: =SUMIF('QA_Criteria'!$A$2:$A$111,B7,'QA_Criteria'!$G$2:$G$111) | I7: =G7 | J7: =G7+(100-H7) | K7: =IF(AND(H7=100,Q7=1,P7=TRUE),G7,"") | L7: =IF(R7>0,"QA_FAIL",IF(K7="","QA_INCOMPLETE",IF(K7<70,"QA_FAIL",IF(OR(K7<85,S7>0),"QA_REVISE","QA_PASS")))) | M7: SERP_ONLY | N7: 6 | O7: 6 | P7: TRUE | Q7: 1 | R7: =COUNTIFS('QA_Issues'!$B$2:$B$93,B7,'QA_Issues'!$D$2:$D$93,"CRITICAL") | S7: =COUNTIFS('QA_Issues'!$B$2:$B$93,B7,'QA_Issues'!$D$2:$D$93,"MAJOR") | T7: =COUNTIFS('QA_Issues'!$B$2:$B$93,B7,'QA_Issues'!$D$2:$D$93,"MINOR") | U7: =COUNTIFS('QA_Issues'!$B$2:$B$93,B7,'QA_Issues'!$D$2:$D$93,"LIMITATION") | V7: ISSUE-0048; ISSUE-0049; ISSUE-0050; ISSUE-0051; ISSUE-0052; ISSUE-0053; ISSUE-0054; ISSUE-0055; ISSUE-0056 | W7: evidence_batch_017_166; live_source_comparison; customizer_audit; serp_evidence
A8: 167 | B8: jeminise.com+pamnest-twin-halloween-comforter-set-with-sheets-5-pieces-design-04 | C8: https://jeminise.com/products/pamnest-twin-halloween-comforter-set-with-sheets-5-pieces-design-04 | D8: pamnest-twin-halloween-comforter-set-with-sheets-5-pieces-design-04 | E8: 8879779283143 | F8: r1 | G8: =SUMIF('QA_Criteria'!$A$2:$A$111,B8,'QA_Criteria'!$F$2:$F$111) | H8: =SUMIF('QA_Criteria'!$A$2:$A$111,B8,'QA_Criteria'!$G$2:$G$111) | I8: =G8 | J8: =G8+(100-H8) | K8: =IF(AND(H8=100,Q8=1,P8=TRUE),G8,"") | L8: =IF(R8>0,"QA_FAIL",IF(K8="","QA_INCOMPLETE",IF(K8<70,"QA_FAIL",IF(OR(K8<85,S8>0),"QA_REVISE","QA_PASS")))) | M8: SERP_ONLY | N8: 6 | O8: 6 | P8: TRUE | Q8: 1 | R8: =COUNTIFS('QA_Issues'!$B$2:$B$93,B8,'QA_Issues'!$D$2:$D$93,"CRITICAL") | S8: =COUNTIFS('QA_Issues'!$B$2:$B$93,B8,'QA_Issues'!$D$2:$D$93,"MAJOR") | T8: =COUNTIFS('QA_Issues'!$B$2:$B$93,B8,'QA_Issues'!$D$2:$D$93,"MINOR") | U8: =COUNTIFS('QA_Issues'!$B$2:$B$93,B8,'QA_Issues'!$D$2:$D$93,"LIMITATION") | V8: ISSUE-0057; ISSUE-0058; ISSUE-0059; ISSUE-0060; ISSUE-0061; ISSUE-0062; ISSUE-0063; ISSUE-0064; ISSUE-0065 | W8: evidence_batch_017_167; live_source_comparison; customizer_audit; serp_evidence
A9: 168 | B9: jeminise.com+pamnest-twin-halloween-comforter-set-with-sheets-5-pieces-design-05 | C9: https://jeminise.com/products/pamnest-twin-halloween-comforter-set-with-sheets-5-pieces-design-05 | D9: pamnest-twin-halloween-comforter-set-with-sheets-5-pieces-design-05 | E9: 8879779348679 | F9: r1 | G9: =SUMIF('QA_Criteria'!$A$2:$A$111,B9,'QA_Criteria'!$F$2:$F$111) | H9: =SUMIF('QA_Criteria'!$A$2:$A$111,B9,'QA_Criteria'!$G$2:$G$111) | I9: =G9 | J9: =G9+(100-H9) | K9: =IF(AND(H9=100,Q9=1,P9=TRUE),G9,"") | L9: =IF(R9>0,"QA_FAIL",IF(K9="","QA_INCOMPLETE",IF(K9<70,"QA_FAIL",IF(OR(K9<85,S9>0),"QA_REVISE","QA_PASS")))) | M9: SERP_ONLY | N9: 6 | O9: 6 | P9: TRUE | Q9: 1 | R9: =COUNTIFS('QA_Issues'!$B$2:$B$93,B9,'QA_Issues'!$D$2:$D$93,"CRITICAL") | S9: =COUNTIFS('QA_Issues'!$B$2:$B$93,B9,'QA_Issues'!$D$2:$D$93,"MAJOR") | T9: =COUNTIFS('QA_Issues'!$B$2:$B$93,B9,'QA_Issues'!$D$2:$D$93,"MINOR") | U9: =COUNTIFS('QA_Issues'!$B$2:$B$93,B9,'QA_Issues'!$D$2:$D$93,"LIMITATION") | V9: ISSUE-0066; ISSUE-0067; ISSUE-0068; ISSUE-0069; ISSUE-0070; ISSUE-0071; ISSUE-0072; ISSUE-0073; ISSUE-0074 | W9: evidence_batch_017_168; live_source_comparison; customizer_audit; serp_evidence
A10: 169 | B10: jeminise.com+pamnest-twin-halloween-comforter-set-with-sheets-5-pieces-design-06 | C10: https://jeminise.com/products/pamnest-twin-halloween-comforter-set-with-sheets-5-pieces-design-06 | D10: pamnest-twin-halloween-comforter-set-with-sheets-5-pieces-design-06 | E10: 8879779381447 | F10: r1 | G10: =SUMIF('QA_Criteria'!$A$2:$A$111,B10,'QA_Criteria'!$F$2:$F$111) | H10: =SUMIF('QA_Criteria'!$A$2:$A$111,B10,'QA_Criteria'!$G$2:$G$111) | I10: =G10 | J10: =G10+(100-H10) | K10: =IF(AND(H10=100,Q10=1,P10=TRUE),G10,"") | L10: =IF(R10>0,"QA_FAIL",IF(K10="","QA_INCOMPLETE",IF(K10<70,"QA_FAIL",IF(OR(K10<85,S10>0),"QA_REVISE","QA_PASS")))) | M10: SERP_ONLY | N10: 6 | O10: 6 | P10: TRUE | Q10: 1 | R10: =COUNTIFS('QA_Issues'!$B$2:$B$93,B10,'QA_Issues'!$D$2:$D$93,"CRITICAL") | S10: =COUNTIFS('QA_Issues'!$B$2:$B$93,B10,'QA_Issues'!$D$2:$D$93,"MAJOR") | T10: =COUNTIFS('QA_Issues'!$B$2:$B$93,B10,'QA_Issues'!$D$2:$D$93,"MINOR") | U10: =COUNTIFS('QA_Issues'!$B$2:$B$93,B10,'QA_Issues'!$D$2:$D$93,"LIMITATION") | V10: ISSUE-0075; ISSUE-0076; ISSUE-0077; ISSUE-0078; ISSUE-0079; ISSUE-0080; ISSUE-0081; ISSUE-0082; ISSUE-0083 | W10: evidence_batch_017_169; live_source_comparison; customizer_audit; serp_evidence
A11: 170 | B11: jeminise.com+pamnest-twin-halloween-comforter-set-with-sheets-5-pieces-design-07 | C11: https://jeminise.com/products/pamnest-twin-halloween-comforter-set-with-sheets-5-pieces-design-07 | D11: pamnest-twin-halloween-comforter-set-with-sheets-5-pieces-design-07 | E11: 8879779414215 | F11: r1 | G11: =SUMIF('QA_Criteria'!$A$2:$A$111,B11,'QA_Criteria'!$F$2:$F$111) | H11: =SUMIF('QA_Criteria'!$A$2:$A$111,B11,'QA_Criteria'!$G$2:$G$111) | I11: =G11 | J11: =G11+(100-H11) | K11: =IF(AND(H11=100,Q11=1,P11=TRUE),G11,"") | L11: =IF(R11>0,"QA_FAIL",IF(K11="","QA_INCOMPLETE",IF(K11<70,"QA_FAIL",IF(OR(K11<85,S11>0),"QA_REVISE","QA_PASS")))) | M11: SERP_ONLY | N11: 6 | O11: 6 | P11: TRUE | Q11: 1 | R11: =COUNTIFS('QA_Issues'!$B$2:$B$93,B11,'QA_Issues'!$D$2:$D$93,"CRITICAL") | S11: =COUNTIFS('QA_Issues'!$B$2:$B$93,B11,'QA_Issues'!$D$2:$D$93,"MAJOR") | T11: =COUNTIFS('QA_Issues'!$B$2:$B$93,B11,'QA_Issues'!$D$2:$D$93,"MINOR") | U11: =COUNTIFS('QA_Issues'!$B$2:$B$93,B11,'QA_Issues'!$D$2:$D$93,"LIMITATION") | V11: ISSUE-0084; ISSUE-0085; ISSUE-0086; ISSUE-0087; ISSUE-0088; ISSUE-0089; ISSUE-0090; ISSUE-0091; ISSUE-0092 | W11: evidence_batch_017_170; live_source_comparison; customizer_audit; serp_evidence

Sheet QA_Criteria
A1: product_key | B1: criterion_id | C1: weight | D1: assessment | E1: rating | F1: earned_points | G1: assessed_weight | H1: reason | I1: evidence_refs | J1: issue_refs
A2: jeminise.com+norse-mythology-raven-within-celtic-knot-frame-quilt-906ee24d68-906ee24d68 | B2: P1 | C2: 15 | D2: FULL | E2: =IF(B2="I1",AVERAGEIF('QA_Images'!$A$2:$A$63,A2,'QA_Images'!$T$2:$T$63)/100,IF(D2="FULL",1,IF(D2="PARTIAL",0.5,IF(D2="FAIL",0,"")))) | F2: =IF(E2="",0,C2*E2) | G2: =IF(B2="I1",20*AVERAGEIF('QA_Images'!$A$2:$A$63,A2,'QA_Images'!$U$2:$U$63)/100,IF(D2="NOT_CHECKED",0,C2)) | H2: Product identity, handle, product ID, URL and canonical match source/live evidence. Product key/handle/product ID/canonical checked against frozen workbook and live product evidence. | I2: evidence_batch_017_161 | J2: ISSUE-0001; ISSUE-0002; ISSUE-0003; ISSUE-0004
A3: jeminise.com+norse-mythology-raven-within-celtic-knot-frame-quilt-906ee24d68-906ee24d68 | B3: P2 | C3: 10 | D3: PARTIAL | E3: =IF(B3="I1",AVERAGEIF('QA_Images'!$A$2:$A$63,A3,'QA_Images'!$T$2:$T$63)/100,IF(D3="FULL",1,IF(D3="PARTIAL",0.5,IF(D3="FAIL",0,"")))) | F3: =IF(E3="",0,C3*E3) | G3: =IF(B3="I1",20*AVERAGEIF('QA_Images'!$A$2:$A$63,A3,'QA_Images'!$U$2:$U$63)/100,IF(D3="NOT_CHECKED",0,C3)) | H3: Source product facts, variants, specifications and personalization claims are evidence-backed. Personalization/specification claims checked against storefront product.js and static customizer config. | I3: evidence_batch_017_161 | J3: ISSUE-0001; ISSUE-0002; ISSUE-0003; ISSUE-0004
A4: jeminise.com+norse-mythology-raven-within-celtic-knot-frame-quilt-906ee24d68-906ee24d68 | B4: K1 | C4: 10 | D4: PARTIAL | E4: =IF(B4="I1",AVERAGEIF('QA_Images'!$A$2:$A$63,A4,'QA_Images'!$T$2:$T$63)/100,IF(D4="FULL",1,IF(D4="PARTIAL",0.5,IF(D4="FAIL",0,"")))) | F4: =IF(E4="",0,C4*E4) | G4: =IF(B4="I1",20*AVERAGEIF('QA_Images'!$A$2:$A$63,A4,'QA_Images'!$U$2:$U$63)/100,IF(D4="NOT_CHECKED",0,C4)) | H4: Primary keyword aligns with product-level US purchase intent. Primary keyword rechecked against US product-level SERP comparables. | I4: evidence_batch_017_161 | J4: ISSUE-0001; ISSUE-0002; ISSUE-0003; ISSUE-0004
A5: jeminise.com+norse-mythology-raven-within-celtic-knot-frame-quilt-906ee24d68-906ee24d68 | B5: K2 | C5: 5 | D5: PARTIAL | E5: =IF(B5="I1",AVERAGEIF('QA_Images'!$A$2:$A$63,A5,'QA_Images'!$T$2:$T$63)/100,IF(D5="FULL",1,IF(D5="PARTIAL",0.5,IF(D5="FAIL",0,"")))) | F5: =IF(E5="",0,C5*E5) | G5: =IF(B5="I1",20*AVERAGEIF('QA_Images'!$A$2:$A$63,A5,'QA_Images'!$U$2:$U$63)/100,IF(D5="NOT_CHECKED",0,C5)) | H5: Intent/cannibalization check distinguishes nearby products. Nearby product cluster has overlap risk, so intent distinction remains only partial. | I5: evidence_batch_017_161 | J5: ISSUE-0001; ISSUE-0002; ISSUE-0003; ISSUE-0004
A6: jeminise.com+norse-mythology-raven-within-celtic-knot-frame-quilt-906ee24d68-906ee24d68 | B6: K3 | C6: 5 | D6: PARTIAL | E6: =IF(B6="I1",AVERAGEIF('QA_Images'!$A$2:$A$63,A6,'QA_Images'!$T$2:$T$63)/100,IF(D6="FULL",1,IF(D6="PARTIAL",0.5,IF(D6="FAIL",0,"")))) | F6: =IF(E6="",0,C6*E6) | G6: =IF(B6="I1",20*AVERAGEIF('QA_Images'!$A$2:$A$63,A6,'QA_Images'!$U$2:$U$63)/100,IF(D6="NOT_CHECKED",0,C6)) | H6: Keyword evidence is supported by SERP comparables without unsupported volume claims. Evidence is public SERP only; no Search Console, keyword volume or customer-search corpus provided. | I6: evidence_batch_017_161 | J6: ISSUE-0001; ISSUE-0002; ISSUE-0003; ISSUE-0004
A7: jeminise.com+norse-mythology-raven-within-celtic-knot-frame-quilt-906ee24d68-906ee24d68 | B7: T1 | C7: 10 | D7: PARTIAL | E7: =IF(B7="I1",AVERAGEIF('QA_Images'!$A$2:$A$63,A7,'QA_Images'!$T$2:$T$63)/100,IF(D7="FULL",1,IF(D7="PARTIAL",0.5,IF(D7="FAIL",0,"")))) | F7: =IF(E7="",0,C7*E7) | G7: =IF(B7="I1",20*AVERAGEIF('QA_Images'!$A$2:$A$63,A7,'QA_Images'!$U$2:$U$63)/100,IF(D7="NOT_CHECKED",0,C7)) | H7: SEO title and H1 are relevant, specific and grounded in visible/source facts. Proposed H1 is blank, so the title/H1 pair cannot be fully verified. | I7: evidence_batch_017_161 | J7: ISSUE-0001; ISSUE-0002; ISSUE-0003; ISSUE-0004
A8: jeminise.com+norse-mythology-raven-within-celtic-knot-frame-quilt-906ee24d68-906ee24d68 | B8: T2 | C8: 5 | D8: PARTIAL | E8: =IF(B8="I1",AVERAGEIF('QA_Images'!$A$2:$A$63,A8,'QA_Images'!$T$2:$T$63)/100,IF(D8="FULL",1,IF(D8="PARTIAL",0.5,IF(D8="FAIL",0,"")))) | F8: =IF(E8="",0,C8*E8) | G8: =IF(B8="I1",20*AVERAGEIF('QA_Images'!$A$2:$A$63,A8,'QA_Images'!$U$2:$U$63)/100,IF(D8="NOT_CHECKED",0,C8)) | H8: Meta description is concise, publish-ready and avoids unsupported claims. Meta description checked for length, specificity and supportable claims. | I8: evidence_batch_017_161 | J8: ISSUE-0001; ISSUE-0002; ISSUE-0003; ISSUE-0004
A9: jeminise.com+norse-mythology-raven-within-celtic-knot-frame-quilt-906ee24d68-906ee24d68 | B9: D1 | C9: 10 | D9: FAIL | E9: =IF(B9="I1",AVERAGEIF('QA_Images'!$A$2:$A$63,A9,'QA_Images'!$T$2:$T$63)/100,IF(D9="FULL",1,IF(D9="PARTIAL",0.5,IF(D9="FAIL",0,"")))) | F9: =IF(E9="",0,C9*E9) | G9: =IF(B9="I1",20*AVERAGEIF('QA_Images'!$A$2:$A$63,A9,'QA_Images'!$U$2:$U$63)/100,IF(D9="NOT_CHECKED",0,C9)) | H9: Description HTML is publish-ready and free of internal draft/QA instructions. Description HTML still contains internal QA/import language. | I9: evidence_batch_017_161 | J9: ISSUE-0001; ISSUE-0002; ISSUE-0003; ISSUE-0004
A10: jeminise.com+norse-mythology-raven-within-celtic-knot-frame-quilt-906ee24d68-906ee24d68 | B10: D2 | C10: 5 | D10: PARTIAL | E10: =IF(B10="I1",AVERAGEIF('QA_Images'!$A$2:$A$63,A10,'QA_Images'!$T$2:$T$63)/100,IF(D10="FULL",1,IF(D10="PARTIAL",0.5,IF(D10="FAIL",0,"")))) | F10: =IF(E10="",0,C10*E10) | G10: =IF(B10="I1",20*AVERAGEIF('QA_Images'!$A$2:$A$63,A10,'QA_Images'!$U$2:$U$63)/100,IF(D10="NOT_CHECKED",0,C10)) | H10: Description content covers verified design, product type, use case and constraints. Description covers motif/product type but remains templated and does not always map every verified constraint. | I10: evidence_batch_017_161 | J10: ISSUE-0001; ISSUE-0002; ISSUE-0003; ISSUE-0004
A11: jeminise.com+norse-mythology-raven-within-celtic-knot-frame-quilt-906ee24d68-906ee24d68 | B11: I1 | C11: 20 | D11: FULL | E11: =IF(B11="I1",AVERAGEIF('QA_Images'!$A$2:$A$63,A11,'QA_Images'!$T$2:$T$63)/100,IF(D11="FULL",1,IF(D11="PARTIAL",0.5,IF(D11="FAIL",0,"")))) | F11: =IF(E11="",0,C11*E11) | G11: =IF(B11="I1",20*AVERAGEIF('QA_Images'!$A$2:$A$63,A11,'QA_Images'!$U$2:$U$63)/100,IF(D11="NOT_CHECKED",0,C11)) | H11: Image coverage, image observations and alt text quality, derived from QA_Images. Derived from average image QA score; see QA_Images. | I11: evidence_batch_017_161 | J11: ISSUE-0001; ISSUE-0002; ISSUE-0003; ISSUE-0004
A12: jeminise.com+norse-mythology-raven-within-celtic-knot-frame-quilt-906ee24d68-906ee24d68 | B12: E1 | C12: 5 | D12: PARTIAL | E12: =IF(B12="I1",AVERAGEIF('QA_Images'!$A$2:$A$63,A12,'QA_Images'!$T$2:$T$63)/100,IF(D12="FULL",1,IF(D12="PARTIAL",0.5,IF(D12="FAIL",0,"")))) | F12: =IF(E12="",0,C12*E12) | G12: =IF(B12="I1",20*AVERAGEIF('QA_Images'!$A$2:$A$63,A12,'QA_Images'!$U$2:$U$63)/100,IF(D12="NOT_CHECKED",0,C12)) | H12: Evidence chain is traceable and limitations are explicitly separated from failures. Evidence chain is traceable, with admin-export limitation explicitly separated. | I12: evidence_batch_017_161 | J12: ISSUE-0001; ISSUE-0002; ISSUE-0003; ISSUE-0004
A13: jeminise.com+norse-mythology-viking-shield-with-crossed-axes-quilt-ca630a284e-ca630a284e | B13: P1 | C13: 15 | D13: FULL | E13: =IF(B13="I1",AVERAGEIF('QA_Images'!$A$2:$A$63,A13,'QA_Images'!$T$2:$T$63)/100,IF(D13="FULL",1,IF(D13="PARTIAL",0.5,IF(D13="FAIL",0,"")))) | F13: =IF(E13="",0,C13*E13) | G13: =IF(B13="I1",20*AVERAGEIF('QA_Images'!$A$2:$A$63,A13,'QA_Images'!$U$2:$U$63)/100,IF(D13="NOT_CHECKED",0,C13)) | H13: Product identity, handle, product ID, URL and canonical match source/live evidence. Product key/handle/product ID/canonical checked against frozen workbook and live product evidence. | I13: evidence_batch_017_162 | J13: ISSUE-0011; ISSUE-0012; ISSUE-0013; ISSUE-0014; ISSUE-0015
... A111: jeminise.com+pamnest-twin-halloween-comforter-set-with-sheets-5-pieces-design-07 | B111: E1 | C111: 5 | D111: PARTIAL | E111: =IF(B111="I1",AVERAGEIF('QA_Images'!$A$2:$A$63,A111,'QA_Images'!$T$2:$T$63)/100,IF(D111="FULL",1,IF(D111="PARTIAL",0.5,IF(D111="FAIL",0,"")))) | F111: =IF(E111="",0,C111*E111) | G111: =IF(B111="I1",20*AVERAGEIF('QA_Images'!$A$2:$A$63,A111,'QA_Images'!$U$2:$U$63)/100,IF(D111="NOT_CHECKED",0,C111)) | H111: Evidence chain is traceable and limitations are explicitly separated from failures. Evidence chain is traceable, with admin-export limitation explicitly separated. | I111: evidence_batch_017_170 | J111: ISSUE-0084; ISSUE-0085; ISSUE-0086; ISSUE-0087

Sheet QA_Images
A1: product_key | B1: qa_image_key | C1: image_url_source | D1: image_url_workbook | E1: media_id | F1: workbook_image_id | G1: variant | H1: image_location | I1: check_method | J1: checked_at | K1: qa_observation | L1: submitted_observation | M1: storefront_alt_observed | N1: alt_action | O1: alt_effective | P1: IM1 | Q1: IM2 | R1: IM3 | S1: IM4 | T1: image_verified_points | U1: image_assessed_weight | V1: image_final_score | W1: image_score_lower_bound | X1: image_score_upper_bound | Y1: issue_refs | Z1: evidence_refs
A2: jeminise.com+norse-mythology-raven-within-celtic-knot-frame-quilt-906ee24d68-906ee24d68 | B2: img_4a32db49ec01b0ad | C2: https://cdn.shopify.com/s/files/1/0792/5098/1063/files/f5df6ea5afdf042e566b7af241d22bd6929357120dcb00f0bc65a8916d20bdd1.jpg?v=1785104402 | D2: https://cdn.shopify.com/s/files/1/0792/5098/1063/files/f5df6ea5afdf042e566b7af241d22bd6929357120dcb00f0bc65a8916d20bdd1.jpg?v=1785104402 | E2: 47540522516679 | F2: 47540522516679 | H2: GALLERY | I2: DIRECT_IMAGE_DOWNLOAD_AND_SOURCE_ROW_REVIEW | J2: 2026-09-07T21:30:37+07:00 | K2: Direct QA opened downloaded image 161_01; source SHA 5F2E3952F9CFEE8BFB3FA02B98D3FE9BA2F05643499C0504FF9BF49991B087D9. Submitted observation reviewed against gallery position. | L2: Main product mockup showing blue Norse raven Celtic knot quilt. | M2: UNKNOWN | N2: SET | O2: Blue Norse Raven Celtic Knot Quilt displayed in a main product mockup | P2: FULL | Q2: FULL | R2: PARTIAL | S2: FULL | T2: =IF(P2="FULL",40,IF(P2="PARTIAL",40/2,0))+IF(Q2="FULL",30,IF(Q2="PARTIAL",30/2,0))+IF(R2="FULL",20,IF(R2="PARTIAL",20/2,0))+IF(S2="FULL",10,IF(S2="PARTIAL",10/2,0)) | U2: =IF(P2="NOT_CHECKED",0,40)+IF(Q2="NOT_CHECKED",0,30)+IF(R2="NOT_CHECKED",0,20)+IF(S2="NOT_CHECKED",0,10) | V2: =IF(U2=100,T2,"") | W2: =T2 | X2: =T2+(100-U2) | Y2: ISSUE-0005 | Z2: D:\Shopify_Workspace\jeminise_seo\seo_runs\jeminise.com\20260906_234129\qa\20260907_212312\images\161_01.jpg; seo_runs\jeminise.com\20260906_234129\evidence\images\161_norse-mythology-raven-within-celtic-knot-frame-quilt-906ee24d68-906ee24d68\image_01_47540522516679.jpg; seo_runs\jeminise.com\20260906_234129\evidence\contact_sheets\161_norse-mythology-raven-within-celtic-knot-frame-quilt-906ee24d68-906ee24d68.jpg
A3: jeminise.com+norse-mythology-raven-within-celtic-knot-frame-quilt-906ee24d68-906ee24d68 | B3: img_05c15f39a6bc4f33 | C3: https://cdn.shopify.com/s/files/1/0792/5098/1063/files/bbce88f2a66fabf46529458b35db7d33399da290b604d17e49b58d179adc7c2a.jpg?v=1785104402 | D3: https://cdn.shopify.com/s/files/1/0792/5098/1063/files/bbce88f2a66fabf46529458b35db7d33399da290b604d17e49b58d179adc7c2a.jpg?v=1785104402 | E3: 47540522549447 | F3: 47540522549447 | H3: GALLERY | I3: DIRECT_IMAGE_DOWNLOAD_AND_SOURCE_ROW_REVIEW | J3: 2026-09-07T21:30:37+07:00 | K3: Direct QA opened downloaded image 161_02; source SHA 45402A7B1C4420CCA68969194E972CDDBDF716BE753B81A373687CDEF4DE4F8F. Submitted observation reviewed against gallery position. | L3: Secondary flat, close-up or bedroom mockup showing blue Norse raven Celtic knot quilt. | M3: UNKNOWN | N3: SET | O3: Close-up of the print on Blue Norse Raven Celtic Knot Quilt | P3: FULL | Q3: FULL | R3: FULL | S3: FULL | T3: =IF(P3="FULL",40,IF(P3="PARTIAL",40/2,0))+IF(Q3="FULL",30,IF(Q3="PARTIAL",30/2,0))+IF(R3="FULL",20,IF(R3="PARTIAL",20/2,0))+IF(S3="FULL",10,IF(S3="PARTIAL",10/2,0)) | U3: =IF(P3="NOT_CHECKED",0,40)+IF(Q3="NOT_CHECKED",0,30)+IF(R3="NOT_CHECKED",0,20)+IF(S3="NOT_CHECKED",0,10) | V3: =IF(U3=100,T3,"") | W3: =T3 | X3: =T3+(100-U3) | Z3: D:\Shopify_Workspace\jeminise_seo\seo_runs\jeminise.com\20260906_234129\qa\20260907_212312\images\161_02.jpg; seo_runs\jeminise.com\20260906_234129\evidence\images\161_norse-mythology-raven-within-celtic-knot-frame-quilt-906ee24d68-906ee24d68\image_02_47540522549447.jpg; seo_runs\jeminise.com\20260906_234129\evidence\contact_sheets\161_norse-mythology-raven-within-celtic-knot-frame-quilt-906ee24d68-906ee24d68.jpg
A4: jeminise.com+norse-mythology-raven-within-celtic-knot-frame-quilt-906ee24d68-906ee24d68 | B4: img_6bf8da2d85e8de01 | C4: https://cdn.shopify.com/s/files/1/0792/5098/1063/files/27dd51b6fe9a32b87ac804b19987fb134fc4570b327d844efdae0740d4303aab.jpg?v=1785104402 | D4: https://cdn.shopify.com/s/files/1/0792/5098/1063/files/27dd51b6fe9a32b87ac804b19987fb134fc4570b327d844efdae0740d4303aab.jpg?v=1785104402 | E4: 47540522582215 | F4: 47540522582215 | H4: GALLERY | I4: DIRECT_IMAGE_DOWNLOAD_AND_SOURCE_ROW_REVIEW | J4: 2026-09-07T21:30:37+07:00 | K4: Direct QA opened downloaded image 161_03; source SHA 50AFEA49D61BC29A92A4DF63F7CA1E547341FA8C7CF4D1CEB1CB69E9AA916042. Submitted observation reviewed against gallery position. | L4: Bedding type, feature, lifestyle or material image for blue Norse raven Celtic knot quilt. | M4: UNKNOWN | N4: SET | O4: Lifestyle bedroom mockup of Blue Norse Raven Celtic Knot Quilt | P4: FULL | Q4: PARTIAL | R4: FULL | S4: FULL | T4: =IF(P4="FULL",40,IF(P4="PARTIAL",40/2,0))+IF(Q4="FULL",30,IF(Q4="PARTIAL",30/2,0))+IF(R4="FULL",20,IF(R4="PARTIAL",20/2,0))+IF(S4="FULL",10,IF(S4="PARTIAL",10/2,0)) | U4: =IF(P4="NOT_CHECKED",0,40)+IF(Q4="NOT_CHECKED",0,30)+IF(R4="NOT_CHECKED",0,20)+IF(S4="NOT_CHECKED",0,10) | V4: =IF(U4=100,T4,"") | W4: =T4 | X4: =T4+(100-U4) | Y4: ISSUE-0006 | Z4: D:\Shopify_Workspace\jeminise_seo\seo_runs\jeminise.com\20260906_234129\qa\20260907_212312\images\161_03.jpg; seo_runs\jeminise.com\20260906_234129\evidence\images\161_norse-mythology-raven-within-celtic-knot-frame-quilt-906ee24d68-906ee24d68\image_03_47540522582215.jpg; seo_runs\jeminise.com\20260906_234129\evidence\contact_sheets\161_norse-mythology-raven-within-celtic-knot-frame-quilt-906ee24d68-906ee24d68.jpg
A5: jeminise.com+norse-mythology-raven-within-celtic-knot-frame-quilt-906ee24d68-906ee24d68 | B5: img_0b8db06ccd8ee1f6 | C5: https://cdn.shopify.com/s/files/1/0792/5098/1063/files/c63b8bede4de84261bd2bc195d98188fb288eba460ea7d07b0ef625dba18ed45.jpg?v=1785104402 | D5: https://cdn.shopify.com/s/files/1/0792/5098/1063/files/c63b8bede4de84261bd2bc195d98188fb288eba460ea7d07b0ef625dba18ed45.jpg?v=1785104402 | E5: 47540522614983 | F5: 47540522614983 | H5: GALLERY | I5: DIRECT_IMAGE_DOWNLOAD_AND_SOURCE_ROW_REVIEW | J5: 2026-09-07T21:30:37+07:00 | K5: Direct QA opened downloaded image 161_04; source SHA 1EBFE3B8D9025B494ACFD0CA4022F40FA6A0C8FA2F48B98C0ADA0B86EB2641DE. Submitted observation reviewed against gallery position. | L5: Detail, feature panel or lifestyle image connected to blue Norse raven Celtic knot quilt. | M5: UNKNOWN | N5: SET | O5: Front bed view of Blue Norse Raven Celtic Knot Quilt | P5: FULL | Q5: PARTIAL | R5: FULL | S5: FULL | T5: =IF(P5="FULL",40,IF(P5="PARTIAL",40/2,0))+IF(Q5="FULL",30,IF(Q5="PARTIAL",30/2,0))+IF(R5="FULL",20,IF(R5="PARTIAL",20/2,0))+IF(S5="FULL",10,IF(S5="PARTIAL",10/2,0)) | U5: =IF(P5="NOT_CHECKED",0,40)+IF(Q5="NOT_CHECKED",0,30)+IF(R5="NOT_CHECKED",0,20)+IF(S5="NOT_CHECKED",0,10) | V5: =IF(U5=100,T5,"") | W5: =T5 | X5: =T5+(100-U5) | Y5: ISSUE-0007 | Z5: D:\Shopify_Workspace\jeminise_seo\seo_runs\jeminise.com\20260906_234129\qa\20260907_212312\images\161_04.jpg; seo_runs\jeminise.com\20260906_234129\evidence\images\161_norse-mythology-raven-within-celtic-knot-frame-quilt-906ee24d68-906ee24d68\image_04_47540522614983.jpg; seo_runs\jeminise.com\20260906_234129\evidence\contact_sheets\161_norse-mythology-raven-within-celtic-knot-frame-quilt-906ee24d68-906ee24d68.jpg
A6: jeminise.com+norse-mythology-raven-within-celtic-knot-frame-quilt-906ee24d68-906ee24d68 | B6: img_bec905db5c55388b | C6: https://cdn.shopify.com/s/files/1/0792/5098/1063/files/bbe527fc7f68c31328261559b7b766ec905010bb91f9515c6d557dd1b085f14b.jpg?v=1785104402 | D6: https://cdn.shopify.com/s/files/1/0792/5098/1063/files/bbe527fc7f68c31328261559b7b766ec905010bb91f9515c6d557dd1b085f14b.jpg?v=1785104402 | E6: 47540522647751 | F6: 47540522647751 | H6: GALLERY | I6: DIRECT_IMAGE_DOWNLOAD_AND_SOURCE_ROW_REVIEW | J6: 2026-09-07T21:30:37+07:00 | K6: Direct QA opened downloaded image 161_05; source SHA 8B8AB476B72DF5DECE8B47FF68FE7F7C254464FAC6C53140000397E0CCAF3C53. Submitted observation reviewed against gallery position. | L6: Additional mockup, care or size information for blue Norse raven Celtic knot quilt. | M6: UNKNOWN | N6: SET | O6: Fitted sheet or size feature image for Blue Norse Raven Celtic Knot Quilt | P6: FULL | Q6: FULL | R6: FULL | S6: FULL | T6: =IF(P6="FULL",40,IF(P6="PARTIAL",40/2,0))+IF(Q6="FULL",30,IF(Q6="PARTIAL",30/2,0))+IF(R6="FULL",20,IF(R6="PARTIAL",20/2,0))+IF(S6="FULL",10,IF(S6="PARTIAL",10/2,0)) | U6: =IF(P6="NOT_CHECKED",0,40)+IF(Q6="NOT_CHECKED",0,30)+IF(R6="NOT_CHECKED",0,20)+IF(S6="NOT_CHECKED",0,10) | V6: =IF(U6=100,T6,"") | W6: =T6 | X6: =T6+(100-U6) | Z6: D:\Shopify_Workspace\jeminise_seo\seo_runs\jeminise.com\20260906_234129\qa\20260907_212312\images\161_05.jpg; seo_runs\jeminise.com\20260906_234129\evidence\images\161_norse-mythology-raven-within-celtic-knot-frame-quilt-906ee24d68-906ee24d68\image_05_47540522647751.jpg; seo_runs\jeminise.com\20260906_234129\evidence\contact_sheets\161_norse-mythology-raven-within-celtic-knot-frame-quilt-906ee24d68-906ee24d68.jpg
A7: jeminise.com+norse-mythology-raven-within-celtic-knot-frame-quilt-906ee24d68-906ee24d68 | B7: img_4a8ac5f2d547d70c | C7: https://cdn.shopify.com/s/files/1/0792/5098/1063/files/5cc9f4f96bdb0280d8a3c4b98775690e61d79ad5625e9f20a101536548fe3b0e.jpg?v=1785104402 | D7: https://cdn.shopify.com/s/files/1/0792/5098/1063/files/5cc9f4f96bdb0280d8a3c4b98775690e61d79ad5625e9f20a101536548fe3b0e.jpg?v=1785104402 | E7: 47540522680519 | F7: 47540522680519 | H7: GALLERY | I7: DIRECT_IMAGE_DOWNLOAD_AND_SOURCE_ROW_REVIEW | J7: 2026-09-07T21:30:37+07:00 | K7: Direct QA opened downloaded image 161_06; source SHA 6A3B322F6DA7163F9772280430DDE0229605BBF4DC984034ECA74EE7B134A75A. Submitted observation reviewed against gallery position. | L7: Easy-care, size guide or product feature image for blue Norse raven Celtic knot quilt. | M7: UNKNOWN | N7: SET | O7: Set contents and size chart image for Blue Norse Raven Celtic Knot Quilt | P7: FULL | Q7: PARTIAL | R7: PARTIAL | S7: FULL | T7: =IF(P7="FULL",40,IF(P7="PARTIAL",40/2,0))+IF(Q7="FULL",30,IF(Q7="PARTIAL",30/2,0))+IF(R7="FULL",20,IF(R7="PARTIAL",20/2,0))+IF(S7="FULL",10,IF(S7="PARTIAL",10/2,0)) | U7: =IF(P7="NOT_CHECKED",0,40)+IF(Q7="NOT_CHECKED",0,30)+IF(R7="NOT_CHECKED",0,20)+IF(S7="NOT_CHECKED",0,10) | V7: =IF(U7=100,T7,"") | W7: =T7 | X7: =T7+(100-U7) | Y7: ISSUE-0008; ISSUE-0009 | Z7: D:\Shopify_Workspace\jeminise_seo\seo_runs\jeminise.com\20260906_234129\qa\20260907_212312\images\161_06.jpg; seo_runs\jeminise.com\20260906_234129\evidence\images\161_norse-mythology-raven-within-celtic-knot-frame-quilt-906ee24d68-906ee24d68\image_06_47540522680519.jpg; seo_runs\jeminise.com\20260906_234129\evidence\contact_sheets\161_norse-mythology-raven-within-celtic-knot-frame-quilt-906ee24d68-906ee24d68.jpg
A8: jeminise.com+norse-mythology-raven-within-celtic-knot-frame-quilt-906ee24d68-906ee24d68 | B8: img_6ca30d95daecc374 | C8: https://cdn.shopify.com/s/files/1/0792/5098/1063/files/31facc27e0d676d03e5239357f2912111f3e0640688af1ac241589e99b6705fb.jpg?v=1785104402 | D8: https://cdn.shopify.com/s/files/1/0792/5098/1063/files/31facc27e0d676d03e5239357f2912111f3e0640688af1ac241589e99b6705fb.jpg?v=1785104402 | E8: 47540522713287 | F8: 47540522713287 | H8: GALLERY | I8: DIRECT_IMAGE_DOWNLOAD_AND_SOURCE_ROW_REVIEW | J8: 2026-09-07T21:30:37+07:00 | K8: Direct QA opened downloaded image 161_07; source SHA ECD93B622C766ABF2C6D708D77408DEDEB63C129220B99F56A5244F09EC16214. Submitted observation reviewed against gallery position. | L8: Additional lifestyle, feature or product detail image showing blue Norse raven Celtic knot quilt. | M8: UNKNOWN | N8: SET | O8: Additional product mockup of Blue Norse Raven Celtic Knot Quilt | P8: FULL | Q8: PARTIAL | R8: FULL | S8: FULL | T8: =IF(P8="FULL",40,IF(P8="PARTIAL",40/2,0))+IF(Q8="FULL",30,IF(Q8="PARTIAL",30/2,0))+IF(R8="FULL",20,IF(R8="PARTIAL",20/2,0))+IF(S8="FULL",10,IF(S8="PARTIAL",10/2,0)) | U8: =IF(P8="NOT_CHECKED",0,40)+IF(Q8="NOT_CHECKED",0,30)+IF(R8="NOT_CHECKED",0,20)+IF(S8="NOT_CHECKED",0,10) | V8: =IF(U8=100,T8,"") | W8: =T8 | X8: =T8+(100-U8) | Y8: ISSUE-0010 | Z8: D:\Shopify_Workspace\jeminise_seo\seo_runs\jeminise.com\20260906_234129\qa\20260907_212312\images\161_07.jpg; seo_runs\jeminise.com\20260906_234129\evidence\images\161_norse-mythology-raven-within-celtic-knot-frame-quilt-906ee24d68-906ee24d68\image_07_47540522713287.jpg; seo_runs\jeminise.com\20260906_234129\evidence\contact_sheets\161_norse-mythology-raven-within-celtic-knot-frame-quilt-906ee24d68-906ee24d68.jpg
A9: jeminise.com+norse-mythology-viking-shield-with-crossed-axes-quilt-ca630a284e-ca630a284e | B9: img_42492548a1a20fbe | C9: https://cdn.shopify.com/s/files/1/0792/5098/1063/files/a0bb7b2e86bb5a07b6f85d9046b813c1954eadf01e22807354afd66a9ebfdea6.jpg?v=1785104553 | D9: https://cdn.shopify.com/s/files/1/0792/5098/1063/files/a0bb7b2e86bb5a07b6f85d9046b813c1954eadf01e22807354afd66a9ebfdea6.jpg?v=1785104553 | E9: 47540537688263 | F9: 47540537688263 | H9: GALLERY | I9: DIRECT_IMAGE_DOWNLOAD_AND_SOURCE_ROW_REVIEW | J9: 2026-09-07T21:30:37+07:00 | K9: Direct QA opened downloaded image 162_01; source SHA 5010AD7F41130DFEFF8A19435EE269E7B39D6F6B4778A6627DD6F02631CA1448. Submitted observation reviewed against gallery position. | L9: Main product mockup showing Valhalla Viking shield crossed axes quilt. | M9: UNKNOWN | N9: SET | O9: Valhalla Viking Shield Crossed Axes Quilt displayed in a main product mockup | P9: FULL | Q9: FULL | R9: PARTIAL | S9: FULL | T9: =IF(P9="FULL",40,IF(P9="PARTIAL",40/2,0))+IF(Q9="FULL",30,IF(Q9="PARTIAL",30/2,0))+IF(R9="FULL",20,IF(R9="PARTIAL",20/2,0))+IF(S9="FULL",10,IF(S9="PARTIAL",10/2,0)) | U9: =IF(P9="NOT_CHECKED",0,40)+IF(Q9="NOT_CHECKED",0,30)+IF(R9="NOT_CHECKED",0,20)+IF(S9="NOT_CHECKED",0,10) | V9: =IF(U9=100,T9,"") | W9: =T9 | X9: =T9+(100-U9) | Y9: ISSUE-0016 | Z9: D:\Shopify_Workspace\jeminise_seo\seo_runs\jeminise.com\20260906_234129\qa\20260907_212312\images\162_01.jpg; seo_runs\jeminise.com\20260906_234129\evidence\images\162_norse-mythology-viking-shield-with-crossed-axes-quilt-ca630a284e-ca630a284e\image_01_47540537688263.jpg; seo_runs\jeminise.com\20260906_234129\evidence\contact_sheets\162_norse-mythology-viking-shield-with-crossed-axes-quilt-ca630a284e-ca630a284e.jpg
A10: jeminise.com+norse-mythology-viking-shield-with-crossed-axes-quilt-ca630a284e-ca630a284e | B10: img_95da18ab7d222f8a | C10: https://cdn.shopify.com/s/files/1/0792/5098/1063/files/cdc35c826f340b6635063d4154a0b5dfe33f71c7ea05f07fdfc6546f09c22e28.jpg?v=1785104553 | D10: https://cdn.shopify.com/s/files/1/0792/5098/1063/files/cdc35c826f340b6635063d4154a0b5dfe33f71c7ea05f07fdfc6546f09c22e28.jpg?v=1785104553 | E10: 47540537721031 | F10: 47540537721031 | H10: GALLERY | I10: DIRECT_IMAGE_DOWNLOAD_AND_SOURCE_ROW_REVIEW | J10: 2026-09-07T21:30:37+07:00 | K10: Direct QA opened downloaded image 162_02; source SHA B780F1C2A1A631706AC39C588D420C8721F546FD3FC03AB4A8CDE4017456E7C6. Submitted observation reviewed against gallery position. | L10: Secondary flat, close-up or bedroom mockup showing Valhalla Viking shield crossed axes quilt. | M10: UNKNOWN | N10: SET | O10: Close-up of the print on Valhalla Viking Shield Crossed Axes Quilt | P10: FULL | Q10: FULL | R10: FULL | S10: FULL | T10: =IF(P10="FULL",40,IF(P10="PARTIAL",40/2,0))+IF(Q10="FULL",30,IF(Q10="PARTIAL",30/2,0))+IF(R10="FULL",20,IF(R10="PARTIAL",20/2,0))+IF(S10="FULL",10,IF(S10="PARTIAL",10/2,0)) | U10: =IF(P10="NOT_CHECKED",0,40)+IF(Q10="NOT_CHECKED",0,30)+IF(R10="NOT_CHECKED",0,20)+IF(S10="NOT_CHECKED",0,10) | V10: =IF(U10=100,T10,"") | W10: =T10 | X10: =T10+(100-U10) | Z10: D:\Shopify_Workspace\jeminise_seo\seo_runs\jeminise.com\20260906_234129\qa\20260907_212312\images\162_02.jpg; seo_runs\jeminise.com\20260906_234129\evidence\images\162_norse-mythology-viking-shield-with-crossed-axes-quilt-ca630a284e-ca630a284e\image_02_47540537721031.jpg; seo_runs\jeminise.com\20260906_234129\evidence\contact_sheets\162_norse-mythology-viking-shield-with-crossed-axes-quilt-ca630a284e-ca630a284e.jpg
A11: jeminise.com+norse-mythology-viking-shield-with-crossed-axes-quilt-ca630a284e-ca630a284e | B11: img_c06b4b0b74770f0a | C11: https://cdn.shopify.com/s/files/1/0792/5098/1063/files/7127a02e884cad7c5184ce1b2946ac662960d39acad6edb3b8a21f844cc7fb83.jpg?v=1785104553 | D11: https://cdn.shopify.com/s/files/1/0792/5098/1063/files/7127a02e884cad7c5184ce1b2946ac662960d39acad6edb3b8a21f844cc7fb83.jpg?v=1785104553 | E11: 47540537753799 | F11: 47540537753799 | H11: GALLERY | I11: DIRECT_IMAGE_DOWNLOAD_AND_SOURCE_ROW_REVIEW | J11: 2026-09-07T21:30:37+07:00 | K11: Direct QA opened downloaded image 162_03; source SHA 41AFB4C92D4CF29D2AD3187CEC72EC16F2171CC7F58A62794E269C4CAE36A378. Submitted observation reviewed against gallery position. | L11: Bedding type, feature, lifestyle or material image for Valhalla Viking shield crossed axes quilt. | M11: UNKNOWN | N11: SET | O11: Lifestyle bedroom mockup of Valhalla Viking Shield Crossed Axes Quilt | P11: FULL | Q11: PARTIAL | R11: FULL | S11: FULL | T11: =IF(P11="FULL",40,IF(P11="PARTIAL",40/2,0))+IF(Q11="FULL",30,IF(Q11="PARTIAL",30/2,0))+IF(R11="FULL",20,IF(R11="PARTIAL",20/2,0))+IF(S11="FULL",10,IF(S11="PARTIAL",10/2,0)) | U11: =IF(P11="NOT_CHECKED",0,40)+IF(Q11="NOT_CHECKED",0,30)+IF(R11="NOT_CHECKED",0,20)+IF(S11="NOT_CHECKED",0,10) | V11: =IF(U11=100,T11,"") | W11: =T11 | X11: =T11+(100-U11) | Y11: ISSUE-0017 | Z11: D:\Shopify_Workspace\jeminise_seo\seo_runs\jeminise.com\20260906_234129\qa\20260907_212312\images\162_03.jpg; seo_runs\jeminise.com\20260906_234129\evidence\images\162_norse-mythology-viking-shield-with-crossed-axes-quilt-ca630a284e-ca630a284e\image_03_47540537753799.jpg; seo_runs\jeminise.com\20260906_234129\evidence\contact_sheets\162_norse-mythology-viking-shield-with-crossed-axes-quilt-ca630a284e-ca630a284e.jpg
A12: jeminise.com+norse-mythology-viking-shield-with-crossed-axes-quilt-ca630a284e-ca630a284e | B12: img_54624a6c9dde416f | C12: https://cdn.shopify.com/s/files/1/0792/5098/1063/files/e1bca6ad0b85bcfa2b85d2a0322d79680fde7448a15adec1757a81eb07c4bf6f.jpg?v=1785104553 | D12: https://cdn.shopify.com/s/files/1/0792/5098/1063/files/e1bca6ad0b85bcfa2b85d2a0322d79680fde7448a15adec1757a81eb07c4bf6f.jpg?v=1785104553 | E12: 47540537786567 | F12: 47540537786567 | H12: GALLERY | I12: DIRECT_IMAGE_DOWNLOAD_AND_SOURCE_ROW_REVIEW | J12: 2026-09-07T21:30:37+07:00 | K12: Direct QA opened downloaded image 162_04; source SHA A41A44134043C9136539F8E607535E3D11B3ACB18100BB96CEC2DA445F2ABD0F. Submitted observation reviewed against gallery position. | L12: Detail, feature panel or lifestyle image connected to Valhalla Viking shield crossed axes quilt. | M12: UNKNOWN | N12: SET | O12: Front bed view of Valhalla Viking Shield Crossed Axes Quilt | P12: FULL | Q12: PARTIAL | R12: FULL | S12: FULL | T12: =IF(P12="FULL",40,IF(P12="PARTIAL",40/2,0))+IF(Q12="FULL",30,IF(Q12="PARTIAL",30/2,0))+IF(R12="FULL",20,IF(R12="PARTIAL",20/2,0))+IF(S12="FULL",10,IF(S12="PARTIAL",10/2,0)) | U12: =IF(P12="NOT_CHECKED",0,40)+IF(Q12="NOT_CHECKED",0,30)+IF(R12="NOT_CHECKED",0,20)+IF(S12="NOT_CHECKED",0,10) | V12: =IF(U12=100,T12,"") | W12: =T12 | X12: =T12+(100-U12) | Y12: ISSUE-0018 | Z12: D:\Shopify_Workspace\jeminise_seo\seo_runs\jeminise.com\20260906_234129\qa\20260907_212312\images\162_04.jpg; seo_runs\jeminise.com\20260906_234129\evidence\images\162_norse-mythology-viking-shield-with-crossed-axes-quilt-ca630a284e-ca630a284e\image_04_47540537786567.jpg; seo_runs\jeminise.com\20260906_234129\evidence\contact_sheets\162_norse-mythology-viking-shield-with-crossed-axes-quilt-ca630a284e-ca630a284e.jpg
A13: jeminise.com+norse-mythology-viking-shield-with-crossed-axes-quilt-ca630a284e-ca630a284e | B13: img_342f31e7d8496cf1 | C13: https://cdn.shopify.com/s/files/1/0792/5098/1063/files/77fb3f8c371cf27dd16588f3cf56fb24c12deaa2922c16412de893b0e53890dd.jpg?v=1785104553 | D13: https://cdn.shopify.com/s/files/1/0792/5098/1063/files/77fb3f8c371cf27dd16588f3cf56fb24c12deaa2922c16412de893b0e53890dd.jpg?v=1785104553 | E13: 47540537819335 | F13: 47540537819335 | H13: GALLERY | I13: DIRECT_IMAGE_DOWNLOAD_AND_SOURCE_ROW_REVIEW | J13: 2026-09-07T21:30:37+07:00 | K13: Direct QA opened downloaded image 162_05; source SHA 022469EE5C53116CFE68E563776876B274B93C35FCEE1527E5772890999A92A5. Submitted observation reviewed against gallery position. | L13: Additional mockup, care or size information for Valhalla Viking shield crossed axes quilt. | M13: UNKNOWN | N13: SET | O13: Fitted sheet or size feature image for Valhalla Viking Shield Crossed Axes Quilt | P13: FULL | Q13: FULL | R13: FULL | S13: FULL | T13: =IF(P13="FULL",40,IF(P13="PARTIAL",40/2,0))+IF(Q13="FULL",30,IF(Q13="PARTIAL",30/2,0))+IF(R13="FULL",20,IF(R13="PARTIAL",20/2,0))+IF(S13="FULL",10,IF(S13="PARTIAL",10/2,0)) | U13: =IF(P13="NOT_CHECKED",0,40)+IF(Q13="NOT_CHECKED",0,30)+IF(R13="NOT_CHECKED",0,20)+IF(S13="NOT_CHECKED",0,10) | V13: =IF(U13=100,T13,"") | W13: =T13 | X13: =T13+(100-U13) | Z13: D:\Shopify_Workspace\jeminise_seo\seo_runs\jeminise.com\20260906_234129\qa\20260907_212312\images\162_05.jpg; seo_runs\jeminise.com\20260906_234129\evidence\images\162_norse-mythology-viking-shield-with-crossed-axes-quilt-ca630a284e-ca630a284e\image_05_47540537819335.jpg; seo_runs\jeminise.com\20260906_234129\evidence\contact_sheets\162_norse-mythology-viking-shield-with-crossed-axes-quilt-ca630a284e-ca630a284e.jpg
A14: jeminise.com+norse-mythology-viking-shield-with-crossed-axes-quilt-ca630a284e-ca630a284e | B14: img_038029ec09923701 | C14: https://cdn.shopify.com/s/files/1/0792/5098/1063/files/ca05f793ad1004a8bcf1b14bc5f968c4664bf701819e6903e275f14d034862a6.jpg?v=1785104553 | D14: https://cdn.shopify.com/s/files/1/0792/5098/1063/files/ca05f793ad1004a8bcf1b14bc5f968c4664bf701819e6903e275f14d034862a6.jpg?v=1785104553 | E14: 47540537852103 | F14: 47540537852103 | H14: GALLERY | I14: DIRECT_IMAGE_DOWNLOAD_AND_SOURCE_ROW_REVIEW | J14: 2026-09-07T21:30:37+07:00 | K14: Direct QA opened downloaded image 162_06; source SHA 84F9B1437ED7CF29C5BD3E8670F1DC69484C8566CD13FA309647552B8E571C6F. Submitted observation reviewed against gallery position. | L14: Easy-care, size guide or product feature image for Valhalla Viking shield crossed axes quilt. | M14: UNKNOWN | N14: SET | O14: Set contents and size chart image for Valhalla Viking Shield Crossed Axes Quilt | P14: FULL | Q14: PARTIAL | R14: PARTIAL | S14: FULL | T14: =IF(P14="FULL",40,IF(P14="PARTIAL",40/2,0))+IF(Q14="FULL",30,IF(Q14="PARTIAL",30/2,0))+IF(R14="FULL",20,IF(R14="PARTIAL",20/2,0))+IF(S14="FULL",10,IF(S14="PARTIAL",10/2,0)) | U14: =IF(P14="NOT_CHECKED",0,40)+IF(Q14="NOT_CHECKED",0,30)+IF(R14="NOT_CHECKED",0,20)+IF(S14="NOT_CHECKED",0,10) | V14: =IF(U14=100,T14,"") | W14: =T14 | X14: =T14+(100-U14) | Y14: ISSUE-0019; ISSUE-0020 | Z14: D:\Shopify_Workspace\jeminise_seo\seo_runs\jeminise.com\20260906_234129\qa\20260907_212312\images\162_06.jpg; seo_runs\jeminise.com\20260906_234129\evidence\images\162_norse-mythology-viking-shield-with-crossed-axes-quilt-ca630a284e-ca630a284e\image_06_47540537852103.jpg; seo_runs\jeminise.com\20260906_234129\evidence\contact_sheets\162_norse-mythology-viking-shield-with-crossed-axes-quilt-ca630a284e-ca630a284e.jpg
A15: jeminise.com+norse-mythology-viking-shield-with-crossed-axes-quilt-ca630a284e-ca630a284e | B15: img_02da08e65517a2bf | C15: https://cdn.shopify.com/s/files/1/0792/5098/1063/files/b002678b1b933df28fb349bc6ff5667b37b28acab3f3e263980071a114b93302.jpg?v=1785104552 | D15: https://cdn.shopify.com/s/files/1/0792/5098/1063/files/b002678b1b933df28fb349bc6ff5667b37b28acab3f3e263980071a114b93302.jpg?v=1785104552 | E15: 47540537884871 | F15: 47540537884871 | H15: GALLERY | I15: DIRECT_IMAGE_DOWNLOAD_AND_SOURCE_ROW_REVIEW | J15: 2026-09-07T21:30:37+07:00 | K15: Direct QA opened downloaded image 162_07; source SHA E00737BD21CBC4629256B07CC5E47B44B21178025F4DFB8775B2F14A88AD5809. Submitted observation reviewed against gallery position. | L15: Additional lifestyle, feature or product detail image showing Valhalla Viking shield crossed axes quilt. | M15: UNKNOWN | N15: SET | O15: Additional product mockup of Valhalla Viking Shield Crossed Axes Quilt | P15: FULL | Q15: PARTIAL | R15: FULL | S15: FULL | T15: =IF(P15="FULL",40,IF(P15="PARTIAL",40/2,0))+IF(Q15="FULL",30,IF(Q15="PARTIAL",30/2,0))+IF(R15="FULL",20,IF(R15="PARTIAL",20/2,0))+IF(S15="FULL",10,IF(S15="PARTIAL",10/2,0)) | U15: =IF(P15="NOT_CHECKED",0,40)+IF(Q15="NOT_CHECKED",0,30)+IF(R15="NOT_CHECKED",0,20)+IF(S15="NOT_CHECKED",0,10) | V15: =IF(U15=100,T15,"") | W15: =T15 | X15: =T15+(100-U15) | Y15: ISSUE-0021 | Z15: D:\Shopify_Workspace\jeminise_seo\seo_runs\jeminise.com\20260906_234129\qa\20260907_212312\images\162_07.jpg; seo_runs\jeminise.com\20260906_234129\evidence\images\162_norse-mythology-viking-shield-with-crossed-axes-quilt-ca630a284e-ca630a284e\image_07_47540537884871.jpg; seo_runs\jeminise.com\20260906_234129\evidence\contact_sheets\162_norse-mythology-viking-shield-with-crossed-axes-quilt-ca630a284e-ca630a284e.jpg
A16: jeminise.com+owl-patchwork-pattern-quilt-set-animals-quilt-set-style-owl-nights | B16: img_c8bf6eea06d88efc | C16: https://cdn.shopify.com/s/files/1/0792/5098/1063/files/b12b5b630d5361e095b70248a7029d44aa83474cedccaae8a99938e5a82aa9e5.jpg?v=1787233687 | D16: https://cdn.shopify.com/s/files/1/0792/5098/1063/files/b12b5b630d5361e095b70248a7029d44aa83474cedccaae8a99938e5a82aa9e5.jpg?v=1787233687 | E16: 47933462872263 | F16: 47933462872263 | H16: GALLERY | I16: DIRECT_IMAGE_DOWNLOAD_AND_SOURCE_ROW_REVIEW | J16: 2026-09-07T21:30:37+07:00 | K16: Direct QA opened downloaded image 163_01; source SHA 7138DFE66AFC3B8B7EEB314B221FDE7A551A1AB49A73821AC810E671B220EBB8. Submitted observation reviewed against gallery position. | L16: Main product mockup showing blue gold owl night patchwork quilt. | M16: UNKNOWN | N16: SET | O16: Blue Gold Owl Night Patchwork Quilt displayed in a main product mockup | P16: FULL | Q16: FULL | R16: PARTIAL | S16: FULL | T16: =IF(P16="FULL",40,IF(P16="PARTIAL",40/2,0))+IF(Q16="FULL",30,IF(Q16="PARTIAL",30/2,0))+IF(R16="FULL",20,IF(R16="PARTIAL",20/2,0))+IF(S16="FULL",10,IF(S16="PARTIAL",10/2,0)) | U16: =IF(P16="NOT_CHECKED",0,40)+IF(Q16="NOT_CHECKED",0,30)+IF(R16="NOT_CHECKED",0,20)+IF(S16="NOT_CHECKED",0,10) | V16: =IF(U16=100,T16,"") | W16: =T16 | X16: =T16+(100-U16) | Y16: ISSUE-0026 | Z16: D:\Shopify_Workspace\jeminise_seo\seo_runs\jeminise.com\20260906_234129\qa\20260907_212312\images\163_01.jpg; seo_runs\jeminise.com\20260906_234129\evidence\images\163_owl-patchwork-pattern-quilt-set-animals-quilt-set-style-owl-nights\image_01_47933462872263.jpg; seo_runs\jeminise.com\20260906_234129\evidence\contact_sheets\163_owl-patchwork-pattern-quilt-set-animals-quilt-set-style-owl-nights.jpg
A17: jeminise.com+owl-patchwork-pattern-quilt-set-animals-quilt-set-style-owl-nights | B17: img_2c601500ab0cd47c | C17: https://cdn.shopify.com/s/files/1/0792/5098/1063/files/41113dc58569ae2adc6d3dde435731253d18a0408ae05d7000f8517dee0c01a4.jpg?v=1787233687 | D17: https://cdn.shopify.com/s/files/1/0792/5098/1063/files/41113dc58569ae2adc6d3dde435731253d18a0408ae05d7000f8517dee0c01a4.jpg?v=1787233687 | E17: 47933462905031 | F17: 47933462905031 | H17: GALLERY | I17: DIRECT_IMAGE_DOWNLOAD_AND_SOURCE_ROW_REVIEW | J17: 2026-09-07T21:30:37+07:00 | K17: Direct QA opened downloaded image 163_02; source SHA CD31251B5B8F32DE988065F660F0353DB2C45B880C9F3620314B74DD3928E704. Submitted observation reviewed against gallery position. | L17: Secondary flat, close-up or bedroom mockup showing blue gold owl night patchwork quilt. | M17: UNKNOWN | N17: SET | O17: Close-up of the print on Blue Gold Owl Night Patchwork Quilt | P17: FULL | Q17: FULL | R17: FULL | S17: FULL | T17: =IF(P17="FULL",40,IF(P17="PARTIAL",40/2,0))+IF(Q17="FULL",30,IF(Q17="PARTIAL",30/2,0))+IF(R17="FULL",20,IF(R17="PARTIAL",20/2,0))+IF(S17="FULL",10,IF(S17="PARTIAL",10/2,0)) | U17: =IF(P17="NOT_CHECKED",0,40)+IF(Q17="NOT_CHECKED",0,30)+IF(R17="NOT_CHECKED",0,20)+IF(S17="NOT_CHECKED",0,10) | V17: =IF(U17=100,T17,"") | W17: =T17 | X17: =T17+(100-U17) | Z17: D:\Shopify_Workspace\jeminise_seo\seo_runs\jeminise.com\20260906_234129\qa\20260907_212312\images\163_02.jpg; seo_runs\jeminise.com\20260906_234129\evidence\images\163_owl-patchwork-pattern-quilt-set-animals-quilt-set-style-owl-nights\image_02_47933462905031.jpg; seo_runs\jeminise.com\20260906_234129\evidence\contact_sheets\163_owl-patchwork-pattern-quilt-set-animals-quilt-set-style-owl-nights.jpg
A18: jeminise.com+owl-patchwork-pattern-quilt-set-animals-quilt-set-style-owl-nights | B18: img_5f334955b7afbf46 | C18: https://cdn.shopify.com/s/files/1/0792/5098/1063/files/fd5e9ddd0678c2d4c24c4bd3dfda693b589b9dd151f9f214cdc48d107b8e6592.jpg?v=1787233688 | D18: https://cdn.shopify.com/s/files/1/0792/5098/1063/files/fd5e9ddd0678c2d4c24c4bd3dfda693b589b9dd151f9f214cdc48d107b8e6592.jpg?v=1787233688 | E18: 47933462937799 | F18: 47933462937799 | H18: GALLERY | I18: DIRECT_IMAGE_DOWNLOAD_AND_SOURCE_ROW_REVIEW | J18: 2026-09-07T21:30:37+07:00 | K18: Direct QA opened downloaded image 163_03; source SHA 59594C7BC02BE5BDACB92B4688B2BAB04A4D4CE43BD553322FFEE957262032E7. Submitted observation reviewed against gallery position. | L18: Bedding type, feature, lifestyle or material image for blue gold owl night patchwork quilt. | M18: UNKNOWN | N18: SET | O18: Lifestyle bedroom mockup of Blue Gold Owl Night Patchwork Quilt | P18: FULL | Q18: PARTIAL | R18: FULL | S18: FULL | T18: =IF(P18="FULL",40,IF(P18="PARTIAL",40/2,0))+IF(Q18="FULL",30,IF(Q18="PARTIAL",30/2,0))+IF(R18="FULL",20,IF(R18="PARTIAL",20/2,0))+IF(S18="FULL",10,IF(S18="PARTIAL",10/2,0)) | U18: =IF(P18="NOT_CHECKED",0,40)+IF(Q18="NOT_CHECKED",0,30)+IF(R18="NOT_CHECKED",0,20)+IF(S18="NOT_CHECKED",0,10) | V18: =IF(U18=100,T18,"") | W18: =T18 | X18: =T18+(100-U18) | Y18: ISSUE-0027 | Z18: D:\Shopify_Workspace\jeminise_seo\seo_runs\jeminise.com\20260906_234129\qa\20260907_212312\images\163_03.jpg; seo_runs\jeminise.com\20260906_234129\evidence\images\163_owl-patchwork-pattern-quilt-set-animals-quilt-set-style-owl-nights\image_03_47933462937799.jpg; seo_runs\jeminise.com\20260906_234129\evidence\contact_sheets\163_owl-patchwork-pattern-quilt-set-animals-quilt-set-style-owl-nights.jpg
A19: jeminise.com+owl-patchwork-pattern-quilt-set-animals-quilt-set-style-owl-nights | B19: img_d0eb5575d6e4be02 | C19: https://cdn.shopify.com/s/files/1/0792/5098/1063/files/ce286ca93c0b88510ca875a37e7b75b32cb61e52da352d95c54cd2628b51fbf3.jpg?v=1787233687 | D19: https://cdn.shopify.com/s/files/1/0792/5098/1063/files/ce286ca93c0b88510ca875a37e7b75b32cb61e52da352d95c54cd2628b51fbf3.jpg?v=1787233687 | E19: 47933462970567 | F19: 47933462970567 | H19: GALLERY | I19: DIRECT_IMAGE_DOWNLOAD_AND_SOURCE_ROW_REVIEW | J19: 2026-09-07T21:30:37+07:00 | K19: Direct QA opened downloaded image 163_04; source SHA B615DCC136FA994B3F17AE5605C0231562540AF45A710706609A5E7F0DECB471. Submitted observation reviewed against gallery position. | L19: Detail, feature panel or lifestyle image connected to blue gold owl night patchwork quilt. | M19: UNKNOWN | N19: SET | O19: Front bed view of Blue Gold Owl Night Patchwork Quilt | P19: FULL | Q19: PARTIAL | R19: FULL | S19: FULL | T19: =IF(P19="FULL",40,IF(P19="PARTIAL",40/2,0))+IF(Q19="FULL",30,IF(Q19="PARTIAL",30/2,0))+IF(R19="FULL",20,IF(R19="PARTIAL",20/2,0))+IF(S19="FULL",10,IF(S19="PARTIAL",10/2,0)) | U19: =IF(P19="NOT_CHECKED",0,40)+IF(Q19="NOT_CHECKED",0,30)+IF(R19="NOT_CHECKED",0,20)+IF(S19="NOT_CHECKED",0,10) | V19: =IF(U19=100,T19,"") | W19: =T19 | X19: =T19+(100-U19) | Y19: ISSUE-0028 | Z19: D:\Shopify_Workspace\jeminise_seo\seo_runs\jeminise.com\20260906_234129\qa\20260907_212312\images\163_04.jpg; seo_runs\jeminise.com\20260906_234129\evidence\images\163_owl-patchwork-pattern-quilt-set-animals-quilt-set-style-owl-nights\image_04_47933462970567.jpg; seo_runs\jeminise.com\20260906_234129\evidence\contact_sheets\163_owl-patchwork-pattern-quilt-set-animals-quilt-set-style-owl-nights.jpg
A20: jeminise.com+owl-patchwork-pattern-quilt-set-animals-quilt-set-style-owl-nights | B20: img_48f38ae67adbf28d | C20: https://cdn.shopify.com/s/files/1/0792/5098/1063/files/dac8033ccef3e1ff953003c53d9a62b59fa1e74b2ab002ec0c056348688e6569.jpg?v=1787233688 | D20: https://cdn.shopify.com/s/files/1/0792/5098/1063/files/dac8033ccef3e1ff953003c53d9a62b59fa1e74b2ab002ec0c056348688e6569.jpg?v=1787233688 | E20: 47933463003335 | F20: 47933463003335 | H20: GALLERY | I20: DIRECT_IMAGE_DOWNLOAD_AND_SOURCE_ROW_REVIEW | J20: 2026-09-07T21:30:37+07:00 | K20: Direct QA opened downloaded image 163_05; source SHA D92DACF13E1ACDF944A6CF3810C5348EAC95A8413D0B3131929B0D3FA724E40B. Submitted observation reviewed against gallery position. | L20: Additional mockup, care or size information for blue gold owl night patchwork quilt. | M20: UNKNOWN | N20: SET | O20: Fitted sheet or size feature image for Blue Gold Owl Night Patchwork Quilt | P20: FULL | Q20: FULL | R20: FULL | S20: FULL | T20: =IF(P20="FULL",40,IF(P20="PARTIAL",40/2,0))+IF(Q20="FULL",30,IF(Q20="PARTIAL",30/2,0))+IF(R20="FULL",20,IF(R20="PARTIAL",20/2,0))+IF(S20="FULL",10,IF(S20="PARTIAL",10/2,0)) | U20: =IF(P20="NOT_CHECKED",0,40)+IF(Q20="NOT_CHECKED",0,30)+IF(R20="NOT_CHECKED",0,20)+IF(S20="NOT_CHECKED",0,10) | V20: =IF(U20=100,T20,"") | W20: =T20 | X20: =T20+(100-U20) | Z20: D:\Shopify_Workspace\jeminise_seo\seo_runs\jeminise.com\20260906_234129\qa\20260907_212312\images\163_05.jpg; seo_runs\jeminise.com\20260906_234129\evidence\images\163_owl-patchwork-pattern-quilt-set-animals-quilt-set-style-owl-nights\image_05_47933463003335.jpg; seo_runs\jeminise.com\20260906_234129\evidence\contact_sheets\163_owl-patchwork-pattern-quilt-set-animals-quilt-set-style-owl-nights.jpg
A21: jeminise.com+owl-patchwork-pattern-quilt-set-animals-quilt-set-style-owl-nights | B21: img_62ecd3b014c00446 | C21: https://cdn.shopify.com/s/files/1/0792/5098/1063/files/f095089ab7e2322f9d282beb998fa6a7ca93bd23ffea553618ab9ab073cac9e5.jpg?v=1787233687 | D21: https://cdn.shopify.com/s/files/1/0792/5098/1063/files/f095089ab7e2322f9d282beb998fa6a7ca93bd23ffea553618ab9ab073cac9e5.jpg?v=1787233687 | E21: 47933463036103 | F21: 47933463036103 | H21: GALLERY | I21: DIRECT_IMAGE_DOWNLOAD_AND_SOURCE_ROW_REVIEW | J21: 2026-09-07T21:30:37+07:00 | K21: Direct QA opened downloaded image 163_06; source SHA 710952B45AC0519ADA1619AF79A25569674FB331F17F6CFD1ABA7EE5820193D9. Submitted observation reviewed against gallery position. | L21: Easy-care, size guide or product feature image for blue gold owl night patchwork quilt. | M21: UNKNOWN | N21: SET | O21: Set contents and size chart image for Blue Gold Owl Night Patchwork Quilt | P21: FULL | Q21: PARTIAL | R21: PARTIAL | S21: FULL | T21: =IF(P21="FULL",40,IF(P21="PARTIAL",40/2,0))+IF(Q21="FULL",30,IF(Q21="PARTIAL",30/2,0))+IF(R21="FULL",20,IF(R21="PARTIAL",20/2,0))+IF(S21="FULL",10,IF(S21="PARTIAL",10/2,0)) | U21: =IF(P21="NOT_CHECKED",0,40)+IF(Q21="NOT_CHECKED",0,30)+IF(R21="NOT_CHECKED",0,20)+IF(S21="NOT_CHECKED",0,10) | V21: =IF(U21=100,T21,"") | W21: =T21 | X21: =T21+(100-U21) | Y21: ISSUE-0029; ISSUE-0030 | Z21: D:\Shopify_Workspace\jeminise_seo\seo_runs\jeminise.com\20260906_234129\qa\20260907_212312\images\163_06.jpg; seo_runs\jeminise.com\20260906_234129\evidence\images\163_owl-patchwork-pattern-quilt-set-animals-quilt-set-style-owl-nights\image_06_47933463036103.jpg; seo_runs\jeminise.com\20260906_234129\evidence\contact_sheets\163_owl-patchwork-pattern-quilt-set-animals-quilt-set-style-owl-nights.jpg
